Workbook

Sheet данные строй
A2: Стойка железобетонная | B2: Самонесущий изолированный повод | C2: Монтаж воздушной линии
A3: СВ 95-3 | B3: СИП-3 1х50 | C3: ВЛ-10кВ
A4: СВ 110-5 | B4: СИП-3 1х70 | C4: ВЛ-6кВ
B5: СИП-2 3х50+1х50 | C5: ВЛ-0,4кВ
B6: СИП-2 3х70+1х70
B7: СИП-2 3х95+1х95
B8: СИП-2 3х120+1х120
B9: СИП-2 3х95+1х120
B10: СИП-4 4х16
B11: СИП-3 1х95
B12: СИП-4 2х16
B13: СИП-2 3х35+1х35

Sheet Данные организации
A1: организация | C1: ООО "Энергосистемы" | D1: ООО «Гефест» | E1: ООО "Энком" | G1: ПАО "Россети Московский регион"
A2: реквизиты | C2: ОГРН 1135044003709 ИНН 5044089069 КПП 504401001 | D2: ОГРН 1215000057238 ИНН 5044122213 КПП 504401001 | E2: ОГРН 1077762950055 ИНН 7743668640 КПП 770801001 | G2: ОГРН 1057746555811 ИНН 5036065113 КПП 772501001
A3: адрес | C3: 141508, Московская область, г.о. Солнечногорск, г. Солнечногорск, ул. Промышленная, стр. 5, помещение 179 | D3: 141508, Московская область, г.о. Солнечногорск, г Солнечногорск, ул Промышленная, строение 29А, корпус 1, офис 11 | E3: 107140, г.Москва, ул. Краснопрудная, д. 12/1, стр. 1, помещ. 1/6 | G3: 115114, город Москва, проезд Павелецкий 2-й, дом 3, строение 2
A4: район | G4: Солнечногорский р-н | I4: Химкинский р-н
G5: СРЭС филиала | I5: ХРЭС филиала
A6: директор | C6: И.о.генерального директора | D6: Генеральный директор | E6: Генеральный директор | G6: Начальник СРЭС СЭС филиала | I6: Начальник ХРЭС СЭС филиала
A7: директор ФИО | C7: Чернявская Н.Ю. | D7: Звездов Р.Е. | E7: Дандре Г.А. | G7: Чуев А.Н.
A8: Строй.контроль | B8: Инженер по строительному контролю | C8: Инженер по строительному контролю | D8: Специалист по строительному контролю | E8: Специалист по строительному контролю | G8: Гл. специалист ССК УКС | H8: Гл. специалист ССК УКС | I8: Гл. специалист ССК УКС
A9: Приказ стр.контр. | B9: Приказ № 13-ОТ/25 от 05 мая 2025 (НОСТРОЙ С-50-085497) | C9: Приказ № 18-ОТ/24 от 03 июня 2024 (НОСТРОЙ С-50-188017) | D9: Приказ №01/24-ОТ от 15.01.2024 (НРС № С-61-104369) | E9: НРС № С-77-286715 | G9: Приказ № от 2026г (НРС С-31-330248) | H9: Приказ №53 от 13 марта 2025г. (НРС С-50-77-262451) | I9: Приказ №1904 от 03 июня 2026г (НРС С-50-069023)
A10: ФИО стр.контр. | B10: Русин В.А. | C10: Капитонов Д.А. | D10: Саженова Л.В. | E10: Филлипов А.Ю. | G10: Курчин М.М. | H10: Шатковский А.Н. | I10: Алексанян Г.Р.
A11: Представитель | G11: Мастер СРЭС СЭС филиала | I11: -
A12: ФИО предст. | G12: Курчин М.М. | I12: -
A18: Прораб | C18: Прораб | D18: Мастер электромонтажного участка | E18: Главный инженер
A19: Приказ прораб | C19: Приказ №05-ОТ/24 от 09 января 2024г | D19: Приказ №01/24-ОТ от 15.01.2024 | E19: Приказ № ОТ-25 от 12.01.2024
A20: ФИО прораб | C20: Волков М.Ю. | D20: Красилов К.А. | E20: Горбан Г.К.
A23: сцепленные организация | C23: =CONCATENATE(C2,",",C3) -> ОГРН 1135044003709 ИНН 5044089069 КПП 504401001,141508, Московская область, г.о. Солнечногорск, г. Солнечногорск, ул. Промышленная, стр. 5, помещение 179 | D23: =CONCATENATE(D2,",",D3) -> ОГРН 1215000057238 ИНН 5044122213 КПП 504401001,141508, Московская область, г.о. Солнечногорск, г Солнечногорск, ул Промышленная, строение 29А, корпус 1, офис 11 | G23: =CONCATENATE(G8," ",G1,"-",G10," .",G9) -> Гл. специалист ССК УКС ПАО "Россети Московский регион"-Курчин М.М. .Приказ № от 2026г (НРС С-31-330248) | H23: =CONCATENATE(H8," ",G1,"-",H10,".",H9) -> Гл. специалист ССК УКС ПАО "Россети Московский регион"-Шатковский А.Н..Приказ №53 от 13 марта 2025г. (НРС С-50-77-262451) | I23: =CONCATENATE(I8," ",G1,"-",I10," .",I9) -> Гл. специалист ССК УКС ПАО "Россети Московский регион"-Алексанян Г.Р. .Приказ №1904 от 03 июня 2026г (НРС С-50-069023)
A24: сцепленные организация | C24: =CONCATENATE(C1,",",C2,",",C3) -> ООО "Энергосистемы",ОГРН 1135044003709 ИНН 5044089069 КПП 504401001,141508, Московская область, г.о. Солнечногорск, г. Солнечногорск, ул. Промышленная, стр. 5, помещение 179 | D24: =CONCATENATE(D1,",",D2,",",D3) -> ООО «Гефест»,ОГРН 1215000057238 ИНН 5044122213 КПП 504401001,141508, Московская область, г.о. Солнечногорск, г Солнечногорск, ул Промышленная, строение 29А, корпус 1, офис 11 | G24: =CONCATENATE(G8," ",G1,"-",G10) -> Гл. специалист ССК УКС ПАО "Россети Московский регион"-Курчин М.М. | H24: =CONCATENATE(H8," ",G1,"-",H10) -> Гл. специалист ССК УКС ПАО "Россети Московский регион"-Шатковский А.Н. | I24: =CONCATENATE(I8," ",G1,"-",I10) -> Гл. специалист ССК УКС ПАО "Россети Московский регион"-Алексанян Г.Р.
C25: =CONCATENATE(C8," ",C1,"-",C10,".",C9) -> Инженер по строительному контролю ООО "Энергосистемы"-Капитонов Д.А..Приказ № 18-ОТ/24 от 03 июня 2024 (НОСТРОЙ С-50-188017) | D25: =CONCATENATE(D8," ",D1,"-",D10,".",D9) -> Специалист по строительному контролю ООО «Гефест»-Саженова Л.В..Приказ №01/24-ОТ от 15.01.2024 (НРС № С-61-104369) | G25: =CONCATENATE(G8," ",G1) -> Гл. специалист ССК УКС ПАО "Россети Московский регион" | H25: =CONCATENATE(H8," ",G1) -> Гл. специалист ССК УКС ПАО "Россети Московский регион" | I25: =CONCATENATE(I8," ",G1) -> Гл. специалист ССК УКС ПАО "Россети Московский регион"
C26: =CONCATENATE(C8," ",C1) -> Инженер по строительному контролю ООО "Энергосистемы" | D26: =CONCATENATE(D8," ",D1) -> Специалист по строительному контролю ООО «Гефест» | G26: =CONCATENATE(G6," ",G1," ",G7) -> Начальник СРЭС СЭС филиала ПАО "Россети Московский регион" Чуев А.Н. | I26: =CONCATENATE(I6," ",G1," ",I7) -> Начальник ХРЭС СЭС филиала ПАО "Россети Московский регион"
C27: =CONCATENATE(C18," ",C1,"-",C20,".",C19) -> Прораб ООО "Энергосистемы"-Волков М.Ю..Приказ №05-ОТ/24 от 09 января 2024г | D27: =CONCATENATE(D18," ",D1,"-",D20,".",D19) -> Мастер электромонтажного участка ООО «Гефест»-Красилов К.А..Приказ №01/24-ОТ от 15.01.2024 | G27: =CONCATENATE(G14," ",G1," ",G15) -> ПАО "Россети Московский регион" | I27: =CONCATENATE(I14," ",G1," ",I15) -> ПАО "Россети Московский регион"
C28: =CONCATENATE(C18," ",C1," ",C20) -> Прораб ООО "Энергосистемы" Волков М.Ю. | D28: =CONCATENATE(D18," ",D1,"-",D20) -> Мастер электромонтажного участка ООО «Гефест»-Красилов К.А. | G28: =CONCATENATE(G16," ",G1," ",G17) -> ПАО "Россети Московский регион"
C29: =CONCATENATE(C18," ",C1) -> Прораб ООО "Энергосистемы" | D29: =CONCATENATE(D18," ",D1) -> Мастер электромонтажного участка ООО «Гефест»

Sheet Данные объект
A1: Данные объекта
A2: № САП | B2: SAP - 301971
A3: Объект | B3: Строительство ВЛИ-0,38 кВ от ТП-10/0,4 кВ № 4232, ПС-110/10 кВ №20 Алабушево, установка ВРЩ-0,4 кВ, в т.ч. ПИР, МО, Солнечногорский р-н, п. Жилино, уч. 20А
A4: р-н | B4: Солнечногорский р-н
A5: Адрес | B5: Солнечногорск, посёлок Жилино, земельный участок 20А
A6: Дата старт | B6: 21.02.2025
A7: Дата финиш | B7: 21.02.2025
A8: Наименование электроустановки
A9: ВРЩ | B9: ВРЩ-0,4 кВ
A10: Монтажная организация
A11: Организация | B11: ООО"Энергосистемы" | C11: =CONCATENATE(B11," ",B12," ",B13) -> ООО"Энергосистемы" ОГРН 1135044003709 ИНН 5044089069 КПП 504401001 141508, Московская область, г.о. Солнечногорск, г. Солнечногорск, ул. Промышленная, стр. 5, помещение 179
A12: Реквизиты | B12: ='[1]Данные организации'!B2:C2 -> ОГРН 1135044003709 ИНН 5044089069 КПП 504401001
A13: адрес | B13: 141508, Московская область, г.о. Солнечногорск, г. Солнечногорск, ул. Промышленная, стр. 5, помещение 179
A14: Должность | B14: Генеральный директор
A15: ФИО | B15: Звездов Р.Е. | C15: =CONCATENATE(B14," ",B11," ",B15) -> Генеральный директор ООО"Энергосистемы" Звездов Р.Е.
A16: Должность | B16: Инженер по строительному контролю | C16: =CONCATENATE(B16," ",B11) -> Инженер по строительному контролю ООО"Энергосистемы"
A17: Ф.И.О. | B17: Русин В.А. | C17: =CONCATENATE(B16," ",B11," ",B17) -> Инженер по строительному контролю ООО"Энергосистемы" Русин В.А.
A18: Приказ | B18: Приказ № 13-ОТ/25 от 05 мая 2025 (НОСТРОЙ С-50-085497) | C18: =CONCATENATE(B16," ",B11," ",B17,".",B18) -> Инженер по строительному контролю ООО"Энергосистемы" Русин В.А..Приказ № 13-ОТ/25 от 05 мая 2025 (НОСТРОЙ С-50-085497)
A19: Должность | B19: Прораб | C19: =CONCATENATE(B19," ",B11) -> Прораб ООО"Энергосистемы"
A20: Ф.И.О. | B20: Волков М.Ю. | C20: =CONCATENATE(B19," ",B11," ",B20) -> Прораб ООО"Энергосистемы" Волков М.Ю.
A21: Приказ | B21: Приказ №05-ОТ/24 от 09 января 2024г | C21: =CONCATENATE(B19," ",B11," ",B20,".",B21) -> Прораб ООО"Энергосистемы" Волков М.Ю..Приказ №05-ОТ/24 от 09 января 2024г
A22: Заказчик
A23: Организация | B23: ПАО "Россети Московский регион" | C23: =CONCATENATE(B23," ",B24,",",B25) -> ПАО "Россети Московский регион" ОГРН 1057746555811 ИНН 5036065113 КПП 772501001,115114, город Москва, проезд Павелецкий 2-й, дом 3, строение 2
A24: Реквизиты | B24: ='[2]Данные организации'!F2 -> ОГРН 1057746555811 ИНН 5036065113 КПП 772501001
A25: адрес | B25: ='[2]Данные организации'!F3 -> 115114, город Москва, проезд Павелецкий 2-й, дом 3, строение 2
A26: Должность | B26: Начальник СРЭС СЭС филиала | C26: =CONCATENATE(B26," ",B23) -> Начальник СРЭС СЭС филиала ПАО "Россети Московский регион"
A27: Ф.И.О. | B27: Чуев А.Н. | C27: =CONCATENATE(B26," ",B23," ",B27) -> Начальник СРЭС СЭС филиала ПАО "Россети Московский регион" Чуев А.Н.
A28: Должность | B28: Гл. спец. сектора по льготным договорам тп | C28: =CONCATENATE(B28," ",B23) -> Гл. спец. сектора по льготным договорам тп ПАО "Россети Московский регион"
A29: Ф.И.О. | B29: Ефремкин Е.И. | C29: =CONCATENATE(B28," ",B23," ",B29) -> Гл. спец. сектора по льготным договорам тп ПАО "Россети Московский регион" Ефремкин Е.И.
A30: Должность | B30: Гл. специалист ПТГ | C30: =CONCATENATE(B30," ",B23) -> Гл. специалист ПТГ ПАО "Россети Московский регион"
A31: Ф.И.О. | B31: Царькова Н.К. | C31: =CONCATENATE(B30," ",B23," ",B31) -> Гл. специалист ПТГ ПАО "Россети Московский регион" Царькова Н.К.
A32: Должность | B32: Гл. специалист ССК УКС | C32: =CONCATENATE(B32," ",B23) -> Гл. специалист ССК УКС ПАО "Россети Московский регион"
A33: Ф.И.О. | B33: Алексанян Г.Р. | C33: =CONCATENATE(B32," ",B23," ",B33) -> Гл. специалист ССК УКС ПАО "Россети Московский регион" Алексанян Г.Р.
A34: Приказ | B34: Приказ №1904 от 03 июня 2026г (НРС С-50-069023) | C34: =CONCATENATE(B32," ",B23," ",B33,".",B34) -> Гл. специалист ССК УКС ПАО "Россети Московский регион" Алексанян Г.Р..Приказ №1904 от 03 июня 2026г (НРС С-50-069023)
A35: Должность | B35: Мастер СРЭС СЭС филиала | C35: =CONCATENATE(B35," ",B23) -> Мастер СРЭС СЭС филиала ПАО "Россети Московский регион"
A36: Ф.И.О. | B36: Курчин М.М. | C36: =CONCATENATE(B35," ",B23," ",B36) -> Мастер СРЭС СЭС филиала ПАО "Россети Московский регион" Курчин М.М.
A37: Приказ | C37: =CONCATENATE(B35," ",B23," ",B36,", ",B37) -> Мастер СРЭС СЭС филиала ПАО "Россети Московский регион" Курчин М.М.,
A38: Проект
A39: Организация | B39: ООО"Энергосистемы"
A40: Реквизиты | B40: ОГРН 1135044003709 ИНН 5044089069 КПП 504401001
...

Sheet АОСР-1
AJ1: Приказ Минстроя №344/пр от 16.05.2023
AJ2: приложение №3
A3: Объект капитального строительства
A4: ='Данные объект'!B3 -> Строительство ВЛИ-0,38 кВ от ТП-10/0,4 кВ № 4232, ПС-110/10 кВ №20 Алабушево, установка ВРЩ-0,4 кВ, в т.ч. ПИР, МО, Солнечногорский р-н, п. Жилино, уч. 20А
A5: ='Данные объект'!B9 -> ВРЩ-0,4 кВ
A6: (наименование объекта капитального строительства в соответствии с проектной документацией, почтовый или строительный адрес объекта капитального строительства)
A7: Застройщик, технический заказчик, лицо, ответственное за эксплуатацию здания, сооружения, или региональный оператор
A8: ='Данные объект'!B23 -> ПАО "Россети Московский регион"
A9: (фамилия, имя, отчество (последнее - при наличии), адрес места жительства, ОРГНИП, ИНН индивидуального предпринимателя, полное и (или) сокращенное наименование, ОГРН, ИНН, адрес юридического лица в пределах его нахождения, телефон или факс,
A10: ='Данные объект'!B24 -> ОГРН 1057746555811 ИНН 5036065113 КПП 772501001
A11: полное и (или) сокращенное наименование, ОГРН, ИНН саморегулируемой организации, членом которой является указанное юридическое лицо или индивидуальный предприниматель (за исключением случаев, когда членство в саморегулируемых организациях в области, строительства, реконструкции, капитального ремонта объектов капитального строительства не требуется); фамилия, имя, отчество
A12: ='Данные объект'!B25 -> 115114, город Москва, проезд Павелецкий 2-й, дом 3, строение 2
A13: (последнее - при наличии), паспортные данные, адрес места жительства, телефон или факс - для физических лиц, не являющихся индивидуальными предпринимателями)
A14: Лицо, осуществляющее строительство, реконструкцию, капитальный ремонт
A15: ='Данные объект'!B11 -> ООО"Энергосистемы"
A16: (фамилия, имя, отчество (последнее - при наличии), адрес места жительства, ОРГНИП, ИНН индивидуального предпринимателя,
A17: ='Данные объект'!B12 -> ОГРН 1135044003709 ИНН 5044089069 КПП 504401001
A18: полное и (или) сокращенное наименование, ОГРН, ИНН, адрес юридического лица в пределах его местонахождения, телефон или факс,
A19: ='Данные объект'!B13 -> 141508, Московская область, г.о. Солнечногорск, г. Солнечногорск, ул. Промышленная, стр. 5, помещение 179
A20: полное и (или) сокращенное наименование, ОГРН, ИНН саморегулируемой организации, членом которой является указанное юридическое лицо или индивидуальный предприниматель (за исключением случаев, когда членство в саморегулируемых организациях в области строительства, реконструкции, капитального ремонта объектов капитального строительства не требуется)
A21: Лицо, осуществляющее подготовку проектной документации
A22: ='Данные объект'!B39 -> ООО"Энергосистемы"
A23: (фамилия, имя, отчество (последнее - при наличии), адрес места жительства, ОРГНИП, ИНН индивидуального предпринимателя,
A24: ='Данные объект'!B12 -> ОГРН 1135044003709 ИНН 5044089069 КПП 504401001
A25: полное и (или) сокращенное наименование, ОГРН, ИНН, адрес юридического лица в пределах его места нахождения, телефон или факс,
A26: ='Данные объект'!B13 -> 141508, Московская область, г.о. Солнечногорск, г. Солнечногорск, ул. Промышленная, стр. 5, помещение 179
A27: полное и (или) сокращенное наименование, ОГРН, ИНН саморегулируемой организации, членом которой является указанное юридическое лицо или индивидуальный предприниматель (за исключением случаев, когда членство в саморегулируемых организациях в области архитектурно-строительного проектирования не требуется)
A29: АКТ
A30: освидетельствования скрытых работ
B32: № | C32: 1 | E32: /ВРЩ | AB32: =P77 -> 21.02.2025 | AJ32: г.
AB33: (дата составления акта)
A35: Представитель застройщика, технического заказчика, лица, ответственного за эксплуатацию здания, сооружения, или регионального оператора по вопросам строительного контроля
A36: ='Данные объект'!C34 -> Гл. специалист ССК УКС ПАО "Россети Московский регион" Алексанян Г.Р..Приказ №1904 от 03 июня 2026г (НРС С-50-069023)
A37: (должность (при наличии), фамилия, инициалы, идентификационный номер в национальном реестре специалистов в области строительства (за исключением случаев, когда членство в саморегулируемых организациях в области строительства, реконструкции, капитального ремонта обектов капитального строительства не требуется), реквизиты распорядительного документа, подтверждающего полномочия,
A38: ='Данные объект'!C23 -> ПАО "Россети Московский регион" ОГРН 1057746555811 ИНН 5036065113 КПП 772501001,115114, город Москва, проезд Павелецкий 2-й, дом 3, строение 2
A39: с указанием полного и (или) сокращенного наименования, ОГРН, ИНН, адреса юридического лица в пределах его места нахождения (в случае осуществления строительного контроля на основании договора с застройщиком или техническим заказчиком), фамилии, имени, отчества (последнее - при наличии), адреса места жительства, ОГРНИП, ИНН индивиуального предпринимателя (в случае осуществления строительного контроля на основании договора с застройщиком или техническим заказчиком)
A40: Представитель лица, осуществляющего строительство, реконструкцию, капитальный ремонт
A41: ='Данные объект'!C21 -> Прораб ООО"Энергосистемы" Волков М.Ю..Приказ №05-ОТ/24 от 09 января 2024г
A42: (должность (при наличии), фамилия, инициалы, реквизиты распорядительного документа, подтверждающего полномочия)
A43: Представитель лица, осуществляющего строительство, реконструкцию, капитальный ремонт, по вопросам строительного контроля
...

Sheet АОСР-2
AJ1: Приказ Минстроя №344/пр от 16.05.2023
AJ2: приложение №3
A3: Объект капитального строительства
A4: ='Данные объект'!B3 -> Строительство ВЛИ-0,38 кВ от ТП-10/0,4 кВ № 4232, ПС-110/10 кВ №20 Алабушево, установка ВРЩ-0,4 кВ, в т.ч. ПИР, МО, Солнечногорский р-н, п. Жилино, уч. 20А
A5: ='Данные объект'!B9 -> ВРЩ-0,4 кВ
A6: (наименование объекта капитального строительства в соответствии с проектной документацией, почтовый или строительный адрес объекта капитального строительства)
A7: Застройщик, технический заказчик, лицо, ответственное за эксплуатацию здания, сооружения, или региональный оператор
A8: ='Данные объект'!B23 -> ПАО "Россети Московский регион"
A9: (фамилия, имя, отчество (последнее - при наличии), адрес места жительства, ОРГНИП, ИНН индивидуального предпринимателя, полное и (или) сокращенное наименование, ОГРН, ИНН, адрес юридического лица в пределах его нахождения, телефон или факс,
A10: ='Данные объект'!B24 -> ОГРН 1057746555811 ИНН 5036065113 КПП 772501001
A11: полное и (или) сокращенное наименование, ОГРН, ИНН саморегулируемой организации, членом которой является указанное юридическое лицо или индивидуальный предприниматель (за исключением случаев, когда членство в саморегулируемых организациях в области, строительства, реконструкции, капитального ремонта объектов капитального строительства не требуется); фамилия, имя, отчество
A12: ='Данные объект'!B25 -> 115114, город Москва, проезд Павелецкий 2-й, дом 3, строение 2
A13: (последнее - при наличии), паспортные данные, адрес места жительства, телефон или факс - для физических лиц, не являющихся индивидуальными предпринимателями)
A14: Лицо, осуществляющее строительство, реконструкцию, капитальный ремонт
A15: ='Данные объект'!B11 -> ООО"Энергосистемы"
A16: (фамилия, имя, отчество (последнее - при наличии), адрес места жительства, ОРГНИП, ИНН индивидуального предпринимателя,
A17: ='Данные объект'!B12 -> ОГРН 1135044003709 ИНН 5044089069 КПП 504401001
A18: полное и (или) сокращенное наименование, ОГРН, ИНН, адрес юридического лица в пределах его местонахождения, телефон или факс,
A19: ='Данные объект'!B13 -> 141508, Московская область, г.о. Солнечногорск, г. Солнечногорск, ул. Промышленная, стр. 5, помещение 179
A20: полное и (или) сокращенное наименование, ОГРН, ИНН саморегулируемой организации, членом которой является указанное юридическое лицо или индивидуальный предприниматель (за исключением случаев, когда членство в саморегулируемых организациях в области строительства, реконструкции, капитального ремонта объектов капитального строительства не требуется)
A21: Лицо, осуществляющее подготовку проектной документации
A22: ='Данные объект'!B39 -> ООО"Энергосистемы"
A23: (фамилия, имя, отчество (последнее - при наличии), адрес места жительства, ОРГНИП, ИНН индивидуального предпринимателя,
A24: ='Данные объект'!B12 -> ОГРН 1135044003709 ИНН 5044089069 КПП 504401001
A25: полное и (или) сокращенное наименование, ОГРН, ИНН, адрес юридического лица в пределах его места нахождения, телефон или факс,
A26: ='Данные объект'!B13 -> 141508, Московская область, г.о. Солнечногорск, г. Солнечногорск, ул. Промышленная, стр. 5, помещение 179
A27: полное и (или) сокращенное наименование, ОГРН, ИНН саморегулируемой организации, членом которой является указанное юридическое лицо или индивидуальный предприниматель (за исключением случаев, когда членство в саморегулируемых организациях в области архитектурно-строительного проектирования не требуется)
A29: АКТ
A30: освидетельствования скрытых работ
B32: № | C32: ='АОСР-1'!C32+1 -> 2 | E32: ='АОСР-1'!E32:G32 -> /ВРЩ | AB32: =P80 -> 21.02.2025 | AJ32: г.
AB33: (дата составления акта)
A35: Представитель застройщика, технического заказчика, лица, ответственного за эксплуатацию здания, сооружения, или регионального оператора по вопросам строительного контроля
A36: ='Данные объект'!C34 -> Гл. специалист ССК УКС ПАО "Россети Московский регион" Алексанян Г.Р..Приказ №1904 от 03 июня 2026г (НРС С-50-069023)
A37: (должность (при наличии), фамилия, инициалы, идентификационный номер в национальном реестре специалистов в области строительства (за исключением случаев, когда членство в саморегулируемых организациях в области строительства, реконструкции, капитального ремонта обектов капитального строительства не требуется), реквизиты распорядительного документа, подтверждающего полномочия,
A38: ='Данные объект'!C23 -> ПАО "Россети Московский регион" ОГРН 1057746555811 ИНН 5036065113 КПП 772501001,115114, город Москва, проезд Павелецкий 2-й, дом 3, строение 2
A39: с указанием полного и (или) сокращенного наименования, ОГРН, ИНН, адреса юридического лица в пределах его места нахождения (в случае осуществления строительного контроля на основании договора с застройщиком или техническим заказчиком), фамилии, имени, отчества (последнее - при наличии), адреса места жительства, ОГРНИП, ИНН индивиуального предпринимателя (в случае осуществления строительного контроля на основании договора с застройщиком или техническим заказчиком)
A40: Представитель лица, осуществляющего строительство, реконструкцию, капитальный ремонт
A41: ='Данные объект'!C21 -> Прораб ООО"Энергосистемы" Волков М.Ю..Приказ №05-ОТ/24 от 09 января 2024г
A42: (должность (при наличии), фамилия, инициалы, реквизиты распорядительного документа, подтверждающего полномочия)
A43: Представитель лица, осуществляющего строительство, реконструкцию, капитальный ремонт, по вопросам строительного контроля
...

Sheet АОСР-3
AJ1: Приказ Минстроя №344/пр от 16.05.2023
AJ2: приложение №3
A3: Объект капитального строительства
A4: ='Данные объект'!B3 -> Строительство ВЛИ-0,38 кВ от ТП-10/0,4 кВ № 4232, ПС-110/10 кВ №20 Алабушево, установка ВРЩ-0,4 кВ, в т.ч. ПИР, МО, Солнечногорский р-н, п. Жилино, уч. 20А
A5: ='Данные объект'!B9 -> ВРЩ-0,4 кВ
A6: (наименование объекта капитального строительства в соответствии с проектной документацией, почтовый или строительный адрес объекта капитального строительства)
A7: Застройщик, технический заказчик, лицо, ответственное за эксплуатацию здания, сооружения, или региональный оператор
A8: ='Данные объект'!B23 -> ПАО "Россети Московский регион"
A9: (фамилия, имя, отчество (последнее - при наличии), адрес места жительства, ОРГНИП, ИНН индивидуального предпринимателя, полное и (или) сокращенное наименование, ОГРН, ИНН, адрес юридического лица в пределах его нахождения, телефон или факс,
A10: ='Данные объект'!B24 -> ОГРН 1057746555811 ИНН 5036065113 КПП 772501001
A11: полное и (или) сокращенное наименование, ОГРН, ИНН саморегулируемой организации, членом которой является указанное юридическое лицо или индивидуальный предприниматель (за исключением случаев, когда членство в саморегулируемых организациях в области, строительства, реконструкции, капитального ремонта объектов капитального строительства не требуется); фамилия, имя, отчество
A12: ='Данные объект'!B25 -> 115114, город Москва, проезд Павелецкий 2-й, дом 3, строение 2
A13: (последнее - при наличии), паспортные данные, адрес места жительства, телефон или факс - для физических лиц, не являющихся индивидуальными предпринимателями)
A14: Лицо, осуществляющее строительство, реконструкцию, капитальный ремонт
A15: ='Данные объект'!B11 -> ООО"Энергосистемы"
A16: (фамилия, имя, отчество (последнее - при наличии), адрес места жительства, ОРГНИП, ИНН индивидуального предпринимателя,
A17: ='Данные объект'!B12 -> ОГРН 1135044003709 ИНН 5044089069 КПП 504401001
A18: полное и (или) сокращенное наименование, ОГРН, ИНН, адрес юридического лица в пределах его местонахождения, телефон или факс,
A19: ='Данные объект'!B13 -> 141508, Московская область, г.о. Солнечногорск, г. Солнечногорск, ул. Промышленная, стр. 5, помещение 179
A20: полное и (или) сокращенное наименование, ОГРН, ИНН саморегулируемой организации, членом которой является указанное юридическое лицо или индивидуальный предприниматель (за исключением случаев, когда членство в саморегулируемых организациях в области строительства, реконструкции, капитального ремонта объектов капитального строительства не требуется)
A21: Лицо, осуществляющее подготовку проектной документации
A22: ='Данные объект'!B39 -> ООО"Энергосистемы"
A23: (фамилия, имя, отчество (последнее - при наличии), адрес места жительства, ОРГНИП, ИНН индивидуального предпринимателя,
A24: ='Данные объект'!B12 -> ОГРН 1135044003709 ИНН 5044089069 КПП 504401001
A25: полное и (или) сокращенное наименование, ОГРН, ИНН, адрес юридического лица в пределах его места нахождения, телефон или факс,
A26: ='Данные объект'!B13 -> 141508, Московская область, г.о. Солнечногорск, г. Солнечногорск, ул. Промышленная, стр. 5, помещение 179
A27: полное и (или) сокращенное наименование, ОГРН, ИНН саморегулируемой организации, членом которой является указанное юридическое лицо или индивидуальный предприниматель (за исключением случаев, когда членство в саморегулируемых организациях в области архитектурно-строительного проектирования не требуется)
A29: АКТ
A30: освидетельствования скрытых работ
B32: № | C32: ='АОСР-2'!C32+1 -> 3 | E32: ='АОСР-2'!E32:G32 -> /ВРЩ | AB32: =P78 -> 21.02.2025 | AJ32: г.
AB33: (дата составления акта)
A35: Представитель застройщика, технического заказчика, лица, ответственного за эксплуатацию здания, сооружения, или регионального оператора по вопросам строительного контроля
A36: ='Данные объект'!C34 -> Гл. специалист ССК УКС ПАО "Россети Московский регион" Алексанян Г.Р..Приказ №1904 от 03 июня 2026г (НРС С-50-069023)
A37: (должность (при наличии), фамилия, инициалы, идентификационный номер в национальном реестре специалистов в области строительства (за исключением случаев, когда членство в саморегулируемых организациях в области строительства, реконструкции, капитального ремонта обектов капитального строительства не требуется), реквизиты распорядительного документа, подтверждающего полномочия,
A38: ='Данные объект'!C23 -> ПАО "Россети Московский регион" ОГРН 1057746555811 ИНН 5036065113 КПП 772501001,115114, город Москва, проезд Павелецкий 2-й, дом 3, строение 2
A39: с указанием полного и (или) сокращенного наименования, ОГРН, ИНН, адреса юридического лица в пределах его места нахождения (в случае осуществления строительного контроля на основании договора с застройщиком или техническим заказчиком), фамилии, имени, отчества (последнее - при наличии), адреса места жительства, ОГРНИП, ИНН индивиуального предпринимателя (в случае осуществления строительного контроля на основании договора с застройщиком или техническим заказчиком)
A40: Представитель лица, осуществляющего строительство, реконструкцию, капитальный ремонт
A41: ='Данные объект'!C21 -> Прораб ООО"Энергосистемы" Волков М.Ю..Приказ №05-ОТ/24 от 09 января 2024г
A42: (должность (при наличии), фамилия, инициалы, реквизиты распорядительного документа, подтверждающего полномочия)
A43: Представитель лица, осуществляющего строительство, реконструкцию, капитальный ремонт, по вопросам строительного контроля
...

Sheet АОСР-4
AJ1: Приказ Минстроя №344/пр от 16.05.2023
AJ2: приложение №3
A3: Объект капитального строительства
A4: ='Данные объект'!B3 -> Строительство ВЛИ-0,38 кВ от ТП-10/0,4 кВ № 4232, ПС-110/10 кВ №20 Алабушево, установка ВРЩ-0,4 кВ, в т.ч. ПИР, МО, Солнечногорский р-н, п. Жилино, уч. 20А
A5: ='Данные объект'!B9 -> ВРЩ-0,4 кВ
A6: (наименование объекта капитального строительства в соответствии с проектной документацией, почтовый или строительный адрес объекта капитального строительства)
A7: Застройщик, технический заказчик, лицо, ответственное за эксплуатацию здания, сооружения, или региональный оператор
A8: ='Данные объект'!B23 -> ПАО "Россети Московский регион"
A9: (фамилия, имя, отчество (последнее - при наличии), адрес места жительства, ОРГНИП, ИНН индивидуального предпринимателя, полное и (или) сокращенное наименование, ОГРН, ИНН, адрес юридического лица в пределах его нахождения, телефон или факс,
A10: ='Данные объект'!B24 -> ОГРН 1057746555811 ИНН 5036065113 КПП 772501001
A11: полное и (или) сокращенное наименование, ОГРН, ИНН саморегулируемой организации, членом которой является указанное юридическое лицо или индивидуальный предприниматель (за исключением случаев, когда членство в саморегулируемых организациях в области, строительства, реконструкции, капитального ремонта объектов капитального строительства не требуется); фамилия, имя, отчество
A12: ='Данные объект'!B25 -> 115114, город Москва, проезд Павелецкий 2-й, дом 3, строение 2
A13: (последнее - при наличии), паспортные данные, адрес места жительства, телефон или факс - для физических лиц, не являющихся индивидуальными предпринимателями)
A14: Лицо, осуществляющее строительство, реконструкцию, капитальный ремонт
A15: ='Данные объект'!B11 -> ООО"Энергосистемы"
A16: (фамилия, имя, отчество (последнее - при наличии), адрес места жительства, ОРГНИП, ИНН индивидуального предпринимателя,
A17: ='Данные объект'!B12 -> ОГРН 1135044003709 ИНН 5044089069 КПП 504401001
A18: полное и (или) сокращенное наименование, ОГРН, ИНН, адрес юридического лица в пределах его местонахождения, телефон или факс,
A19: ='Данные объект'!B13 -> 141508, Московская область, г.о. Солнечногорск, г. Солнечногорск, ул. Промышленная, стр. 5, помещение 179
A20: полное и (или) сокращенное наименование, ОГРН, ИНН саморегулируемой организации, членом которой является указанное юридическое лицо или индивидуальный предприниматель (за исключением случаев, когда членство в саморегулируемых организациях в области строительства, реконструкции, капитального ремонта объектов капитального строительства не требуется)
A21: Лицо, осуществляющее подготовку проектной документации
A22: ='Данные объект'!B39 -> ООО"Энергосистемы"
A23: (фамилия, имя, отчество (последнее - при наличии), адрес места жительства, ОРГНИП, ИНН индивидуального предпринимателя,
A24: ='Данные объект'!B12 -> ОГРН 1135044003709 ИНН 5044089069 КПП 504401001
A25: полное и (или) сокращенное наименование, ОГРН, ИНН, адрес юридического лица в пределах его места нахождения, телефон или факс,
A26: ='Данные объект'!B13 -> 141508, Московская область, г.о. Солнечногорск, г. Солнечногорск, ул. Промышленная, стр. 5, помещение 179
A27: полное и (или) сокращенное наименование, ОГРН, ИНН саморегулируемой организации, членом которой является указанное юридическое лицо или индивидуальный предприниматель (за исключением случаев, когда членство в саморегулируемых организациях в области архитектурно-строительного проектирования не требуется)
A29: АКТ
A30: освидетельствования скрытых работ
B32: № | C32: ='АОСР-3'!C32+1 -> 4 | E32: ='АОСР-2'!E32:G32 -> /ВРЩ | AB32: =P78 -> 21.02.2025 | AJ32: г.
AB33: (дата составления акта)
A35: Представитель застройщика, технического заказчика, лица, ответственного за эксплуатацию здания, сооружения, или регионального оператора по вопросам строительного контроля
A36: ='Данные объект'!C34 -> Гл. специалист ССК УКС ПАО "Россети Московский регион" Алексанян Г.Р..Приказ №1904 от 03 июня 2026г (НРС С-50-069023)
A37: (должность (при наличии), фамилия, инициалы, идентификационный номер в национальном реестре специалистов в области строительства (за исключением случаев, когда членство в саморегулируемых организациях в области строительства, реконструкции, капитального ремонта обектов капитального строительства не требуется), реквизиты распорядительного документа, подтверждающего полномочия,
A38: ='Данные объект'!C23 -> ПАО "Россети Московский регион" ОГРН 1057746555811 ИНН 5036065113 КПП 772501001,115114, город Москва, проезд Павелецкий 2-й, дом 3, строение 2
A39: с указанием полного и (или) сокращенного наименования, ОГРН, ИНН, адреса юридического лица в пределах его места нахождения (в случае осуществления строительного контроля на основании договора с застройщиком или техническим заказчиком), фамилии, имени, отчества (последнее - при наличии), адреса места жительства, ОГРНИП, ИНН индивиуального предпринимателя (в случае осуществления строительного контроля на основании договора с застройщиком или техническим заказчиком)
A40: Представитель лица, осуществляющего строительство, реконструкцию, капитальный ремонт
A41: ='Данные объект'!C21 -> Прораб ООО"Энергосистемы" Волков М.Ю..Приказ №05-ОТ/24 от 09 января 2024г
A42: (должность (при наличии), фамилия, инициалы, реквизиты распорядительного документа, подтверждающего полномочия)
A43: Представитель лица, осуществляющего строительство, реконструкцию, капитальный ремонт, по вопросам строительного контроля
...

Sheet АОСР-5
AJ1: Приказ Минстроя №344/пр от 16.05.2023
AJ2: приложение №3
A3: Объект капитального строительства
A4: ='Данные объект'!B3 -> Строительство ВЛИ-0,38 кВ от ТП-10/0,4 кВ № 4232, ПС-110/10 кВ №20 Алабушево, установка ВРЩ-0,4 кВ, в т.ч. ПИР, МО, Солнечногорский р-н, п. Жилино, уч. 20А
A5: ='Данные объект'!B9 -> ВРЩ-0,4 кВ
A6: (наименование объекта капитального строительства в соответствии с проектной документацией, почтовый или строительный адрес объекта капитального строительства)
A7: Застройщик, технический заказчик, лицо, ответственное за эксплуатацию здания, сооружения, или региональный оператор
A8: ='Данные объект'!B23 -> ПАО "Россети Московский регион"
A9: (фамилия, имя, отчество (последнее - при наличии), адрес места жительства, ОРГНИП, ИНН индивидуального предпринимателя, полное и (или) сокращенное наименование, ОГРН, ИНН, адрес юридического лица в пределах его нахождения, телефон или факс,
A10: ='Данные объект'!B24 -> ОГРН 1057746555811 ИНН 5036065113 КПП 772501001
A11: полное и (или) сокращенное наименование, ОГРН, ИНН саморегулируемой организации, членом которой является указанное юридическое лицо или индивидуальный предприниматель (за исключением случаев, когда членство в саморегулируемых организациях в области, строительства, реконструкции, капитального ремонта объектов капитального строительства не требуется); фамилия, имя, отчество
A12: ='Данные объект'!B25 -> 115114, город Москва, проезд Павелецкий 2-й, дом 3, строение 2
A13: (последнее - при наличии), паспортные данные, адрес места жительства, телефон или факс - для физических лиц, не являющихся индивидуальными предпринимателями)
A14: Лицо, осуществляющее строительство, реконструкцию, капитальный ремонт
A15: ='Данные объект'!B11 -> ООО"Энергосистемы"
A16: (фамилия, имя, отчество (последнее - при наличии), адрес места жительства, ОРГНИП, ИНН индивидуального предпринимателя,
A17: ='Данные объект'!B12 -> ОГРН 1135044003709 ИНН 5044089069 КПП 504401001
A18: полное и (или) сокращенное наименование, ОГРН, ИНН, адрес юридического лица в пределах его местонахождения, телефон или факс,
A19: ='Данные объект'!B13 -> 141508, Московская область, г.о. Солнечногорск, г. Солнечногорск, ул. Промышленная, стр. 5, помещение 179
A20: полное и (или) сокращенное наименование, ОГРН, ИНН саморегулируемой организации, членом которой является указанное юридическое лицо или индивидуальный предприниматель (за исключением случаев, когда членство в саморегулируемых организациях в области строительства, реконструкции, капитального ремонта объектов капитального строительства не требуется)
A21: Лицо, осуществляющее подготовку проектной документации
A22: ='Данные объект'!B39 -> ООО"Энергосистемы"
A23: (фамилия, имя, отчество (последнее - при наличии), адрес места жительства, ОРГНИП, ИНН индивидуального предпринимателя,
A24: ='Данные объект'!B12 -> ОГРН 1135044003709 ИНН 5044089069 КПП 504401001
A25: полное и (или) сокращенное наименование, ОГРН, ИНН, адрес юридического лица в пределах его места нахождения, телефон или факс,
A26: ='Данные объект'!B13 -> 141508, Московская область, г.о. Солнечногорск, г. Солнечногорск, ул. Промышленная, стр. 5, помещение 179
A27: полное и (или) сокращенное наименование, ОГРН, ИНН саморегулируемой организации, членом которой является указанное юридическое лицо или индивидуальный предприниматель (за исключением случаев, когда членство в саморегулируемых организациях в области архитектурно-строительного проектирования не требуется)
A29: АКТ
A30: освидетельствования скрытых работ
B32: № | C32: ='АОСР-4'!C32+1 -> 5 | E32: ='АОСР-3'!E32:G32 -> /ВРЩ | AB32: =P80 -> 21.02.2025 | AJ32: г.
AB33: (дата составления акта)
A35: Представитель застройщика, технического заказчика, лица, ответственного за эксплуатацию здания, сооружения, или регионального оператора по вопросам строительного контроля
A36: ='Данные объект'!C34 -> Гл. специалист ССК УКС ПАО "Россети Московский регион" Алексанян Г.Р..Приказ №1904 от 03 июня 2026г (НРС С-50-069023)
A37: (должность (при наличии), фамилия, инициалы, идентификационный номер в национальном реестре специалистов в области строительства (за исключением случаев, когда членство в саморегулируемых организациях в области строительства, реконструкции, капитального ремонта обектов капитального строительства не требуется), реквизиты распорядительного документа, подтверждающего полномочия,
A38: ='Данные объект'!C23 -> ПАО "Россети Московский регион" ОГРН 1057746555811 ИНН 5036065113 КПП 772501001,115114, город Москва, проезд Павелецкий 2-й, дом 3, строение 2
A39: с указанием полного и (или) сокращенного наименования, ОГРН, ИНН, адреса юридического лица в пределах его места нахождения (в случае осуществления строительного контроля на основании договора с застройщиком или техническим заказчиком), фамилии, имени, отчества (последнее - при наличии), адреса места жительства, ОГРНИП, ИНН индивиуального предпринимателя (в случае осуществления строительного контроля на основании договора с застройщиком или техническим заказчиком)
A40: Представитель лица, осуществляющего строительство, реконструкцию, капитальный ремонт
A41: ='Данные объект'!C21 -> Прораб ООО"Энергосистемы" Волков М.Ю..Приказ №05-ОТ/24 от 09 января 2024г
A42: (должность (при наличии), фамилия, инициалы, реквизиты распорядительного документа, подтверждающего полномочия)
A43: Представитель лица, осуществляющего строительство, реконструкцию, капитальный ремонт, по вопросам строительного контроля
...

Sheet АОСР-6
AJ1: Приказ Минстроя №344/пр от 16.05.2023
AJ2: приложение №3
A3: Объект капитального строительства
A4: ='Данные объект'!B3 -> Строительство ВЛИ-0,38 кВ от ТП-10/0,4 кВ № 4232, ПС-110/10 кВ №20 Алабушево, установка ВРЩ-0,4 кВ, в т.ч. ПИР, МО, Солнечногорский р-н, п. Жилино, уч. 20А
A5: ='Данные объект'!B9 -> ВРЩ-0,4 кВ
A6: (наименование объекта капитального строительства в соответствии с проектной документацией, почтовый или строительный адрес объекта капитального строительства)
A7: Застройщик, технический заказчик, лицо, ответственное за эксплуатацию здания, сооружения, или региональный оператор
A8: ='Данные объект'!B23 -> ПАО "Россети Московский регион"
A9: (фамилия, имя, отчество (последнее - при наличии), адрес места жительства, ОРГНИП, ИНН индивидуального предпринимателя, полное и (или) сокращенное наименование, ОГРН, ИНН, адрес юридического лица в пределах его нахождения, телефон или факс,
A10: ='Данные объект'!B24 -> ОГРН 1057746555811 ИНН 5036065113 КПП 772501001
A11: полное и (или) сокращенное наименование, ОГРН, ИНН саморегулируемой организации, членом которой является указанное юридическое лицо или индивидуальный предприниматель (за исключением случаев, когда членство в саморегулируемых организациях в области, строительства, реконструкции, капитального ремонта объектов капитального строительства не требуется); фамилия, имя, отчество
A12: ='Данные объект'!B25 -> 115114, город Москва, проезд Павелецкий 2-й, дом 3, строение 2
A13: (последнее - при наличии), паспортные данные, адрес места жительства, телефон или факс - для физических лиц, не являющихся индивидуальными предпринимателями)
A14: Лицо, осуществляющее строительство, реконструкцию, капитальный ремонт
A15: ='Данные объект'!B11 -> ООО"Энергосистемы"
A16: (фамилия, имя, отчество (последнее - при наличии), адрес места жительства, ОРГНИП, ИНН индивидуального предпринимателя,
A17: ='Данные объект'!B12 -> ОГРН 1135044003709 ИНН 5044089069 КПП 504401001
A18: полное и (или) сокращенное наименование, ОГРН, ИНН, адрес юридического лица в пределах его местонахождения, телефон или факс,
A19: ='Данные объект'!B13 -> 141508, Московская область, г.о. Солнечногорск, г. Солнечногорск, ул. Промышленная, стр. 5, помещение 179
A20: полное и (или) сокращенное наименование, ОГРН, ИНН саморегулируемой организации, членом которой является указанное юридическое лицо или индивидуальный предприниматель (за исключением случаев, когда членство в саморегулируемых организациях в области строительства, реконструкции, капитального ремонта объектов капитального строительства не требуется)
A21: Лицо, осуществляющее подготовку проектной документации
A22: ='Данные объект'!B39 -> ООО"Энергосистемы"
A23: (фамилия, имя, отчество (последнее - при наличии), адрес места жительства, ОРГНИП, ИНН индивидуального предпринимателя,
A24: ='Данные объект'!B12 -> ОГРН 1135044003709 ИНН 5044089069 КПП 504401001
A25: полное и (или) сокращенное наименование, ОГРН, ИНН, адрес юридического лица в пределах его места нахождения, телефон или факс,
A26: ='Данные объект'!B13 -> 141508, Московская область, г.о. Солнечногорск, г. Солнечногорск, ул. Промышленная, стр. 5, помещение 179
A27: полное и (или) сокращенное наименование, ОГРН, ИНН саморегулируемой организации, членом которой является указанное юридическое лицо или индивидуальный предприниматель (за исключением случаев, когда членство в саморегулируемых организациях в области архитектурно-строительного проектирования не требуется)
A29: АКТ
A30: освидетельствования скрытых работ
B32: № | C32: ='АОСР-5'!C32+1 -> 6 | E32: ='АОСР-5'!E32 -> /ВРЩ | AB32: =P80 -> 21.02.2025 | AJ32: г.
AB33: (дата составления акта)
A35: Представитель застройщика, технического заказчика, лица, ответственного за эксплуатацию здания, сооружения, или регионального оператора по вопросам строительного контроля
A36: ='Данные объект'!C34 -> Гл. специалист ССК УКС ПАО "Россети Московский регион" Алексанян Г.Р..Приказ №1904 от 03 июня 2026г (НРС С-50-069023)
A37: (должность (при наличии), фамилия, инициалы, идентификационный номер в национальном реестре специалистов в области строительства (за исключением случаев, когда членство в саморегулируемых организациях в области строительства, реконструкции, капитального ремонта обектов капитального строительства не требуется), реквизиты распорядительного документа, подтверждающего полномочия,
A38: ='Данные объект'!C23 -> ПАО "Россети Московский регион" ОГРН 1057746555811 ИНН 5036065113 КПП 772501001,115114, город Москва, проезд Павелецкий 2-й, дом 3, строение 2
A39: с указанием полного и (или) сокращенного наименования, ОГРН, ИНН, адреса юридического лица в пределах его места нахождения (в случае осуществления строительного контроля на основании договора с застройщиком или техническим заказчиком), фамилии, имени, отчества (последнее - при наличии), адреса места жительства, ОГРНИП, ИНН индивиуального предпринимателя (в случае осуществления строительного контроля на основании договора с застройщиком или техническим заказчиком)
A40: Представитель лица, осуществляющего строительство, реконструкцию, капитальный ремонт
A41: ='Данные объект'!C21 -> Прораб ООО"Энергосистемы" Волков М.Ю..Приказ №05-ОТ/24 от 09 января 2024г
A42: (должность (при наличии), фамилия, инициалы, реквизиты распорядительного документа, подтверждающего полномочия)
A43: Представитель лица, осуществляющего строительство, реконструкцию, капитальный ремонт, по вопросам строительного контроля
...
