Workbook
Name aaaa: '[1]связ.данные(оборудование)'!$L$17:$L$23
Name кабель: [2]Данные!$F$46:$F$48

Sheet Данные организации
A1: организация | C1: ООО "Энергосистемы" | D1: ООО «Гефест» | F1: ПАО "Россети Московский регион"
A2: реквизиты | C2: ОГРН 1135044003709 ИНН 5044089069 КПП 504401001 | D2: ОГРН 1215000057238 ИНН 5044122213 КПП 504401001 | F2: ОГРН 1057746555811 ИНН 5036065113 КПП 772501001
A3: адрес | C3: 141508, Московская область, г.о. Солнечногорск, г. Солнечногорск, ул. Промышленная, стр. 5, помещение 179 | D3: 141508, Московская область, г.о. Солнечногорск, г Солнечногорск, ул Промышленная, строение 29А, корпус 1, офис 11 | F3: 115114, город Москва, проезд Павелецкий 2-й, дом 3, строение 2
A4: район | F4: Солнечногорский р-н | G4: Химкинский р-н
F5: СРЭС филиала | G5: ХРЭС филиала
A6: директор | C6: И.о.генерального директора | D6: Генеральный директор | F6: Начальник СРЭС СЭС филиала | G6: Начальник ХРЭС СЭС филиала
A7: директор ФИО | C7: Чернявская Н.Ю. | D7: Звездов Р.Е. | F7: Чуев А.Н. | G7: Арнаутов А.П.
A8: Строй.контроль | B8: Инженер по строительному контролю | C8: Инженер по строительному контролю | D8: Специалист по строительному контролю | F8: Гл. специалист ССК УКС | G8: Гл. специалист ССК УКС
A9: Приказ стр.контр. | B9: Приказ № 13-ОТ/25 от 05 мая 2025 (НОСТРОЙ С-50-085497) | C9: Приказ № 13-ОТ/25 от 05 мая 2025 (НОСТРОЙ С-50-085497) | D9: Приказ №01/24-ОТ от 15.01.2024 (НРС № С-61-104369) | F9: Приказ № от 2026г (НРС С-31-330248) | G9: Приказ №1904 от 03 июня 2026г (НРС С-50-069023)
A10: ФИО стр.контр. | B10: Русин В.А. | C10: Русин В.А. | D10: Саженова Л.В. | F10: Курчин М.М. | G10: Алексанян Г.Р.
A11: Представитель | F11: Мастер СРЭС СЭС филиала | G11: Технический надзор
A12: ФИО предст. | F12: Курчин М.М.
A13: Геодезист | C13: Геодезист | D13: Геодезист
A14: ФИО | C14: Андречик Л.В. | D14: Андречик Л.В. | F14: Мастер СРЭС СЭС филиала
F15: Курчин М.М.
A18: Прораб | C18: Прораб | D18: Мастер электромонтажного участка
A19: Приказ прораб | C19: Приказ №05-ОТ/24 от 09 января 2024г | D19: Приказ №01/24-ОТ от 15.01.2024
A20: ФИО прораб | C20: Волков М.Ю. | D20: Красилов К.А.
A23: сцепленные организация | C23: =CONCATENATE(C2,",",C3) -> ОГРН 1135044003709 ИНН 5044089069 КПП 504401001,141508, Московская область, г.о. Солнечногорск, г. Солнечногорск, ул. Промышленная, стр. 5, помещение 179 | D23: =CONCATENATE(D2,",",D3) -> ОГРН 1215000057238 ИНН 5044122213 КПП 504401001,141508, Московская область, г.о. Солнечногорск, г Солнечногорск, ул Промышленная, строение 29А, корпус 1, офис 11 | F23: =CONCATENATE(F8," ",F1,"-",F10," .",F9) -> Гл. специалист ССК УКС ПАО "Россети Московский регион"-Курчин М.М. .Приказ № от 2026г (НРС С-31-330248) | G23: =CONCATENATE(G8," ",F1,"-",G10," .",G9) -> Гл. специалист ССК УКС ПАО "Россети Московский регион"-Алексанян Г.Р. .Приказ №1904 от 03 июня 2026г (НРС С-50-069023)
A24: сцепленные организация | C24: =CONCATENATE(C1,",",C2,",",C3) -> ООО "Энергосистемы",ОГРН 1135044003709 ИНН 5044089069 КПП 504401001,141508, Московская область, г.о. Солнечногорск, г. Солнечногорск, ул. Промышленная, стр. 5, помещение 179 | D24: =CONCATENATE(D1,",",D2,",",D3) -> ООО «Гефест»,ОГРН 1215000057238 ИНН 5044122213 КПП 504401001,141508, Московская область, г.о. Солнечногорск, г Солнечногорск, ул Промышленная, строение 29А, корпус 1, офис 11 | F24: =CONCATENATE(F8," ",F1,"-",F10) -> Гл. специалист ССК УКС ПАО "Россети Московский регион"-Курчин М.М. | G24: =CONCATENATE(G8," ",F1,"-",G10) -> Гл. специалист ССК УКС ПАО "Россети Московский регион"-Алексанян Г.Р.
C25: =CONCATENATE(C8," ",C1,"-",C10,".",C9) -> Инженер по строительному контролю ООО "Энергосистемы"-Русин В.А..Приказ № 13-ОТ/25 от 05 мая 2025 (НОСТРОЙ С-50-085497) | D25: =CONCATENATE(D8," ",D1,"-",D10,".",D9) -> Специалист по строительному контролю ООО «Гефест»-Саженова Л.В..Приказ №01/24-ОТ от 15.01.2024 (НРС № С-61-104369) | F25: =CONCATENATE(F8," ",F1) -> Гл. специалист ССК УКС ПАО "Россети Московский регион" | G25: =CONCATENATE(G8," ",F1) -> Гл. специалист ССК УКС ПАО "Россети Московский регион"
C26: =CONCATENATE(C8," ",C1) -> Инженер по строительному контролю ООО "Энергосистемы" | D26: =CONCATENATE(D8," ",D1) -> Специалист по строительному контролю ООО «Гефест» | F26: =CONCATENATE(F6," ",F1," ",F7) -> Начальник СРЭС СЭС филиала ПАО "Россети Московский регион" Чуев А.Н. | G26: =CONCATENATE(G6," ",F1," ",G7) -> Начальник ХРЭС СЭС филиала ПАО "Россети Московский регион" Арнаутов А.П.
C27: =CONCATENATE(C18," ",C1,"-",C20,".",C19) -> Прораб ООО "Энергосистемы"-Волков М.Ю..Приказ №05-ОТ/24 от 09 января 2024г | D27: =CONCATENATE(D18," ",D1,"-",D20,".",D19) -> Мастер электромонтажного участка ООО «Гефест»-Красилов К.А..Приказ №01/24-ОТ от 15.01.2024 | F27: =CONCATENATE(F14," ",F1," ",F15) -> Мастер СРЭС СЭС филиала ПАО "Россети Московский регион" Курчин М.М. | G27: =CONCATENATE(G14," ",F1," ",G15) -> ПАО "Россети Московский регион"
C28: =CONCATENATE(C18," ",C1," ",C20) -> Прораб ООО "Энергосистемы" Волков М.Ю. | D28: =CONCATENATE(D18," ",D1,"-",D20) -> Мастер электромонтажного участка ООО «Гефест»-Красилов К.А. | F28: =CONCATENATE(F16," ",F1," ",F17) -> ПАО "Россети Московский регион"
C29: =CONCATENATE(C18," ",C1) -> Прораб ООО "Энергосистемы" | D29: =CONCATENATE(D18," ",D1) -> Мастер электромонтажного участка ООО «Гефест»

Sheet Данные 
A1: Объект | B1: Строительство 2БКТП-10/0,4 кВ № 1 с трансформаторами 2х1250 кВА и № 2 с трансформаторами 2х1000 кВА, 2КЛ-10 кВ от яч. 6 и яч. 17 РУ-10кВ РП-10 кВ № 26116 до 1-ой и 2-ой сек. РУ-10 кВ сооруж. БКТП-10/0,4 кВ № 1, 2КЛ-10 кВ от 1-ой и 2-ой сек. РУ-10 кВ сооруж. БКТП-10/0,4 кВ № 1 до 1-ой и 2-ой сек. РУ-10 кВ сооруж. БКТП-10/0,4 кВ № 2, 48КЛ-0,4 кВ от сооруж. БКТП-10/0,4 кВ № 1 и № 2 до сооруж. ВРУ-0,4 кВ № 1, 2, 3 к.1-8, в т.ч. ПИР, МО, Солнечногорский р-н, г.п. Андреевка, р.п. Андреевка | C1: Номер договора | E1: С259941-309788
A2: Город | B2: Солнечногорский р-н | C2: Дата договора
A3: Адрес | B3: городское поселение Андреевка, рабочий поселок Андреевка
A4: Дата работ | B4: 25.08.2025
A5: Год | B5: 2025
A6: Монтажная организация
A7: Организация | B7: ООО "Энергосистемы"
A8: Реквизиты | B8: ОГРН 1135044003709 ИНН 5044089069 КПП 504401001
A9: Адрес | B9: 141508, Московская область, г.о. Солнечногорск, г. Солнечногорск, ул. Промышленная, стр. 5, помещение 179
A10: Должность | B10: Прораб | H10: =CONCATENATE(B10," ",B7," ",B11,", ",B12) -> Прораб ООО "Энергосистемы" Волков М.Ю., Приказ №05-ОТ/24 от 09 января 2024г
A11: Ф.И.О. | B11: Волков М.Ю.
A12: Приказ | B12: Приказ №05-ОТ/24 от 09 января 2024г
A13: Должность | B13: Инженер по строительному контролю | H13: =CONCATENATE(B13," ",B7," ",B14,", ",B15) -> Инженер по строительному контролю ООО "Энергосистемы" Русин В.А., Приказ № 13-ОТ/25 от 05 мая 2025 (НОСТРОЙ С-50-085497)
A14: Ф.И.О. | B14: Русин В.А.
A15: Приказ | B15: Приказ № 13-ОТ/25 от 05 мая 2025 (НОСТРОЙ С-50-085497)
A16: Подрядчик ГНБ
A17: Организация | B17: ООО «КСС Регион» | H17: Россия, 142300, Московская область, ГО Чехов, ов, ул. Полиграфистов, д. 14А, ком. 29
A18: Должность | B18: Гл.инженер
A19: Ф.И.О. | B19: Сигарев А.А.
A20: Должность | B20: -
A21: Ф.И.О. | B21: Ефремкин Е.И.
A22: Заказчик | H22: =CONCATENATE(B23," ",B24," ",B25) -> ПАО "Россети Московский регион" ОГРН 1057746555811 ИНН 5036065113 КПП 772501001 115114, город Москва, проезд Павелецкий 2-й, дом 3, строение 2
A23: Организация | B23: ='Данные организации'!F1 -> ПАО "Россети Московский регион" | H23: =CONCATENATE(B26," ",B27," ",B28) -> Гл. специалист ССК УКС Алексанян Г.Р. Приказ №1904 от 03 июня 2026г (НРС С-50-069023)
A24: Реквизиты | B24: ='Данные организации'!F2 -> ОГРН 1057746555811 ИНН 5036065113 КПП 772501001
A25: Адрес | B25: ='Данные организации'!F3 -> 115114, город Москва, проезд Павелецкий 2-й, дом 3, строение 2
A26: Должность | B26: Гл. специалист ССК УКС
A27: Ф.И.О. | B27: Алексанян Г.Р.
A28: Приказ | B28: Приказ №1904 от 03 июня 2026г (НРС С-50-069023)
A30: Проект
A31: Организация | B31: ООО "Энергосистемы"
A32: Город | B32: г. Солнечногорск
A33: Шифр проекта | B33: 4741-259941-257-12/23
A34: Название | B34: =B1 -> Строительство 2БКТП-10/0,4 кВ № 1 с трансформаторами 2х1250 кВА и № 2 с трансформаторами 2х1000 кВА, 2КЛ-10 кВ от яч. 6 и яч. 17 РУ-10кВ РП-10 кВ № 26116 до 1-ой и 2-ой сек. РУ-10 кВ сооруж. БКТП-10/0,4 кВ № 1, 2КЛ-10 кВ от 1-ой и 2-ой сек. РУ-10 кВ сооруж. БКТП-10/0,4 кВ № 1 до 1-ой и 2-ой сек. РУ-10 кВ сооруж. БКТП-10/0,4 кВ № 2, 48КЛ-0,4 кВ от сооруж. БКТП-10/0,4 кВ № 1 и № 2 до сооруж. ВРУ-0,4 кВ № 1, 2, 3 к.1-8, в т.ч. ПИР, МО, Солнечногорский р-н, г.п. Андреевка, р.п. Андреевка
A36: Объект | B36: ГНБ №1
A37: № ГНБ | B37: 1
A38: Длинна труб по профилю, м | B38: 3х150
A39: Длинна по профилю, м | B39: 150
A40: Длинна трубы, м (6 или 12) | B40: 6
A41: Диаметр труб, мм | B41: Ø160

Sheet АОСР-1
AJ1: Приказ Минстроя №344/пр от 16.05.2023
AJ2: приложение №3
A3: Объект капитального строительства
A4: ='Данные '!B1 -> Строительство 2БКТП-10/0,4 кВ № 1 с трансформаторами 2х1250 кВА и № 2 с трансформаторами 2х1000 кВА, 2КЛ-10 кВ от яч. 6 и яч. 17 РУ-10кВ РП-10 кВ № 26116 до 1-ой и 2-ой сек. РУ-10 кВ сооруж. БКТП-10/0,4 кВ № 1, 2КЛ-10 кВ от 1-ой и 2-ой сек. РУ-10 кВ сооруж. БКТП-10/0,4 кВ № 1 до 1-ой и 2-ой сек. РУ-10 кВ сооруж. БКТП-10/0,4 кВ № 2, 48КЛ-0,4 кВ от сооруж. БКТП-10/0,4 кВ № 1 и № 2 до сооруж. ВРУ-0,4 кВ № 1, 2, 3 к.1-8, в т.ч. ПИР, МО, Солнечногорский р-н, г.п. Андреевка, р.п. Андреевка
A5: ='Данные '!B36 -> ГНБ №1
A6: (наименование объекта капитального строительства в соответствии с проектной документацией, почтовый или строительный адрес объекта капитального строительства)
A7: Застройщик, технический заказчик, лицо, ответственное за эксплуатацию здания, сооружения, или региональный оператор
A8: ='Данные '!B23 -> ПАО "Россети Московский регион"
A9: (фамилия, имя, отчество (последнее - при наличии), адрес места жительства, ОРГНИП, ИНН индивидуального предпринимателя, полное и (или) сокращенное наименование, ОГРН, ИНН, адрес юридического лица в пределах его нахождения, телефон или факс,
A10: ='Данные '!B24 -> ОГРН 1057746555811 ИНН 5036065113 КПП 772501001
A11: полное и (или) сокращенное наименование, ОГРН, ИНН саморегулируемой организации, членом которой является указанное юридическое лицо или индивидуальный предприниматель (за исключением случаев, когда членство в саморегулируемых организациях в области, строительства, реконструкции, капитального ремонта объектов капитального строительства не требуется); фамилия, имя, отчество
A12: ='Данные '!B25 -> 115114, город Москва, проезд Павелецкий 2-й, дом 3, строение 2
A13: (последнее - при наличии), паспортные данные, адрес места жительства, телефон или факс - для физических лиц, не являющихся индивидуальными предпринимателями)
A14: Лицо, осуществляющее строительство, реконструкцию, капитальный ремонт
A15: ='Данные '!B7 -> ООО "Энергосистемы"
A16: (фамилия, имя, отчество (последнее - при наличии), адрес места жительства, ОРГНИП, ИНН индивидуального предпринимателя,
A17: ='Данные '!B8 -> ОГРН 1135044003709 ИНН 5044089069 КПП 504401001
A18: полное и (или) сокращенное наименование, ОГРН, ИНН, адрес юридического лица в пределах его местонахождения, телефон или факс,
A19: ='Данные '!B9 -> 141508, Московская область, г.о. Солнечногорск, г. Солнечногорск, ул. Промышленная, стр. 5, помещение 179
A20: полное и (или) сокращенное наименование, ОГРН, ИНН саморегулируемой организации, членом которой является указанное юридическое лицо или индивидуальный предприниматель (за исключением случаев, когда членство в саморегулируемых организациях в области строительства, реконструкции, капитального ремонта объектов капитального строительства не требуется)
A21: Лицо, осуществляющее подготовку проектной документации
A22: ='Данные '!B7 -> ООО "Энергосистемы"
A23: (фамилия, имя, отчество (последнее - при наличии), адрес места жительства, ОРГНИП, ИНН индивидуального предпринимателя,
A24: ='Данные '!B8 -> ОГРН 1135044003709 ИНН 5044089069 КПП 504401001
A25: полное и (или) сокращенное наименование, ОГРН, ИНН, адрес юридического лица в пределах его места нахождения, телефон или факс,
A26: ='Данные '!B9 -> 141508, Московская область, г.о. Солнечногорск, г. Солнечногорск, ул. Промышленная, стр. 5, помещение 179
A27: полное и (или) сокращенное наименование, ОГРН, ИНН саморегулируемой организации, членом которой является указанное юридическое лицо или индивидуальный предприниматель (за исключением случаев, когда членство в саморегулируемых организациях в области архитектурно-строительного проектирования не требуется)
A29: АКТ
A30: освидетельствования скрытых работ
B32: Обустройство закрытого перехода № | M32: ='Данные '!B37 -> 1 | O32: (методом ГНБ) | Z32: =M76 -> 25.08.2025
Z33: (дата составления акта)
A35: Представитель застройщика, технического заказчика, лица, ответственного за эксплуатацию здания, сооружения, или регионального оператора по вопросам строительного контроля
A36: ='Данные '!H23 -> Гл. специалист ССК УКС Алексанян Г.Р. Приказ №1904 от 03 июня 2026г (НРС С-50-069023)
A37: (должность (при наличии), фамилия, инициалы, идентификационный номер в национальном реестре специалистов в области строительства (за исключением случаев, когда членство в саморегулируемых организациях в области строительства, реконструкции, капитального ремонта обектов капитального строительства не требуется), реквизиты распоряительного документа, подтверждающего полномочия,
A38: ='Данные '!H22 -> ПАО "Россети Московский регион" ОГРН 1057746555811 ИНН 5036065113 КПП 772501001 115114, город Москва, проезд Павелецкий 2-й, дом 3, строение 2
A39: с указанием полного и (или) сокращенного наименования, ОГРН, ИНН, адреса юридического лица в пределах его места нахождения (в случае осуществления строительного контроля на основании договора с застройщиком или техническим заказчиком), фамилии, имени, отчества (последнее - при наличии), адреса места жительства, ОГРНИП, ИНН индивиуального предпринимателя (в случае осуществления строительного контроля на основании договора с застройщиком или техническим заказчиком)
A40: Представитель лица, осуществляющего строительство, реконструкцию, капитальный ремонт
A41: ='Данные '!H10 -> Прораб ООО "Энергосистемы" Волков М.Ю., Приказ №05-ОТ/24 от 09 января 2024г
A42: (должность (при наличии), фамилия, инициалы, реквизиты распорядительного документа, подтверждающего полномочия)
A43: Представитель лица, осуществляющего строительство, реконструкцию, капитальный ремонт, по вопросам строительного контроля
...

Sheet Форма 1
A1: СП 341.1325800.2017
A2: Приложение К, форма 1
A4: Протокол №1 Бурения скважины методом горизонтального направленного бурения
A6: Наименование строительной организации, юридический и почтовый адреса, контактные телефоны | D6: =CONCATENATE('Данные '!B17,",",'Данные '!H17) -> ООО «КСС Регион»,Россия, 142300, Московская область, ГО Чехов, ов, ул. Полиграфистов, д. 14А, ком. 29
A7: Объект (наименование, шифр) | D7: ='Данные '!B1 -> Строительство 2БКТП-10/0,4 кВ № 1 с трансформаторами 2х1250 кВА и № 2 с трансформаторами 2х1000 кВА, 2КЛ-10 кВ от яч. 6 и яч. 17 РУ-10кВ РП-10 кВ № 26116 до 1-ой и 2-ой сек. РУ-10 кВ сооруж. БКТП-10/0,4 кВ № 1, 2КЛ-10 кВ от 1-ой и 2-ой сек. РУ-10 кВ сооруж. БКТП-10/0,4 кВ № 1 до 1-ой и 2-ой сек. РУ-10 кВ сооруж. БКТП-10/0,4 кВ № 2, 48КЛ-0,4 кВ от сооруж. БКТП-10/0,4 кВ № 1 и № 2 до сооруж. ВРУ-0,4 кВ № 1, 2, 3 к.1-8, в т.ч. ПИР, МО, Солнечногорский р-н, г.п. Андреевка, р.п. Андреевка
A8: Адрес производства работ (уточненное географическое месторасположение в конкретном регионе, населенный пункт, улица, номера строений в непосредственной близости) | D8: ='Данные '!B3 -> городское поселение Андреевка, рабочий поселок Андреевка
A9: Наименование перехода методом ГНБ (текстовое наименование, пикеты, литерные обозначения, нумерация или обозначения скважины) | D9: ='Данные '!B36 -> ГНБ №1
A10: Вид прокладываемой методом ГНБ коммуникации (наименование коммуникации, обозначения технических характеристик трубопровода(ов) по НД, их число в скважине) | D10: ='АОСР-1'!B67 -> Труба ПЭ F110 D160мм
A11: Фирма-производитель и наименование установки ГНБ | D11: XCMG, XZ360E
A12: Длина одной буровой штанги, м | D12: 3
A13: Система локации, тип зонда | D13: DigiTrak серия F5, 5XD19/12 синий
A14: Должность, инициалы, фамилия лица, ответственного за составление протокола бурения | D14: Гл. инженер Сигарев А.А.
A15: Должность, инициалы, фамилия руководителя буровых работ | D15: Гл. инженер Сигарев А.А.
A17: Таблица 1
A19: Номер штанги | B19: Длина пилотной скважины, м | C19: Угол наклона буровой головки, % | D19: Глубина нахождения буровой головки, см | E19: Примечание (фиксирование ориентиров по профилю бурения)
A20: 1 | B20: 3 | C20: 20 | D20: 105 | E20: Котлован стартовый
A21: =A20+1 -> 2 | B21: =B20+3 -> 6 | C21: =C20-4 -> 16 | D21: 167
A22: =A21+1 -> 3 | B22: =B21+3 -> 9 | C22: =C21-4 -> 12 | D22: 231
A23: =A22+1 -> 4 | B23: =B22+3 -> 12 | C23: =C22-4 -> 8 | D23: 294
A24: =A23+1 -> 5 | B24: =B23+3 -> 15 | C24: =C23-4 -> 4 | D24: 365
A25: =A24+1 -> 6 | B25: =B24+3 -> 18 | C25: =C24-4 -> 0 | D25: 417
A26: =A25+1 -> 7 | B26: =B25+3 -> 21 | C26: 0 | D26: 418
A27: =A26+1 -> 8 | B27: =B26+3 -> 24 | C27: 0 | D27: 420
A28: =A27+1 -> 9 | B28: =B27+3 -> 27 | C28: 0 | D28: 419
A29: =A28+1 -> 10 | B29: =B28+3 -> 30 | C29: 0 | D29: 419
A30: =A29+1 -> 11 | B30: =B29+3 -> 33 | C30: 0 | D30: 418
A31: =A30+1 -> 12 | B31: =B30+3 -> 36 | C31: 0 | D31: 418
A32: =A31+1 -> 13 | B32: =B31+3 -> 39 | C32: 0 | D32: 417
A33: =A32+1 -> 14 | B33: =B32+3 -> 42 | C33: 0 | D33: 418
A34: =A33+1 -> 15 | B34: =B33+3 -> 45 | C34: 0 | D34: 419
A35: =A34+1 -> 16 | B35: =B34+3 -> 48 | C35: 0 | D35: 418
A36: =A35+1 -> 17 | B36: =B35+3 -> 51 | C36: 0 | D36: 418
A37: =A36+1 -> 18 | B37: =B36+3 -> 54 | C37: 0 | D37: 417
... A58: =A57+1 -> 39 | B58: =B57+3 -> 117 | C58: 0 | D58: 390
A59: =A58+1 -> 40 | B59: =B58+3 -> 120 | C59: =C60-3 -> 3 | D59: 354
A60: =A59+1 -> 41 | B60: =B59+3 -> 123 | C60: =C61-3 -> 6 | D60: 321
A61: =A60+1 -> 42 | B61: =B60+3 -> 126 | C61: =C62-3 -> 9 | D61: 290
A62: =A61+1 -> 43 | B62: =B61+3 -> 129 | C62: =C63-3 -> 12 | D62: 268
A63: =A62+1 -> 44 | B63: =B62+3 -> 132 | C63: =C64-3 -> 15 | D63: 221
A64: =A63+1 -> 45 | B64: =B63+3 -> 135 | C64: =C65-3 -> 18 | D64: 198
...

Sheet Форма 2
A1: СП 341.1325800.2017
A2: Приложение К, форма 2
A4: Строительство (ремонт) | B4: ='Данные '!B1 -> Строительство 2БКТП-10/0,4 кВ № 1 с трансформаторами 2х1250 кВА и № 2 с трансформаторами 2х1000 кВА, 2КЛ-10 кВ от яч. 6 и яч. 17 РУ-10кВ РП-10 кВ № 26116 до 1-ой и 2-ой сек. РУ-10 кВ сооруж. БКТП-10/0,4 кВ № 1, 2КЛ-10 кВ от 1-ой и 2-ой сек. РУ-10 кВ сооруж. БКТП-10/0,4 кВ № 1 до 1-ой и 2-ой сек. РУ-10 кВ сооруж. БКТП-10/0,4 кВ № 2, 48КЛ-0,4 кВ от сооруж. БКТП-10/0,4 кВ № 1 и № 2 до сооруж. ВРУ-0,4 кВ № 1, 2, 3 к.1-8, в т.ч. ПИР, МО, Солнечногорский р-н, г.п. Андреевка, р.п. Андреевка
A5: Объект | B5: ='Данные '!B36 -> ГНБ №1
B7: АКТ № | C7: ='АОСР-1'!M32 -> 1
A8: приёмки пилотной скважины (основной, резервной) нитки подводного перехода
F10: ='Данные '!B4 -> 25.08.2025
A12: Составлен представителями:
A13: подрядчика | B13: =CONCATENATE('Данные '!B18," ",'Данные '!B17," ",'Данные '!B19) -> Гл.инженер ООО «КСС Регион» Сигарев А.А.
B14: (должность, организация, инициалы, фамилия)
A15: технического надзора заказчика <*> | B15: =CONCATENATE('Данные '!B20," ",'Данные '!B19," ",'Данные '!B21) -> - Сигарев А.А. Ефремкин Е.И.
B16: (должность, организация, инициалы, фамилия)
A17: заказчика | B17: =CONCATENATE('Данные '!B10," ",'Данные '!B7," ",'Данные '!B11) -> Прораб ООО "Энергосистемы" Волков М.Ю.
B18: (должность, организация, инициалы, фамилия)
A20: в том, что проведенными промерами фактического положения пилотной скважины и контролем углов наклона и азимута во время бурения установлено:
A21: пилотная скважина на участке: выполнена в соответствии с проектной документацией, чертеж № , принята и считается готовой для производства работ по расширению пилотной скважины. | B21: =B5 -> ГНБ №1 | C21: выполнена в соответствии с проектной документацией,
A22: чертеж № | B22: ='Данные '!B33 -> 4741-259941-257-12/23
A23: принята и считается готовой для производства работ по расширению пилотной скважины.
A24: Ведомость проектных и фактических отметок пилотной скважины по оси подводного перехода прилагается.
A26: Представитель подрядчика | B26: ='Данные '!B18 -> Гл.инженер | G26: ='Данные '!B19 -> Сигарев А.А.
B27: (должность) | E27: (подпись) | G27: (дата)
A28: Представитель технического надзора заказчика <*>
B29: (должность) | E29: (подпись) | G29: (дата)
A30: Представитель заказчика | B30: ='Данные '!B7 -> ООО "Энергосистемы" | G30: ='Данные '!B11 -> Волков М.Ю.
B31: (должность) | E31: (подпись) | G31: (дата)
A34: <*> Приводится и заполняется в случае осуществления технического надзора специализированной организацией по договору с заказчиком.

Sheet Форма 3
A1: СП 341.1325800.2017
A2: Приложение К, форма 3
A4: Строительство (ремонт) | B4: ='Данные '!B1 -> Строительство 2БКТП-10/0,4 кВ № 1 с трансформаторами 2х1250 кВА и № 2 с трансформаторами 2х1000 кВА, 2КЛ-10 кВ от яч. 6 и яч. 17 РУ-10кВ РП-10 кВ № 26116 до 1-ой и 2-ой сек. РУ-10 кВ сооруж. БКТП-10/0,4 кВ № 1, 2КЛ-10 кВ от 1-ой и 2-ой сек. РУ-10 кВ сооруж. БКТП-10/0,4 кВ № 1 до 1-ой и 2-ой сек. РУ-10 кВ сооруж. БКТП-10/0,4 кВ № 2, 48КЛ-0,4 кВ от сооруж. БКТП-10/0,4 кВ № 1 и № 2 до сооруж. ВРУ-0,4 кВ № 1, 2, 3 к.1-8, в т.ч. ПИР, МО, Солнечногорский р-н, г.п. Андреевка, р.п. Андреевка
A5: Объект | B5: ='Данные '!B36 -> ГНБ №1
C7: АКТ № | D7: ='Форма 2'!C7 -> 1
A8: приёмки расширенной скважины и готовности для протягивания трубопровода (основной, резервной) нитки подводного перехода
F10: ='Форма 2'!F10 -> 25.08.2025
A12: Составлен представителями:
A13: подрядчика | B13: =CONCATENATE('Данные '!B18," ",'Данные '!B17," ",'Данные '!B19) -> Гл.инженер ООО «КСС Регион» Сигарев А.А.
B14: (должность, организация, инициалы, фамилия)
A15: технического надзора заказчика <*>
B16: (должность, организация, инициалы, фамилия)
A17: заказчика | B17: =CONCATENATE('Данные '!B10," ",'Данные '!B7," ",'Данные '!B11) -> Прораб ООО "Энергосистемы" Волков М.Ю.
B18: (должность, организация, инициалы, фамилия)
A20: в том, что расширение пилотной скважины на участке | C20: =B5 -> ГНБ №1 | F20: выполнено в соответствии
A21: с проектной документацией № | C21: ='Данные '!B33 -> 4741-259941-257-12/23
A22: Скважина расширена до диаметра | C22: ='Форма 1'!B75 -> 500 | D22: мм, принята и считается готовой для производства работ по
A23: протягиванию трубопровода.
A25: Представитель подрядчика | B25: ='Данные '!B18 -> Гл.инженер
B26: (должность) | D26: (подпись) | F26: (дата)
A27: Представитель технического надзора заказчика <*>
B28: (должность) | D28: (подпись) | F28: (дата)
A29: Представитель заказчика | B29: ='Данные '!B10 -> Прораб
B30: (должность) | D30: (подпись) | F30: (дата)
A33: <*> Приводится и заполняется в случае осуществления технического надзора специализированной организацией по договору с заказчиком.

Sheet Форма 4
A1: СП 341.1325800.2017
A2: Приложение К, форма 4
A4: Строительство (ремонт) | B4: ='Данные '!B1 -> Строительство 2БКТП-10/0,4 кВ № 1 с трансформаторами 2х1250 кВА и № 2 с трансформаторами 2х1000 кВА, 2КЛ-10 кВ от яч. 6 и яч. 17 РУ-10кВ РП-10 кВ № 26116 до 1-ой и 2-ой сек. РУ-10 кВ сооруж. БКТП-10/0,4 кВ № 1, 2КЛ-10 кВ от 1-ой и 2-ой сек. РУ-10 кВ сооруж. БКТП-10/0,4 кВ № 1 до 1-ой и 2-ой сек. РУ-10 кВ сооруж. БКТП-10/0,4 кВ № 2, 48КЛ-0,4 кВ от сооруж. БКТП-10/0,4 кВ № 1 и № 2 до сооруж. ВРУ-0,4 кВ № 1, 2, 3 к.1-8, в т.ч. ПИР, МО, Солнечногорский р-н, г.п. Андреевка, р.п. Андреевка
A5: Объект | B5: ='Данные '!B36 -> ГНБ №1
C8: АКТ № | D8: ='Форма 2'!C7 -> 1
A9: приёмки трубопровода (пакета труб) для протягивания перехода ГНБ
A11: Участок от ПК/км _________ до ПК/км __________
F13: ='Форма 2'!F10 -> 25.08.2025
A15: Комиссия в составе представителей:
A16: подрядчика | B16: =CONCATENATE('Данные '!B18," ",'Данные '!B17," ",'Данные '!B19) -> Гл.инженер ООО «КСС Регион» Сигарев А.А.
B17: (должность, организация, инициалы, фамилия)
A18: генерального подрядчика | B18: =CONCATENATE('Данные '!B10," ",'Данные '!B7," ",'Данные '!B11) -> Прораб ООО "Энергосистемы" Волков М.Ю.
B19: (должность, организация, инициалы, фамилия)
A20: технического надзора заказчика
B21: (должность, организация, инициалы, фамилия)
A22: лица, осуществляющего подготовку проектной документации
B23: (должность, организация, инициалы, фамилия)
A24: лица, ответственного за эксплуатацию
B25: (должность, организация, инициалы, фамилия)
A26: провела освидетельствование работ, выполненных | D26: ='Данные '!B17 -> ООО «КСС Регион»
D27: (наименование строительно-монтажной организации)
A29: по подготовке для протягивания трубопровода (участка трубопровода, передового звена трубопровода, пакета труб).
A31: Комиссии предъявлены:
A32: 1. Проектная документация на устройство перехода ГНБ № ____________________, | D32: ='Данные '!B37 -> 1
A33: разработчик | B33: ='Данные '!B31 -> ООО "Энергосистемы" | D33: № | E33: ='Данные '!B33 -> 4741-259941-257-12/23
A34: 2. Документы качества на материалы и изделия, примененные при сборке трубопровода.
A35: 3. Исполнительные стандартизированные формы контроля качества по сборке трубопровода.
A36: 4. _________________________________________________________________________
A37: 5. _________________________________________________________________________
A39: Комиссия, ознакомившись с представленными документами и проверив выполнение
A40: работ в натуре, установила: _______________________________________________
A41: Подготовленный к протягиванию трубопровод (участок трубопровода, передовое звено трубопровода,
A42: пакет труб) общей длиной | B42: ='Данные '!B38 -> 3х150 | C42: м собран из труб по НД | E42: ='АОСР-1'!B67 -> Труба ПЭ F110 D160мм
A43: длиной | B43: ='Данные '!B40 -> 6 | C43: м
A45: Соединение труб выполнено сваркой (муфтами, замковыми элементами, другим способом) по НД нагревательным элементом в соответствии с проектом.
A46: Трубы имеют (не имеют) защитное покрытие типа не имеют.
A47: Передовое звено соединено с окончательным расширителем диаметра | E47: ='Форма 1'!B75 -> 500 | F47: мм
A49: На основании рассмотренных данных решили:
A50: 1. Подготовленный к протягиванию трубопровод (участок трубопровода, пакет труб) соответствует проекту.
A51: 2. Повреждений изоляции не обнаружено, сварочно-монтажные и изоляционные работы, а также испытания выполнены в полном объеме.
...

Sheet Форма 5
K1: СП 341.1325800.2017
K2: Приложение К, форма 5
G4: Строительство (ремонт) | H4: ='Данные '!B1 -> Строительство 2БКТП-10/0,4 кВ № 1 с трансформаторами 2х1250 кВА и № 2 с трансформаторами 2х1000 кВА, 2КЛ-10 кВ от яч. 6 и яч. 17 РУ-10кВ РП-10 кВ № 26116 до 1-ой и 2-ой сек. РУ-10 кВ сооруж. БКТП-10/0,4 кВ № 1, 2КЛ-10 кВ от 1-ой и 2-ой сек. РУ-10 кВ сооруж. БКТП-10/0,4 кВ № 1 до 1-ой и 2-ой сек. РУ-10 кВ сооруж. БКТП-10/0,4 кВ № 2, 48КЛ-0,4 кВ от сооруж. БКТП-10/0,4 кВ № 1 и № 2 до сооруж. ВРУ-0,4 кВ № 1, 2, 3 к.1-8, в т.ч. ПИР, МО, Солнечногорский р-н, г.п. Андреевка, р.п. Андреевка
H5: Объект | I5: ='Данные '!B36 -> ГНБ №1
A7: Журнал
A8: контроля параметров бурового раствора
A11: Показатель активности ионов водорода воды, ед. pH
A12: Дата, время | B12: Место отбора пробы раствора | C12: Параметры бурового раствора | K12: Исполнитель должность, инициалы, фамилия, подпись
C13: Плотность, г/см3 | D13: Условная вязкость, с | E13: Показатель фильтрации, см3 | F13: Толщина фильтрационной корки, мм | G13: Пластическая вязкость, мПа·с | H13: Динамическое напряжение сдвига (ДНС), дПа | I13: Статическое напряжение сдвига (СНС), дПа
I14: СНС10с | J14: СНС10мин
A15: 1 | B15: 2 | C15: 3 | D15: 4 | E15: 5 | F15: 6 | G15: 7 | H15: 8 | I15: 9 | J15: 10 | K15: 11
A16: ='Данные '!B4 -> 25.08.2025 | B16: ='Данные '!B36 -> ГНБ №1 | C16: 1.02 | D16: 82 | E16: 11 | F16: 0.6 | G16: 13 | H16: 84 | I16: 17 | J16: 80 | K16: =CONCATENATE('Данные '!B18," ",'Данные '!B17," ",'Данные '!B19) -> Гл.инженер ООО «КСС Регион» Сигарев А.А.
A19: Комплексный реагент для буровых растворов «BENTEX» ТУ №2164-003-09824493-12
A20: СЕРТИФИКАТ СООТВЕТСТВИЯ № 0233750, ПАСПОРТ КАЧЕСТВА от 30.10.2024, НОМЕР ПАРТИИ 4099

Sheet Форма 6
A1: СП 341.1325800.2017
A2: Приложение К, форма 6
A4: Строительство (ремонт) | B4: ='Данные '!B1 -> Строительство 2БКТП-10/0,4 кВ № 1 с трансформаторами 2х1250 кВА и № 2 с трансформаторами 2х1000 кВА, 2КЛ-10 кВ от яч. 6 и яч. 17 РУ-10кВ РП-10 кВ № 26116 до 1-ой и 2-ой сек. РУ-10 кВ сооруж. БКТП-10/0,4 кВ № 1, 2КЛ-10 кВ от 1-ой и 2-ой сек. РУ-10 кВ сооруж. БКТП-10/0,4 кВ № 1 до 1-ой и 2-ой сек. РУ-10 кВ сооруж. БКТП-10/0,4 кВ № 2, 48КЛ-0,4 кВ от сооруж. БКТП-10/0,4 кВ № 1 и № 2 до сооруж. ВРУ-0,4 кВ № 1, 2, 3 к.1-8, в т.ч. ПИР, МО, Солнечногорский р-н, г.п. Андреевка, р.п. Андреевка
A5: Объект | B5: ='Данные '!B36 -> ГНБ №1
C7: АКТ № | D7: ='Форма 2'!C7 -> 1
A8: приёмки ЗП, проложенного методом ГНБ
A10: Участок : | B10: ='Данные '!#REF! -> #REF!
F12: ='Форма 2'!F10 -> 25.08.2025
A15: Комиссия в составе представителей:
A17: подрядчика | B17: =CONCATENATE('Данные '!B18," ",'Данные '!B17," ",'Данные '!B19) -> Гл.инженер ООО «КСС Регион» Сигарев А.А.
B18: (должность, организация, инициалы, фамилия)
A19: генерального подрядчика | B19: =CONCATENATE('Данные '!B10," ",'Данные '!B7," ",'Данные '!B11) -> Прораб ООО "Энергосистемы" Волков М.Ю.
B20: (должность, организация, инициалы, фамилия)
A21: технического надзора заказчика
B22: (должность, организация, инициалы, фамилия)
A23: лица, осуществляющего подготовку проектной документации
B24: (должность, организация, инициалы, фамилия)
A25: лица, ответственного за эксплуатацию
B26: (должность, организация, инициалы, фамилия)
A27: провела освидетельствование работ, выполненных
A28: ='Данные '!B7 -> ООО "Энергосистемы"
A29: (наименование строительно-монтажной организации)
A30: по прокладке методом ГНБ подземного трубопровода
A31: ='Данные '!B1 -> Строительство 2БКТП-10/0,4 кВ № 1 с трансформаторами 2х1250 кВА и № 2 с трансформаторами 2х1000 кВА, 2КЛ-10 кВ от яч. 6 и яч. 17 РУ-10кВ РП-10 кВ № 26116 до 1-ой и 2-ой сек. РУ-10 кВ сооруж. БКТП-10/0,4 кВ № 1, 2КЛ-10 кВ от 1-ой и 2-ой сек. РУ-10 кВ сооруж. БКТП-10/0,4 кВ № 1 до 1-ой и 2-ой сек. РУ-10 кВ сооруж. БКТП-10/0,4 кВ № 2, 48КЛ-0,4 кВ от сооруж. БКТП-10/0,4 кВ № 1 и № 2 до сооруж. ВРУ-0,4 кВ № 1, 2, 3 к.1-8, в т.ч. ПИР, МО, Солнечногорский р-н, г.п. Андреевка, р.п. Андреевка
A32: (наименование объекта)
A34: Комиссии предъявлены:
A35: Проектная документация на устройство перехода | D35: ='Данные '!B36 -> ГНБ №1 | E35: , разработчик | F35: ='Данные '!B31 -> ООО "Энергосистемы"
A36: Проект производства работ.
A37: Протокол бурения скважины.
A38: Исполнительная производственная документация и стандартизованные формы контроля качества для данного вида коммуникации.
A39: Исполнительные чертежи планового положения и продольного профиля трубопровода.
A41: Комиссия, ознакомившись с представленными материалами, установила:
A42: Трубопровод длиной | B42: ='Данные '!B39 -> 150 | C42: м, диаметром | D42: ='Данные '!B41 -> Ø160 | E42: мм проложен методом ГНБ
A43: с использованием буровой установки типа | C43: ='Форма 1'!D11 -> XCMG, XZ360E
A45: Начало работ | B45: =B46 -> 25.08.2025
A46: Окончание работ | B46: =F12 -> 25.08.2025
A48: При выполнении работ применены:
A49: Комплексный реагент для буровых растворов «BENTEX» ТУ 2164-003-09824493-2012, Сертификат соответствия № 0233750, партия № 4099
A51: (наименование материалов, конструкций, изделий со ссылкой на документы, подтверждающие качество)
A53: При выполнении работ отсутствуют (допущены) отклонения от проектной документации
...
