Workbook

Sheet Данные организации
A1: организация | B1: ООО"Энергосистемы" | C1: ООО «Гефест» | D1: ООО "Энком" | F1: ПАО "Россети Московский регион"
A2: реквизиты | B2: ОГРН 1135044003709 ИНН 5044089069 КПП 504401001 | C2: ОГРН 1215000057238 ИНН 5044122213 КПП 504401001 | D2: ОГРН 1077762950055 ИНН 7743668640 КПП 770801001 | F2: ОГРН 1057746555811 ИНН 5036065113 КПП 772501001
A3: адрес | B3: 141508, Московская область, г.о. Солнечногорск, г. Солнечногорск, ул. Промышленная, стр. 5, помещение 179 | C3: 141508, Московская область, г.о. Солнечногорск, г Солнечногорск, ул Промышленная, строение 29А, корпус 1, офис 11 | D3: 107140, г.Москва, ул. Краснопрудная, д. 12/1, стр. 1, помещ. 1/6 | F3: 115114, город Москва, проезд Павелецкий 2-й, дом 3, строение 2
A4: район | F4: Солнечногорский р-н | G4: Химкинский р-н
F5: СРЭС филиала | G5: ХРЭС филиала
A6: директор | B6: И.о.генерального директора | C6: Генеральный директор | D6: Генеральный директор | F6: Начальник СРЭС СЭС филиала | G6: Начальник ХРЭС СЭС филиала
A7: директор ФИО | B7: Чернявская Н.Ю. | C7: Звездов Р.Е. | D7: Дандре Г.А. | F7: Чуев А.Н. | G7: Игнатьев К.А.
A8: Строй.контроль | B8: Инженер по строительному контролю | C8: Специалист по строительному контролю | D8: Специалист по строительному контролю | F8: Гл. специалист ССК УКС | G8: Гл. специалист ССК УКС
A9: Приказ стр.контр. | B9: Приказ № 18-ОТ/24 от 03 июня 2024 (НОСТРОЙ С-50-188017) | C9: Приказ №01/24-ОТ от 15.01.2024 (НРС № С-61-104369) | D9: НРС № С-77-286715 | F9: Приказ №263 от 31 января 2024г (НОСТРОЙ С-50-138711) | G9: Приказ №263 от 31 января 2024г (НОСТРОЙ С-50-15922)
A10: ФИО стр.контр. | B10: Капитонов Д.А. | C10: Саженова Л.В. | D10: Филлипов А.Ю. | F10: Жижкевич М.А. | G10: Хлебнов Д.Ф.
A11: Представитель | F11: Мастер СРЭС СЭС филиала | G11: Технический надзор | I11: 60
A12: ФИО предст. | F12: Набоков С.А. | I12: 36
F14: Мастер СРЭС СЭС филиала | G14: Гл.инженер
F15: Набоков С.А. | G15: Петрунин А.Ю.
A18: Прораб | B18: Прораб | C18: Мастер электромонтажного участка | D18: Главный инженер
A19: Приказ прораб | B19: Приказ №05-ОТ/24 от 09 января 2024г | C19: Приказ №01/24-ОТ от 15.01.2024 | D19: Приказ № ОТ-25 от 12.01.2024
A20: ФИО прораб | B20: Волков М.Ю. | C20: Красилов К.А. | D20: Горбан Г.К.
A23: сцепленные организация | B23: =CONCATENATE(B2,",",B3) -> ОГРН 1135044003709 ИНН 5044089069 КПП 504401001,141508, Московская область, г.о. Солнечногорск, г. Солнечногорск, ул. Промышленная, стр. 5, помещение 179 | C23: =CONCATENATE(C2,",",C3) -> ОГРН 1215000057238 ИНН 5044122213 КПП 504401001,141508, Московская область, г.о. Солнечногорск, г Солнечногорск, ул Промышленная, строение 29А, корпус 1, офис 11 | F23: =CONCATENATE(F8," ",F1,"-",F10," .",F9) -> Гл. специалист ССК УКС ПАО "Россети Московский регион"-Жижкевич М.А. .Приказ №263 от 31 января 2024г (НОСТРОЙ С-50-138711) | G23: =CONCATENATE(G8," ",F1,"-",G10," .",G9) -> Гл. специалист ССК УКС ПАО "Россети Московский регион"-Хлебнов Д.Ф. .Приказ №263 от 31 января 2024г (НОСТРОЙ С-50-15922)
A24: сцепленные организация | B24: =CONCATENATE(B1,",",B2,",",B3) -> ООО"Энергосистемы",ОГРН 1135044003709 ИНН 5044089069 КПП 504401001,141508, Московская область, г.о. Солнечногорск, г. Солнечногорск, ул. Промышленная, стр. 5, помещение 179 | C24: =CONCATENATE(C1,",",C2,",",C3) -> ООО «Гефест»,ОГРН 1215000057238 ИНН 5044122213 КПП 504401001,141508, Московская область, г.о. Солнечногорск, г Солнечногорск, ул Промышленная, строение 29А, корпус 1, офис 11 | F24: =CONCATENATE(F8," ",F1,"-",F10) -> Гл. специалист ССК УКС ПАО "Россети Московский регион"-Жижкевич М.А. | G24: =CONCATENATE(G8," ",F1,"-",G10) -> Гл. специалист ССК УКС ПАО "Россети Московский регион"-Хлебнов Д.Ф.
B25: =CONCATENATE(B8," ",B1,"-",B10,".",B9) -> Инженер по строительному контролю ООО"Энергосистемы"-Капитонов Д.А..Приказ № 18-ОТ/24 от 03 июня 2024 (НОСТРОЙ С-50-188017) | C25: =CONCATENATE(C8," ",C1,"-",C10,".",C9) -> Специалист по строительному контролю ООО «Гефест»-Саженова Л.В..Приказ №01/24-ОТ от 15.01.2024 (НРС № С-61-104369) | F25: =CONCATENATE(F8," ",F1) -> Гл. специалист ССК УКС ПАО "Россети Московский регион" | G25: =CONCATENATE(G8," ",F1) -> Гл. специалист ССК УКС ПАО "Россети Московский регион"
B26: =CONCATENATE(B8," ",B1) -> Инженер по строительному контролю ООО"Энергосистемы" | C26: =CONCATENATE(C8," ",C1) -> Специалист по строительному контролю ООО «Гефест» | F26: =CONCATENATE(F6," ",F1," ",F7) -> Начальник СРЭС СЭС филиала ПАО "Россети Московский регион" Чуев А.Н. | G26: =CONCATENATE(G6," ",F1," ",G7) -> Начальник ХРЭС СЭС филиала ПАО "Россети Московский регион" Игнатьев К.А.
B27: =CONCATENATE(B18," ",B1,"-",B20,".",B19) -> Прораб ООО"Энергосистемы"-Волков М.Ю..Приказ №05-ОТ/24 от 09 января 2024г | C27: =CONCATENATE(C18," ",C1,"-",C20,".",C19) -> Мастер электромонтажного участка ООО «Гефест»-Красилов К.А..Приказ №01/24-ОТ от 15.01.2024 | F27: =CONCATENATE(F14," ",F1," ",F15) -> Мастер СРЭС СЭС филиала ПАО "Россети Московский регион" Набоков С.А. | G27: =CONCATENATE(G14," ",F1," ",G15) -> Гл.инженер ПАО "Россети Московский регион" Петрунин А.Ю.
B28: =CONCATENATE(B18," ",B1," ",B20) -> Прораб ООО"Энергосистемы" Волков М.Ю. | C28: =CONCATENATE(C18," ",C1,"-",C20) -> Мастер электромонтажного участка ООО «Гефест»-Красилов К.А. | F28: =CONCATENATE(F16," ",F1," ",F17) -> ПАО "Россети Московский регион"
B29: =CONCATENATE(B18," ",B1) -> Прораб ООО"Энергосистемы" | C29: =CONCATENATE(C18," ",C1) -> Мастер электромонтажного участка ООО «Гефест»

Sheet Данные объект
A1: Данные объекта
A2: № САП | B2: SAP - 297671
A3: Объект | B3: Реконструкция КТП-6/0,4 кВ кВ № 4118 путем замены трансформаторов 2х630 кВА на трансформаторы 2х1000 кВА и замены АВ в РУ-0,4 кВ, ПС-110/20/10/6 кВ № 429 Шереметьево, в т.ч. ПИР, МО, Солнечногорский р-н, г. Лобня, Шереметьевское ш., д.10
A4: р-н | B4: Солнечногорский р-н
A5: Адрес | B5: Лобня г, Шереметьевское ш, дом 10
A6: Дата разбивки | B6: Дата разбивки гео
A7: Дата старт | B7: Дата старт
A8: Дата финиш | B8: 25.06.2025
A9: год | B9: 2025
A10: Температура воздуха | B10: 15
A11: Влажность | B11: 70
A12: Атмосферное давление | B12: 745
A13: Наименование электроустановки
A14: Общий | B14: =_xlfn.CONCAT(B15, " ",B16, " ",B17, " ",B18, " ",B19, " ", B20) -> КТП № АСП № ВЛ от ТП ф. ВЛ от ТП ф. КЛ от ТП ф ВРЩ вблизи ТП
A15: ТП | B15: КТП №
A16: ТП | B16: АСП №
A17: ВЛ-10 | B17: ВЛ от ТП ф.
A18: ВЛ-0,4 | B18: ВЛ от ТП ф.
A19: КЛ | B19: КЛ от ТП ф
A20: ВРЩ | B20: ВРЩ вблизи ТП
A21: Монтажная организация
A22: Организация | B22: ООО"Энергосистемы" | C22: =CONCATENATE(B22," ",B23," ",B24) -> ООО"Энергосистемы" ОГРН 1135044003709 ИНН 5044089069 КПП 504401001 141508, Московская область, г.о. Солнечногорск, г. Солнечногорск, ул. Промышленная, стр. 5, помещение 179
A23: Реквизиты | B23: ='Данные организации'!B2 -> ОГРН 1135044003709 ИНН 5044089069 КПП 504401001
A24: адрес | B24: ='Данные организации'!B3 -> 141508, Московская область, г.о. Солнечногорск, г. Солнечногорск, ул. Промышленная, стр. 5, помещение 179
A25: Должность | B25: Генеральный директор
A26: ФИО | B26: Звездов Р.Е. | C26: =CONCATENATE(B25," ",B22," ",B26) -> Генеральный директор ООО"Энергосистемы" Звездов Р.Е.
A27: Должность | B27: Специалист по строительному контролю | C27: =CONCATENATE(B27," ",B22) -> Специалист по строительному контролю ООО"Энергосистемы"
A28: Ф.И.О. | B28: Саженова Л.В. | C28: =CONCATENATE(B27," ",B22," ",B28) -> Специалист по строительному контролю ООО"Энергосистемы" Саженова Л.В.
A29: Приказ | B29: Приказ №01/24-ОТ от 15.01.2024 (НРС № С-61-104369) | C29: =CONCATENATE(B27," ",B22," ",B28,".",B29) -> Специалист по строительному контролю ООО"Энергосистемы" Саженова Л.В..Приказ №01/24-ОТ от 15.01.2024 (НРС № С-61-104369)
A30: Должность | B30: Мастер электромонтажного участка | C30: =CONCATENATE(B30," ",B22) -> Мастер электромонтажного участка ООО"Энергосистемы"
A31: Ф.И.О. | B31: Красилов К.А. | C31: =CONCATENATE(B30," ",B22," ",B31) -> Мастер электромонтажного участка ООО"Энергосистемы" Красилов К.А.
A32: Приказ | C32: =CONCATENATE(B30," ",B22," ",B31,".",B32) -> Мастер электромонтажного участка ООО"Энергосистемы" Красилов К.А..
A33: Заказчик
A34: Организация | B34: ='Данные организации'!F1 -> ПАО "Россети Московский регион"
A35: Реквизиты | B35: ='Данные организации'!F2 -> ОГРН 1057746555811 ИНН 5036065113 КПП 772501001
A36: адрес | B36: ='Данные организации'!F3 -> 115114, город Москва, проезд Павелецкий 2-й, дом 3, строение 2
A37: Должность | C37: =CONCATENATE(B37," ",B34) -> ПАО "Россети Московский регион"
A38: Ф.И.О. | C38: =CONCATENATE(B37," ",B34," ",B38) -> ПАО "Россети Московский регион"
A39: Должность | C39: =CONCATENATE(B39," ",B34) -> ПАО "Россети Московский регион"
A40: Ф.И.О. | C40: =CONCATENATE(B39," ",B34," ",B40) -> ПАО "Россети Московский регион"
...

Sheet Оборудование
A1: № п/п | B1: Тип | F1: Заводской номер | G1: Метрологические характеристики | I1: Дата поверки очередная | J1: № аттестата (свидетельства) | N1: Просрочен
G2: Диапазон измерения | H2: Класс точности | N2: Действителен
A3: 2 | B3: Микроомметр ИКС-30А | F3: 134 | G3: 1[мОм]¸ 100[кОм] | H3: 0.1 | I3: 47945 | J3: С-ТТ/08-04-2026/517582895
A4: 5 | B4: Мегаомметр Е6-32 | F4: 13909.21 | G4: 1[Ом]- 99,9[ГОм] | H4: 2,5 | I4: 46850 | J4: С-ТТ/08-04-2026/517582908
A5: 6 | B5: Гигрометр ВИТ-1 | F5: 575164 | G5: 0-25 0С | H5: 0.2 | I5: 46859 | J5: С-ТТ/17-04-2026/519855627
A6: 7 | B6: Измеритель сопротивления ИФН-300 | F6: 5723.21 | G6: 10-450В | H6: 0.025 | I6: 46850 | J6: С-ТТ/08-04-2026/517582901
A7: 8 | B7: Измерители параметров УЗО ПЗО-510 | F7: 0367.21 | G7: 10-500мА | H7: 0.025 | I7: 46850 | J7: С-ТТ/08-04-2026/517582904
A8: 9 | B8: Токовые клещи Р-266F | F8: 2305044479 | G8: 2-1000В | H8: 2.5 | I8: - | J8: 0100-002477-2024-2305044479
A9: 10 | B9: Барометр БАММ-1 | F9: 914 | G9: 80-60кПа | H9: 0.2 | I9: 46171 | J9: С-ТТ/29-05-2025/436149634
A10: 11 | B10: Клещи токоизмерительные многофункциональные | F10: 1 | G10: 2-1000В | H10: 2.5 | I10: - | J10: 0100-003808-2025-1
A11: 12 | B11: Устройство комплектное испытательные Сатурн-М | F11: 21091434 | G11: 25-2000А | H11: 1.5 | I11: 46175 | J11: С-ТТ/02-06-2025/436806316
A12: 13 | B12: Аппараты испытания диэлектриков СКАТ-70М | F12: 15036 | G12: 0-70кВ | H12: 2 | I12: 46175 | J12: С-ТТ/02-06-2025/436900431
A13: 14 | B13: Измеритель сопротивления заземления ИС-20 | F13: 3141 | G13: 0,01- 999 Ом | H13: 3 | I13: 46850 | J13: С-ТТ/08-04-2026/517582910

Sheet Титул
A3: ИСПЫТАТЕЛЬНАЯ ЛАБОРАТОРИЯ
A4: ЭЛЕКТРОУСТАНОВОК ЗДАНИЙ
A5: ='Данные объект'!B58 -> ООО «Энергосистемы»
A10: Свидетельство о регистрации лаборатории:
A11: ='Данные объект'!B63 -> №5.3-6420 от 15 мая 2024г
A12: ='Данные объект'!B68 -> Действительно до 16 мая 2027г
A13: ='Данные объект'!C22 -> ООО"Энергосистемы" ОГРН 1135044003709 ИНН 5044089069 КПП 504401001 141508, Московская область, г.о. Солнечногорск, г. Солнечногорск, ул. Промышленная, стр. 5, помещение 179
A14: Тел. _____________
A15: e-mail: _______________
A20: Руководитель испытательной лаборатории
A21: =A5 -> ООО «Энергосистемы»
A23: ='Данные объект'!B62 -> Щербаков А.А.
A29: ТЕХНИЧЕСКИЙ ОТЧЕТ №1 от | H29: ='Данные объект'!B8 -> 25.06.2025
A30: проверки (испытаний) электроустановки
A32: ='Данные объект'!B14 -> КТП № АСП № ВЛ от ТП ф. ВЛ от ТП ф. КЛ от ТП ф ВРЩ вблизи ТП
A33: наименование электроустановки
A35: по адресу: | C35: ='Данные объект'!B5 -> Лобня г, Шереметьевское ш, дом 10
A37: Заказчик: | C37: ='Данные объект'!B34 -> ПАО "Россети Московский регион"
A39: Цель испытаний: | D39: Приемо-сдаточные
A49: Листов всего:
A50: Протокол испытаний распространяется только на электроустановки зданий и сооружений, подвергаемых испытаниям.
A51: Протокол испытаний не может быть частично или полностью перепечатан без разрешения Заказчика или Испытательной лаборатории.
A52: Отчет прошивается, в конце каждого протокола рядом с подписями ставится печать Испытательной лаборатории.
F55: ='Данные объект'!B9 -> 2025

Sheet прот.№1
A1: ='Данные объект'!B58 -> ООО «Энергосистемы» | G1: Заказчик: | H1: ='Данные объект'!B34 -> ПАО "Россети Московский регион"
A2: ='Данные объект'!C58 -> Испытательная электролаборатория 141508, Московская область, г.о. Солнечногорск, г. Солнечногорск, ул. Промышленная, стр. 5, помещение 179, Свидетельсто о регистрации №5.3-6420 от 15 мая 2024г | G2: Объект: | H2: =_xlfn.CONCAT('Данные объект'!$B$15, " ",'Данные объект'!$B$16) -> КТП № АСП №
G3: Адрес: | H3: ='Данные объект'!B5 -> Лобня г, Шереметьевское ш, дом 10
J5: Дата проведения испытания:
J6: ='Данные объект'!B8 -> 25.06.2025
A7: Протокол №1
A8: проверки сопротивлений заземлителей и заземляющих устройств
A10: 1. Результаты внешнего осмотра (целостности и надёжности заземляющих устройств):
A11: удовлетворительно
A12: 2. Вид грунта: | B12: суглинок
A13: 3. Характер грунта: | D13: средней влажности
D14: (влажный, средней влажности, сухой)
A15: 4. Заземляющее устройство, применяемое для электроустановки: | F15: до и выше 1000 В
F16: (до 1000 В, до и выше 1000 В, свыше 1000 В)
A17: 5. Режим нейтрали: | C17: глухозаземленная
A18: 6. Удельное сопротивление грунта, Ом × м: | E18: 100
A19: Результаты испытаний:
A20: № п/п | B20: Назначение заземлителя, заземляющего устройства | E20: Расстояние до потенциальных и токовых электродов, м | F20: Сопротивление заземлителей (заземляющих устройств), Ом | I20: Кпопр. | J20: Вывод о соответств. Нормативн. Документу
F21: Допус-тимое | G21: Изме-ренное | H21: Приведённое
A22: 1 | B22: Контур заземления КТП №3865 | E22: 20-30 | F22: 4,0 | G22: 2,2 | H22: 2,2 | I22: 1,0 | J22: Соответств. НД
A23: 2 | B23: Трансформатор ТМГ-400/6 У1; 6/0,4 | E23: 20-30 | F23: 4,0 | G23: 2.1 | H23: 2.3 | I23: 1,0 | J23: Соответств. НД
A25: 8. Условия окружающей среды при проведении измерений:
A26: 8.1 Температура воздуха | C26: ='Данные объект'!B10 -> 15 | D26: °С
A27: 8.2 Влажность | C27: ='Данные объект'!B11 -> 70 | D27: %
A28: 8.3 Атмосферное давление | C28: ='Данные объект'!B12 -> 745 | D28: мм рт. ст.
A29: 9. Нормативно-технический документ: Таблица 35, 36 ПТЭЭП, п.1.8.39. ПУЭ.
A30: 10. Измерительные приборы:
A32: № п/п | B32: Тип | F32: Заводской номер | G32: Метрологические характеристики | I32: Дата поверки очередная | J32: № аттестата (свидетельства)
G33: Диапазон измерения | H33: Класс точности
A34: 1 | B34: Мегаомметр Е6-32 | F34: 13909.21 | G34: 1[Ом]- 99,9[ГОм] | H34: 2,5 | I34: =Оборудование!I4 -> 46850 | J34: =Оборудование!J4 -> С-ТТ/08-04-2026/517582908
A35: 2 | B35: Микроомметр ИКС-30А | F35: 134 | G35: 1[мОм]¸ 100[кОм] | H35: 0.1 | I35: =Оборудование!I3 -> 47945 | J35: =Оборудование!J3 -> С-ТТ/08-04-2026/517582895
A36: 3 | B36: Аппараты испытания диэлектриков СКАТ-70М | F36: 15036 | G36: 0-70кВ | H36: 2 | I36: =Оборудование!I12 -> 46175 | J36: =Оборудование!J12 -> С-ТТ/02-06-2025/436900431
A37: 4 | B37: Измеритель сопротивления заземления ИС-20 | F37: 3141 | G37: 0,01- 999 Ом | H37: 3 | I37: =Оборудование!I13 -> 46850 | J37: =Оборудование!J13 -> С-ТТ/08-04-2026/517582910
A38: 11. Заключение на соответствие требованиям НТД: Данные измерений и испытаний соответствуют нормам НТД. Годно к эксплуатации.
A39: Объёмы ПНР утверждены заказчиком.
A40: Проверку провели: | C40: ='Данные объект'!$B$64 -> Зам. руководителя ЭИЛ | I40: ='Данные объект'!$B$65 -> Фечин А.А.
C41: (должность) | G41: (подпись) | I41: (Ф.И.О.)
C44: ='Данные объект'!$B$66 -> Инженер ЭИЛ | I44: ='Данные объект'!$B$67 -> Косырин А.Н.
C45: (должность) | G45: (подпись) | I45: (Ф.И.О.)
A47: Проверил: | C47: ='Данные объект'!$B$61 -> Руководитель ЭИЛ | I47: ='Данные объект'!$B$62 -> Щербаков А.А.
...

Sheet прот.№2
A1: ='Данные объект'!B58 -> ООО «Энергосистемы» | G1: Заказчик: | H1: ='Данные объект'!B34 -> ПАО "Россети Московский регион"
A2: ='Данные объект'!C58 -> Испытательная электролаборатория 141508, Московская область, г.о. Солнечногорск, г. Солнечногорск, ул. Промышленная, стр. 5, помещение 179, Свидетельсто о регистрации №5.3-6420 от 15 мая 2024г | G2: Объект: | H2: =_xlfn.CONCAT('Данные объект'!$B$15, " ",'Данные объект'!$B$16) -> КТП № АСП №
G3: Адрес: | H3: ='Данные объект'!B5 -> Лобня г, Шереметьевское ш, дом 10
J5: Дата проведения испытания:
J6: ='Данные объект'!B8 -> 25.06.2025
A7: Протокол №2
A8: проверки цепи между заземлителями и заземляемыми элементами
A10: Результаты испытаний:
A11: п/п | B11: Месторасположение и наименование электрооборудования | F11: Сопротивление цепи заземления (Ом) | J11: Вывод о соответствии нормативному документу
F12: Измеренное | H12: Значение по НД
A13: 1 | B13: Контур заземления КТП №3865 | F13: 0,02 | H13: ≤ 0,05 | J13: Соответств. НД
A14: 2 | B14: Трансформатор ТМГ-400/6 У1; 6/0,4 | F14: 0,03 | H14: ≤ 0,05 | J14: Соответств. НД
A15: 3 | B15: Камера сборная КСО-399 | F15: 0,02 | H15: ≤ 0,05 | J15: Соответств. НД
A16: 2. Условия окружающей среды при проведении измерений:
A17: 2.1 Температура воздуха | C17: =прот.№1!C26 -> 15 | D17: °С
A18: 2.2 Влажность | C18: =прот.№1!C27 -> 70 | D18: %
A19: 2.3 Атмосферное давление | C19: =прот.№1!C28 -> 745 | D19: мм рт. ст.
A20: 3. Нормативно-технический документ: Приложение № 3, пп 26.1,28.5 ПТЭЭП, п.1.8.39. ПУЭ.
A21: 4. Измерительные приборы:
A23: № п/п | B23: Тип | F23: Заводской номер | G23: Метрологические характеристики | I23: Дата поверки очередная | J23: № аттестата (свидетельства)
G24: Диапазон измерения | H24: Класс точности
A25: 1 | B25: Мегаомметр Е6-32 | F25: 13909.21 | G25: 1[Ом]- 99,9[ГОм] | H25: 2,5 | I25: =Оборудование!I4 -> 46850 | J25: =Оборудование!J4 -> С-ТТ/08-04-2026/517582908
A26: 2 | B26: Микроомметр ИКС-30А | F26: 134 | G26: 1[мОм]¸ 100[кОм] | H26: 0.1 | I26: =Оборудование!I3 -> 47945 | J26: =Оборудование!J3 -> С-ТТ/08-04-2026/517582895
A27: 3 | B27: Аппараты испытания диэлектриков СКАТ-70М | F27: 15036 | G27: 0-70кВ | H27: 2 | I27: =Оборудование!I12 -> 46175 | J27: =Оборудование!J12 -> С-ТТ/02-06-2025/436900431
A28: 4 | B28: Измеритель сопротивления заземления ИС-20 | F28: 3141 | G28: 0,01- 999 Ом | H28: 3 | I28: =Оборудование!I13 -> 46850 | J28: =Оборудование!J13 -> С-ТТ/08-04-2026/517582910
A30: 5. Заключение на соответствие требованиям НТД:
A31: 5.1. Проверена целостность и прочность проводников заземления и зануления, переходные контакты их соединений.
A32: Сопротивление переходных контактов выше нормы, указаны в п/п нет.
A33: Не заземлено оборудование, указанное в п/п нет.
A34: Величина измеренного переходного сопротивления контактов заземляющих и нулевых проводников, элементов электрооборудования соответствует нормам НТД.
A35: Объёмы ПНР утверждены заказчиком.
A37: Проверку провели: | C37: ='Данные объект'!$B$64 -> Зам. руководителя ЭИЛ | I37: ='Данные объект'!$B$65 -> Фечин А.А.
C38: (должность) | G38: (подпись) | I38: (Ф.И.О.)
C41: ='Данные объект'!$B$66 -> Инженер ЭИЛ | I41: ='Данные объект'!$B$67 -> Косырин А.Н.
C42: (должность) | G42: (подпись) | I42: (Ф.И.О.)
A44: Проверил: | C44: ='Данные объект'!$B$61 -> Руководитель ЭИЛ | I44: ='Данные объект'!$B$62 -> Щербаков А.А.
C45: (должность) | G45: (подпись) | I45: (Ф.И.О.)

Sheet прот.№3
A1: ='Данные объект'!B58 -> ООО «Энергосистемы» | G1: Заказчик: | H1: ='Данные объект'!B34 -> ПАО "Россети Московский регион"
A2: ='Данные объект'!C58 -> Испытательная электролаборатория 141508, Московская область, г.о. Солнечногорск, г. Солнечногорск, ул. Промышленная, стр. 5, помещение 179, Свидетельсто о регистрации №5.3-6420 от 15 мая 2024г | G2: Объект: | H2: =_xlfn.CONCAT('Данные объект'!$B$15, " ",'Данные объект'!$B$16) -> КТП № АСП №
G3: Адрес: | H3: ='Данные объект'!B5 -> Лобня г, Шереметьевское ш, дом 10
J5: Дата проведения испытания:
J6: ='Данные объект'!B8 -> 25.06.2025
A7: Протокол №3
A8: испытания изоляции повышенным напряжением переменного тока
A10: № | B10: Наименование объектов испытаний | C10: Номин. напряжкВ. | D10: Рабочее. напряж. кВ. | E10: Сопрот. изоляции. МОм. | F10: Испытат. напряж. кВ | G10: Продолж. испыт. (мин.) | H10: Результат испытания.
B11: Опора №1. Разъединитель РЛНД-1-10/400У1
A12: 1 | B12: ф. А | C12: 10 | D12: 6 | E12: 20 000 | F12: 32 | G12: 1 | H12: выдержали
A13: 2 | B13: ф. В | C13: 10 | D13: 6 | E13: 20 000 | F13: 32 | G13: 1 | H13: выдержали
A14: 3 | B14: ф. С | C14: 10 | D14: 6 | E14: 20 000 | F14: 32 | G14: 1 | H14: выдержали
B15: КТП-3865 (штырьевые изоляторы и КЛ-10кВ СИП-3)
A16: 4 | B16: ф. А | C16: 10 | D16: 10 | E16: 15 000 | F16: 32 | G16: 1 | H16: выдержали
A17: 5 | B17: ф. В | C17: 10 | D17: 10 | E17: 15 000 | F17: 32 | G17: 1 | H17: выдержали
A18: 6 | B18: ф. С | C18: 10 | D18: 10 | E18: 15 000 | F18: 32 | G18: 1 | H18: выдержали
B19: КТП-3865 (Включатель нагрузки ВНА-10/630)
A20: 7 | B20: ф. А | C20: 10 | D20: 10 | E20: 25 000 | F20: 32 | G20: 1 | H20: выдержали
A21: 8 | B21: ф. В | C21: 10 | D21: 10 | E21: 25 000 | F21: 32 | G21: 1 | H21: выдержали
A22: 9 | B22: ф. С | C22: 10 | D22: 10 | E22: 25 000 | F22: 32 | G22: 1 | H22: выдержали
A24: НОРМАТИВНЫЕ ДОКУМЕНТЫ: т.18 ПЭЭП; т.1.8.37; т.1.8.35 ПУЭ
A25: ЗАКЛЮЧЕНИЕ: Оборудование испытание выдержало и может нормально эксплуатироваться.
A26: Перепечатка без разрешения производственной лаборатории запрещена.
A27: Объёмы ПНР утверждены заказчиком.
A29: Измерительные приборы:
A31: № п/п | B31: Тип | F31: Заводской номер | G31: Метрологические характеристики | I31: Дата поверки очередная | J31: № аттестата (свидетельства)
G32: Диапазон измерения | H32: Класс точности
A33: 1 | B33: Мегаомметр Е6-32 | F33: 13909.21 | G33: 1[Ом]- 99,9[ГОм] | H33: 2,5 | I33: =Оборудование!I4 -> 46850 | J33: =Оборудование!J4 -> С-ТТ/08-04-2026/517582908
A34: 2 | B34: Микроомметр ИКС-30А | F34: 134 | G34: 1[мОм]¸ 100[кОм] | H34: 0.1 | I34: =Оборудование!I3 -> 47945 | J34: =Оборудование!J3 -> С-ТТ/08-04-2026/517582895
A35: 3 | B35: Аппараты испытания диэлектриков СКАТ-70М | F35: 15036 | G35: 0-70кВ | H35: 2 | I35: =Оборудование!I12 -> 46175 | J35: =Оборудование!J12 -> С-ТТ/02-06-2025/436900431
A36: 4 | B36: Измеритель сопротивления заземления ИС-20 | F36: 3141 | G36: 0,01- 999 Ом | H36: 3 | I36: =Оборудование!I13 -> 46850 | J36: =Оборудование!J13 -> С-ТТ/08-04-2026/517582910
A38: Проверку провели: | C38: ='Данные объект'!$B$64 -> Зам. руководителя ЭИЛ | I38: ='Данные объект'!$B$65 -> Фечин А.А.
C39: (должность) | G39: (подпись) | I39: (Ф.И.О.)
C42: ='Данные объект'!$B$66 -> Инженер ЭИЛ | I42: ='Данные объект'!$B$67 -> Косырин А.Н.
C43: (должность) | G43: (подпись) | I43: (Ф.И.О.)
A45: Проверил: | C45: ='Данные объект'!$B$61 -> Руководитель ЭИЛ | I45: ='Данные объект'!$B$62 -> Щербаков А.А.
C46: (должность) | G46: (подпись) | I46: (Ф.И.О.)

Sheet прот.№4
A1: ='Данные объект'!B58 -> ООО «Энергосистемы» | G1: Заказчик: | H1: ='Данные объект'!B34 -> ПАО "Россети Московский регион"
A2: ='Данные объект'!C58 -> Испытательная электролаборатория 141508, Московская область, г.о. Солнечногорск, г. Солнечногорск, ул. Промышленная, стр. 5, помещение 179, Свидетельсто о регистрации №5.3-6420 от 15 мая 2024г | G2: Объект: | H2: =_xlfn.CONCAT('Данные объект'!$B$15, " ",'Данные объект'!$B$16) -> КТП № АСП №
G3: Адрес: | H3: ='Данные объект'!B5 -> Лобня г, Шереметьевское ш, дом 10
J5: Дата проведения испытания:
J6: 45803
A7: Протокол №4
A8: испытания силового трансформатора
A9: 1. Паспортные данные трансформатора
A10: Тип | B10: Заводской № | C10: Обозначение обмоток | D10: Мощность кВА | E10: Напряжение кВ | F10: Ток А | G10: Uк,% | H10: Группа соединения | I10: Охлаждение
A11: ТМГ-1000/6-0,4 | B11: №2402ИГ055 | C11: А, В, С | D11: 1000 | E11: 6 | F11: 96.2 | G11: 5.41 | H11: Y/Yн-0 | I11: Естеств.
C12: а, в, с, 0 | E12: 0.4 | F12: 1443.4
A13: 2. Сопротивление (Ом) обмоток постоянному току при температуре + 20˚ С
A14: Фаза | B14: Наименование обмоток
B15: Первичная | G15: Вторичная
B16: Положение переключателя
B17: I | C17: II | D17: III | E17: IV | F17: V
A18: АВ | B18: 0.3754 | C18: 0.3727 | D18: 0.3533 | E18: 0.3449 | F18: 0.3325 | G18: а-0 | H18: 0.001444
A19: ВС | B19: 0.3754 | C19: 0.3669 | D19: 0.3558 | E19: 0.344 | F19: 0.3318 | G19: в-0 | H19: 0.001439
A20: АС | B20: 0.3768 | C20: 0.3677 | D20: 0.3547 | E20: 0.3445 | F20: 0.331 | G20: с-0 | H20: 0.0014641
A21: Максимальное расхождение между фазами, % | B21: 0.37 | C21: 1.57 | D21: 0.7 | E21: 0.26 | F21: 0.45 | H21: 0.0007332
A22: 3. Сопротивление изоляции обмоток относительно корпуса и других обмоток измеренное
A23: мегомметром MIC-2500 : высшего напряжения 3550 МОм, низшего 3920 МОм.
A25: 4. Увлажнённость обмоток проверена методом абсорбции при температуре + 10 С
A26: Кабс = R60/R15 Кабс = 3550/1974 = 1,8
A28: 5. Дополнительные испытания:
A29: а) Измерение коэффициента трансформации.
A30: Положение Переключателя | B30: АВ – ав | E30: ВС - вс | H30: СА - са
B31: Напряжение | D31: Коэфф. трансф. | E31: Напряжение | G31: Коэфф. трансф. | H31: Напряжение | J31: Коэфф. трансф.
B32: АВ | C32: ав | E32: ВС | F32: вс | H32: СА | I32: са
A33: I | B33: - | C33: - | D33: - | E33: - | F33: - | G33: - | H33: - | I33: - | J33: -
A34: II | B34: - | C34: - | D34: - | E34: - | F34: - | G34: - | H34: - | I34: - | J34: -
A35: III | B35: - | C35: - | D35: - | E35: - | F35: - | G35: - | H35: - | I35: - | J35: -
A36: IV | B36: - | C36: - | D36: - | E36: - | F36: - | G36: - | H36: - | I36: - | J36: -
A37: V | B37: - | C37: - | D37: - | E37: - | F37: - | G37: - | H37: - | I37: - | J37: -
A38: 6. Замечания и приложения: __Переключатель положений установлен в положение III__
A40: 7. Нормативно-технический документ: Приложение 3 Раздел 2 ПТЭЭП; глава 1.8.16. ПУЭ;
A41: Раздел 6 РД 34.45-51.300-97
A42: Объёмы ПНР утверждены заказчиком.
A44: 8. Измерительные приборы:
A46: № п/п | B46: Тип | F46: Заводской номер | G46: Метрологические характеристики | I46: Дата поверки очередная | J46: № аттестата (свидетельства)
...

Sheet прот.№5
A1: ='Данные объект'!B58 -> ООО «Энергосистемы» | G1: Заказчик: | H1: ='Данные объект'!B34 -> ПАО "Россети Московский регион"
A2: ='Данные объект'!C58 -> Испытательная электролаборатория 141508, Московская область, г.о. Солнечногорск, г. Солнечногорск, ул. Промышленная, стр. 5, помещение 179, Свидетельсто о регистрации №5.3-6420 от 15 мая 2024г | G2: Объект: | H2: =_xlfn.CONCAT('Данные объект'!$B$15, " ",'Данные объект'!$B$16) -> КТП № АСП №
G3: Адрес: | H3: ='Данные объект'!B5 -> Лобня г, Шереметьевское ш, дом 10
J5: Дата проведения испытания:
J6: ='Данные объект'!B8 -> 25.06.2025
A7: Протокол №5
A8: испытания разрядников и ОПН
A10: Паспортные данные:
A11: Тип | B11: Номинальное линейное 1 элем., кВ | C11: Конструктивное исполнение | E11: Дополнительные данные
C12: Число элементов на фазу | D12: Ном. напр. элем. на фазу, кВ
A13: ОПН-П-6/7, 6/10/550 УХЛ1 | B13: 6 | C13: 1 | D13: 6 | E13: -
A15: Результат испытаний
A17: Место установки | B17: Фаза | C17: Порядковый номер элемента, считая сверху | D17: Заводской № элемента | E17: Сопротив-ление изоляции, МОм | F17: Измерение токов проводимости | H17: Пробивное напряжение, кВ
F18: Перем. напряж., кВ | G18: Ток проводи- мости, мА
A19: КСО-399 | B19: А | C19: А 436907 | D19: 15 700 | E19: 7,6 | F19: 0,52 | G19: 0,9 | H19: Соответствует
B20: В | C20: А 436908 | D20: 15 700 | E20: 7,6 | F20: 0,54 | G20: 0,9 | H20: Соответствует
B21: С | C21: А 436906 | D21: 16 700 | E21: 7,6 | F21: 0,57 | G21: 0,9 | H21: Соответствует
A23: Примененные приборы и оборудование:
A25: № п/п | B25: Тип | F25: Заводской номер | G25: Метрологические характеристики | I25: Дата поверки очередная | J25: № аттестата (свидетельства)
G26: Диапазон измерения | H26: Класс точности
A27: 1 | B27: Мегаомметр Е6-32 | F27: 13909.21 | G27: 1[Ом]- 99,9[ГОм] | H27: 2,5 | I27: =Оборудование!I4 -> 46850 | J27: =Оборудование!J4 -> С-ТТ/08-04-2026/517582908
A28: 2 | B28: Микроомметр ИКС-30А | F28: 134 | G28: 1[мОм]¸ 100[кОм] | H28: 0.1 | I28: =Оборудование!I3 -> 47945 | J28: =Оборудование!J3 -> С-ТТ/08-04-2026/517582895
A29: 3 | B29: Аппараты испытания диэлектриков СКАТ-70М | F29: 15036 | G29: 0-70кВ | H29: 2 | I29: =Оборудование!I12 -> 46175 | J29: =Оборудование!J12 -> С-ТТ/02-06-2025/436900431
A30: 4 | B30: Измеритель сопротивления заземления ИС-20 | F30: 3141 | G30: 0,01- 999 Ом | H30: 3 | I30: =Оборудование!I13 -> 46850 | J30: =Оборудование!J13 -> С-ТТ/08-04-2026/517582910
A31: Условия окружающей среды при проведении измерений:
A32: Температура воздуха | C32: =прот.№1!C26 -> 15 | D32: °С
A33: Влажность | C33: =прот.№1!C27 -> 70 | D33: %
A34: Атмосферное давление | C34: =прот.№1!C28 -> 745 | D34: мм рт. ст.
A36: 5. Нормативно-технический документ:
A38: ПТЭЭП (Прилож. 3 Раздел 17); ПУЭ (глава 1.8.31.); РД 34.45-51.300-97 (Раздел 21)
A39: Объёмы ПНР утверждены заказчиком.
A41: Проверку провели: | C41: ='Данные объект'!$B$64 -> Зам. руководителя ЭИЛ | I41: ='Данные объект'!$B$65 -> Фечин А.А.
C42: (должность) | G42: (подпись) | I42: (Ф.И.О.)
C45: ='Данные объект'!$B$66 -> Инженер ЭИЛ | I45: ='Данные объект'!$B$67 -> Косырин А.Н.
C46: (должность) | G46: (подпись) | I46: (Ф.И.О.)
A48: Проверил: | C48: ='Данные объект'!$B$61 -> Руководитель ЭИЛ | I48: ='Данные объект'!$B$62 -> Щербаков А.А.
C49: (должность) | G49: (подпись) | I49: (Ф.И.О.)

Sheet прот.№6
A1: ='Данные объект'!B58 -> ООО «Энергосистемы» | G1: Заказчик: | H1: ='Данные объект'!B34 -> ПАО "Россети Московский регион"
A2: ='Данные объект'!C58 -> Испытательная электролаборатория 141508, Московская область, г.о. Солнечногорск, г. Солнечногорск, ул. Промышленная, стр. 5, помещение 179, Свидетельсто о регистрации №5.3-6420 от 15 мая 2024г | G2: Объект: | H2: =_xlfn.CONCAT('Данные объект'!$B$15, " ",'Данные объект'!$B$16) -> КТП № АСП №
G3: Адрес: | H3: ='Данные объект'!B5 -> Лобня г, Шереметьевское ш, дом 10
J5: Дата проведения испытания:
J6: ='Данные объект'!B8 -> 25.06.2025
A7: Протокол №6
A8: проверки расцепителей мгновенного действия автоматических выключателей в электроустановках напряжением до 1000В
A10: Место установки, назначение | B10: Автоматический выключатель | H10: Верхнее значение тока срабатывания с коэф. 1,1(А) | I10: Время срабатывания (с) | K10: Вывод о соответствии Н.Д.
B11: Тип, характеристика | C11: I ном. (А) | D11: Ток срабатывания мгновенного расцепителя (А)
D12: Фаза А | E12: Фаза В | F12: Фаза С | G12: Ноль, 0 | I12: Факт. | J12: по НД
A13: ВРЩ-0,4кВ | B13: ВА57-35 Iотс= 10Iном | C13: 250 | D13: =$C$13*10 -> 2500 | E13: =$C13*10+5 -> 2505 | F13: =$C13*10-9 -> 2491 | G13: - | H13: =C13*10*1.1 -> 2750 | I13: 0,2 | J13: 0,2 | K13: Соотв.НД.
A14: КТП №3865 ф.1 | B14: ВА57-35 Iотс= 10Iном | C14: 63 | D14: =$C$14*10 -> 630 | E14: =$C14*10+5 -> 635 | F14: =$C14*10-10 -> 620 | G14: - | H14: =C14*10*1.1 -> 693 | I14: 0,09 | J14: 0,2 | K14: Соотв.НД.
A15: ВРЩ-0,4кВ | B15: ВА57-35 Iотс= 10Iном | C15: 40 | D15: =$C$15*10 -> 400 | E15: =$C15*10+5 -> 405 | F15: =$C15*10-15 -> 385 | G15: - | H15: =C15*10*1.1 -> 440 | I15: 0,07 | J15: 0,2 | K15: Соотв.НД.
A16: РУ 0,4кВ ЩО-70М | B16: ВА04-35 Iотс= 10Iном | C16: 250 | D16: =$C$16*10 -> 2500 | E16: =$C16*10+5 -> 2505 | F16: =$C16*10-10 -> 2490 | G16: - | H16: =C16*10*1.1 -> 2750 | I16: 0,08 | J16: 0,2 | K16: Соотв.НД.
A17: РУ 0,4кВ ЩО-70М | B17: ВА04-35 Iотс= 10Iном | C17: 200 | D17: =$C$17*10 -> 2000 | E17: =$C17*10+5 -> 2005 | F17: =$C17*10-10 -> 1990 | G17: - | H17: =C17*10*1.1 -> 2200 | I17: 0,09 | J17: 0,2 | K17: Соотв.НД.
A18: РУ 0,4кВ ЩО-70М | B18: ВА04-35 Iотс= 10Iном | C18: 200 | D18: =$C$18*10 -> 2000 | E18: =$C18*10+5 -> 2005 | F18: =$C18*10-15 -> 1985 | G18: - | H18: =C18*10*1.1 -> 2200 | I18: 0,06 | J18: 0,2 | K18: Соотв.НД.
A19: РУ 0,4кВ ЩО-70М | B19: ВА04-35 Iотс= 10Iном | C19: 160 | D19: =$C$19*10 -> 1600 | E19: =$C19*10+5 -> 1605 | F19: =$C19*10-10 -> 1590 | G19: - | H19: =C19*10*1.1 -> 1760 | I19: 0,07 | J19: 0,2 | K19: Соотв.НД.
A20: РУ 0,4кВ ЩО-70М | B20: ВА04-35 Iотс= 10Iном | C20: 160 | D20: =$C$20*10 -> 1600 | E20: =$C20*10+5 -> 1605 | F20: =$C20*10-15 -> 1585 | G20: - | H20: =C20*10*1.1 -> 1760 | I20: 0,07 | J20: 0,2 | K20: Соотв.НД.
A21: РУ 0,4кВ ЩО-70М | B21: ВА04-31 Iотс= 10Iном | C21: 16 | D21: =$C$21*10 -> 160 | E21: =$C21*10+5 -> 165 | F21: =$C21*10-10 -> 150 | G21: - | H21: =C21*10*1.1 -> 176 | I21: 0,06 | J21: 0,2 | K21: Соотв.НД.
A22: Условия окружающей среды при проведении измерений:
A24: Температура воздуха | C24: =прот.№1!C26 -> 15 | D24: °С
A25: Влажность | C25: =прот.№1!C27 -> 70 | D25: %
A26: Атмосферное давление | C26: =прот.№1!C28 -> 745 | D26: мм рт. ст.
A28: Измерительные приборы:
A30: № п/п | B30: Тип | F30: Заводской номер | G30: Метрологические характеристики | I30: Дата поверки очередная | J30: № аттестата (свидетельства)
G31: Диапазон измерения | H31: Класс точности
A32: 1 | B32: Мегаомметр Е6-32 | F32: 13909.21 | G32: 1[Ом]- 99,9[ГОм] | H32: 2,5 | I32: =Оборудование!I4 -> 46850 | J32: =Оборудование!J4 -> С-ТТ/08-04-2026/517582908
A33: 2 | B33: Микроомметр ИКС-30А | F33: 134 | G33: 1[мОм]¸ 100[кОм] | H33: 0.1 | I33: =Оборудование!I3 -> 47945 | J33: =Оборудование!J3 -> С-ТТ/08-04-2026/517582895
A34: 3 | B34: Аппараты испытания диэлектриков СКАТ-70М | F34: 15036 | G34: 0-70кВ | H34: 2 | I34: =Оборудование!I12 -> 46175 | J34: =Оборудование!J12 -> С-ТТ/02-06-2025/436900431
A35: 4 | B35: Измеритель сопротивления заземления ИС-20 | F35: 3141 | G35: 0,01- 999 Ом | H35: 3 | I35: =Оборудование!I13 -> 46850 | J35: =Оборудование!J13 -> С-ТТ/08-04-2026/517582910
A36: Заключение на соответствие требованиям НТД:
A37: Данные измерений и испытаний соответствуют нормам НТД. Годно к эксплуатации.
A38: Перепечатка без разрешения испытательной лаборатории запрещена.
A39: НОРМАТИВНЫЕ ДОКУМЕНТЫ: ПУЭ 1.8.37.; ПТЭЭП прилож. 3 раздел 28. п28.1, п.28.3, п.28.6.
A40: ЗАКЛЮЧЕНИЕ: Автоматические выключатели соответствуют НД.
A41: Объёмы ПНР утверждены заказчиком.
A44: Проверку провели: | C44: ='Данные объект'!$B$64 -> Зам. руководителя ЭИЛ | I44: ='Данные объект'!$B$65 -> Фечин А.А.
C45: (должность) | G45: (подпись) | I45: (Ф.И.О.)
C48: ='Данные объект'!$B$66 -> Инженер ЭИЛ | I48: ='Данные объект'!$B$67 -> Косырин А.Н.
C49: (должность) | G49: (подпись) | I49: (Ф.И.О.)
...

Sheet прот.№7
A1: ='Данные объект'!B58 -> ООО «Энергосистемы» | G1: Заказчик: | H1: ='Данные объект'!B34 -> ПАО "Россети Московский регион"
A2: ='Данные объект'!C58 -> Испытательная электролаборатория 141508, Московская область, г.о. Солнечногорск, г. Солнечногорск, ул. Промышленная, стр. 5, помещение 179, Свидетельсто о регистрации №5.3-6420 от 15 мая 2024г | G2: Объект: | H2: =CONCATENATE('Данные объект'!$B$17, " ",'Данные объект'!$B$18) -> ВЛ от ТП ф. ВЛ от ТП ф.
G3: Адрес: | H3: ='Данные объект'!B5 -> Лобня г, Шереметьевское ш, дом 10
J5: Дата проведения испытания:
J6: ='Данные объект'!B8 -> 25.06.2025
A7: Протокол №7
A8: проверки сопротивлений заземлителей и заземляющих устройств
A10: 1. Результаты внешнего осмотра (целостности и надёжности заземляющих устройств):
A11: удовлетворительно
A12: 2. Вид грунта: | B12: суглинок
A13: 3. Характер грунта: | D13: средней влажности
D14: влажный, средней влажности, сухой
A15: 4. Заземляющее устройство, применяемое для электроустановки: | F15: до 1000 В
F16: до 1000 В, до и выше 1000 В, свыше 1000 В
A17: 5. Режим нейтрали: | C17: глухозаземленная
A18: 6. Удельное сопротивление грунта, Ом × м: | E18: 80
A19: Результаты испытаний:
A21: № п/п | B21: Назначение заземлителя, заземляющего устройства | E21: Расстояние до потенциальных и токовых электродов, м | F21: Сопротивление заземлителей (заземляющих устройств), Ом | I21: Кпопр. | J21: Вывод о соответств. Нормативн. Документу
F22: Допустимое | G22: Измеренное | H22: Приведённое
A23: 1 | B23: Опора № 2 | E23: 20-30 | F23: 30 | G23: 12,4 | H23: 12,4 | I23: 1 | J23: Соответств. НД
A24: 2 | B24: Опора № 3 | E24: 20-30 | F24: 30 | G24: 12,7 | H24: 12,7 | I24: 1 | J24: Соответств. НД
A25: 3 | B25: Опора № 4 | E25: 20-30 | F25: 30 | G25: 13,0 | H25: 13,0 | I25: 1 | J25: Соответств. НД
A26: 4 | B26: Опора № 5 | E26: 20-30 | F26: 30 | G26: 12,9 | H26: 12,9 | I26: 1 | J26: Соответств. НД
A27: 8. Условия окружающей среды при проведении измерений:
A28: 8.1 Температура воздуха | C28: ='Данные объект'!B10 -> 15 | D28: °С
A29: 8.2 Влажность | C29: ='Данные объект'!B11 -> 70 | D29: %
A30: 8.3 Атмосферное давление | C30: ='Данные объект'!B12 -> 745 | D30: мм рт. ст.
A31: 9. Нормативно-технический документ: Таблица 35, 36 ПТЭЭП, п.1.8.39. ПУЭ.
A32: Объёмы ПНР утверждены заказчиком.
A33: 10. Измерительные приборы:
A35: № п/п | B35: Тип | F35: Заводской номер | G35: Метрологические характеристики | I35: Дата поверки очередная | J35: № аттестата (свидетельства)
G36: Диапазон измерения | H36: Класс точности
A37: 1 | B37: Мегаомметр Е6-32 | F37: 13909.21 | G37: 1[Ом]- 99,9[ГОм] | H37: 2,5 | I37: =Оборудование!I4 -> 46850 | J37: =Оборудование!J4 -> С-ТТ/08-04-2026/517582908
A38: 2 | B38: Микроомметр ИКС-30А | F38: 134 | G38: 1[мОм]¸ 100[кОм] | H38: 0.1 | I38: =Оборудование!I3 -> 47945 | J38: =Оборудование!J3 -> С-ТТ/08-04-2026/517582895
A39: 3 | B39: Аппараты испытания диэлектриков СКАТ-70М | F39: 15036 | G39: 0-70кВ | H39: 2 | I39: =Оборудование!I12 -> 46175 | J39: =Оборудование!J12 -> С-ТТ/02-06-2025/436900431
A40: 4 | B40: Измеритель сопротивления заземления ИС-20 | F40: 3141 | G40: 0,01- 999 Ом | H40: 3 | I40: =Оборудование!I13 -> 46850 | J40: =Оборудование!J13 -> С-ТТ/08-04-2026/517582910
A41: 11. Заключение на соответствие требованиям НТД: Данные измерений и испытаний соответствуют нормам НТД. Годно к эксплуатации.
A43: Проверку провели: | C43: ='Данные объект'!$B$64 -> Зам. руководителя ЭИЛ | I43: ='Данные объект'!$B$65 -> Фечин А.А.
C44: (должность) | G44: (подпись) | I44: (Ф.И.О.)
C47: ='Данные объект'!$B$66 -> Инженер ЭИЛ | I47: ='Данные объект'!$B$67 -> Косырин А.Н.
...

Sheet прот.№8
A1: ='Данные объект'!B58 -> ООО «Энергосистемы» | G1: Заказчик: | H1: ='Данные объект'!B34 -> ПАО "Россети Московский регион"
A2: ='Данные объект'!C58 -> Испытательная электролаборатория 141508, Московская область, г.о. Солнечногорск, г. Солнечногорск, ул. Промышленная, стр. 5, помещение 179, Свидетельсто о регистрации №5.3-6420 от 15 мая 2024г | G2: Объект: | H2: =CONCATENATE('Данные объект'!$B$17, " ",'Данные объект'!$B$18) -> ВЛ от ТП ф. ВЛ от ТП ф.
G3: Адрес: | H3: ='Данные объект'!B5 -> Лобня г, Шереметьевское ш, дом 10
J5: Дата проведения испытания:
J6: ='Данные объект'!B8 -> 25.06.2025
A9: Протокол №8
A10: проверки сопротивления изоляции проводов и кабелей
A11: Результаты испытаний:
A12: № п/п | B12: Наименование линий, по проекту | C12: Рабочее напряжение,В | D12: Марка провода, кабеля | E12: Количество жил, сечение провода кабеля,мм² | F12: Сопротивление изоляции, МОм | P12: Вывод о соответствии нормативному документу
F13: L1-L2 (А-В) | G13: L2-L3 (В-С) | H13: L3-L1 (С-А) | I13: L1-N (А-N) (PEN) | J13: L2-N (В-N) (PEN) | K13: L3-N (С-N) (PEN) | L13: L1-PE (А-РЕ) | M13: L2-PE (В-РЕ) | N13: L3-PE (С-РЕ) | O13: N-PE
A14: 1 | B14: 2 | C14: 3 | D14: 4 | E14: 5 | F14: 6 | G14: 7 | H14: 8 | I14: 9 | J14: 10 | K14: 11 | L14: 12 | M14: 13 | N14: 14 | O14: 15 | P14: 16
A15: 1 | B15: ВЛ-0,4кВ ОТ КТП №2999 до опоры №1, ф.1 | C15: 0.4 | D15: СИП2 | E15: 3х70+1х70 | F15: >103 | G15: >103 | H15: >103 | I15: >103 | J15: >103 | K15: >103 | L15: - | M15: - | N15: - | O15: - | P15: Соотв НД
A16: 2 | B16: КЛ-0,4кВ от КТП №3865 ф.1 | C16: 0.4 | D16: АСБл-10 | E16: 3х120 | F16: >103 | G16: >103 | H16: >103 | I16: >103 | J16: >103 | K16: >103 | L16: - | M16: - | N16: - | O16: - | P16: Соотв НД
A17: 3 | B17: ВЛ-10кВ от сущ. Опоры №1 ф. 829445 до КТП №2999 | C17: 10 | D17: 3СИП3 | E17: 1х70 | F17: >103 | G17: >103 | H17: >103 | I17: >103 | J17: >103 | K17: >103 | L17: - | M17: - | N17: - | O17: - | P17: Соотв НД
A18: Выполнена фазировка жил провода.
A19: 2. Условия окружающей среды при проведении измерений:
A20: Температура воздуха | C20: =прот.№1!C26 -> 15 | D20: °С
A21: Влажность | C21: =прот.№1!C27 -> 70 | D21: %
A22: Атмосферное давление | C22: =прот.№1!C28 -> 745 | D22: мм рт. ст.
A23: Нормативно-технический документ: ПУЭ 1.8.37,2.1.13-2.1.17., ГОСТ Р50571-16-99.
A24: Измерительные приборы:
A26: № п/п | B26: Тип | F26: Заводской номер | G26: Метрологические характеристики | I26: Дата поверки очередная | J26: № аттестата (свидетельства)
G27: Диапазон измерения | H27: Класс точности
A28: 1 | B28: Мегаомметр Е6-32 | F28: 13909.21 | G28: 1[Ом]- 99,9[ГОм] | H28: 2,5 | I28: =Оборудование!I4 -> 46850 | J28: =Оборудование!J4 -> С-ТТ/08-04-2026/517582908
A29: 2 | B29: Микроомметр ИКС-30А | F29: 134 | G29: 1[мОм]¸ 100[кОм] | H29: 0.1 | I29: =Оборудование!I3 -> 47945 | J29: =Оборудование!J3 -> С-ТТ/08-04-2026/517582895
A30: 3 | B30: Аппараты испытания диэлектриков СКАТ-70М | F30: 15036 | G30: 0-70кВ | H30: 2 | I30: =Оборудование!I12 -> 46175 | J30: =Оборудование!J12 -> С-ТТ/02-06-2025/436900431
A31: 4 | B31: Измеритель сопротивления заземления ИС-20 | F31: 3141 | G31: 0,01- 999 Ом | H31: 3 | I31: =Оборудование!I13 -> 46850 | J31: =Оборудование!J13 -> С-ТТ/08-04-2026/517582910
A32: Примечание: Перепечатка без разрешения запрещена.
A33: 6. Заключение на соответствие требованиям НТД: Сопротивление изоляции соответствует НТД. Годно к эксплуатации.
A34: Объёмы ПНР утверждены заказчиком.
A36: Проверку провели: | C36: ='Данные объект'!$B$64 -> Зам. руководителя ЭИЛ | I36: ='Данные объект'!$B$65 -> Фечин А.А.
C37: (должность) | G37: (подпись) | I37: (Ф.И.О.)
C40: ='Данные объект'!$B$66 -> Инженер ЭИЛ | I40: ='Данные объект'!$B$67 -> Косырин А.Н.
C41: (должность) | G41: (подпись) | I41: (Ф.И.О.)
A43: Проверил: | C43: ='Данные объект'!$B$61 -> Руководитель ЭИЛ | I43: ='Данные объект'!$B$62 -> Щербаков А.А.
C44: (должность) | G44: (подпись) | I44: (Ф.И.О.)

Sheet прот.№9
A1: ='Данные объект'!B58 -> ООО «Энергосистемы» | G1: Заказчик: | H1: ='Данные объект'!B34 -> ПАО "Россети Московский регион"
A2: ='Данные объект'!C58 -> Испытательная электролаборатория 141508, Московская область, г.о. Солнечногорск, г. Солнечногорск, ул. Промышленная, стр. 5, помещение 179, Свидетельсто о регистрации №5.3-6420 от 15 мая 2024г | G2: Объект: | H2: =_xlfn.CONCAT('Данные объект'!$B$15, " ",'Данные объект'!$B$16) -> КТП № АСП №
G3: Адрес: | H3: ='Данные объект'!B5 -> Лобня г, Шереметьевское ш, дом 10
J5: Дата проведения испытания:
J6: ='Данные объект'!B8 -> 25.06.2025
A7: Протокол №9
A8: проверки цепи «фаза-нуль» в электроустановках напряжением до 1000 В с глухим заземлением нейтрали
A10: Наименование оборудования или цепи | B10: Автомат (предохранитель) | H10: Iк.з. (А) | I10: Время срабатывания (с) | J10: Вывод о Соответст- вии Н.Д.
B11: Тип аппарата защиты | C11: Характеристика | D11: I ном (А) | E11: По Н.Д. Iк.з. должен составлять не менее.
E12: Эл. магн расц. (А) | F12: Тепл расц. (А) | G12: Пл. вставка (А)
B13: =H2 -> КТП № АСП №
A14: ф.А | B14: ВА04-35 | C14: - | D14: 200 | E14: - | F14: 600 | G14: - | H14: 616 | I14: 4,7 | J14: Соотв.НД.
A15: ф.В | D15: 200 | E15: - | F15: 600 | G15: - | H15: 612 | I15: 4,8 | J15: Соотв.НД.
A16: ф.С | D16: 200 | E16: - | F16: 600 | G16: - | H16: 615 | I16: 4,9 | J16: Соотв.НД.
A18: Условия окружающей среды при проведении измерений:
A19: Температура воздуха | C19: =прот.№1!C26 -> 15 | D19: °С
A20: Влажность | C20: =прот.№1!C27 -> 70 | D20: %
A21: Атмосферное давление | C21: =прот.№1!C28 -> 745 | D21: мм рт. ст.
A22: Нормативно-технический документ: ПУЭ 1.8.39(п.4); ПТЭЭП (приложение 3,п.28.4), ГОСТ Р50571-16-99.
A23: Объёмы ПНР утверждены заказчиком.
A24: Измерительные приборы:
A26: № п/п | B26: Тип | F26: Заводской номер | G26: Метрологические характеристики | I26: Дата поверки очередная | J26: № аттестата (свидетельства)
G27: Диапазон измерения | H27: Класс точности
A28: 1 | B28: Мегаомметр Е6-32 | F28: 13909.21 | G28: 1[Ом]- 99,9[ГОм] | H28: 2,5 | I28: =Оборудование!I4 -> 46850 | J28: =Оборудование!J4 -> С-ТТ/08-04-2026/517582908
A29: 2 | B29: Микроомметр ИКС-30А | F29: 134 | G29: 1[мОм]¸ 100[кОм] | H29: 0.1 | I29: =Оборудование!I3 -> 47945 | J29: =Оборудование!J3 -> С-ТТ/08-04-2026/517582895
A30: 3 | B30: Аппараты испытания диэлектриков СКАТ-70М | F30: 15036 | G30: 0-70кВ | H30: 2 | I30: =Оборудование!I12 -> 46175 | J30: =Оборудование!J12 -> С-ТТ/02-06-2025/436900431
A31: 4 | B31: Измеритель сопротивления заземления ИС-20 | F31: 3141 | G31: 0,01- 999 Ом | H31: 3 | I31: =Оборудование!I13 -> 46850 | J31: =Оборудование!J13 -> С-ТТ/08-04-2026/517582910
A33: Заключение на соответствие требованиям НТД:
A34: Токи короткого замыкания на землю соответствуют НТД и обеспечивают надёжное срабатывания защиты.
A37: Проверку провели: | C37: ='Данные объект'!$B$64 -> Зам. руководителя ЭИЛ | I37: ='Данные объект'!$B$65 -> Фечин А.А.
C38: (должность) | G38: (подпись) | I38: (Ф.И.О.)
C41: ='Данные объект'!$B$66 -> Инженер ЭИЛ | I41: ='Данные объект'!$B$67 -> Косырин А.Н.
C42: (должность) | G42: (подпись) | I42: (Ф.И.О.)
A44: Проверил: | C44: ='Данные объект'!$B$61 -> Руководитель ЭИЛ | I44: ='Данные объект'!$B$62 -> Щербаков А.А.
C45: (должность) | G45: (подпись) | I45: (Ф.И.О.)

Sheet прот.№10
A1: ='Данные объект'!B58 -> ООО «Энергосистемы» | G1: Заказчик: | H1: ='Данные объект'!B34 -> ПАО "Россети Московский регион"
A2: ='Данные объект'!C58 -> Испытательная электролаборатория 141508, Московская область, г.о. Солнечногорск, г. Солнечногорск, ул. Промышленная, стр. 5, помещение 179, Свидетельсто о регистрации №5.3-6420 от 15 мая 2024г | G2: Объект: | H2: =CONCATENATE('Данные объект'!$B$17, " ",'Данные объект'!$B$18) -> ВЛ от ТП ф. ВЛ от ТП ф.
G3: Адрес: | H3: ='Данные объект'!B5 -> Лобня г, Шереметьевское ш, дом 10
J5: Дата проведения испытания:
J6: ='Данные объект'!B8 -> 25.06.2025
A7: Протокол №10
A8: проверки цепи между заземлителями и заземляемыми элементами
A10: Результаты испытаний:
A11: № п/п | B11: Месторасположение и наименование электрооборудования | F11: Сопротивление цепи заземления (Ом) | J11: Вывод о соответствии нормативному документу
F12: Измеренное | H12: Значение по НД
A13: 1 | B13: Опора № 2 | F13: 0.03 | H13: ≤ 0,05 | J13: Соответств. НД
A14: 2 | B14: Опора № 7 | F14: 0.02 | H14: =$H$13 -> ≤ 0,05 | J14: Соответств. НД
A15: 3 | B15: Опора № 8 | F15: 0.03 | H15: =$H$13 -> ≤ 0,05 | J15: Соответств. НД
A16: 4 | B16: Опора № 9 | F16: 0.01 | H16: =$H$13 -> ≤ 0,05 | J16: Соответств. НД
A17: 5 | B17: Опора № 10 | F17: 0.03 | H17: =$H$13 -> ≤ 0,05 | J17: Соответств. НД
A19: 2. Условия окружающей среды при проведении измерений:
A20: 2.1 Температура воздуха | C20: =прот.№1!C26 -> 15 | D20: °С
A21: 2.2 Влажность | C21: =прот.№1!C27 -> 70 | D21: %
A22: 2.3 Атмосферное давление | C22: =прот.№1!C28 -> 745 | D22: мм рт. ст.
A23: 3. Нормативно-технический документ: Приложение № 3, пп 26.1,28.5 ПТЭЭП, п.1.8.39. ПУЭ.
A24: 4. Измерительные приборы:
A26: № п/п | B26: Тип | F26: Заводской номер | G26: Метрологические характеристики | I26: Дата поверки очередная | J26: № аттестата (свидетельства)
G27: Диапазон измерения | H27: Класс точности
A28: 1 | B28: Мегаомметр Е6-32 | F28: 13909.21 | G28: 1[Ом]- 99,9[ГОм] | H28: 2,5 | I28: =Оборудование!I4 -> 46850 | J28: =Оборудование!J4 -> С-ТТ/08-04-2026/517582908
A29: 2 | B29: Микроомметр ИКС-30А | F29: 134 | G29: 1[мОм]¸ 100[кОм] | H29: 0.1 | I29: =Оборудование!I3 -> 47945 | J29: =Оборудование!J3 -> С-ТТ/08-04-2026/517582895
A30: 3 | B30: Аппараты испытания диэлектриков СКАТ-70М | F30: 15036 | G30: 0-70кВ | H30: 2 | I30: =Оборудование!I12 -> 46175 | J30: =Оборудование!J12 -> С-ТТ/02-06-2025/436900431
A31: 4 | B31: Измеритель сопротивления заземления ИС-20 | F31: 3141 | G31: 0,01- 999 Ом | H31: 3 | I31: =Оборудование!I13 -> 46850 | J31: =Оборудование!J13 -> С-ТТ/08-04-2026/517582910
A33: 5. Заключение на соответствие требованиям НТД:
A34: 5.1. Проверена целостность и прочность проводников заземления и зануления, переходные контакты их соединений.
A35: Сопротивление переходных контактов выше нормы, указаны в п/п нет.
A36: Не заземлено оборудование, указанное в п/п нет.
A37: 5.4 Величина измеренного переходного сопротивления контактов заземляющих и нулевых проводников, элементов электрооборудования соответствует нормам НТД.
A38: Объёмы ПНР утверждены заказчиком.
A40: Проверку провели: | C40: ='Данные объект'!$B$64 -> Зам. руководителя ЭИЛ | I40: ='Данные объект'!$B$65 -> Фечин А.А.
C41: (должность) | G41: (подпись) | I41: (Ф.И.О.)
C44: ='Данные объект'!$B$66 -> Инженер ЭИЛ | I44: ='Данные объект'!$B$67 -> Косырин А.Н.
C45: (должность) | G45: (подпись) | I45: (Ф.И.О.)
A47: Проверил: | C47: ='Данные объект'!$B$61 -> Руководитель ЭИЛ | I47: ='Данные объект'!$B$62 -> Щербаков А.А.
C48: (должность) | G48: (подпись) | I48: (Ф.И.О.)

Sheet прот.№11
A1: ='Данные объект'!B58 -> ООО «Энергосистемы» | G1: Заказчик: | H1: ='Данные объект'!B34 -> ПАО "Россети Московский регион"
A2: ='Данные объект'!C58 -> Испытательная электролаборатория 141508, Московская область, г.о. Солнечногорск, г. Солнечногорск, ул. Промышленная, стр. 5, помещение 179, Свидетельсто о регистрации №5.3-6420 от 15 мая 2024г | G2: Объект: | H2: ='Данные объект'!B18 -> ВЛ от ТП ф.
G3: Адрес: | H3: ='Данные объект'!B5 -> Лобня г, Шереметьевское ш, дом 10
J5: Дата проведения испытания:
J6: ='Данные объект'!B8 -> 25.06.2025
A8: Протокол №11
A9: проверки расцепителей мгновенного действия автоматических выключателей в электроустановках напряжением до 1000В
A10: Место установки, назначение | B10: Автоматический выключатель | H10: Верхнее значение тока срабатывания с коэф. 1,1(А) | I10: Время срабатывания (с) | K10: Вывод о соответствии Н.Д.
B11: Тип, характеристика | C11: I ном. (А) | D11: Ток срабатывания мгновенного расцепителя (А)
D12: Фаза А | E12: Фаза В | F12: Фаза С | G12: Ноль, 0 | I12: Факт. | J12: по НД
A13: ШУ-1 на опоре № 7 | B13: ВА101 3Р-016А-С | C13: 16 | D13: =C$13*10 -> 160 | E13: =C13*10+10 -> 170 | F13: =C$13*10-5 -> 155 | G13: - | H13: =C$13*10*1.1 -> 176 | I13: 0,07 | J13: 0,2 | K13: соответствует
A16: Условия окружающей среды при проведении измерений:
A17: Температура воздуха | C17: =прот.№1!C26 -> 15 | D17: °С
A18: Влажность | C18: =прот.№1!C27 -> 70 | D18: %
A19: Атмосферное давление | C19: =прот.№1!C28 -> 745 | D19: мм рт. ст.
A21: Измерительные приборы:
A23: № п/п | B23: Тип | F23: Заводской номер | G23: Метрологические характеристики | I23: Дата поверки очередная | J23: № аттестата (свидетельства)
G24: Диапазон измерения | H24: Класс точности
A25: 1 | B25: Мегаомметр Е6-32 | F25: 13909.21 | G25: 1[Ом]- 99,9[ГОм] | H25: 2,5 | I25: =Оборудование!I4 -> 46850 | J25: =Оборудование!J4 -> С-ТТ/08-04-2026/517582908
A26: 2 | B26: Микроомметр ИКС-30А | F26: 134 | G26: 1[мОм]¸ 100[кОм] | H26: 0.1 | I26: =Оборудование!I3 -> 47945 | J26: =Оборудование!J3 -> С-ТТ/08-04-2026/517582895
A27: 3 | B27: Аппараты испытания диэлектриков СКАТ-70М | F27: 15036 | G27: 0-70кВ | H27: 2 | I27: =Оборудование!I12 -> 46175 | J27: =Оборудование!J12 -> С-ТТ/02-06-2025/436900431
A28: 4 | B28: Измеритель сопротивления заземления ИС-20 | F28: 3141 | G28: 0,01- 999 Ом | H28: 3 | I28: =Оборудование!I13 -> 46850 | J28: =Оборудование!J13 -> С-ТТ/08-04-2026/517582910
A29: Заключение на соответствие требованиям НТД: Данные измерений и испытаний соответствуют нормам НТД. Годно к эксплуатации.
A31: Перепечатка без разрешения испытательной лаборатории запрещена.
A33: НОРМАТИВНЫЕ ДОКУМЕНТЫ: ПУЭ 1.8.37.; ПТЭЭП прилож. 3 раздел 28. п28.1, п.28.3, п.28.6.;
A34: ЗАКЛЮЧЕНИЕ: Автоматические выключатели соответствуют НД.
A35: Объёмы ПНР утверждены заказчиком.
A38: Проверку провели: | C38: ='Данные объект'!$B$64 -> Зам. руководителя ЭИЛ | I38: ='Данные объект'!$B$65 -> Фечин А.А.
C39: (должность) | G39: (подпись) | I39: (Ф.И.О.)
C42: ='Данные объект'!$B$66 -> Инженер ЭИЛ | I42: ='Данные объект'!$B$67 -> Косырин А.Н.
C43: (должность) | G43: (подпись) | I43: (Ф.И.О.)
A45: Проверил: | C45: ='Данные объект'!$B$61 -> Руководитель ЭИЛ | I45: ='Данные объект'!$B$62 -> Щербаков А.А.
C46: (должность) | G46: (подпись) | I46: (Ф.И.О.)

Sheet Прот.№12
A1: ='Данные объект'!B58 -> ООО «Энергосистемы» | H1: Заказчик: | I1: ='Данные объект'!B34 -> ПАО "Россети Московский регион"
A2: ='Данные объект'!C58 -> Испытательная электролаборатория 141508, Московская область, г.о. Солнечногорск, г. Солнечногорск, ул. Промышленная, стр. 5, помещение 179, Свидетельсто о регистрации №5.3-6420 от 15 мая 2024г | H2: Объект: | I2: ='Данные объект'!B19 -> КЛ от ТП ф
H3: Адрес: | I3: ='Данные объект'!B5 -> Лобня г, Шереметьевское ш, дом 10
K5: Дата проведения испытания:
K6: ='Данные объект'!B8 -> 25.06.2025
A8: Протокол №7
A9: проверки сопротивления изоляции проводов и кабелей
A10: Результаты испытаний:
A11: № п/п | B11: Наименование объекта | D11: Категория контроля | E11: Cхема испытания | F11: Результаты испытания | O11: Результат испытания
F12: Мегаомметром | H12: Кенотроном
F13: Сопр. изоляции (МОм) | H13: Испыт. напр. (кВ) | I13: Продолжительность испыт. (мин.) | J13: Ток утечки (мкА) | M13: Коэффициент асимметрии Imax/Imin
F14: до испыт. | G14: после испыт. | J14: Imax | K14: Imin | L14: Доп. | M14: Изм. | N14: Доп.
A15: 1 | B15: 2 | D15: 3 | E15: 4 | F15: 5 | G15: 6 | H15: 7 | I15: 8 | J15: 9 | K15: 10 | L15: 11 | M15: 12 | N15: 13 | O15: 14
A16: 1 | B16: Кабель проложенный вновь от КТП №3864 до КТП №3865 Марка АСБл-10 3х120 Раб. Напр. 10кВ сечение 3х120 Длина 690 м | D16: После монтажа | E16: А-В+С+Зазем. | F16: 910 | G16: 910 | H16: 60 | I16: 10 | J16: 70 | K16: 50 | L16: 500 | M16: 1.4 | N16: 8 | O16: Выдержал
E17: В-А+С+Зазем. | F17: 850 | G17: 850 | H17: 60 | I17: 10 | J17: 80 | K17: 30 | L17: 500 | M17: 1.25 | N17: 8 | O17: Выдержал
E18: С-А+В+Зазем. | F18: 950 | G18: 950 | H18: 60 | I18: 10 | J18: 70 | K18: 40 | L18: 500 | M18: 1.75 | N18: 8 | O18: Выдержал
A19: 2 | B19: Кабель проложенный вновь от КТП №3865 до ВРЩ Марка АВБбШв 4х95 Раб. Напр. 10кВ сечение 4х95 Длина 305 м | D19: После монтажа | E19: А-В+С+Зазем. | F19: 850 | G19: 850 | H19: 60 | I19: 10 | J19: 80 | K19: 30 | L19: 500 | M19: 1.25 | N19: 8 | O19: Выдержал
E20: В-А+С+Зазем. | F20: 950 | G20: 950 | H20: 60 | I20: 10 | J20: 70 | K20: 40 | L20: 500 | M20: 1.75 | N20: 8 | O20: Выдержал
E21: С-А+В+Зазем. | F21: 910 | G21: 910 | H21: 60 | I21: 10 | J21: 70 | K21: 50 | L21: 500 | M21: 1.4 | N21: 8 | O21: Выдержал
A23: Выполнена фазировка жил провода.
A24: 2. Условия окружающей среды при проведении измерений:
A25: Температура воздуха | C25: =прот.№1!C26 -> 15 | D25: °С
A26: Влажность | C26: =прот.№1!C27 -> 70 | D26: %
A27: Атмосферное давление | C27: =прот.№1!C28 -> 745 | D27: мм рт. ст.
A28: Нормативно-технический документ: ПУЭ 1.8.37,2.1.13-2.1.17., ГОСТ Р50571-16-99.
A29: Объёмы ПНР утверждены заказчиком.
A30: Измерительные приборы:
A32: № п/п | B32: Тип | F32: Заводской номер | G32: Метрологические характеристики | I32: Дата поверки очередная | J32: № аттестата (свидетельства)
G33: Диапазон измерения | H33: Класс точности
A34: 1 | B34: Мегаомметр Е6-32 | F34: 13909.21 | G34: 1[Ом]- 99,9[ГОм] | H34: 2,5 | I34: =Оборудование!I4 -> 46850 | J34: =Оборудование!J4 -> С-ТТ/08-04-2026/517582908
A35: 2 | B35: Микроомметр ИКС-30А | F35: 134 | G35: 1[мОм]¸ 100[кОм] | H35: 0.1 | I35: =Оборудование!I3 -> 47945 | J35: =Оборудование!J3 -> С-ТТ/08-04-2026/517582895
A36: 3 | B36: Аппараты испытания диэлектриков СКАТ-70М | F36: 15036 | G36: 0-70кВ | H36: 2 | I36: =Оборудование!I12 -> 46175 | J36: =Оборудование!J12 -> С-ТТ/02-06-2025/436900431
A37: 4 | B37: Измеритель сопротивления заземления ИС-20 | F37: 3141 | G37: 0,01- 999 Ом | H37: 3 | I37: =Оборудование!I13 -> 46850 | J37: =Оборудование!J13 -> С-ТТ/08-04-2026/517582910
A40: Проверку провели: | C40: ='Данные объект'!$B$64 -> Зам. руководителя ЭИЛ | I40: ='Данные объект'!$B$65 -> Фечин А.А.
C41: (должность) | G41: (подпись) | I41: (Ф.И.О.)
C44: ='Данные объект'!$B$66 -> Инженер ЭИЛ | I44: ='Данные объект'!$B$67 -> Косырин А.Н.
C45: (должность) | G45: (подпись) | I45: (Ф.И.О.)
A47: Проверил: | C47: ='Данные объект'!$B$61 -> Руководитель ЭИЛ | I47: ='Данные объект'!$B$62 -> Щербаков А.А.
C48: (должность) | G48: (подпись) | I48: (Ф.И.О.)

Sheet Прот.№13
A1: ='Данные объект'!B58 -> ООО «Энергосистемы» | F1: Заказчик: | G1: ='Данные объект'!B34 -> ПАО "Россети Московский регион"
A2: ='Данные объект'!C58 -> Испытательная электролаборатория 141508, Московская область, г.о. Солнечногорск, г. Солнечногорск, ул. Промышленная, стр. 5, помещение 179, Свидетельсто о регистрации №5.3-6420 от 15 мая 2024г | F2: Объект: | G2: ='Данные объект'!B17 -> ВЛ от ТП ф.
F3: Адрес: | G3: ='Данные объект'!B5 -> Лобня г, Шереметьевское ш, дом 10
I5: Дата проведения испытания:
I6: ='Данные объект'!B8 -> 25.06.2025
A7: Протокол №13
A8: на ревизию и наладку разъединителей РЛК-IV-10/400-УХЛ1 с приводом ПР-7 перед включением в сеть, заводской номер 47015217281
A10: № | B10: Программа | G10: Нормируемая величина | I10: Результат
A11: 1 | B11: Проверить чистоту изоляторов, отсутствие трещин и сколов | G11: - | I11: Исправны | J11: Исправны
A12: 2 | B12: Проверить затяжку резьбовых и крепёжных деталей | G12: - | I12: Затянуты | J12: Затянуты
A13: 3 | B13: Проверить перекрытие торцов главных ножей при включении разъединителя | G13: 13-16мм | I13: Соответствует норме | J13: Соответствует норме
A14: 4 | B14: Проверить несовпадение подвижных и неподвижных контактов главных ножей в горизонтальной плоскости | G14: Не более 3мм | I14: Соответствует норме | J14: Соответствует норме
A15: 5 | B15: Проверить неодновременность включения отдельных полюсов | G15: Не более 3мм | I15: Соответствует норме | J15: Соответствует норме
A16: 6 | B16: Проверить контактное нажатие разъёмных контактов главных ножей заземления | G16: Вытягивающее Усилие 6-8кГ/с | I16: В пределах нормы | J16: В пределах нормы
A17: 7 | B17: Проверить кратчайшие изоляционные расстояния между разомкнутыми контактами главных ножей, между разомкнутыми контактами заземляющих ножей | G17: Не менее 130 мм | I17: Соответствует норме | J17: Соответствует норме
A18: 8 | B18: Проверить фиксацию конечных наложений рукоятки привода фиксаторами. Проверить работу блок-замка | G18: Надёжная фиксация | I18: Исправны | J18: Исправны
A19: Заключение: по данным ревизии и наладки РЛК-IV-10/400-УХЛ1 с приводом ПР-7 - исправны и cоответствуют заводским данным.
A20: Объёмы ПНР утверждены заказчиком.
A22: Проверку провели: | C22: ='Данные объект'!$B$64 -> Зам. руководителя ЭИЛ | I22: ='Данные объект'!$B$65 -> Фечин А.А.
C23: (должность) | G23: (подпись) | I23: (Ф.И.О.)
C26: ='Данные объект'!$B$66 -> Инженер ЭИЛ | I26: ='Данные объект'!$B$67 -> Косырин А.Н.
C27: (должность) | G27: (подпись) | I27: (Ф.И.О.)
A29: Проверил: | C29: ='Данные объект'!$B$61 -> Руководитель ЭИЛ | I29: ='Данные объект'!$B$62 -> Щербаков А.А.
C30: (должность) | G30: (подпись) | I30: (Ф.И.О.)

Sheet Заключение
A1: ='Данные объект'!B58 -> ООО «Энергосистемы» | G1: Заказчик: | H1: ='Данные объект'!B34 -> ПАО "Россети Московский регион"
A2: ='Данные объект'!C58 -> Испытательная электролаборатория 141508, Московская область, г.о. Солнечногорск, г. Солнечногорск, ул. Промышленная, стр. 5, помещение 179, Свидетельсто о регистрации №5.3-6420 от 15 мая 2024г | G2: Объект: | H2: ='Данные объект'!B14 -> КТП № АСП № ВЛ от ТП ф. ВЛ от ТП ф. КЛ от ТП ф ВРЩ вблизи ТП
G3: Адрес: | H3: ='Данные объект'!B5 -> Лобня г, Шереметьевское ш, дом 10
J5: Дата проведения испытания:
J6: ='Данные объект'!B8 -> 25.06.2025
A9: З А К Л Ю Ч Е Н И Е
A12: Наименование электроустановки:
A13: ='Данные объект'!B14 -> КТП № АСП № ВЛ от ТП ф. ВЛ от ТП ф. КЛ от ТП ф ВРЩ вблизи ТП
A14: ='Данные объект'!B17 -> ВЛ от ТП ф.
A15: ='Данные объект'!B18 -> ВЛ от ТП ф.
A16: По адресу:
A17: ='Данные объект'!B5 -> Лобня г, Шереметьевское ш, дом 10
A18: ____________________________________________________________
A21: Соответствует: | C21: Проект, РД 34.45-51.300-97, ПУЭ
A23: ________________________________________________
A24: Проверку провели: | C24: ='Данные объект'!$B$64 -> Зам. руководителя ЭИЛ | I24: ='Данные объект'!$B$65 -> Фечин А.А.
C25: (должность) | G25: (подпись) | I25: (Ф.И.О.)
C28: ='Данные объект'!$B$66 -> Инженер ЭИЛ | I28: ='Данные объект'!$B$67 -> Косырин А.Н.
C29: (должность) | G29: (подпись) | I29: (Ф.И.О.)
A31: Проверил: | C31: ='Данные объект'!$B$61 -> Руководитель ЭИЛ | I31: ='Данные объект'!$B$62 -> Щербаков А.А.
C32: (должность) | G32: (подпись) | I32: (Ф.И.О.)

Sheet Протокол _ВНА
A1: ='Данные объект'!B58 -> ООО «Энергосистемы» | G1: Заказчик: | H1: ='Данные объект'!B34 -> ПАО "Россети Московский регион"
