Workbook

Sheet Данные организации
A1: организация | C1: ООО "Энергосистемы" | D1: ООО «Гефест» | E1: ООО "Энком" | G1: ПАО "Россети Московский регион"
A2: реквизиты | C2: ОГРН 1135044003709 ИНН 5044089069 КПП 504401001 | D2: ОГРН 1215000057238 ИНН 5044122213 КПП 504401001 | E2: ОГРН 1077762950055 ИНН 7743668640 КПП 770801001 | G2: ОГРН 1057746555811 ИНН 5036065113 КПП 772501001
A3: адрес | C3: 141508, Московская область, г.о. Солнечногорск, г. Солнечногорск, ул. Промышленная, стр. 5, помещение 179 | D3: 141508, Московская область, г.о. Солнечногорск, г Солнечногорск, ул Промышленная, строение 29А, корпус 1, офис 11 | E3: 107140, г.Москва, ул. Краснопрудная, д. 12/1, стр. 1, помещ. 1/6 | G3: 115114, город Москва, проезд Павелецкий 2-й, дом 3, строение 2
A4: район | G4: Солнечногорский р-н | I4: Химкинский р-н
G5: СРЭС филиала | I5: ХРЭС филиала
A6: директор | C6: И.о.генерального директора | D6: Генеральный директор | E6: Генеральный директор | G6: Начальник СРЭС СЭС филиала | I6: Начальник ХРЭС СЭС филиала
A7: директор ФИО | C7: Чернявская Н.Ю. | D7: Звездов Р.Е. | E7: Дандре Г.А. | G7: Чуев А.Н. | I7: Арнаутов А.П.
A8: Строй.контроль | B8: Инженер по строительному контролю | C8: Инженер по строительному контролю | D8: Специалист по строительному контролю | E8: Специалист по строительному контролю | G8: Приказ №2363 от 29 июля 2025г | I8: Приказ №2363 от 29 июля 2025г
A9: Приказ стр.контр. | B9: Приказ № 13-ОТ/25 от 05 мая 2025 | C9: Приказ № 18-ОТ/24 от 03 июня 2024 | D9: Приказ №01/24-ОТ от 15.01.2024 | E9: Приказ № ОТ-25 от 12.01.2024 | G9: Гл. специалист ССК УКС | H9: Гл. специалист ССК УКС | I9: Гл. специалист ССК УКС
B10: НОСТРОЙ С-50-085497 | C10: НОСТРОЙ С-50-188017 | D10: НРС № С-61-104369 | E10: НРС № С-77-286715 | G10: Приказ № от июля 2026г | H10: Приказ №53 от 13 марта 2025г. | I10: Приказ №1904 от 03 июня 2026г
A11: ФИО стр.контр. | B11: Русин В.А. | C11: Капитонов Д.А. | D11: Саженова Л.В. | E11: Филлипов А.Ю. | G11: НРС С-31-330248 | H11: НРС С-50-77-262451 | I11: НРС С-50-069023
A12: Представитель | G12: Курчин М.М. | H12: Шатковский А.Н. | I12: Алексанян Г.Р.
A13: ФИО предст. | G13: Мастер СРЭС СЭС филиала | I13: Технический надзор
G14: Курчин М.М.
A19: Прораб | C19: Прораб | D19: Мастер электромонтажного участка | E19: Главный инженер
A20: Приказ прораб | C20: Приказ №05-ОТ/24 от 09 января 2024г | D20: Приказ №01/24-ОТ от 15.01.2024 | E20: Приказ № ОТ-25 от 12.01.2024
A21: ФИО прораб | C21: Волков М.Ю. | D21: Красилов К.А. | E21: Горбан Г.К.
A24: сцепленные организация | C24: =CONCATENATE(C2,",",C3) -> ОГРН 1135044003709 ИНН 5044089069 КПП 504401001,141508, Московская область, г.о. Солнечногорск, г. Солнечногорск, ул. Промышленная, стр. 5, помещение 179 | D24: =CONCATENATE(D2,",",D3) -> ОГРН 1215000057238 ИНН 5044122213 КПП 504401001,141508, Московская область, г.о. Солнечногорск, г Солнечногорск, ул Промышленная, строение 29А, корпус 1, офис 11
A25: сцепленные организация | C25: =CONCATENATE(C1,",",C2,",",C3) -> ООО "Энергосистемы",ОГРН 1135044003709 ИНН 5044089069 КПП 504401001,141508, Московская область, г.о. Солнечногорск, г. Солнечногорск, ул. Промышленная, стр. 5, помещение 179 | D25: =CONCATENATE(D1,",",D2,",",D3) -> ООО «Гефест»,ОГРН 1215000057238 ИНН 5044122213 КПП 504401001,141508, Московская область, г.о. Солнечногорск, г Солнечногорск, ул Промышленная, строение 29А, корпус 1, офис 11 | G25: =CONCATENATE(G9," ",G1,"-",G12," .",G10,"-",G11) -> Гл. специалист ССК УКС ПАО "Россети Московский регион"-Курчин М.М. .Приказ № от июля 2026г-НРС С-31-330248 | H25: =CONCATENATE(H9," ",G1,"-",H12,".",H10,"-",H11) -> Гл. специалист ССК УКС ПАО "Россети Московский регион"-Шатковский А.Н..Приказ №53 от 13 марта 2025г.-НРС С-50-77-262451 | I25: =CONCATENATE(I9," ",G1,"-",I12," .",I10,"-",I11) -> Гл. специалист ССК УКС ПАО "Россети Московский регион"-Алексанян Г.Р. .Приказ №1904 от 03 июня 2026г-НРС С-50-069023
C26: =CONCATENATE(C8," ",C1,"-",C11,".",C9) -> Инженер по строительному контролю ООО "Энергосистемы"-Капитонов Д.А..Приказ № 18-ОТ/24 от 03 июня 2024 | D26: =CONCATENATE(D8," ",D1,"-",D11,".",D9) -> Специалист по строительному контролю ООО «Гефест»-Саженова Л.В..Приказ №01/24-ОТ от 15.01.2024 | G26: =CONCATENATE(G9," ",G1,"-",G12) -> Гл. специалист ССК УКС ПАО "Россети Московский регион"-Курчин М.М. | H26: =CONCATENATE(H9," ",G1," ",H12) -> Гл. специалист ССК УКС ПАО "Россети Московский регион" Шатковский А.Н. | I26: =CONCATENATE(I9," ",G1,"-",I12) -> Гл. специалист ССК УКС ПАО "Россети Московский регион"-Алексанян Г.Р.
C27: =CONCATENATE(C8," ",C1) -> Инженер по строительному контролю ООО "Энергосистемы" | D27: =CONCATENATE(D8," ",D1) -> Специалист по строительному контролю ООО «Гефест» | G27: =CONCATENATE(G9," ",G1) -> Гл. специалист ССК УКС ПАО "Россети Московский регион" | H27: =CONCATENATE(H9," ",G1) -> Гл. специалист ССК УКС ПАО "Россети Московский регион" | I27: =CONCATENATE(I9," ",G1) -> Гл. специалист ССК УКС ПАО "Россети Московский регион"
C28: =CONCATENATE(C19," ",C1,"-",C21,".",C20) -> Прораб ООО "Энергосистемы"-Волков М.Ю..Приказ №05-ОТ/24 от 09 января 2024г | D28: =CONCATENATE(D19," ",D1,"-",D21,".",D20) -> Мастер электромонтажного участка ООО «Гефест»-Красилов К.А..Приказ №01/24-ОТ от 15.01.2024 | G28: =CONCATENATE(G6," ",G1," ",G7) -> Начальник СРЭС СЭС филиала ПАО "Россети Московский регион" Чуев А.Н. | I28: =CONCATENATE(I6," ",G1," ",I7) -> Начальник ХРЭС СЭС филиала ПАО "Россети Московский регион" Арнаутов А.П.
C29: =CONCATENATE(C19," ",C1," ",C21) -> Прораб ООО "Энергосистемы" Волков М.Ю. | D29: =CONCATENATE(D19," ",D1,"-",D21) -> Мастер электромонтажного участка ООО «Гефест»-Красилов К.А. | G29: =CONCATENATE(G16," ",G1," ",G17) -> ПАО "Россети Московский регион" | I29: =CONCATENATE(I16," ",G1," ",I17) -> ПАО "Россети Московский регион"
C30: =CONCATENATE(C19," ",C1) -> Прораб ООО "Энергосистемы" | D30: =CONCATENATE(D19," ",D1) -> Мастер электромонтажного участка ООО «Гефест» | G30: =CONCATENATE(G18," ",G1," ",G19) -> ПАО "Россети Московский регион"

Sheet Данные объект
A1: Данные объекта
A2: № САП | B2: SAP - 309788
A3: Объект | B3: Строительство 2БКТП-10/0,4 кВ № 1 с трансформаторами 2х1250 кВА и № 2 с трансформаторами 2х1000 кВА, 2КЛ-10 кВ от яч. 6 и яч. 17 РУ-10кВ РП-10 кВ № 26116 до 1-ой и 2-ой сек. РУ-10 кВ сооруж. БКТП-10/0,4 кВ № 1, 2КЛ-10 кВ от 1-ой и 2-ой сек. РУ-10 кВ сооруж. БКТП-10/0,4 кВ № 1 до 1-ой и 2-ой сек. РУ-10 кВ сооруж. БКТП-10/0,4 кВ № 2, 48КЛ-0,4 кВ от сооруж. БКТП-10/0,4 кВ № 1 и № 2 до сооруж. ВРУ-0,4 кВ № 1, 2, 3 к.1-8, в т.ч. ПИР, МО, Солнечногорский р-н, г.п. Андреевка, р.п. Андреевка
A4: р-н | B4: Химкинский р-н
A5: Адрес
A6: Дата разбивки
A7: Дата старт
A8: Дата финиш
A9: год
A10: Наименование электроустановки
B11: КЛ-6кВ от ф. ЦРП-3 С.1 - ТП-350 от КРУН-6кВ №4; КЛ-10кВ ф. 35207 от КРУН-10кВ №2
A12: ВЛ-10 | B12: ВЛ от ТП ф.
A13: ВЛ-0,4 | B13: ВЛ от ТП ф.
A14: КЛ | B14: КЛ от ТП ф
A15: ВРЩ | B15: ВРЩ вблизи ТП
A16: Монтажная организация
A17: Организация | B17: ООО"Энергосистемы" | C17: =CONCATENATE(B17," ",B18," ",B19) -> ООО"Энергосистемы" ОГРН 1135044003709 ИНН 5044089069 КПП 504401001 141508, Московская область, г.о. Солнечногорск, г. Солнечногорск, ул. Промышленная, стр. 5, помещение 179
A18: Реквизиты | B18: ОГРН 1135044003709 ИНН 5044089069 КПП 504401001 | C18: По выпадающим
A19: адрес | B19: 141508, Московская область, г.о. Солнечногорск, г. Солнечногорск, ул. Промышленная, стр. 5, помещение 179 | C19: 1. Энергосистемы 2.Гефест 3.Энком
A20: Должность | B20: И.о.генерального директора
A21: ФИО | B21: Чернявская Н.Ю. | C21: =CONCATENATE(B20," ",B17," ",B21) -> И.о.генерального директора ООО"Энергосистемы" Чернявская Н.Ю.
A22: Должность | B22: Специалист по строительному контролю | C22: =CONCATENATE(B22," ",B17) -> Специалист по строительному контролю ООО"Энергосистемы"
A23: Ф.И.О. | B23: Русин В.А. | C23: =CONCATENATE(B22," ",B17," ",B23) -> Специалист по строительному контролю ООО"Энергосистемы" Русин В.А.
A24: Приказ | B24: Приказ № 13-ОТ/25 от 05 мая 2025 | C24: =CONCATENATE(B22," ",B17," ",B23,".",B24) -> Специалист по строительному контролю ООО"Энергосистемы" Русин В.А..Приказ № 13-ОТ/25 от 05 мая 2025
B25: НОСТРОЙ С-50-085497
A26: Должность | B26: Прораб | C26: =CONCATENATE(B26," ",B17) -> Прораб ООО"Энергосистемы"
A27: Ф.И.О. | B27: Волков М.Ю. | C27: =CONCATENATE(B26," ",B17," ",B27) -> Прораб ООО"Энергосистемы" Волков М.Ю.
A28: Приказ | B28: Приказ №05-ОТ/24 от 09 января 2024г | C28: =CONCATENATE(B26," ",B17," ",B27,".",B28) -> Прораб ООО"Энергосистемы" Волков М.Ю..Приказ №05-ОТ/24 от 09 января 2024г
A29: Заказчик
A30: Организация | B30: ПАО "Россети Московский регион"
A31: Реквизиты | B31: ='[1]Данные организации'!F2 -> ОГРН 1057746555811 ИНН 5036065113 КПП 772501001
A32: адрес | B32: ='[1]Данные организации'!F3 -> 115114, город Москва, проезд Павелецкий 2-й, дом 3, строение 2
A33: Должность | B33: Начальник СРЭС СЭС филиала | C33: =CONCATENATE(B33," ",B30) -> Начальник СРЭС СЭС филиала ПАО "Россети Московский регион"
A34: Ф.И.О. | B34: Чуев А.Н. | C34: =CONCATENATE(B33," ",B30," ",B34) -> Начальник СРЭС СЭС филиала ПАО "Россети Московский регион" Чуев А.Н.
A35: Должность | B35: Гл. спец. сектора по льготным договорам тп | C35: =CONCATENATE(B35," ",B30) -> Гл. спец. сектора по льготным договорам тп ПАО "Россети Московский регион"
A36: Ф.И.О. | B36: Ефремкин Е.И. | C36: =CONCATENATE(B35," ",B30," ",B36) -> Гл. спец. сектора по льготным договорам тп ПАО "Россети Московский регион" Ефремкин Е.И.
A37: Должность | B37: Гл. специалист ПТГ | C37: =CONCATENATE(B37," ",B30) -> Гл. специалист ПТГ ПАО "Россети Московский регион"
A38: Ф.И.О. | B38: Царькова Н.К. | C38: =CONCATENATE(B37," ",B30," ",B38) -> Гл. специалист ПТГ ПАО "Россети Московский регион" Царькова Н.К.
B39: Приказ №2363 от 29 июля 2025г | C39: =CONCATENATE(B33," ",B30," ",B34," ",B39) -> Начальник СРЭС СЭС филиала ПАО "Россети Московский регион" Чуев А.Н. Приказ №2363 от 29 июля 2025г
A40: Должность | B40: Гл. специалист ССК УКС | C40: =CONCATENATE(B40," ",B30) -> Гл. специалист ССК УКС ПАО "Россети Московский регион"
...

Sheet Обложка
I1: приказ Минстроя РФ №1026/пр от 02.12.2022
A21: ОБЩИЙ ЖУРНАЛ РАБОТ,
A22: в котором ведется учет выполнения работ по строительству, реконструкции, капитальному ремонту объекта капитального строительства
E23: № | F23: ='Данные объект'!B2 -> SAP - 309788

Sheet Титульный лист
A1: Общий журнал работ, в котором ведется учет выполнения работ
A2: по строительству, реконтрукции, капитальному ремонту
A3: объекта капитального строительства
P4: № | Q4: ='Данные объект'!B2 -> SAP - 309788
A6: по | C6: Строительству
C7: ( указать строительство, реконструкция, капитальный ремонт)
A8: ='Данные объект'!B3 -> Строительство 2БКТП-10/0,4 кВ № 1 с трансформаторами 2х1250 кВА и № 2 с трансформаторами 2х1000 кВА, 2КЛ-10 кВ от яч. 6 и яч. 17 РУ-10кВ РП-10 кВ № 26116 до 1-ой и 2-ой сек. РУ-10 кВ сооруж. БКТП-10/0,4 кВ № 1, 2КЛ-10 кВ от 1-ой и 2-ой сек. РУ-10 кВ сооруж. БКТП-10/0,4 кВ № 1 до 1-ой и 2-ой сек. РУ-10 кВ сооруж. БКТП-10/0,4 кВ № 2, 48КЛ-0,4 кВ от сооруж. БКТП-10/0,4 кВ № 1 и № 2 до сооруж. ВРУ-0,4 кВ № 1, 2, 3 к.1-8, в т.ч. ПИР, МО, Солнечногорский р-н, г.п. Андреевка, р.п. Андреевка
A10: (наименование объекта капитального строительства, его почтовый или строительный адрес)
A12: Застройщик
A13: ='Данные объект'!B17 -> ООО"Энергосистемы"
A14: (фамилия, имя, отчество (последнее - при наличии), адрес места жительства, ОГРНИП, ИНН индивидуального предпринимателя,
A15: ='Данные объект'!B18 -> ОГРН 1135044003709 ИНН 5044089069 КПП 504401001
A16: полное и (или) сокращенное наименование, ОГРН, ИНН, место нахождения юридического лица, телефон/факс, адрес электронной почты (при наличии),
A17: ='Данные объект'!B19 -> 141508, Московская область, г.о. Солнечногорск, г. Солнечногорск, ул. Промышленная, стр. 5, помещение 179
A18: полное и (или) сокращенное наименование, ОГРН, ИНН саморегулируемой организации, членом которой является указанное юридическое лицо или индивидуальный предприниматель (за исключением случаев, когда членство в саморегулируемых организациях в области инженерных изысканий, архитектурно-строительного проектирования, строительства, реконструкции, капитального ремонта объектов капитального строительства не требуется);
A20: фамилия, имя, отчество (последнее - при наличии), паспортные данные, адрес места жительства, телефон/факс, адрес электронной почты (при наличии) - для физических лиц, не являющихся индивидуальными предпринимателями)
A22: Уполномоченный представитель застройщика
A23: №№/ пп | C23: Фамилия, имя, отчество (последнее при наличии) | J23: Должность (при наличии) | O23: Наименование, дата, номер документа, подтверждающего полномочие | T23: Идентификационный номер в национальном реестре специалистов в области строительства (за исключением случаев, когда членство в саморегулируемых организациях в области инженерных изысканий, архитектурно- строительного проектирования, строительства, реконструкции, капитального ремонта объектов капитального строительства не требуется) | AG23: Подпись
A24: 1 | C24: 2 | J24: 3 | O24: 4 | T24: 5 | AG24: 6
A25: 1
A26: 2
A30: Технический заказчик
A31: =CONCATENATE('Данные объект'!B30," ",'Данные объект'!B31) -> ПАО "Россети Московский регион" ОГРН 1057746555811 ИНН 5036065113 КПП 772501001
A32: (полное и (или) сокращенное наименование, ОГРН, ИНН, место нахождения юридического лица, телефон/факс, адрес электронной почты (при наличии),
A33: ='Данные объект'!B32 -> 115114, город Москва, проезд Павелецкий 2-й, дом 3, строение 2
A34: полное и (или) сокращенное наименование, ОГРН, ИНН саморегулируемой организации, членом которой является указанное юридическое лицо (за исключением случаев, когда членство в саморегулируемых организациях в области инженерных изысканий, архитектурно-строительного проектирования, строительства, реконструкции, капитального ремонта объектов капитального строительства не требуется);
A36: Уполномоченный представитель технического заказчика
A37: №№/ пп | C37: Фамилия, имя, отчество (последнее при наличии) | J37: Должность (при наличии) | O37: Наименование, дата, номер документа, подтверждаю-щего полномочие | T37: Идентификационный номер в национальном реестре специалистов в области строительства (за исключением случаев, когда членство в саморегулируемых организациях в области инженерных изысканий, архитектурно- строительного проектирования, строительства, реконструкции, капитального ремонта объектов капитального строительства не требуется) | AG37: Подпись
A38: 1 | C38: 2 | J38: 3 | O38: 4 | T38: 5 | AG38: 6
C39: ='Данные объект'!B34 -> Чуев А.Н. | J39: ='Данные объект'!C33 -> Начальник СРЭС СЭС филиала ПАО "Россети Московский регион" | O39: ='Данные объект'!B39 -> Приказ №2363 от 29 июля 2025г
A42: Лицо, ответственное за эксплуатацию здания, сооружения, или региональный оператор (заполняется в случае, если договор строительного подряда заключается с лицом, ответственным за эксплуатацию здания, сооружения, или региональным оператором)
A44: (фамилия, имя, отчество (последнее - при наличии), адрес места жительства, ОГРНИП, ИНН индивидуального предпринимателя,
A46: полное и (или) сокращенное наименование, ОГРН, ИНН, место нахождения юридического лица, телефон/факс, адрес электронной почты (при наличии),
A48: фамилия, имя, отчество (последнее - при наличии), паспортные данные, адрес места жительства, телефон/факс, адрес электронной почты (при наличии) - для физических лиц, не являющихся индивидуальными предпринимателями)
A50: Уполномоченный представитель лица, ответственного за эксплуатацию здания, сооружения, или регионального оператора (заполняется в случае, если договор строительного подряда заключается с лицом, ответственным за эксплуатацию здания, сооружения, или региональным оператором)
A51: №№/ пп | C51: Фамилия, имя, отчество (последнее при наличии) | O51: Должность (при наличии) | V51: Наименование, дата, номер документа, подтверждающего полномочие | AE51: Подпись
A52: 1 | C52: 2 | O52: 3 | V52: 4 | AE52: 5
A58: Сведения о выданном разрешении на строительство (заполняется в случае, если разрешение на строительство требуется в соответствии со статьей 51 Градостроительного кодекса Российской Федерации (Собрание законодательства Российской Федерации, 2005, № 1, ст. 16; 2022, № 29, ст. 5317)
A60: (номер, дата выдачи разрешения на строительство, наименование органа исполнительной власти,
A62: государственной корпорации или органа местного самоуправления, выдавших разрешение)
...

Sheet Раздел1
A1: РАЗДЕЛ 1
A2: Список инженерно-технического персонала лица, осуществляющего строительство, реконструкцию, капитальный ремонт, занятого при строительстве, реконструкции, капитальном ремонте объекта капитального строительства
A3: № п/п | B3: Полное и (или) сокращенное наименование или фамилия, имя отчество (последнее - при наличии) лица, осуществляющего строительство, реконструкцию, капитальный ремонт | C3: Фамилия, инициалы, должность (при наличии) лица, входящего в список инженерно- технического персонала | D3: Дата начала работ на объекте капитального строительства с указанием вида работ | E3: Дата окончания работ на объекте капитального строительства | F3: Должность (при наличии), фамилия, инициалы, подпись уполномоченного представителя лица, осуществляющего строительство, реконструкцию, капитальный ремонт
A4: 1 | B4: 2 | C4: 3 | D4: 4 | E4: 5 | F4: 6
A5: 1 | B5: Русин В.А. | C5: Специалист СК ООО "Энергосистемы" | D5: ='Данные объект'!B7 -> 0 | E5: ='Данные объект'!B8 -> 0 | F5: ='Данные объект'!C21 -> И.о.генерального директора ООО"Энергосистемы" Чернявская Н.Ю.
A6: 2 | B6: Волков М.Ю. | C6: Прораб ООО "Энергосистемы" | D6: ='Данные объект'!B7 -> 0 | E6: ='Данные объект'!B8 -> 0 | F6: ='Данные объект'!C21 -> И.о.генерального директора ООО"Энергосистемы" Чернявская Н.Ю.
A7: 3 | B7: Фечин А.А. | C7: Главный энергетик ООО "Энергосистемы" | D7: ='Данные объект'!B7 -> 0 | E7: ='Данные объект'!B8 -> 0 | F7: ='Данные объект'!C21 -> И.о.генерального директора ООО"Энергосистемы" Чернявская Н.Ю.

Sheet Раздел2
A1: РАЗДЕЛ 2
A2: Перечень специальных журналов, в которых ведется учет выполнения работ, а также журналов авторского надзора лица, осуществляющего подготовку проектной документации
A3: № п/п | B3: Наименование специального журнала (журнала авторского надзора) и дата его выдачи | C3: Полное и (или) сокращенное наименование или фамилия, имя, отчество (при наличии) лица, осуществляющего строительство, реконструкцию, капитальный ремонт (лица, осуществляющего подготовку проектной документации), ведущих журнал, их уполномоченных представителей с указанием должности (при наличии), фамилии, инициалов | D3: Дата передачи застройщику или заказчику журнала | E3: Подпись уполномоченного представителя застройщика или технического заказчика, лица, ответственного за эксплуатацию здания, сооружения, и (или) регионального оператора
A4: 1 | B4: 2 | C4: 3 | D4: 4 | E4: 5
A5: 1 | B5: Журнал входного контроля | C5: ='Данные объект'!C23 -> Специалист по строительному контролю ООО"Энергосистемы" Русин В.А.

Sheet Раздел3
A1: РАЗДЕЛ 3
A2: Сведения о выполнении работ в процессе строительства, реконструкции, капитального ремонта объекта капитального строительства
A3: № п/п | B3: Дата выпол-нения работ | C3: Условия произ-водства работ | D3: Наименование работ, выполняемых в процессе строительства, реконструкции, капитального ремонта объекта капитального строительства с указанием осей, рядов, отметов, пикетов, этажей, ярусов, секций, помещений, в которых выполнялись работы, сведения о методах выполнения работ, применяемых строительных материалах, изделиях и конструкциях, проведенных испытаниях конструкций, оборудования, систем, сетей и устройств (опробование вхолостую или под нагрузкой, подача электроэнергии, давления, испытания на прочность и герметичность) | E3: Должность (при наличии), фамилия, инициалы,подпись уполномоченного представителя лица, осуществляющего строительство, реконструкцию, капитальный ремонт
A4: 1 | B4: 2 | C4: 3 | D4: 3 | E4: 4
F5: Заполняется от руки

Sheet Раздел4
A1: РАЗДЕЛ 4
A2: Сведения о строительном контроле в процессе строительства, реконструкции, капитального ремонта объекта капитального строительства
A3: № п/п | B3: Сведения о проведении строительного контроля при строительстве, реконструкции, капитальном ремонте объекта капитального строительства | C3: Выявленные недостатки | D3: Срок устранения выявленных недостатков | E3: Должность (при наличии), фамилия, инициалы, подпись уполномоченного представителя застройщика или технического заказчика, лица, ответственного за эксплуатацию здания, сооружения, и(или) регионального оператора по вопросам строительного контроля | F3: Дата устранения недостатков | G3: Должность (при наличии), фамилия, инициалы, подпись уполномоченного представителя застройщика или технического заказчика, лица, ответственного за эксплуатацию здания, сооружения, и(или) регионального оператора по вопросам строительного контроля
A4: 1 | B4: 2 | C4: 3 | D4: 4 | E4: 5 | F4: 6 | G4: 7
A5: 1 | B5: Произведен строительный контроль | C5: не выявлены | D5: - | E5: ='Данные объект'!C41 -> Гл. специалист ССК УКС ПАО "Россети Московский регион" Алексанян Г.Р. | F5: - | G5: ='Данные объект'!C41 -> Гл. специалист ССК УКС ПАО "Россети Московский регион" Алексанян Г.Р.
A6: 2 | B6: Произведен строительный контроль | C6: не выявлены | D6: - | E6: ='Данные объект'!C23 -> Специалист по строительному контролю ООО"Энергосистемы" Русин В.А. | F6: - | G6: ='Данные объект'!C23 -> Специалист по строительному контролю ООО"Энергосистемы" Русин В.А.

Sheet Раздел5
A1: РАЗДЕЛ 5
A2: Перечень исполнительной документации при строительстве, реконструкции, капитальном ремонте объекта капитального строительства
A3: № п/п | B3: Наименование исполнительной документации (с указанием наименования и реквизитов документа, вида работ, места расположения конструкций, участков сетей инженерно- технического обеспечения) | C3: Дата подписания документа, должности (при наличии), фамилии, инициалы лиц, подписавших документы
A4: 1 | B4: 2 | C4: 3
A5: 1 | B5: АОСР Выемка грунта под прокладку КЛ-6/10 кВ | C5: 16.07.2025 Гл.Специалист ССК УКС ПАО "Россети Московский Регион" Хлебнов Д.Ф. Прораб ООО "Энергосистемы" Волков М.Ю. Специалист СК ООО "Энергосистемы" Русин В.А.
A6: 2
A7: 3
A8: 4
A9: 5
A10: 6

Sheet Раздел6
A1: РАЗДЕЛ 6
A2: Сведения о государственном строительном надзоре при строительстве, реконструкции, капитальном ремонте объекта капитального строительства
A3: № п/п | B3: Дата контрольного (надзорного) мероприятия | C3: Данные о проведенных органом государственного строительного надзора контрольных (надзорных) мероприятиях | D3: Срок устранения выявленных нарушений | E3: Должность, фамилия, инициалы, подпись должностного лица | F3: Фактическая дата устранения выявленных нарушений | G3: Должность, фамилия, инициалы, подпись должностного лица
A4: 1 | B4: 2 | C4: 3 | D4: 4 | E4: 5 | F4: 6 | G4: 7

Sheet ярлык
A1: В журнале пронумеровано и прошнуровано
A3: “ ____ ” _____________ 20___ г.
A5: (должность, фамилия, инициалы и подпись руководителя организации,
A7: выдавшего журнал)
A9: В журнале пронумеровано и прошнуровано
A11: “ ____ ” _____________ 20___ г.
A13: (должность, фамилия, инициалы и подпись руководителя организации,
A15: выдавшего журнал)
