Workbook

Sheet Данные организации
A1: организация | B1: ООО "Энергосистемы" | C1: ООО «Гефест» | D1: ООО "Энком" | F1: ПАО "Россети Московский регион" | I1: Члены комиссии
A2: реквизиты | B2: ОГРН 1135044003709 ИНН 5044089069 КПП 504401001 | C2: ОГРН 1215000057238 ИНН 5044122213 КПП 504401001 | D2: ОГРН 1077762950055 ИНН 7743668640 КПП 770801001 | F2: ОГРН 1057746555811 ИНН 5036065113 КПП 772501001 | I2: ООО"Энергосистемы" | J2: ООО «Гефест» | K2: ООО «Энком» | L2: ПАО "Россети Московский регион"
A3: адрес | B3: 141508, Московская область, г.о. Солнечногорск, г. Солнечногорск, ул. Промышленная, стр. 5, помещение 179 | C3: 141508, Московская область, г.о. Солнечногорск, г Солнечногорск, ул Промышленная, строение 29А, корпус 1, офис 11 | D3: 107140, г.Москва, ул. Краснопрудная, д. 12/1, стр. 1, помещ. 1/6 | F3: 115114, город Москва, проезд Павелецкий 2-й, дом 3, строение 2 | I3: Главный энергетик ООО "Энергосистемы" | J3: Генеральный директор ООО "Гефест" | K3: Генеральный директор ООО "Энком"
A4: район | F4: Солнечногорский р-н | H4: Химкинский р-н | I4: Фечин А.А. | J4: Звездов Р.Е. | K4: Дандре Г.А.
F5: СРЭС филиала | H5: ХРЭС филиала | I5: Прораб ООО "Энергосистемы" | J5: Мастер электромонтажного участка ООО "Гефест" | K5: Главный инженер ООО "Энком"
A6: директор | B6: И.о.генерального директора | C6: Генеральный директор | D6: Генеральный директор | F6: Начальник СРЭС СЭС филиала | H6: Начальник ХРЭС СЭС филиала | I6: Волков М.Ю. | J6: Красилов К.А. | K6: Горбан Г.К.
A7: директор ФИО | B7: Чернявская Н.Ю. | C7: Звездов Р.Е. | D7: Дандре Г.А. | F7: Чуев А.Н. | H7: Арнаутов А.П. | I7: Инженер-электрик ООО "Энергосистемы" | J7: Главный специалист проектного отдела ООО "Гефест" | K7: Специалист по строительному контролю ООО "Энком"
A8: Строй.контроль | B8: Инженер по строительному контролю | C8: Специалист по строительному контролю | F8: Гл. специалист ССК УКС | G8: Гл. специалист ССК УКС | H8: Гл. специалист ССК УКС | I8: Высоцкий А.В. | J8: Павлова К.П. | K8: Филлипов А.Ю.
A9: Приказ стр.контр. | B9: Приказ № 18-ОТ/24 от 03 июня 2024 (НОСТРОЙ С-50-188017) | C9: Приказ №01/24-ОТ от 15.01.2024 (НРС № С-61-104369) | F9: Приказ №2363 от 29 июля 2025г (НРС С-50-069023) | G9: Приказ №53 от 13 марта 2025г. (НРС С-50-77-262451) | H9: Приказ №2363 от 29 июля 2025г (НОСТРОЙ С-50-15922)
A10: ФИО стр.контр. | B10: Капитонов Д.А. | C10: Саженова Л.В. | F10: Алексанян Г.Р. | G10: Шатковский А.Н. | H10: Хлебнов Д.Ф.
A11: Представитель | F11: Технический надзор | H11: Технический надзор
A12: ФИО предст.
F14: Гл. спец. сектора по льготным договорам тп | H14: Гл.инженер
F15: Ефремкин Е.И. | H15: Игнатьев К.А.
F16: Гл. специалист ПТГ
F17: Царькова Н.К.
A18: Прораб | B18: Прораб | C18: Мастер электромонтажного участка | D18: Главный инженер
A19: Приказ прораб | B19: Приказ №05-ОТ/24 от 09 января 2024г | C19: Приказ №01/24-ОТ от 15.01.2024 | D19: Приказ № ОТ-25 от 12.01.2024
A20: ФИО прораб | B20: Волков М.Ю. | C20: Красилов К.А. | D20: Горбан Г.К.
A23: сцепленные организация | B23: =CONCATENATE(B2,",",B3) -> ОГРН 1135044003709 ИНН 5044089069 КПП 504401001,141508, Московская область, г.о. Солнечногорск, г. Солнечногорск, ул. Промышленная, стр. 5, помещение 179 | C23: =CONCATENATE(C2,",",C3) -> ОГРН 1215000057238 ИНН 5044122213 КПП 504401001,141508, Московская область, г.о. Солнечногорск, г Солнечногорск, ул Промышленная, строение 29А, корпус 1, офис 11 | F23: =CONCATENATE(F8," ",F1,"-",F10," .",F9) -> Гл. специалист ССК УКС ПАО "Россети Московский регион"-Алексанян Г.Р. .Приказ №2363 от 29 июля 2025г (НРС С-50-069023) | G23: =CONCATENATE(G8," ",F1,"-",G9,".",G10) -> Гл. специалист ССК УКС ПАО "Россети Московский регион"-Приказ №53 от 13 марта 2025г. (НРС С-50-77-262451).Шатковский А.Н. | H23: =CONCATENATE(H8," ",F1,"-",H10," .",H9) -> Гл. специалист ССК УКС ПАО "Россети Московский регион"-Хлебнов Д.Ф. .Приказ №2363 от 29 июля 2025г (НОСТРОЙ С-50-15922)
A24: сцепленные организация | B24: =CONCATENATE(B1,",",B2,",",B3) -> ООО "Энергосистемы",ОГРН 1135044003709 ИНН 5044089069 КПП 504401001,141508, Московская область, г.о. Солнечногорск, г. Солнечногорск, ул. Промышленная, стр. 5, помещение 179 | C24: =CONCATENATE(C1,",",C2,",",C3) -> ООО «Гефест»,ОГРН 1215000057238 ИНН 5044122213 КПП 504401001,141508, Московская область, г.о. Солнечногорск, г Солнечногорск, ул Промышленная, строение 29А, корпус 1, офис 11 | F24: =CONCATENATE(F8," ",F1," ",F10) -> Гл. специалист ССК УКС ПАО "Россети Московский регион" Алексанян Г.Р. | G24: =CONCATENATE(G8," ",F1," ",G10) -> Гл. специалист ССК УКС ПАО "Россети Московский регион" Шатковский А.Н. | H24: =CONCATENATE(H8," ",F1," ",H10) -> Гл. специалист ССК УКС ПАО "Россети Московский регион" Хлебнов Д.Ф. | I24: Зам.начальника СРЭС филиала ПАО "Россети Московский Регион" Минин А.Л. | J24: Представитель ХРЭС филиала ПАО "Россети Московский Регион"
B25: =CONCATENATE(B8," ",B1,"-",B10,".",B9) -> Инженер по строительному контролю ООО "Энергосистемы"-Капитонов Д.А..Приказ № 18-ОТ/24 от 03 июня 2024 (НОСТРОЙ С-50-188017) | C25: =CONCATENATE(C8," ",C1,"-",C10,".",C9) -> Специалист по строительному контролю ООО «Гефест»-Саженова Л.В..Приказ №01/24-ОТ от 15.01.2024 (НРС № С-61-104369) | F25: =CONCATENATE(F8," ",F1) -> Гл. специалист ССК УКС ПАО "Россети Московский регион" | H25: =CONCATENATE(H8," ",F1) -> Гл. специалист ССК УКС ПАО "Россети Московский регион"
B26: =CONCATENATE(B8," ",B1) -> Инженер по строительному контролю ООО "Энергосистемы" | C26: =CONCATENATE(C8," ",C1) -> Специалист по строительному контролю ООО «Гефест» | F26: =CONCATENATE(F6," ",F1," ",F7) -> Начальник СРЭС СЭС филиала ПАО "Россети Московский регион" Чуев А.Н. | H26: =CONCATENATE(H6," ",F1," ",H7) -> Начальник ХРЭС СЭС филиала ПАО "Россети Московский регион" Арнаутов А.П.
B27: =CONCATENATE(B18," ",B1,"-",B20,".",B19) -> Прораб ООО "Энергосистемы"-Волков М.Ю..Приказ №05-ОТ/24 от 09 января 2024г | C27: =CONCATENATE(C18," ",C1,"-",C20,".",C19) -> Мастер электромонтажного участка ООО «Гефест»-Красилов К.А..Приказ №01/24-ОТ от 15.01.2024 | F27: =CONCATENATE(F14," ",F1," ",F15) -> Гл. спец. сектора по льготным договорам тп ПАО "Россети Московский регион" Ефремкин Е.И. | H27: =CONCATENATE(H14," ",F1," ",H15) -> Гл.инженер ПАО "Россети Московский регион" Игнатьев К.А.
B28: =CONCATENATE(B18," ",B1," ",B20) -> Прораб ООО "Энергосистемы" Волков М.Ю. | C28: =CONCATENATE(C18," ",C1,"-",C20) -> Мастер электромонтажного участка ООО «Гефест»-Красилов К.А. | F28: =CONCATENATE(F16," ",F1," ",F17) -> Гл. специалист ПТГ ПАО "Россети Московский регион" Царькова Н.К.
B29: =CONCATENATE(B18," ",B1) -> Прораб ООО "Энергосистемы" | C29: =CONCATENATE(C18," ",C1) -> Мастер электромонтажного участка ООО «Гефест»
A32: Приказы НТД
A33: До 14.11.24 | B33: методическими указаниями ПАО "Россети Московский регион" (утв. Приказом от 05.10.2023 г. № 1021)
A34: От 14.11.24 | B34: методическими указаниями ПАО "Россети Московский регион" (утв. Приказом от 14.11.2024 г. № 1254)
B35: Приказы
B36: по приказу №05-ОТ/24 от 09 января 2024г. в составе:
B37: по приказу №01/24-ОТ от 15.01.2024г. в составе:

Sheet Данные объект
A1: Данные объекта
A2: № САП | B2: SAP - 288007
A3: Объект | B3: Строительство ТП-10/0,4 кВ, ВЛЗ-10 кВ от ВЛЗ-10 кВ ф. «Кочугино» ПС №185 "Воробьево", ВЛИ-0,38 кВ, рлр, в т.ч. ПИР, МО, Солнечногорский р-н, г. Солнечногорск
A4: р-н | B4: Солнечногорский р-н
A5: Адрес | B5: 141533,Российская Федерация, г.о.Солнечногорск
A6: Дата старт | B6: 25.09.2024
A7: Дата финиш | B7: 15.01.2025
A8: Наименование электроустановки
A9: ТП | B9: ТП№
A10: Монтажная организация
A11: Организация | B11: ООО "Энергосистемы" | C11: =CONCATENATE(B11," ",B12," ",B13) -> ООО "Энергосистемы" ОГРН 1077762950055 ИНН 7743668640 КПП 770801001 107140, г.Москва, ул. Краснопрудная, д. 12/1, стр. 1, помещ. 1/6
A12: Реквизиты | B12: ОГРН 1077762950055 ИНН 7743668640 КПП 770801001
A13: адрес | B13: 107140, г.Москва, ул. Краснопрудная, д. 12/1, стр. 1, помещ. 1/6
A14: Должность | B14: Генеральный директор
A15: ФИО | B15: Звездов Р.Е. | C15: =CONCATENATE(B14," ",B11," ",B15) -> Генеральный директор ООО "Энергосистемы" Звездов Р.Е.
A16: Должность | B16: Инженер по строительному контролю | C16: =CONCATENATE(B16," ",B11) -> Инженер по строительному контролю ООО "Энергосистемы"
A17: Ф.И.О. | B17: Капитонов Д.А. | C17: =CONCATENATE(B16," ",B11," ",B17) -> Инженер по строительному контролю ООО "Энергосистемы" Капитонов Д.А.
A18: Приказ | B18: Приказ № 18-ОТ/24 от 03 июня 2024 (НОСТРОЙ С-50-188017) | C18: =CONCATENATE(B16," ",B11," ",B17,".",B18) -> Инженер по строительному контролю ООО "Энергосистемы" Капитонов Д.А..Приказ № 18-ОТ/24 от 03 июня 2024 (НОСТРОЙ С-50-188017)
A19: Должность | B19: Прораб | C19: =CONCATENATE(B19," ",B11) -> Прораб ООО "Энергосистемы"
A20: Ф.И.О. | B20: Волков М.Ю. | C20: =CONCATENATE(B19," ",B11," ",B20) -> Прораб ООО "Энергосистемы" Волков М.Ю.
A21: Приказ | B21: Приказ №05-ОТ/24 от 09 января 2024г | C21: =CONCATENATE(B19," ",B11," ",B20,".",B21) -> Прораб ООО "Энергосистемы" Волков М.Ю..Приказ №05-ОТ/24 от 09 января 2024г
A22: Заказчик
A23: Организация | B23: ПАО "Россети Московский регион" | C23: =CONCATENATE(B23," ",B24,",",B25) -> ПАО "Россети Московский регион" ОГРН 1057746555811 ИНН 5036065113 КПП 772501001,115114, город Москва, проезд Павелецкий 2-й, дом 3, строение 2
A24: Реквизиты | B24: ='[1]Данные организации'!F2 -> ОГРН 1057746555811 ИНН 5036065113 КПП 772501001
A25: адрес | B25: ='[1]Данные организации'!F3 -> 115114, город Москва, проезд Павелецкий 2-й, дом 3, строение 2
A26: Должность | B26: Начальник СРЭС СЭС филиала | C26: =CONCATENATE(B26," ",B23) -> Начальник СРЭС СЭС филиала ПАО "Россети Московский регион"
A27: Ф.И.О. | B27: Чуев А.Н. | C27: =CONCATENATE(B26," ",B23," ",B27) -> Начальник СРЭС СЭС филиала ПАО "Россети Московский регион" Чуев А.Н.
A28: Должность | B28: Гл. спец. сектора по льготным договорам тп | C28: =CONCATENATE(B28," ",B23) -> Гл. спец. сектора по льготным договорам тп ПАО "Россети Московский регион"
A29: Ф.И.О. | B29: Ефремкин Е.И. | C29: =CONCATENATE(B28," ",B23," ",B29) -> Гл. спец. сектора по льготным договорам тп ПАО "Россети Московский регион" Ефремкин Е.И.
A30: Должность | B30: Гл. специалист ПТГ | C30: =CONCATENATE(B30," ",B23) -> Гл. специалист ПТГ ПАО "Россети Московский регион"
A31: Ф.И.О. | B31: Царькова Н.К. | C31: =CONCATENATE(B30," ",B23," ",B31) -> Гл. специалист ПТГ ПАО "Россети Московский регион" Царькова Н.К.
A32: Должность | B32: Гл. специалист ССК УКС ПАО "Россети Московский регион" Алексанян Г.Р.
A33: Ф.И.О. | B33: Жижкевич М.А.
A34: Приказ | B34: Приказ №263 от 31 января 2024г (НОСТРОЙ С-50-138711)
A35: Проект
A36: Организация | B36: ООО"Энергосистемы"
A37: Реквизиты | B37: ОГРН 1135044003709 ИНН 5044089069 КПП 504401001
A38: адрес | B38: 141508, Московская область, г.о. Солнечногорск, г. Солнечногорск, ул. Промышленная, стр. 5, помещение 179
A39: Город | B39: г. Солнечногорск
A40: № | B40: проект
...

Sheet  Журнал АВК
J1: Приложение 2
J3: Приложение 49 к приказу от 19.12.2019 № 1414
B10: ЖУРНАЛ №
B11: УЧЕТА РЕЗУЛЬТАТОВ ВХОДНОГО КОНТРОЛЯ И КОНТРОЛЯ КАЧЕСТВА ПОЛУЧАЕМЫХ ДЕТАЛЕЙ,
B12: МАТЕРИАЛОВ, ИЗДЕЛИЙ, КОНСТРУКЦИЙ И ОБОРУДОВАНИЯ
B13: (ПРОДУКЦИИ ДЛЯ ЦЕЛЕЙ СТРОИТЕЛЬСТВА / РЕКОНСТРУКЦИИ)
B20: Наименование объекта | C20: ='Данные объект'!B3 -> Строительство ТП-10/0,4 кВ, ВЛЗ-10 кВ от ВЛЗ-10 кВ ф. «Кочугино» ПС №185 "Воробьево", ВЛИ-0,38 кВ, рлр, в т.ч. ПИР, МО, Солнечногорский р-н, г. Солнечногорск
B21: Адрес объекта | C21: ='Данные объект'!B5 -> 141533,Российская Федерация, г.о.Солнечногорск
B22: Наименование строительной организации | C22: ='Данные объект'!B11 -> ООО "Энергосистемы"
H27: Начат | I27: ='Данные объект'!B6 -> 25.09.2024
H28: Окончен | I28: ='Данные объект'!B7 -> 15.01.2025
A34: № п.п. | B34: Дата поставки | C34: Наименование деталей, материалов, изделий, конструкций, оборудования | D34: Количество | E34: Поставщик | F34: Наименование и номер документа изготовителя | G34: Результат проверки сопроводительных документов изготовителя и визуального осмотра на соответствие требованиям утвержденной проектной документации и соответствующим документам по стандартизации | H34: Решение о необходимости проведения инструментального контроля | I34: Результат инструментального контроля | J34: Подпись лица, осуществляющего контроль со стороны лица, осуществляющего строительство, и застройщика (технического заказчика)
A35: 1 | B35: 2 | C35: 3 | D35: 4 | E35: 5 | F35: 6 | G35: 7 | H35: 8 | I35: 9 | J35: 10
A36: 1 | B36: =I27 -> 25.09.2024 | C36: ='Провод СИП 3'!A37 -> Провод 3СИП3 1х70 | D36: ='Провод СИП 3'!C43 -> 64 м | E36: ='Провод СИП 3'!K39 -> ООО «Цветлит» | F36: ='Провод СИП 3'!A41 -> Паспорт качества на барабан № 23Т1-8223 от 09.01.2023г. | G36: Визуальный | H36: ____ | I36: ____ | J36: /
A37: 2 | B37: =I27 -> 25.09.2024 | C37: ='Провод СИП 2'!A39 -> Провод СИП2 3х70+1х70 | D37: ='Провод СИП 2'!C45 -> 135 м | E37: ='Провод СИП 2'!K41 -> АО «Кирскабель» | F37: ='Провод СИП 2'!A43 -> Паспорт качества на барабан № 22409668 | G37: Визуальный | H37: ____ | I37: ____ | J37: /
A38: 3 | B38: =I27 -> 25.09.2024 | C38: =стойки!A37 -> Ж/б опоры СВ110-5 | D38: =стойки!C43 -> 2 шт | E38: =стойки!K39 -> ООО «Энерго ЖБИ» | F38: =стойки!A41 -> Паспорт №302 от 12.02.2023 | G38: Визуальный | H38: ____ | I38: ____ | J38: /
A39: 4 | B39: =I27 -> 25.09.2024 | C39: =РЛК!A37 -> Разъединитель трехполюсный с приводом РЛК 10/400 | D39: =РЛК!C43 -> 1 шт | E39: =РЛК!K39 -> ООО "НИЛЕД" | F39: =РЛК!K39 -> ООО "НИЛЕД" | G39: Визуальный | H39: ____ | I39: ____ | J39: /
A40: 5 | B40: =I27 -> 25.09.2024 | C40: =ПРВТ!A37 -> Предохранитель-разъеденитель выхлопной ПРВТ-1-10.II-50Л-У1 | D40: 3 шт. | E40: =ПРВТ!K39 -> ОАО "ЗЭТО" | F40: =ПРВТ!A41 -> Паспорт №№20, 33, 44 | G40: Визуальный | H40: ____ | I40: ____ | J40: /
A41: 6 | B41: =I27 -> 25.09.2024 | C41: =КТП!A37 -> Комплектная трансформаторная подстанция КТП-ТК/ВК-250/10/0,4 | D41: =КТП!C43 -> 1 комп. | E41: =КТП!K39 -> ООО "КТП-Энерго" | F41: =КТП!A41 -> Паспорт №5009 от 13.07.2023г. | G41: Визуальный | H41: ____ | I41: ____ | J41: /
A42: 7 | B42: =I27 -> 25.09.2024 | C42: =ТМГ!A37 -> Трансформатор ТМГ-250/10-0,4УХЛ1 | D42: =ТМГ!C43 -> 1 шт. | E42: =ТМГ!K39 -> ТОО "Уральский трансформаторный завод" | F42: =ТМГ!A41 -> Паспорт №2204ФГ406 | G42: Визуальный | H42: ____ | I42: ____ | J42: /
A43: 8 | B43: =I27 -> 25.09.2024 | C43: ='лин.армат 0,4'!A37 -> Линейная арматура 0,4кВ (Заземляющий проводник ЗП6, Зажим Р72, Ответвительный зажим Р70, Натяжной зажим РА1500, Плашечный зажим ПС-2-1, Анкерный кронштейн CS10.3, Комплект промежуточной подвески ES1500, Стяжной хомут Е778, Мателлическая летна F207, Скрепа NC20, Бугель NB20, Герметичный зажим РС481, Ограничитель перенапряжения ОР600/28, Колпачек изолирующий СЕ16-150) | D43: ='лин.армат 0,4'!C43 -> 106 шт | E43: ='лин.армат 0,4'!K39 -> ООО «Нилед» | F43: ='лин.армат 0,4'!A41 -> Сертификат соответствия №РОСС RU.МЛ10.10783 срок действия от 25.11.2022 до 19.11.2028г | G43: Визуальный | H43: ____ | I43: ____ | J43: /
A44: 9 | B44: =I27 -> 25.09.2024 | C44: ='уголок 50'!A37 -> Уголок 50х50х5 | D44: ='уголок 50'!C43 -> 41,6 м | E44: ='уголок 50'!K39 -> ООО «УГМК-Сталь» | F44: ='уголок 50'!A41 -> Сертификат качества №2021644263 | G44: Визуальный | H44: ____ | I44: ____ | J44: /
A45: 10 | B45: =I27 -> 25.09.2024 | C45: ='уголок 63'!A39 -> Уголок 63х63х5 | D45: ='уголок 63'!C45 -> 30 м | E45: ='уголок 63'!K41 -> ООО «УГМК-Сталь» | F45: ='уголок 63'!A43 -> Сертификат качества №2024647014 | G45: Визуальный | H45: ____ | I45: ____ | J45: /
A46: 11 | B46: =I27 -> 25.09.2024 | C46: ='арм. 10'!A37 -> Сталь круглая Ø10 | D46: ='арм. 10'!C43 -> 18 м | E46: ='арм. 10'!K39 -> ООО "УГМК-Сталь" | F46: ='уголок 50'!A41 -> Сертификат качества №2021644263 | G46: Визуальный | H46: ____ | I46: ____ | J46: /
A47: 12 | B47: =I27 -> 25.09.2024 | C47: =ВРЩ!A37 -> ВРЩ-0,4кВ | D47: =ВРЩ!C43 -> 1 шт | E47: =ВРЩ!K39 -> ООО "ИЭК Холдинг" | F47: =ВРЩ!A41 -> Паспорт №б/н | G47: Визуальный | H47: ____ | I47: ____ | J47: /
A48: 13 | B48: =I27 -> 25.09.2024 | C48: ='счетчик СТЭМ'!A37 -> Счетчик электрической энергии СТЭМ 300 | D48: ='счетчик СТЭМ'!C43 -> 1 шт | E48: ='счетчик СТЭМ'!K39 -> ООО "СИ-АРТ" | F48: ='счетчик СТЭМ'!A41 -> Паспорт №25001237 от 06.05.2025г. | G48: Визуальный | H48: ____ | I48: ____ | J48: /
A49: 14 | B49: =I27 -> 25.09.2024 | C49: ='лин.армат 6-10к'!A37 -> Линейная арматура 10кВ (Траверса ТМ74, ТМ73, Зажим SLW.36, Изолятор штырьевой IF27, Колпачок К-9, Заземляющий проводник ЗП1-1, Плашечный зажим CD35, Зажим ответвительный RP150, Хомут Х51, Вязка спиральная СВ70, Траверса ТМ63, Плашечный зажим CD70, Металлическая лента F207, Скрепа NC20) | D49: ='лин.армат 6-10к'!C43 -> 121 шт | E49: ='лин.армат 6-10к'!K39 -> ООО «Нилед» | F49: ='лин.армат 6-10к'!A41 -> Сертификат соответствия №РОСС RU.АМ05.Н22141 | G49: Визуальный | H49: ____ | I49: ____ | J49: /
A50: 15 | B50: =I27 -> 25.09.2024 | C50: =пол.40х4!A37 -> Стальная полоса 40х4 | D50: =пол.40х4!C43 -> 37 м | E50: =пол.40х4!K39 -> МЗ Балаково | F50: =пол.40х4!A41 -> Сертификат качества №21010194 | G50: Визуальный | H50: ____ | I50: ____ | J50: /
A51: 16 | B51: =I27 -> 25.09.2024 | C51: =пол.50х4!A37 -> Стальная полоса 50х4 | D51: =пол.50х4!C43 -> 3 м | E51: =пол.50х4!K39 -> ООО "Тулачермет-сталь" | F51: =пол.50х4!A41 -> Сертификат качества №3968968 | G51: Визуальный | H51: ____ | I51: ____ | J51: /
A52: 17 | B52: =I27 -> 25.09.2024 | C52: ='арм. 12'!A37 -> Сталь круглая Ø12 | D52: ='арм. 12'!C43 -> 102 м | E52: ='арм. 12'!K39 -> ООО "УГМК Сталь" | F52: ='арм. 12'!A41 -> Сертификат качества №2060647170 | G52: Визуальный | H52: ____ | I52: ____ | J52: /
A53: 18 | B53: =I27 -> 25.09.2024 | C53: =' фунд.КТП'!A37 -> Фундаментные блоки ФБС 24.4.6-Т; | D53: =' фунд.КТП'!C43 -> 2 шт | E53: =' фунд.КТП'!K39 -> ООО «ФОРМА ЖБИ» | F53: =' фунд.КТП'!A41 -> Документ №119 от 03.03.2023г. | G53: Визуальный | H53: ____ | I53: ____ | J53: /
A54: 19 | B54: =I27 -> 25.09.2024 | C54: ='арм. 8'!A37 -> Сталь круглая Ø8 | D54: ='арм. 8'!C43 -> 8,1 м | E54: ='арм. 8'!K39 -> ОАО "Белорусский металлургический завод" | F54: ='арм. 8'!A41 -> Сертификат качества №8683-2722 | G54: Визуальный | H54: ____ | I54: ____ | J54: /
A55: 20 | B55: =I27 -> 25.09.2024 | C55: =изоляторы!A39 -> Изолятор штырьевой ШФ20-Г | D55: =изоляторы!C45 -> 6 шт | E55: =изоляторы!K41 -> ООО «Гжельский завод Электроизолятор» | F55: =изоляторы!A43 -> Сертификат соответствия №РОСС RU.АЖ49.Н01642 срок действия от 24.08.2021г до 23.08.2024г | G55: Визуальный | H55: ____ | I55: ____ | J55: /
A56: 21 | B56: =I27 -> 25.09.2024 | C56: =ПКТ!A37 -> Предохранитель высоковольтный с кварцевым наполнителем 3ПКТ-103-6-100А-31,5УЗ | D56: =ПКТ!C43 -> 3 шт | E56: =ПКТ!K39 -> ООО «Экопром» | F56: =ПКТ!A41 -> Сертификат соответствия №РОСС RU.04РИД0.ОСП04.С00591 срок действия от 14.01.2022г до 13.01.2025г | G56: Визуальный | H56: ____ | I56: ____ | J56: /
A57: 22 | B57: =I27 -> 25.09.2024 | C57: =' муфты '!A37 -> Муфта концевая термоусаживаемая 3 КВНТп-1 70/120 | D57: =' муфты '!C43 -> 2 шт | E57: =' муфты '!K39 -> АО "ПЗЭМИ" | F57: =' муфты '!A41 -> Сертификат соответствия №РОСС RU.32001.04ИБФ1.ОСП28.45002 срок действия с 20.12.2023 по 19.12.2026 гг. | G57: Визуальный | H57: ____ | I57: ____ | J57: /
A58: 23 | B58: =I27 -> 25.09.2024 | C58: ='ТТ Т-0,66'!A37 -> Трансформатор тока Т-0,66 400/5 | D58: ='ТТ Т-0,66'!C43 -> 3 шт | E58: ='ТТ Т-0,66'!K39 -> ФК ИК-1 | F58: ='ТТ Т-0,66'!A41 -> Декларация о соответствии №ЕАЭС №RU Д-RU.НВ11.В.00611/19 от 19.11.2019г | G58: Визуальный | H58: ____ | I58: ____ | J58: /
A59: 24 | B59: =I27 -> 25.09.2024 | C59: =РМК!A37 -> Длинно-искровой разрядник РМК | D59: =РМК!C43 -> 3 шт | E59: =РМК!K39 -> АО "НПО "Стример" | F59: =РМК!A41 -> Сертификат соответствия №РОСС RU.ЕФ01.Н00004-22 срок действия от 10.04.2022г до 09.04.2025 | G59: Визуальный | H59: ____ | I59: ____ | J59: /
A60: 25 | B60: =I27 -> 25.09.2024 | C60: ='выключатели ВА'!A37 -> Выключатель автоматический ВА57-35 (250А) - 2 шт. | D60: ='выключатели ВА'!C43 -> 2 | E60: ='выключатели ВА'!K39 -> ООО "КЭАЗ" | F60: ='выключатели ВА'!A41 -> Сертификат соответствия №ЕАЭС RU.С-RU.АБ53.В.02348/21 с 11.11.2021 по 10.11.2026 | G60: Визуальный | H60: ____ | I60: ____ | J60: /
A61: 26 | B61: =$B$60 -> 25.09.2024 | C61: =каб.АСБ!A37 -> Кабель АСБл-10 3х120 | D61: =каб.АСБ!C43 -> 136 м | E61: =каб.АСБ!K39 -> ООО "Камский кабель" | F61: =каб.АСБ!A41 -> Паспорт качества №10793/23 | G61: Визуальный | H61: ____ | I61: ____ | J61: /
A62: 27 | B62: =$B$60 -> 25.09.2024 | C62: =КРН!A37 -> Комплектное распределительное устройство наружной установки, 10кВ, 1000А, ввод КРУН-017-1000-УХЛ1; Комплектное распределительное устройство наружной установки, 10кВ, 1000А, линия КРУН-002-1000-УХЛ1 | D62: =КРН!C43 -> 2 шт | E62: =КРН!K39 -> АО"ЧЭАЗ" | F62: =КРН!A41 -> Декларация о соответствии №РОСС RU Д-RU.АЯ96.В.00016/20 от 11.02.2020г | G62: Визуальный | H62: ____ | I62: ____ | J62: /
...

Sheet КТП
K1: Приложение 1
K3: Приложение 48 к приказу от 19.12.2019 № 1414
F5: ФОРМА
I6: ГОДЕН
I7: (результат контроля продукции)
A8: Объект строительства:
A9: ='Провод СИП 3'!A9:L9 -> Строительство ТП-10/0,4 кВ, ВЛЗ-10 кВ от ВЛЗ-10 кВ ф. «Кочугино» ПС №185 "Воробьево", ВЛИ-0,38 кВ, рлр, в т.ч. ПИР, МО, Солнечногорский р-н, г. Солнечногорск
A11: Заказчик строительства: Филиал ПАО «Россети Московский регион» - Северные электрические сети
A13: АКТ № 1/ | G13: ='Провод СИП 3'!G13 -> SAP - 288007
A14: входного контроля
A16: ='Данные объект'!B5 -> 141533,Российская Федерация, г.о.Солнечногорск | K16: ='Провод СИП 3'!K16:L16 -> 25.09.2024
A17: (место проведения) | K17: (дата)
A19: Нами, комиссией | C19: ='Данные объект'!B11 -> ООО "Энергосистемы" | H19: ='Данные объект'!B43 -> по приказу №05-ОТ/24 от 09 января 2023г. в составе:
C20: (организация, от которой сформирована комиссия)
A22: Председателя: . | C22: ='Данные объект'!C45 -> Главный энергетик ООО "Энергосистемы" Фечин А.А.
A23: (должность, организация, фамилия, имя, отчество)
A25: и членов комиссии:
C26: ='Данные объект'!C47 -> Прораб ООО "Энергосистемы" Волков М.Ю.
A27: (должность, организация, фамилия, имя, отчество)
C28: ='Данные объект'!C49 -> Инженер-электрик ООО "Энергосистемы" Высоцкий А.В.
A29: (должность, организация, фамилия, имя, отчество)
C30: ='Данные объект'!B32 -> Гл. специалист ССК УКС ПАО "Россети Московский регион" Алексанян Г.Р.
A31: (должность, организация, фамилия, имя, отчество)
A32: руководствуясь, | C32: ='Данные объект'!B51 -> методическими указаниями ПАО "Россети Московский регион" (утв. Приказом от 14.11.2024 г. № 1254)
A33: (документ, устанавливающий требевания по организации и проведению входного контроля продукции)
A34: составила настоящий акт о выполненном входном контроле продукции для строительства.
A36: 1. К входному контролю представлена следующая продукция:
A37: Комплектная трансформаторная подстанция КТП-ТК/ВК-250/10/0,4
A38: (наименование продукции)
A39: 1.1. Наименование, номер документа, удостоверяющего качество и НТД на продукцию: | K39: ООО "КТП-Энерго"
K40: (изготовитель,
A41: Паспорт №5009 от 13.07.2023г. | H41: НТД | I41: ТУ-3412-002-03769014-2017
A42: № документа и дата, № партии, дата изготовления) (ГОСТ, ТУ, чертеж КМД)
A43: 1.2. Кол-во: | C43: 1 комп. | E43: Кол-во партии: | G43: 1 комп.
A44: (штуки, объем, вес в ед. изм.) (штуки, объем, вес в ед. изм.)
A45: 1.3. Поставщик: | C45: =K39 -> ООО "КТП-Энерго" | F45: Договор | G45: №79-КТП-Энерго/2023 от 20.06.2023г
A46: (наименование организации) (реквизиты договора на поставку)
A47: 2. Подготовка продукции к контролю по НТД: | F47: выполнена
A48: (выполнена/не выполнена)
A49: 3. При входном контроле проведены следующие контрольные мероприятия:
...

Sheet ТМГ
K1: Приложение 1
K3: Приложение 48 к приказу от 19.12.2019 № 1414
F5: ФОРМА
I6: ГОДЕН
I7: (результат контроля продукции)
A8: Объект строительства:
A9: ='Провод СИП 3'!A9:L9 -> Строительство ТП-10/0,4 кВ, ВЛЗ-10 кВ от ВЛЗ-10 кВ ф. «Кочугино» ПС №185 "Воробьево", ВЛИ-0,38 кВ, рлр, в т.ч. ПИР, МО, Солнечногорский р-н, г. Солнечногорск
A11: Заказчик строительства: Филиал ПАО «Россети Московский регион» - Северные электрические сети
A13: АКТ № 2/ | G13: ='Провод СИП 3'!G13 -> SAP - 288007
A14: входного контроля
A16: ='Данные объект'!B5 -> 141533,Российская Федерация, г.о.Солнечногорск | K16: ='Провод СИП 3'!K16:L16 -> 25.09.2024
A17: (место проведения) | K17: (дата)
A19: Нами, комиссией | C19: ='Данные объект'!B11 -> ООО "Энергосистемы" | H19: ='Данные объект'!B43 -> по приказу №05-ОТ/24 от 09 января 2023г. в составе:
C20: (организация, от которой сформирована комиссия)
A22: Председателя: . | C22: ='Данные объект'!C45 -> Главный энергетик ООО "Энергосистемы" Фечин А.А.
A23: (должность, организация, фамилия, имя, отчество)
A25: и членов комиссии:
C26: ='Данные объект'!C47 -> Прораб ООО "Энергосистемы" Волков М.Ю.
A27: (должность, организация, фамилия, имя, отчество)
C28: ='Данные объект'!C49 -> Инженер-электрик ООО "Энергосистемы" Высоцкий А.В.
A29: (должность, организация, фамилия, имя, отчество)
C30: ='Данные объект'!B32 -> Гл. специалист ССК УКС ПАО "Россети Московский регион" Алексанян Г.Р.
A31: (должность, организация, фамилия, имя, отчество)
A32: руководствуясь, | C32: ='Данные объект'!B51 -> методическими указаниями ПАО "Россети Московский регион" (утв. Приказом от 14.11.2024 г. № 1254)
A33: (документ, устанавливающий требевания по организации и проведению входного контроля продукции)
A34: составила настоящий акт о выполненном входном контроле продукции для строительства.
A36: 1. К входному контролю представлена следующая продукция:
A37: Трансформатор ТМГ-250/10-0,4УХЛ1
A38: (наименование продукции)
A39: 1.1. Наименование, номер документа, удостоверяющего качество и НТД на продукцию: | K39: ТОО "Уральский трансформаторный завод"
K40: (изготовитель,
A41: Паспорт №2204ФГ406 | H41: НТД | I41: ГОСТ 11677-85
A42: № документа и дата, № партии, дата изготовления) (ГОСТ, ТУ, чертеж КМД)
A43: 1.2. Кол-во: | C43: 1 шт. | E43: Кол-во партии: | G43: 1 шт.
A44: (штуки, объем, вес в ед. изм.) (штуки, объем, вес в ед. изм.)
A45: 1.3. Поставщик: | C45: ООО "ЭнергоТранс" | F45: Договор | G45: №198 от 16.03.2023г
A46: (наименование организации) (реквизиты договора на поставку)
A47: 2. Подготовка продукции к контролю по НТД: | F47: выполнена
A48: (выполнена/не выполнена)
A49: 3. При входном контроле проведены следующие контрольные мероприятия:
...

Sheet РЛК
K1: Приложение 1
K3: Приложение 48 к приказу от 19.12.2019 № 1414
F5: ФОРМА
I6: ГОДЕН
I7: (результат контроля продукции)
A8: Объект строительства:
A9: ='Провод СИП 3'!A9:L9 -> Строительство ТП-10/0,4 кВ, ВЛЗ-10 кВ от ВЛЗ-10 кВ ф. «Кочугино» ПС №185 "Воробьево", ВЛИ-0,38 кВ, рлр, в т.ч. ПИР, МО, Солнечногорский р-н, г. Солнечногорск
A11: Заказчик строительства: Филиал ПАО «Россети Московский регион» - Северные электрические сети
A13: АКТ №0/ | G13: ='Провод СИП 3'!G13 -> SAP - 288007
A14: входного контроля
A16: ='Провод СИП 3'!A16 -> 141533,Российская Федерация, г.о.Солнечногорск | K16: ='Провод СИП 3'!K16:L16 -> 25.09.2024
A17: (место проведения) | K17: (дата)
A19: Нами, комиссией | C19: ='Данные объект'!B11 -> ООО "Энергосистемы" | H19: ='Данные объект'!B43 -> по приказу №05-ОТ/24 от 09 января 2023г. в составе:
C20: (организация, от которой сформирована комиссия)
A22: Председателя: . | C22: ='Данные объект'!C45 -> Главный энергетик ООО "Энергосистемы" Фечин А.А.
A23: (должность, организация, фамилия, имя, отчество)
A25: и членов комиссии:
C26: ='Данные объект'!C47 -> Прораб ООО "Энергосистемы" Волков М.Ю.
A27: (должность, организация, фамилия, имя, отчество)
C28: ='Данные объект'!C49 -> Инженер-электрик ООО "Энергосистемы" Высоцкий А.В.
A29: (должность, организация, фамилия, имя, отчество)
C30: ='Данные объект'!B32 -> Гл. специалист ССК УКС ПАО "Россети Московский регион" Алексанян Г.Р.
A31: (должность, организация, фамилия, имя, отчество)
A32: руководствуясь, | C32: ='Данные объект'!B51 -> методическими указаниями ПАО "Россети Московский регион" (утв. Приказом от 14.11.2024 г. № 1254)
A33: (документ, устанавливающий требевания по организации и проведению входного контроля продукции)
A34: составила настоящий акт о выполненном входном контроле продукции для строительства.
A36: 1. К входному контролю представлена следующая продукция:
A37: Разъединитель трехполюсный с приводом РЛК 10/400
A38: (наименование продукции)
A39: 1.1. Наименование, номер документа, удостоверяющего качество и НТД на продукцию: | K39: ООО "НИЛЕД"
K40: (изготовитель,
A41: Сертификат соответствия №РОСС RU.HE42.Н01995 срок действия с 01.10.2024г по 30.09.2027г | H41: НТД | I41: ГОСТ Р 52726-2007
A42: № документа и дата, № партии, дата изготовления) (ГОСТ, ТУ, чертеж КМД)
A43: 1.2. Кол-во: | C43: 1 шт | E43: Кол-во партии: | G43: 1 шт
A44: (штуки, объем, вес в ед. изм.) (штуки, объем, вес в ед. изм.)
A45: 1.3. Поставщик: | C45: ООО ТК "Норма-кабель" | F45: Договор | G45: №НК-398 от 30.11.2023
A46: (наименование организации) (реквизиты договора на поставку)
A47: 2. Подготовка продукции к контролю по НТД: | F47: выполнена
A48: (выполнена/не выполнена)
A49: 3. При входном контроле проведены следующие контрольные мероприятия:
...

Sheet ПРВТ
K1: Приложение 1
K3: Приложение 48 к приказу от 19.12.2019 № 1414
F5: ФОРМА
I6: ГОДЕН
I7: (результат контроля продукции)
A8: Объект строительства:
A9: ='Провод СИП 3'!A9:L9 -> Строительство ТП-10/0,4 кВ, ВЛЗ-10 кВ от ВЛЗ-10 кВ ф. «Кочугино» ПС №185 "Воробьево", ВЛИ-0,38 кВ, рлр, в т.ч. ПИР, МО, Солнечногорский р-н, г. Солнечногорск
A11: Заказчик строительства: Филиал ПАО «Россети Московский регион» - Северные электрические сети
A13: АКТ № 3/ | G13: ='Провод СИП 3'!G13 -> SAP - 288007
A14: входного контроля
A16: ='Провод СИП 3'!A16 -> 141533,Российская Федерация, г.о.Солнечногорск | K16: ='Провод СИП 3'!K16:L16 -> 25.09.2024
A17: (место проведения) | K17: (дата)
A19: Нами, комиссией | C19: ='Данные объект'!B11 -> ООО "Энергосистемы" | H19: ='Данные объект'!B43 -> по приказу №05-ОТ/24 от 09 января 2023г. в составе:
C20: (организация, от которой сформирована комиссия)
A22: Председателя: . | C22: ='Данные объект'!C45 -> Главный энергетик ООО "Энергосистемы" Фечин А.А.
A23: (должность, организация, фамилия, имя, отчество)
A25: и членов комиссии:
C26: ='Данные объект'!C47 -> Прораб ООО "Энергосистемы" Волков М.Ю.
A27: (должность, организация, фамилия, имя, отчество)
C28: ='Данные объект'!C49 -> Инженер-электрик ООО "Энергосистемы" Высоцкий А.В.
A29: (должность, организация, фамилия, имя, отчество)
C30: ='Данные объект'!B32 -> Гл. специалист ССК УКС ПАО "Россети Московский регион" Алексанян Г.Р.
A31: (должность, организация, фамилия, имя, отчество)
A32: руководствуясь, | C32: ='Данные объект'!B51 -> методическими указаниями ПАО "Россети Московский регион" (утв. Приказом от 14.11.2024 г. № 1254)
A33: (документ, устанавливающий требевания по организации и проведению входного контроля продукции)
A34: составила настоящий акт о выполненном входном контроле продукции для строительства.
A36: 1. К входному контролю представлена следующая продукция:
A37: Предохранитель-разъеденитель выхлопной ПРВТ-1-10.II-50Л-У1
A38: (наименование продукции)
A39: 1.1. Наименование, номер документа, удостоверяющего качество и НТД на продукцию: | K39: ОАО "ЗЭТО"
K40: (изготовитель,
A41: Паспорт №№20, 33, 44 | H41: НТД | I41: ТУ-3414-083-49040910-2010
A42: № документа и дата, № партии, дата изготовления) (ГОСТ, ТУ, чертеж КМД)
A43: 1.2. Кол-во: | C43: 3 шт | E43: Кол-во партии: | G43: 3 шт
A44: (штуки, объем, вес в ед. изм.) (штуки, объем, вес в ед. изм.)
A45: 1.3. Поставщик: | C45: ООО ТК "Норма-кабель" | F45: Договор | G45: №НК-398 от 30.11.2023
A46: (наименование организации) (реквизиты договора на поставку)
A47: 2. Подготовка продукции к контролю по НТД: | F47: выполнена
A48: (выполнена/не выполнена)
A49: 3. При входном контроле проведены следующие контрольные мероприятия:
...

Sheet счетчик СТЭМ
K1: Приложение 1
K3: Приложение 48 к приказу от 19.12.2019 № 1414
F5: ФОРМА
I6: ГОДЕН
I7: (результат контроля продукции)
A8: Объект строительства:
A9: ='Данные объект'!B3 -> Строительство ТП-10/0,4 кВ, ВЛЗ-10 кВ от ВЛЗ-10 кВ ф. «Кочугино» ПС №185 "Воробьево", ВЛИ-0,38 кВ, рлр, в т.ч. ПИР, МО, Солнечногорский р-н, г. Солнечногорск
A11: Заказчик строительства: Филиал ПАО «Россети Московский регион» - Северные электрические сети
A13: АКТ № 4/ | G13: ='Данные объект'!B2 -> SAP - 288007
A14: входного контроля
A16: ='Данные объект'!B5 -> 141533,Российская Федерация, г.о.Солнечногорск | K16: ='Данные объект'!B6 -> 25.09.2024
A17: (место проведения) | K17: (дата)
A19: Нами, комиссией | C19: ='Данные объект'!B11 -> ООО "Энергосистемы" | H19: ='Данные объект'!B43 -> по приказу №05-ОТ/24 от 09 января 2023г. в составе:
C20: (организация, от которой сформирована комиссия)
A22: Председателя: . | C22: ='Данные объект'!C45 -> Главный энергетик ООО "Энергосистемы" Фечин А.А.
A23: (должность, организация, фамилия, имя, отчество)
A25: и членов комиссии:
C26: ='Данные объект'!C47 -> Прораб ООО "Энергосистемы" Волков М.Ю.
A27: (должность, организация, фамилия, имя, отчество)
C28: ='Данные объект'!C49 -> Инженер-электрик ООО "Энергосистемы" Высоцкий А.В.
A29: (должность, организация, фамилия, имя, отчество)
C30: ='Данные объект'!B32 -> Гл. специалист ССК УКС ПАО "Россети Московский регион" Алексанян Г.Р.
A31: (должность, организация, фамилия, имя, отчество)
A32: руководствуясь, | C32: ='Данные объект'!B51 -> методическими указаниями ПАО "Россети Московский регион" (утв. Приказом от 14.11.2024 г. № 1254)
A33: (документ, устанавливающий требевания по организации и проведению входного контроля продукции)
A34: составила настоящий акт о выполненном входном контроле продукции для строительства.
A36: 1. К входному контролю представлена следующая продукция:
A37: Счетчик электрической энергии СТЭМ 300
A38: (наименование продукции)
A39: 1.1. Наименование, номер документа, удостоверяющего качество и НТД на продукцию: | K39: ООО "СИ-АРТ"
K40: (изготовитель,
A41: Паспорт №25001237 от 06.05.2025г. | H41: НТД | I41: ТР ТС 004/2011, ТР ТС 020/2011
A42: № документа и дата, № партии, дата изготовления) (ГОСТ, ТУ, чертеж КМД)
A43: 1.2. Кол-во: | C43: 1 шт | E43: Кол-во партии: | G43: =C43 -> 1 шт
A44: (штуки, объем, вес в ед. изм.) (штуки, объем, вес в ед. изм.)
A45: 1.3. Поставщик: | C45: ООО ТК "Норма-кабель" | F45: Договор | G45: №НК-398 от 30.11.2023
A46: (наименование организации) (реквизиты договора на поставку)
A47: 2. Подготовка продукции к контролю по НТД: | F47: выполнена
A48: (выполнена/не выполнена)
A49: 3. При входном контроле проведены следующие контрольные мероприятия:
...

Sheet выключатели ВА
K1: Приложение 1
K3: Приложение 48 к приказу от 19.12.2019 № 1414
F5: ФОРМА
I6: ГОДЕН
I7: (результат контроля продукции)
A8: Объект строительства:
A9: ='Провод СИП 3'!A9:L9 -> Строительство ТП-10/0,4 кВ, ВЛЗ-10 кВ от ВЛЗ-10 кВ ф. «Кочугино» ПС №185 "Воробьево", ВЛИ-0,38 кВ, рлр, в т.ч. ПИР, МО, Солнечногорский р-н, г. Солнечногорск
A11: Заказчик строительства: Филиал ПАО «Россети Московский регион» - Северные электрические сети
A13: АКТ № 5/ | G13: ='Провод СИП 3'!G13 -> SAP - 288007
A14: входного контроля
A16: ='Провод СИП 3'!A16 -> 141533,Российская Федерация, г.о.Солнечногорск | K16: ='Провод СИП 3'!K16:L16 -> 25.09.2024
A17: (место проведения) | K17: (дата)
A19: Нами, комиссией | C19: ='Данные объект'!B11 -> ООО "Энергосистемы" | H19: ='Данные объект'!B43 -> по приказу №05-ОТ/24 от 09 января 2023г. в составе:
C20: (организация, от которой сформирована комиссия)
A22: Председателя: . | C22: ='Данные объект'!C45 -> Главный энергетик ООО "Энергосистемы" Фечин А.А.
A23: (должность, организация, фамилия, имя, отчество)
A25: и членов комиссии:
C26: ='Данные объект'!C47 -> Прораб ООО "Энергосистемы" Волков М.Ю.
A27: (должность, организация, фамилия, имя, отчество)
C28: ='Данные объект'!C49 -> Инженер-электрик ООО "Энергосистемы" Высоцкий А.В.
A29: (должность, организация, фамилия, имя, отчество)
C30: ='Данные объект'!B32 -> Гл. специалист ССК УКС ПАО "Россети Московский регион" Алексанян Г.Р.
A31: (должность, организация, фамилия, имя, отчество)
A32: руководствуясь, | C32: ='Данные объект'!B51 -> методическими указаниями ПАО "Россети Московский регион" (утв. Приказом от 14.11.2024 г. № 1254)
A33: (документ, устанавливающий требевания по организации и проведению входного контроля продукции)
A34: составила настоящий акт о выполненном входном контроле продукции для строительства.
A36: 1. К входному контролю представлена следующая продукция:
A37: Выключатель автоматический ВА57-35 (250А) - 2 шт.
A38: (наименование продукции)
A39: 1.1. Наименование, номер документа, удостоверяющего качество и НТД на продукцию: | K39: ООО "КЭАЗ"
K40: (изготовитель,
A41: Сертификат соответствия №ЕАЭС RU.С-RU.АБ53.В.02348/21 с 11.11.2021 по 10.11.2026 | H41: НТД | I41: ТУ 3422-037-05758109-2011
A42: № документа и дата, № партии, дата изготовления) (ГОСТ, ТУ, чертеж КМД)
A43: 1.2. Кол-во: | C43: 2 | E43: Кол-во партии: | G43: =C43 -> 2
A44: (штуки, объем, вес в ед. изм.) (штуки, объем, вес в ед. изм.)
A45: 1.3. Поставщик: | C45: ООО ТК "Норма-кабель" | F45: Договор | G45: №НК-398 от 30.11.2023
A46: (наименование организации) (реквизиты договора на поставку)
A47: 2. Подготовка продукции к контролю по НТД: | F47: выполнена
A48: (выполнена/не выполнена)
A49: 3. При входном контроле проведены следующие контрольные мероприятия:
...

Sheet стойки
K1: Приложение 1
K3: Приложение 48 к приказу от 19.12.2019 № 1414
F5: ФОРМА
I6: ГОДЕН
I7: (результат контроля продукции)
A8: Объект строительства:
A9: ='Провод СИП 3'!A9:L9 -> Строительство ТП-10/0,4 кВ, ВЛЗ-10 кВ от ВЛЗ-10 кВ ф. «Кочугино» ПС №185 "Воробьево", ВЛИ-0,38 кВ, рлр, в т.ч. ПИР, МО, Солнечногорский р-н, г. Солнечногорск
A11: Заказчик строительства: Филиал ПАО «Россети Московский регион» - Северные электрические сети
A13: АКТ №6/ | G13: ='Провод СИП 3'!G13 -> SAP - 288007
A14: входного контроля
A16: ='Провод СИП 3'!A16 -> 141533,Российская Федерация, г.о.Солнечногорск | K16: ='Провод СИП 3'!K16:L16 -> 25.09.2024
A17: (место проведения) | K17: (дата)
A19: Нами, комиссией | C19: ='Данные объект'!B11 -> ООО "Энергосистемы" | H19: ='Данные объект'!B43 -> по приказу №05-ОТ/24 от 09 января 2023г. в составе:
C20: (организация, от которой сформирована комиссия)
A22: Председателя: . | C22: ='Данные объект'!C45 -> Главный энергетик ООО "Энергосистемы" Фечин А.А.
A23: (должность, организация, фамилия, имя, отчество)
A25: и членов комиссии:
C26: ='Данные объект'!C47 -> Прораб ООО "Энергосистемы" Волков М.Ю.
A27: (должность, организация, фамилия, имя, отчество)
C28: ='Данные объект'!C49 -> Инженер-электрик ООО "Энергосистемы" Высоцкий А.В.
A29: (должность, организация, фамилия, имя, отчество)
C30: ='Данные объект'!B32 -> Гл. специалист ССК УКС ПАО "Россети Московский регион" Алексанян Г.Р.
A31: (должность, организация, фамилия, имя, отчество)
A32: руководствуясь, | C32: ='Данные объект'!B51 -> методическими указаниями ПАО "Россети Московский регион" (утв. Приказом от 14.11.2024 г. № 1254)
A33: (документ, устанавливающий требевания по организации и проведению входного контроля продукции)
A34: составила настоящий акт о выполненном входном контроле продукции для строительства.
A36: 1. К входному контролю представлена следующая продукция:
A37: Ж/б опоры СВ110-5
A38: (наименование продукции)
A39: 1.1. Наименование, номер документа, удостоверяющего качество и НТД на продукцию: | K39: ООО «Энерго ЖБИ»
K40: (изготовитель,
A41: Паспорт №302 от 12.02.2023 | H41: НТД | I41: ТУ 5863-007-96502166-2016
A42: № документа и дата, № партии, дата изготовления) (ГОСТ, ТУ, чертеж КМД)
A43: 1.2. Кол-во: | C43: 2 шт | E43: Кол-во партии: | G43: 36 шт
A44: (штуки, объем, вес в ед. изм.) (штуки, объем, вес в ед. изм.)
A45: 1.3. Поставщик: | C45: ООО ТК "Норма-кабель" | F45: Договор | G45: №НК-398 от 30.11.2023
A46: (наименование организации) (реквизиты договора на поставку)
A47: 2. Подготовка продукции к контролю по НТД: | F47: выполнена
A48: (выполнена/не выполнена)
A49: 3. При входном контроле проведены следующие контрольные мероприятия:
...

Sheet лин.армат 6-10к
K1: Приложение 1
K3: Приложение 48 к приказу от 19.12.2019 № 1414
F5: ФОРМА
I6: ГОДЕН
I7: (результат контроля продукции)
A8: Объект строительства:
A9: ='Провод СИП 3'!A9:L9 -> Строительство ТП-10/0,4 кВ, ВЛЗ-10 кВ от ВЛЗ-10 кВ ф. «Кочугино» ПС №185 "Воробьево", ВЛИ-0,38 кВ, рлр, в т.ч. ПИР, МО, Солнечногорский р-н, г. Солнечногорск
A11: Заказчик строительства: Филиал ПАО «Россети Московский регион» - Северные электрические сети
A13: АКТ № 7/ | G13: ='Провод СИП 3'!G13 -> SAP - 288007
A14: входного контроля
A16: ='Данные объект'!B5 -> 141533,Российская Федерация, г.о.Солнечногорск | K16: ='Провод СИП 3'!K16:L16 -> 25.09.2024
A17: (место проведения) | K17: (дата)
A19: Нами, комиссией | C19: ='Данные объект'!B11 -> ООО "Энергосистемы" | H19: ='Данные объект'!B43 -> по приказу №05-ОТ/24 от 09 января 2023г. в составе:
C20: (организация, от которой сформирована комиссия)
A22: Председателя: . | C22: ='Данные объект'!C45 -> Главный энергетик ООО "Энергосистемы" Фечин А.А.
A23: (должность, организация, фамилия, имя, отчество)
A25: и членов комиссии:
C26: ='Данные объект'!C47 -> Прораб ООО "Энергосистемы" Волков М.Ю.
A27: (должность, организация, фамилия, имя, отчество)
C28: ='Данные объект'!C49 -> Инженер-электрик ООО "Энергосистемы" Высоцкий А.В.
A29: (должность, организация, фамилия, имя, отчество)
C30: ='Данные объект'!B32 -> Гл. специалист ССК УКС ПАО "Россети Московский регион" Алексанян Г.Р.
A31: (должность, организация, фамилия, имя, отчество)
A32: руководствуясь, | C32: ='Данные объект'!B51 -> методическими указаниями ПАО "Россети Московский регион" (утв. Приказом от 14.11.2024 г. № 1254)
A33: (документ, устанавливающий требевания по организации и проведению входного контроля продукции)
A34: составила настоящий акт о выполненном входном контроле продукции для строительства.
A36: 1. К входному контролю представлена следующая продукция:
A37: Линейная арматура 10кВ (Траверса ТМ74, ТМ73, Зажим SLW.36, Изолятор штырьевой IF27, Колпачок К-9, Заземляющий проводник ЗП1-1, Плашечный зажим CD35, Зажим ответвительный RP150, Хомут Х51, Вязка спиральная СВ70, Траверса ТМ63, Плашечный зажим CD70, Металлическая лента F207, Скрепа NC20)
A38: (наименование продукции)
A39: 1.1. Наименование, номер документа, удостоверяющего качество и НТД на продукцию: | K39: ООО «Нилед»
K40: (изготовитель,
A41: Сертификат соответствия №РОСС RU.АМ05.Н22141 | H41: НТД | I41: ТУ 3449-001-52819896-2010
A42: № документа и дата, № партии, дата изготовления) (ГОСТ, ТУ, чертеж КМД)
A43: 1.2. Кол-во: | C43: 121 шт | E43: Кол-во партии: | G43: =C43 -> 121 шт
A44: (штуки, объем, вес в ед. изм.) (штуки, объем, вес в ед. изм.)
A45: 1.3. Поставщик: | C45: ООО ТК "Норма-кабель" | F45: Договор | G45: №НК-375 от 30.11.2022
A46: (наименование организации) (реквизиты договора на поставку)
A47: 2. Подготовка продукции к контролю по НТД: | F47: выполнена
A48: (выполнена/не выполнена)
A49: 3. При входном контроле проведены следующие контрольные мероприятия:
...

Sheet лин.армат 0,4
K1: Приложение 1
K3: Приложение 48 к приказу от 19.12.2019 № 1414
F5: ФОРМА
I6: ГОДЕН
I7: (результат контроля продукции)
A8: Объект строительства:
A9: ='Провод СИП 3'!A9:L9 -> Строительство ТП-10/0,4 кВ, ВЛЗ-10 кВ от ВЛЗ-10 кВ ф. «Кочугино» ПС №185 "Воробьево", ВЛИ-0,38 кВ, рлр, в т.ч. ПИР, МО, Солнечногорский р-н, г. Солнечногорск
A11: Заказчик строительства: Филиал ПАО «Россети Московский регион» - Северные электрические сети
A13: АКТ №14/ | G13: ='Провод СИП 3'!G13 -> SAP - 288007
A14: входного контроля
A16: ='Данные объект'!B5 -> 141533,Российская Федерация, г.о.Солнечногорск | K16: ='Провод СИП 3'!K16:L16 -> 25.09.2024
A17: (место проведения) | K17: (дата)
A19: Нами, комиссией | C19: ='Данные объект'!B11 -> ООО "Энергосистемы" | H19: ='Данные объект'!B43 -> по приказу №05-ОТ/24 от 09 января 2023г. в составе:
C20: (организация, от которой сформирована комиссия)
A22: Председателя: . | C22: ='Данные объект'!C45 -> Главный энергетик ООО "Энергосистемы" Фечин А.А.
A23: (должность, организация, фамилия, имя, отчество)
A25: и членов комиссии:
C26: ='Данные объект'!C47 -> Прораб ООО "Энергосистемы" Волков М.Ю.
A27: (должность, организация, фамилия, имя, отчество)
C28: ='Данные объект'!C49 -> Инженер-электрик ООО "Энергосистемы" Высоцкий А.В.
A29: (должность, организация, фамилия, имя, отчество)
C30: ='Данные объект'!B32 -> Гл. специалист ССК УКС ПАО "Россети Московский регион" Алексанян Г.Р.
A31: (должность, организация, фамилия, имя, отчество)
A32: руководствуясь, | C32: ='Данные объект'!B51 -> методическими указаниями ПАО "Россети Московский регион" (утв. Приказом от 14.11.2024 г. № 1254)
A33: (документ, устанавливающий требевания по организации и проведению входного контроля продукции)
A34: составила настоящий акт о выполненном входном контроле продукции для строительства.
A36: 1. К входному контролю представлена следующая продукция:
A37: Линейная арматура 0,4кВ (Заземляющий проводник ЗП6, Зажим Р72, Ответвительный зажим Р70, Натяжной зажим РА1500, Плашечный зажим ПС-2-1, Анкерный кронштейн CS10.3, Комплект промежуточной подвески ES1500, Стяжной хомут Е778, Мателлическая летна F207, Скрепа NC20, Бугель NB20, Герметичный зажим РС481, Ограничитель перенапряжения ОР600/28, Колпачек изолирующий СЕ16-150)
A38: (наименование продукции)
A39: 1.1. Наименование, номер документа, удостоверяющего качество и НТД на продукцию: | K39: ООО «Нилед»
K40: (изготовитель,
A41: Сертификат соответствия №РОСС RU.МЛ10.10783 срок действия от 25.11.2022 до 19.11.2028г | H41: НТД | I41: ТУ 3449-001-96363109-2016
A43: 1.2. Кол-во: | C43: 106 шт | E43: Кол-во партии: | G43: =C43 -> 106 шт
A44: (штуки, объем, вес в ед. изм.) (штуки, объем, вес в ед. изм.)
A45: 1.3. Поставщик: | C45: ООО ТК "Норма-кабель" | F45: Договор | G45: №НК-3985 от 30.11.2023
A46: (наименование организации) (реквизиты договора на поставку)
A47: 2. Подготовка продукции к контролю по НТД: | F47: выполнена
A48: (выполнена/не выполнена)
A49: 3. При входном контроле проведены следующие контрольные мероприятия:
A51: Количество, масса, объем проверенной продукции (в ед. изм.) | E51: Вид контроля (НТД) и дата сдачи образцов (проб) на контроль | G51: Приборы контроля | I51: № прибора и дата поверки прибора | K51: № и дата протокола контроля | L51: Заключение по контролю (годен/не годен)
...

Sheet ВРЩ
K1: Приложение 1
K3: Приложение 48 к приказу от 19.12.2019 № 1414
F5: ФОРМА
I6: ГОДЕН
I7: (результат контроля продукции)
A8: Объект строительства:
A9: ='Провод СИП 3'!A9:L9 -> Строительство ТП-10/0,4 кВ, ВЛЗ-10 кВ от ВЛЗ-10 кВ ф. «Кочугино» ПС №185 "Воробьево", ВЛИ-0,38 кВ, рлр, в т.ч. ПИР, МО, Солнечногорский р-н, г. Солнечногорск
A11: Заказчик строительства: Филиал ПАО «Россети Московский регион» - Северные электрические сети
A13: АКТ № 3/ | G13: ='Провод СИП 3'!G13 -> SAP - 288007
A14: входного контроля
A16: ='Провод СИП 3'!A16 -> 141533,Российская Федерация, г.о.Солнечногорск | K16: ='Провод СИП 3'!K16:L16 -> 25.09.2024
A17: (место проведения) | K17: (дата)
A19: Нами, комиссией | C19: ='Провод СИП 3'!C19:G19 -> ООО "Энергосистемы" | H19: ='Данные объект'!B43 -> по приказу №05-ОТ/24 от 09 января 2023г. в составе:
C20: (организация, от которой сформирована комиссия)
A22: Председателя: . | C22: ='Данные объект'!C45 -> Главный энергетик ООО "Энергосистемы" Фечин А.А.
A23: (должность, организация, фамилия, имя, отчество)
A25: и членов комиссии:
C26: ='Данные объект'!C47 -> Прораб ООО "Энергосистемы" Волков М.Ю.
A27: (должность, организация, фамилия, имя, отчество)
C28: ='Данные объект'!C49 -> Инженер-электрик ООО "Энергосистемы" Высоцкий А.В.
A29: (должность, организация, фамилия, имя, отчество)
C30: ='Данные объект'!B32 -> Гл. специалист ССК УКС ПАО "Россети Московский регион" Алексанян Г.Р.
A31: (должность, организация, фамилия, имя, отчество)
A32: руководствуясь, | C32: ='Данные объект'!B51 -> методическими указаниями ПАО "Россети Московский регион" (утв. Приказом от 14.11.2024 г. № 1254)
A33: (документ, устанавливающий требевания по организации и проведению входного контроля продукции)
A34: составила настоящий акт о выполненном входном контроле продукции для строительства.
A36: 1. К входному контролю представлена следующая продукция:
A37: ВРЩ-0,4кВ
A38: (наименование продукции)
A39: 1.1. Наименование, номер документа, удостоверяющего качество и НТД на продукцию: | K39: ООО "ИЭК Холдинг"
K40: (изготовитель,
A41: Паспорт №б/н | H41: НТД | I41: ТУ 3430-001-45723747-2019
A42: № документа и дата, № партии, дата изготовления) (ГОСТ, ТУ, чертеж КМД)
A43: 1.2. Кол-во: | C43: 1 шт | E43: Кол-во партии: | G43: =C43 -> 1 шт
A44: (штуки, объем, вес в ед. изм.) (штуки, объем, вес в ед. изм.)
A45: 1.3. Поставщик: | C45: ООО "МФК Техэнерго" | F45: Договор | G45: №Т1/22-238
A46: (наименование организации) (реквизиты договора на поставку)
A47: 2. Подготовка продукции к контролю по НТД: | F47: выполнена
A48: (выполнена/не выполнена)
A49: 3. При входном контроле проведены следующие контрольные мероприятия:
...

Sheet изоляторы
K1: Приложение 1
K3: Приложение 48 к приказу от 19.12.2019 № 1414
F5: ФОРМА
I6: ГОДЕН
I7: (результат контроля продукции)
A8: Объект строительства:
A9: ='Провод СИП 3'!A9:L9 -> Строительство ТП-10/0,4 кВ, ВЛЗ-10 кВ от ВЛЗ-10 кВ ф. «Кочугино» ПС №185 "Воробьево", ВЛИ-0,38 кВ, рлр, в т.ч. ПИР, МО, Солнечногорский р-н, г. Солнечногорск
A11: Заказчик строительства: Филиал ПАО «Россети Московский регион» - Северные электрические сети
A13: АКТ № 0/ | G13: ='Провод СИП 3'!G13 -> SAP - 288007
A14: входного контроля
A16: ='Провод СИП 3'!A16 -> 141533,Российская Федерация, г.о.Солнечногорск | K16: ='Провод СИП 3'!K16:L16 -> 25.09.2024
A17: (место проведения) | K17: (дата)
A19: Нами, комиссией | C19: ='Провод СИП 3'!C19:G19 -> ООО "Энергосистемы" | H19: ='Данные объект'!B43 -> по приказу №05-ОТ/24 от 09 января 2023г. в составе:
C20: (организация, от которой сформирована комиссия)
A22: Председателя: . | C22: ='Данные объект'!C45 -> Главный энергетик ООО "Энергосистемы" Фечин А.А.
A23: (должность, организация, фамилия, имя, отчество)
A25: и членов комиссии:
C26: ='Данные объект'!C47 -> Прораб ООО "Энергосистемы" Волков М.Ю.
A27: (должность, организация, фамилия, имя, отчество)
C28: ='Данные объект'!C49 -> Инженер-электрик ООО "Энергосистемы" Высоцкий А.В.
A29: (должность, организация, фамилия, имя, отчество)
C30: ='Данные объект'!B32 -> Гл. специалист ССК УКС ПАО "Россети Московский регион" Алексанян Г.Р.
A31: (должность, организация, фамилия, имя, отчество)
A33: (должность, организация, фамилия, имя, отчество)
A34: руководствуясь, | C34: ='Данные объект'!B51 -> методическими указаниями ПАО "Россети Московский регион" (утв. Приказом от 14.11.2024 г. № 1254)
A35: (документ, устанавливающий требевания по организации и проведению входного контроля продукции)
A36: составила настоящий акт о выполненном входном контроле продукции для строительства.
A38: 1. К входному контролю представлена следующая продукция:
A39: Изолятор штырьевой ШФ20-Г
A40: (наименование продукции)
A41: 1.1. Наименование, номер документа, удостоверяющего качество и НТД на продукцию: | K41: ООО «Гжельский завод Электроизолятор»
K42: (изготовитель,
A43: Сертификат соответствия №РОСС RU.АЖ49.Н01642 срок действия от 24.08.2021г до 23.08.2024г | H43: НТД | I43: ГОСТ 1232-2017
A44: № документа и дата, № партии, дата изготовления) (ГОСТ, ТУ, чертеж КМД)
A45: 1.2. Кол-во: | C45: 6 шт | E45: Кол-во партии:
A46: (штуки, объем, вес в ед. изм.) (штуки, объем, вес в ед. изм.)
A47: 1.3. Поставщик: | C47: ООО ТК "Норма-кабель" | F47: Договор | G47: №НК-398 от 30.11.2023
A48: (наименование организации) (реквизиты договора на поставку)
A49: 2. Подготовка продукции к контролю по НТД: | F49: выполнена
A50: (выполнена/не выполнена)
...

Sheet  муфты 
K1: Приложение 1
K3: Приложение 48 к приказу от 19.12.2019 № 1414
F5: ФОРМА
I6: ГОДЕН
I7: (результат контроля продукции)
A8: Объект строительства:
A9: ='Данные объект'!B3 -> Строительство ТП-10/0,4 кВ, ВЛЗ-10 кВ от ВЛЗ-10 кВ ф. «Кочугино» ПС №185 "Воробьево", ВЛИ-0,38 кВ, рлр, в т.ч. ПИР, МО, Солнечногорский р-н, г. Солнечногорск
A11: Заказчик строительства: Филиал ПАО «Россети Московский регион» - Северные электрические сети
A13: АКТ № 8/ | G13: ='Данные объект'!B2 -> SAP - 288007
A14: входного контроля
A16: ='Данные объект'!B5 -> 141533,Российская Федерация, г.о.Солнечногорск | K16: ='Данные объект'!B6 -> 25.09.2024
A17: (место проведения) | K17: (дата)
A19: Нами, комиссией | C19: ='Провод СИП 3'!C19:G19 -> ООО "Энергосистемы" | H19: ='Данные объект'!B43 -> по приказу №05-ОТ/24 от 09 января 2023г. в составе:
C20: (организация, от которой сформирована комиссия)
A22: Председателя: . | C22: ='Данные объект'!C45 -> Главный энергетик ООО "Энергосистемы" Фечин А.А.
A23: (должность, организация, фамилия, имя, отчество)
A25: и членов комиссии:
C26: ='Данные объект'!C47 -> Прораб ООО "Энергосистемы" Волков М.Ю.
A27: (должность, организация, фамилия, имя, отчество)
C28: ='Данные объект'!C49 -> Инженер-электрик ООО "Энергосистемы" Высоцкий А.В.
A29: (должность, организация, фамилия, имя, отчество)
C30: ='Данные объект'!B32 -> Гл. специалист ССК УКС ПАО "Россети Московский регион" Алексанян Г.Р.
A31: (должность, организация, фамилия, имя, отчество)
A32: руководствуясь, | C32: ='Данные объект'!B51 -> методическими указаниями ПАО "Россети Московский регион" (утв. Приказом от 14.11.2024 г. № 1254)
A33: (документ, устанавливающий требевания по организации и проведению входного контроля продукции)
A34: составила настоящий акт о выполненном входном контроле продукции для строительства.
A36: 1. К входному контролю представлена следующая продукция:
A37: Муфта концевая термоусаживаемая 3 КВНТп-1 70/120
A38: (наименование продукции)
A39: 1.1. Наименование, номер документа, удостоверяющего качество и НТД на продукцию: | K39: АО "ПЗЭМИ"
K40: (изготовитель,
A41: Сертификат соответствия №РОСС RU.32001.04ИБФ1.ОСП28.45002 срок действия с 20.12.2023 по 19.12.2026 гг. | H41: НТД | I41: ГОСТ 34839-2022
A42: № документа и дата, № партии, дата изготовления) (ГОСТ, ТУ, чертеж КМД)
A43: 1.2. Кол-во: | C43: 2 шт | E43: Кол-во партии: | G43: =C43 -> 2 шт
A44: (штуки, объем, вес в ед. изм.) (штуки, объем, вес в ед. изм.)
A45: 1.3. Поставщик: | C45: ООО "Главстройэнерго" | F45: Договор | G45: №216 от 03.10.2023г
A46: (наименование организации) (реквизиты договора на поставку)
A47: 2. Подготовка продукции к контролю по НТД: | F47: выполнена
A48: (выполнена/не выполнена)
A49: 3. При входном контроле проведены следующие контрольные мероприятия:
...

Sheet ПКТ
K1: Приложение 1
K3: Приложение 48 к приказу от 19.12.2019 № 1414
F5: ФОРМА
I6: ГОДЕН
I7: (результат контроля продукции)
A8: Объект строительства:
A9: ='Провод СИП 3'!A9:L9 -> Строительство ТП-10/0,4 кВ, ВЛЗ-10 кВ от ВЛЗ-10 кВ ф. «Кочугино» ПС №185 "Воробьево", ВЛИ-0,38 кВ, рлр, в т.ч. ПИР, МО, Солнечногорский р-н, г. Солнечногорск
A11: Заказчик строительства: Филиал ПАО «Россети Московский регион» - Северные электрические сети
A13: АКТ № 0/ | G13: ='Провод СИП 3'!G13 -> SAP - 288007
A14: входного контроля
A16: ='Провод СИП 3'!A16 -> 141533,Российская Федерация, г.о.Солнечногорск | K16: ='Провод СИП 3'!K16:L16 -> 25.09.2024
A17: (место проведения) | K17: (дата)
A19: Нами, комиссией | C19: ='Провод СИП 3'!C19:G19 -> ООО "Энергосистемы" | H19: ='Данные объект'!B43 -> по приказу №05-ОТ/24 от 09 января 2023г. в составе:
C20: (организация, от которой сформирована комиссия)
A22: Председателя: . | C22: ='Данные объект'!C45 -> Главный энергетик ООО "Энергосистемы" Фечин А.А.
A23: (должность, организация, фамилия, имя, отчество)
A25: и членов комиссии:
C26: ='Данные объект'!C47 -> Прораб ООО "Энергосистемы" Волков М.Ю.
A27: (должность, организация, фамилия, имя, отчество)
C28: ='Данные объект'!C49 -> Инженер-электрик ООО "Энергосистемы" Высоцкий А.В.
A29: (должность, организация, фамилия, имя, отчество)
C30: ='Данные объект'!B32 -> Гл. специалист ССК УКС ПАО "Россети Московский регион" Алексанян Г.Р.
A31: (должность, организация, фамилия, имя, отчество)
A32: руководствуясь, | C32: ='Данные объект'!B51 -> методическими указаниями ПАО "Россети Московский регион" (утв. Приказом от 14.11.2024 г. № 1254)
A33: (документ, устанавливающий требевания по организации и проведению входного контроля продукции)
A34: составила настоящий акт о выполненном входном контроле продукции для строительства.
A36: 1. К входному контролю представлена следующая продукция:
A37: Предохранитель высоковольтный с кварцевым наполнителем 3ПКТ-103-6-100А-31,5УЗ
A38: (наименование продукции)
A39: 1.1. Наименование, номер документа, удостоверяющего качество и НТД на продукцию: | K39: ООО «Экопром»
K40: (изготовитель,
A41: Сертификат соответствия №РОСС RU.04РИД0.ОСП04.С00591 срок действия от 14.01.2022г до 13.01.2025г | H41: НТД | I41: ТУ 1491-001-02863030-2004
A42: № документа и дата, № партии, дата изготовления) (ГОСТ, ТУ, чертеж КМД)
A43: 1.2. Кол-во: | C43: 3 шт | E43: Кол-во партии: | G43: =C43 -> 3 шт
A44: (штуки, объем, вес в ед. изм.) (штуки, объем, вес в ед. изм.)
A45: 1.3. Поставщик: | C45: ООО ТК "Норма-кабель" | F45: Договор | G45: №НК-398 от 30.11.2023
A46: (наименование организации) (реквизиты договора на поставку)
A47: 2. Подготовка продукции к контролю по НТД: | F47: выполнена
A48: (выполнена/не выполнена)
A49: 3. При входном контроле проведены следующие контрольные мероприятия:
...

Sheet ТТ Т-0,66
K1: Приложение 1
K3: Приложение 48 к приказу от 19.12.2019 № 1414
F5: ФОРМА
I6: ГОДЕН
I7: (результат контроля продукции)
A8: Объект строительства:
A9: ='Провод СИП 3'!A9:L9 -> Строительство ТП-10/0,4 кВ, ВЛЗ-10 кВ от ВЛЗ-10 кВ ф. «Кочугино» ПС №185 "Воробьево", ВЛИ-0,38 кВ, рлр, в т.ч. ПИР, МО, Солнечногорский р-н, г. Солнечногорск
A11: Заказчик строительства: Филиал ПАО «Россети Московский регион» - Северные электрические сети
A13: АКТ № 0/ | G13: ='Провод СИП 3'!G13 -> SAP - 288007
A14: входного контроля
A16: ='Провод СИП 3'!A16 -> 141533,Российская Федерация, г.о.Солнечногорск | K16: ='Провод СИП 3'!K16:L16 -> 25.09.2024
A17: (место проведения) | K17: (дата)
A19: Нами, комиссией | C19: ='Провод СИП 3'!C19:G19 -> ООО "Энергосистемы" | H19: ='Данные объект'!B43 -> по приказу №05-ОТ/24 от 09 января 2023г. в составе:
C20: (организация, от которой сформирована комиссия)
A22: Председателя: . | C22: ='Данные объект'!C45 -> Главный энергетик ООО "Энергосистемы" Фечин А.А.
A23: (должность, организация, фамилия, имя, отчество)
A25: и членов комиссии:
C26: ='Данные объект'!C47 -> Прораб ООО "Энергосистемы" Волков М.Ю.
A27: (должность, организация, фамилия, имя, отчество)
C28: ='Данные объект'!C49 -> Инженер-электрик ООО "Энергосистемы" Высоцкий А.В.
A29: (должность, организация, фамилия, имя, отчество)
C30: ='Данные объект'!B32 -> Гл. специалист ССК УКС ПАО "Россети Московский регион" Алексанян Г.Р.
A31: (должность, организация, фамилия, имя, отчество)
A32: руководствуясь, | C32: ='Данные объект'!B51 -> методическими указаниями ПАО "Россети Московский регион" (утв. Приказом от 14.11.2024 г. № 1254)
A33: (документ, устанавливающий требевания по организации и проведению входного контроля продукции)
A34: составила настоящий акт о выполненном входном контроле продукции для строительства.
A36: 1. К входному контролю представлена следующая продукция:
A37: Трансформатор тока Т-0,66 400/5
A38: (наименование продукции)
A39: 1.1. Наименование, номер документа, удостоверяющего качество и НТД на продукцию: | K39: ФК ИК-1
K40: (изготовитель,
A41: Декларация о соответствии №ЕАЭС №RU Д-RU.НВ11.В.00611/19 от 19.11.2019г | H41: НТД | I41: ТУ 27.11.42-033-08826343-2007
A42: № документа и дата, № партии, дата изготовления) (ГОСТ, ТУ, чертеж КМД)
A43: 1.2. Кол-во: | C43: 3 шт | E43: Кол-во партии: | G43: =C43 -> 3 шт
A44: (штуки, объем, вес в ед. изм.) (штуки, объем, вес в ед. изм.)
A45: 1.3. Поставщик: | C45: ООО ТК "Норма-кабель" | F45: Договор | G45: №НК-398 от 30.11.2023
A46: (наименование организации) (реквизиты договора на поставку)
A47: 2. Подготовка продукции к контролю по НТД: | F47: выполнена
A48: (выполнена/не выполнена)
A49: 3. При входном контроле проведены следующие контрольные мероприятия:
...

Sheet РМК
K1: Приложение 1
K3: Приложение 48 к приказу от 19.12.2019 № 1414
