Workbook
Name _Toc27724337: Пр.6А!$J$1
Name aaaa: '[1]связ.данные(оборудование)'!$L$17:$L$23
Name №диспет: [2]Значения!$CY$15:$CY$18
Name авпвапп: [3]ВыгрузкаОС!$1:$1048576
Name вл04: [2]ОКОФ!$B$2
Name габариты2: [2]Значения!$DF$15:$DF$16
Name Группы_НУ: '[4]Группы НУ'!$A$4:$A$13
Name дис: '[5]3-кв.2016г'!$BW$6
Name кабель: 'связ.данные (Работы)'!$B$85:$B$86
Name кабель: 'связ.данные(оборудование)'!$B$85:$B$86
Name КЛ: 'связ.данные(оборудование)'!$H$64:$H$66
Name кл04: [2]ОКОФ!$E$2
Name кл6: [2]ОКОФ!$D$2
Name ктп2: [2]ОКОФ!$H$2
Name КТП3: [2]Значения!$DE$15:$DE$17
Name мастера2: [2]Значения!$DV$15:$DV$17
Name мурэс: [2]УРЭС!$A$7
Name начи: '[6]Для заполнения'!$L$1:$L$2
Name Оборудование: 'связ.данные(оборудование)'!$H$70:$H$93
Name ОС: [2]Значения!$AL$22:$AL$23
Name ПОДРЯДЧИК: #N/A
Name провод: 'связ.данные (Работы)'!$B$75:$B$82
Name провод: 'связ.данные(оборудование)'!$B$75:$B$82
Name работысмр: 'связ.данные (Работы)'!$B$58:$B$68
Name работысмр: 'связ.данные(оборудование)'!$B$58:$B$68
Name район2: [2]Значения!$DU$15:$DU$16
Name сер: [2]УРЭС!$A$5
Name СПИСКА: [2]КС14!$A$158:$A$162
Name СПИСОК2: '[2]Протокол-старый'!$A$35:$A$40
Name список3: [2]КС14_ХС!$A$154:$A$158
Name стойка: 'связ.данные (Работы)'!$B$71:$B$72
Name стойка: 'связ.данные(оборудование)'!$B$71:$B$72
Name ТМГ: [2]ОКОФ!$F$2
Name ТП: 'связ.данные(оборудование)'!$H$50:$H$60
Name уровень: [2]Значения!$AK$22:$AK$23
Name цецуекуе: [7]Лист10!$1:$1048576

Sheet Главная 
B4: Титульный лист
A5: ОБЩИЕ ФОРМЫ ПРИЕМОСДАТОЧНОЙ ДОКУМЕНТАЦИИ
A6: 1 | B6: Ведомость технической документации (форма 1)
A7: 2 | B7: Акт технической готовности электромонтажных работ (форма 2)
A8: 3 | B8: Ведомость изменений и отступлений от проекта (форма 3)
A9: 4 | B9: Ведомость электромонтажных недоделок, не препятствующих комплексному опробованию (форма 4)
A10: 5 | B10: Акт приемки-передачи оборудования в монтаж (форма ОС-15)
A11: 6 | B11: Акт о выявленных дефектах оборудования (форма ОС-16)
A12: 7 | B12: Ведомость смонтированного электрооборудования (форма 5)
A13: 8 | B13: Акт готовности строительной части помещений (сооружений) к производству электромонтажных работ (форма 6)
A14: 9 | B14: Справка о ликвидации недоделок (форма 6а)
A15: 10 | B15: Акт передачи смонтированного оборудования для производства пусконаладочных работ(форма 6б)
A16: ФОРМЫ ДОКУМЕНТОВ ПО ЭЛЕКТРООБОРУДОВАНИЮ РАСПРЕДЕЛИТЕЛЬНЫХ УСТРОЙСТВ И ЭЛЕКТРИЧЕСКИХ ПОДСТАНЦИЙ НАПРЯЖЕНИЕМ ДО 220 кВ ВКЛЮЧИТЕЛЬНО
A17: 11 | B17: Акт о приемке и монтаже силового трансформатора
A18: ФОРМЫ ДОКУМЕНТОВ ПО АККУМУЛЯТОРНЫМ БАТАРЕЯМ
A19: 12 | B19: Протокол осмотра и проверки технической готовности электромонтажных работ по аккумуляторной батарее
A20: 13 | B20: Ведомость замеров при контрольном разряде аккумуляторной батареи
A21: ФОРМА ДОКУМЕНТОВ ПО ЭЛЕКТРОПРОВОДКАМ
A22: 14 | B22: Акт осмотра канализации из труб перед закрытием
A23: 15 | B23: Протокол испытаний давлением локальных разделительных уплотнений или стальных труб для проводок во взрывоопасных зонах классов В-1 и В-1а.
A24: ФОРМЫ ДОКУМЕНТОВ ПО КАБЕЛЬНЫМ ЛИНИЯМ
A25: 16 | B25: Акт приемки траншей, каналов, туннелей и блоков под монтаж кабелей (форма 14 а);
A26: 17 | B26: Протокол осмотра и проверки изоляции кабелей, на барабане перед прокладкой (форма 15);
A27: 18 | B27: Протокол прогрева кабелей на барабане перед прокладкой при низких температурах (форма 16);
A28: 19 | B28: Акт осмотра кабельной канализации в траншее и каналах перед закрытием (форма 17);
A29: 20 | B29: Журнал прокладки кабелей (форма 18);
A30: 21 | B30: Журнал разделки кабельных муфт напряжением выше 1000 В (форма 19).
A31: ФОРМЫ ДОКУМЕНТОВ ПО ВОЗДУШНЫМ ЛИНИЯМ ЭЛЕКТРОПЕРЕДАЧИ НАПРЯЖЕНИЕМ ДО 220 кВ ВКЛЮЧИТЕЛЬНО
A32: 22 | B32: Акт готовности монолитного фундамента под опору ВЛ (форма 20);
A33: 23 | B33: Акт готовности сборных железобетонных фундаментов под опоры (форма 21);
A34: 24 | B34: Паспорт воздушной линии электропередачи (форма 22);
A35: 25 | B35: Акт замеров в натуре габаритов от проводов ВЛ до пересекаемого объекта (форма 23).
A36: ФОРМЫ ДОКУМЕНТОВ ПО ЗАЗЕМЛЯЮЩИМ УСТРОЙСТВАМ
A37: 26 | B37: Паспорт заземляющего устройства (форма 24).

Sheet связ.данные (Работы)
A1: ТП | B1: ТМГ | C1: КЛ | D1: КЛ | E1: ВЛ | F1: ВРЩ | G1: КСО | H1: КРН
A2: Монтаж ТП | B2: Монтаж ТМГ | C2: Прокладка кабельной линии | D2: Устройство ГНБ кабельной линии | E2: Монтаж воздушной линии | F2: Монтаж ВРЩ-0,4кВ | G2: Монтаж ячеек | H2: Монтаж АСП
A3: КТП-1000/10/0,4кВ | B3: ТМГ-1000/10/0,4кВ | C3: КЛ-10кВ | D3: КЛ-10кВ | E3: ВЛ-10кВ | F3: ВРЩ-0,4кВ | G3: КСО-298 | H3: КРН-10
A4: КТП-630/10/0,4кВ | B4: ТМГ-630/10/0,4кВ | C4: КЛ-6кВ | D4: КЛ-6кВ | E4: ВЛ-6кВ | H4: КРН-6
A5: КТП-400/10/0,4кВ | B5: ТМГ-400/10/0,4кВ | C5: КЛ-0,4кВ | D5: КЛ-0,4кВ | E5: ВЛ-0,4кВ | H5: КРУН-10
A6: КТП-250/10/0,4кВ | B6: ТМГ-250/10/0,4кВ | H6: КРУН-6 | K6: работы | N6: категория
A7: КТП-630/6/0,4кВ | B7: ТМГ-160/10/0,4кВ | K7: Монтаж ТП | L7: КТП-1000/10/0,4кВ
A8: КТП-400/6/0,4кВ | B8: ТМГ-630/6/0,4кВ | K8: Устройство ГНБ кабельной линии | L8: КЛ-0,4кВ
A9: КТП-250/6/0,4кВ | B9: ТМГ-400/6/0,4кВ | K9: Монтаж ВРЩ-0,4кВ
A10: МТП-250/10/0,4кВ | B10: ТМГ-250/6/0,4кВ | K10: Прокладка кабельной линии | L10: КЛ-6кВ
A11: МТП-160/10/0,4кВ | B11: ТМГ-160/6/0,4кВ | K11: Монтаж ВРЩ-0,4кВ | L11: ВРЩ-0,4кВ
A12: МТП-250/6/0,4кВ | K12: Устройство ГНБ кабельной линии | L12: КЛ-10кВ
A13: МТП-160/6/0,4кВ
K14: Монтаж ТП | L14: КТП-630/10/0,4кВ
K19: Прокладка кабельной линии | L19: =OFFSET($A$2,1,MATCH(K19,$A$2:$H$2,0)-1,10,1)

Sheet связ.данные(оборудование)
A2: Подстанция трансформаторная | B2: Трансформатор силовой герметичный | C2: Стойка железобетонная | D2: Самонесущий изолированный повод | E2: Кабель | F2: Трансформаторы тока | G2: Счетчик электрической энергии | H2: Автоматический выключатель | I2: Выключатель нагрузки | J2: Предохранитель высоковольтный | K2: Ограничители перенапряжений высоковольтные | L2: Муфта концевая термоусаживаемая | M2: Муфта соединительная термоусаживаемая | N2: Разъединитель трехполюсный | O2: Длинно-искровой разрядник | P2: Ограничитель перенапряжения нелинейный | Q2: Провод | R2: ВРЩ | S2: КРН | T2: Вакуумный включатель | U2: Микропроцессорное устройство защиты | V2: Копмлектное распределительное устройство наружной установки | W2: Предохранители-разъединители выхлопного типа | X2: Индикатор короткого замыкания | Y2: Блок питания | Z2: Камеры дугогасительные | AA2: Выключатель-разъединитель нагрузки
A3: КТП-1000/10/0,4кВ | B3: ТМГ-1000/10/0,4кВ | C3: СВ 95-3 | D3: СИП-3 1х50 | E3: АСБл 3х120 | F3: Т-0,66 100/5 | G3: СТЭМ-300.153GSU | H3: ВА 57-35 100 А | I3: ВНАП-10/630 | K3: ОПН-П-10/13,7/10/650 | L3: 3КВНТп-10-70/120-Б | M3: 3СТп-10-70/120-Б | N3: РЛК-1-10.IV/400 | O3: РМК-20 | P3: ОР600/28 | Q3: ПуГВ 1х240 | R3: Щит ЩМП | S3: КРУН-10 К/К | T3: ВВТ-10 | U3: Сириус-2-Л-БПТ | V3: яч.КСО-298 | W3: ПРВТ-10-80А | X3: ИКЗ-В34Л УЗ | Y3: Орион-БП-5 | Z3: КДВ-СЭЩ-10 | AA3: CSCS400K3CO 400А
A4: КТП-630/10/0,4кВ | B4: ТМГ-630/10/0,4кВ | C4: СВ 110-5 | D4: СИП-3 1х70 | E4: АСБл 3х240 | F4: Т-0,66 150/5 | H4: ВА 57-35 160 А | J4: ПКТ 101-10-20-20 У1 | L4: 3КВНТп-10-150/240 | M4: 3СТп-10-150/240 | N4: РВЗ-10/630 | Q4: ПуГВ 1х185 | S4: КРУН-10 В/К | T4: ВВУ-СЭЩ-ПЗ-10 | U4: Орион-РТЗ-3 | AA4: CSCS630K3CO 630А
A5: КТП-400/10/0,4кВ | B5: ТМГ-400/10/0,4кВ | D5: СИП-3 1х95 | E5: АВБШв 4х120 | F5: Т-0,66 200/5 | H5: ВА 57-35 200 А | J5: ПКТ 102-10-20-31,5У1 | L5: 4КВтп-1-150/240 | M5: 4СТП-1 16-25 | N5: РВЗФз-10/1000 | Q5: ПуГВ 1х150 | S5: КРУН-6 К/К | T5: Коммутационный модуль серии ISM | AA5: CSCS1250K3CO 1000А
A6: КТП-250/10/0,4кВ | B6: ТМГ-250/10/0,4кВ | D6: СИП-2 3х35+1х35 | E6: АВБШв 4х150 | F6: Т-0,66 250/5 | H6: ВА 57-35 250 А | J6: ПКТ-101-10-31,5-31,5У3 | K6: ОПН-П-6/7,2/10/550 | L6: 4КВНТп-1-70/120 | M6: 4СТП-1 25/50 | N6: РВФЗ-10/630 | Q6: ПуГВ 1х120 | S6: КРУН-6 В/К | T6: Модуль упраления серии СМ
A7: КТП-630/6/0,4кВ | B7: ТМГ-160/10/0,4кВ | D7: СИП-2 3х50+1х50 | E7: АВБШв 4х185 | F7: Т-0,66 300/5 | H7: ВА 57-35 400 А | J7: ПКТ-102-10-40А-31,5У1 | K7: ОПН 6/7,2/5/250 | L7: 4КНТП-1 16-25 | M7: 4СТП-1 70/120 | Q7: ПуГВ 1х95
A8: КТП-400/6/0,4кВ | B8: ТМГ-630/6/0,4кВ | D8: СИП-2 3х70+1х70 | E8: АВБШв 4х240 | F8: Т-0,66 400/5 | H8: ВА 57-35 600 А | J8: ПКТ-102-10-50-31,5У3 | L8: 4КВНТп-1 25/50 | M8: 4СТП-1 150/240 | Q8: Пугв 1х70
A9: КТП-250/6/0,4кВ | B9: ТМГ-400/6/0,4кВ | D9: СИП-2 3х95+1х95 | E9: АВБШв 4х95 | F9: Т-0,66 600/5 | H9: ВА 57-35 63 А | J9: ПКТ 102-10-80-31,5 УХЛ3 | Q9: ПуГВ 1х50
A10: МТП-250/10/0,4кВ | B10: ТМГ-250/6/0,4кВ | D10: СИП-2 3х120+1х95 | E10: АПвВнг(А)-LS 1х95/35 | F10: Т-0,66 1000/5 | H10: ВА 57-35 125 А | J10: ПКТ 102-6-31,5-31,5 У3 | Q10: ПуГВ 1х35
A11: МТП-160/10/0,4кВ | B11: ТМГ-160/6/0,4кВ | D11: СИП-2 3х95+1х120 | E11: АСБл 3х150 | F11: ТОЛ-6 300/5 | H11: ВА 57-35 80 А | Q11: ПуГВ 1х25
A12: МТП-250/6/0,4кВ | B12: ОЛС-СЭЩ-1.25/10 | D12: СИП-2 3х120+1х120 | E12: АСБл 3х185 | F12: ТОЛ-6 400/5 | H12: ВА 47-60М 25 А | Q12: ПуГВ 1х16
A13: МТП-160/6/0,4кВ | B13: ОЛС-СТ-1,25/6П | D13: СИП-4 2х16 | F13: ТОЛ-6 600/5 | Q13: ПуГВ 1х10
D14: СИП-4 4х16 | F14: ТОЛ-6 800/5 | Q14: ПВС 3х2,5
D15: СИП-4 4х25 | F15: ТОЛ-10 300/5 | Q15: КВВГнг 10х2,5
F16: ТОЛ-10 400/5
F17: ТОЛ-10 600/5
F18: ТОЛ-10 800/5
F20: 3хЗНОЛ-СВЭЛ-10М
F21: ТЗЛК-СЭЩ-0,66
F22: ТЗЛЭ-125
F23: ОЛС-П2,5/10

Sheet Данные организации
A1: организация
A2: реквизиты
A3: адрес
A4: район
A6: директор
A7: директор ФИО
A8: Строй.контроль
A9: Приказ стр.контр.
A10: ФИО стр.контр.
A11: Представитель
A12: ФИО предст.
A13: Геодезист
... A20: ФИО прораб
A23: сцепленные организация | C23: =IF(AND(C2="",C3=""),"",CONCATENATE(IF(C2="","",C2),",",IF(C3="","",C3))) | D23: =IF(AND(D2="",D3=""),"",CONCATENATE(IF(D2="","",D2),",",IF(D3="","",D3)))
A24: сцепленные организация | C24: =IF(AND(C1="",C2="",C3=""),"",CONCATENATE(IF(C1="","",C1),",",IF(C2="","",C2),",",IF(C3="","",C3))) | D24: =IF(AND(D1="",D2="",D3=""),"",CONCATENATE(IF(D1="","",D1),",",IF(D2="","",D2),",",IF(D3="","",D3))) | G24: =IF(AND(G9="",G1="",G11="",G10=""),"",CONCATENATE(IF(G9="","",G9)," ",IF(G1="","",G1),"-",IF(G11="","",G11)," .",IF(G10="","",G10))) | H24: =IF(AND(H9="",G1="",H10="",H11=""),"",CONCATENATE(IF(H9="","",H9)," ",IF(G1="","",G1),"-",IF(H10="","",H10),".",IF(H11="","",H11))) | I24: =IF(AND(I9="",G1="",I11="",I10=""),"",CONCATENATE(IF(I9="","",I9)," ",IF(G1="","",G1),"-",IF(I11="","",I11)," .",IF(I10="","",I10)))
C25: =IF(AND(C8="",C1="",C10="",C9=""),"",CONCATENATE(IF(C8="","",C8)," ",IF(C1="","",C1),"-",IF(C10="","",C10),".",IF(C9="","",C9))) | D25: =IF(AND(D8="",D1="",D10="",D9=""),"",CONCATENATE(IF(D8="","",D8)," ",IF(D1="","",D1),"-",IF(D10="","",D10),".",IF(D9="","",D9))) | G25: =IF(AND(G9="",G1="",G11=""),"",CONCATENATE(IF(G9="","",G9)," ",IF(G1="","",G1)," ",IF(G11="","",G11))) | H25: =IF(AND(H9="",G1="",H11=""),"",CONCATENATE(IF(H9="","",H9)," ",IF(G1="","",G1)," ",IF(H11="","",H11))) | I25: =IF(AND(I9="",G1="",I11=""),"",CONCATENATE(IF(I9="","",I9)," ",IF(G1="","",G1),"-",IF(I11="","",I11)))
C26: =IF(AND(C8="",C1=""),"",CONCATENATE(IF(C8="","",C8)," ",IF(C1="","",C1))) | D26: =IF(AND(D8="",D1=""),"",CONCATENATE(IF(D8="","",D8)," ",IF(D1="","",D1))) | G26: =IF(AND(G9="",G1=""),"",CONCATENATE(IF(G9="","",G9)," ",IF(G1="","",G1))) | H26: =IF(AND(H9="",G1=""),"",CONCATENATE(IF(H9="","",H9)," ",IF(G1="","",G1))) | I26: =IF(AND(I9="",G1=""),"",CONCATENATE(IF(I9="","",I9)," ",IF(G1="","",G1)))
C27: =IF(AND(C18="",C1="",C20="",C19=""),"",CONCATENATE(IF(C18="","",C18)," ",IF(C1="","",C1),"-",IF(C20="","",C20),".",IF(C19="","",C19))) | D27: =IF(AND(D18="",D1="",D20="",D19=""),"",CONCATENATE(IF(D18="","",D18)," ",IF(D1="","",D1),"-",IF(D20="","",D20),".",IF(D19="","",D19))) | G27: =IF(AND(G6="",G1="",G7=""),"",CONCATENATE(IF(G6="","",G6)," ",IF(G1="","",G1)," ",IF(G7="","",G7))) | I27: =IF(AND(I6="",G1="",I7=""),"",CONCATENATE(IF(I6="","",I6)," ",IF(G1="","",G1)," ",IF(I7="","",I7)))
C28: =IF(AND(C18="",C1="",C20=""),"",CONCATENATE(IF(C18="","",C18)," ",IF(C1="","",C1)," ",IF(C20="","",C20))) | D28: =IF(AND(D18="",D1="",D20=""),"",CONCATENATE(IF(D18="","",D18)," ",IF(D1="","",D1),"-",IF(D20="","",D20))) | G28: =IF(AND(G15="",G1="",G16=""),"",CONCATENATE(IF(G15="","",G15)," ",IF(G1="","",G1)," ",IF(G16="","",G16))) | I28: =IF(AND(I15="",G1="",I16=""),"",CONCATENATE(IF(I15="","",I15)," ",IF(G1="","",G1)," ",IF(I16="","",I16)))
C29: =IF(AND(C18="",C1=""),"",CONCATENATE(IF(C18="","",C18)," ",IF(C1="","",C1))) | D29: =IF(AND(D18="",D1=""),"",CONCATENATE(IF(D18="","",D18)," ",IF(D1="","",D1))) | G29: =IF(AND(G17="",G1="",G18=""),"",CONCATENATE(IF(G17="","",G17)," ",IF(G1="","",G1)," ",IF(G18="","",G18)))
A31: ДЛЯ АРК (актов раб.комиссии)
A36: Начальник СРЭС
A48: Гл.специалист ССК УКС

Sheet Данные объект
A1: Данные объекта
A2: № САП
A3: Объект
A4: р-н
A5: Адрес
A6: Дата разбивки
A7: Дата старт
A8: Дата финиш
A9: год
A10: Наименование электроустановки
A11: Общий | B11: =_xlfn.CONCAT(B12, ", ",B13, ", ", B14, ", ",B15, ", ",B16, ", ", B17)
A12: ТП
A13: АСП
A14: ВЛ-10
A15: ВЛ-0,4
A16: КЛ
A17: ВРЩ
A18: Монтажная организация
A19: Организация | C19: =IF(AND(B19="",B20="",B21=""),"",CONCATENATE(IF(B19="","",B19)," ",IF(B20="","",B20)," ",IF(B21="","",B21)))
A20: Реквизиты
A21: адрес
A22: Должность
A23: ФИО | C23: =IF(AND(B22="",B19="",B23=""),"",CONCATENATE(IF(B22="","",B22)," ",IF(B19="","",B19)," ",IF(B23="","",B23)))
A24: Должность | C24: =IF(AND(B24="",B19=""),"",CONCATENATE(IF(B24="","",B24)," ",IF(B19="","",B19)))
A25: Ф.И.О. | C25: =IF(AND(B24="",B19="",B25=""),"",CONCATENATE(IF(B24="","",B24)," ",IF(B19="","",B19)," ",IF(B25="","",B25)))
A26: Приказ | C26: =IF(AND(B24="",B19="",B25="",B26=""),"",CONCATENATE(IF(B24="","",B24)," ",IF(B19="","",B19)," ",IF(B25="","",B25),", ",IF(B26="","",B26)))
A27: Должность | C27: =IF(AND(B27="",B19=""),"",CONCATENATE(IF(B27="","",B27)," ",IF(B19="","",B19)))
A28: Ф.И.О. | C28: =IF(AND(B27="",B19="",B28=""),"",CONCATENATE(IF(B27="","",B27)," ",IF(B19="","",B19)," ",IF(B28="","",B28)))
A29: Приказ | C29: =IF(AND(B27="",B19="",B28="",B29=""),"",CONCATENATE(IF(B27="","",B27)," ",IF(B19="","",B19)," ",IF(B28="","",B28),", ",IF(B29="","",B29)))
A30: Должность | C30: =IF(AND(B30="",B19=""),"",CONCATENATE(IF(B30="","",B30)," ",IF(B19="","",B19)))
A31: Ф.И.О. | C31: =IF(AND(B30="",B19="",B31=""),"",CONCATENATE(IF(B30="","",B30)," ",IF(B19="","",B19)," ",IF(B31="","",B31)))
A32: Заказчик
A33: Организация
A34: Реквизиты | B34: =IF('Данные организации'!G2="","",'Данные организации'!G2)
A35: адрес | B35: =IF('Данные организации'!G3="","",'Данные организации'!G3)
A36: Должность | C36: =IF(AND(B36="",B33=""),"",CONCATENATE(IF(B36="","",B36)," ",IF(B33="","",B33)))
A37: Ф.И.О. | C37: =IF(AND(B36="",B33="",B37=""),"",CONCATENATE(IF(B36="","",B36)," ",IF(B33="","",B33)," ",IF(B37="","",B37)))
A38: Должность
A39: Ф.И.О. | C39: =IF(AND(B39="",B33=""),"",CONCATENATE(IF(B39="","",B39)," ",IF(B33="","",B33)))
A40: Должность
...

Sheet Титульный ЭС
A1: ЭЛЕКТРОМОНТАЖНАЯ КОМПАНИЯ ОБЩЕСТВО С ОГРАНИЧЕННОЙ ОТВЕТСТВЕННОСТЬЮ
A4: (Электромонтажная организация)
A6: =IF('Данные организации'!G1="","",'Данные организации'!G1)
A7: (Заказчик)
A10: ИСПОЛНИТЕЛЬНАЯ ДОКУМЕНТАЦИЯ
A11: ПО СДАЧЕ-ПРИЕМКЕ ЭЛЕКТРОМОНТАЖНЫХ РАБОТ
A13: на объекте:
A14: =IF('Данные объект'!B12="","",'Данные объект'!B12)
A15: =IF('Данные объект'!B13="","",'Данные объект'!B13)
A16: =IF('Данные объект'!B14="","",'Данные объект'!B14)
A17: =IF('Данные объект'!B15="","",'Данные объект'!B15)
A18: =IF('Данные объект'!B16="","",'Данные объект'!B16)
A20: по титулу:
A21: =IF('Данные объект'!B2="","",'Данные объект'!B2)
A23: =IF('Данные объект'!B3="","",'Данные объект'!B3)
A25: (объект)
A28: шифр проекта:
A29: =IF('Данные объект'!B56="","",'Данные объект'!B56)
A48: =IF('Данные объект'!B4="","",'Данные объект'!B4)
A49: =IF('Данные объект'!B9="","",'Данные объект'!B9)

Sheet Титульный подрядчик
A1: ОБЩЕСТВО С ОГРАНИЧЕННОЙ ОТВЕТСТВЕННОСТЬЮ
A4: (Электромонтажная организация)
A6: =IF('Данные объект'!B30="","",'Данные объект'!B30)
A7: (Заказчик)
A10: ИСПОЛНИТЕЛЬНАЯ ДОКУМЕНТАЦИЯ
A11: ПО СДАЧЕ-ПРИЕМКЕ ЭЛЕКТРОМОНТАЖНЫХ РАБОТ
A16: на объекте:
A17: =IF('Данные объект'!B12="","",'Данные объект'!B12)
A18: =IF('Данные объект'!B13="","",'Данные объект'!B13)
A19: =IF('Данные объект'!B14="","",'Данные объект'!B14)
A20: =IF('Данные объект'!B15="","",'Данные объект'!B15)
A21: =IF('Данные объект'!B16="","",'Данные объект'!B16)
A23: по титулу:
A24: =IF('Данные объект'!B2="","",'Данные объект'!B2)
A26: =IF('Данные объект'!B3="","",'Данные объект'!B3)
A28: (объект)
A34: шифр проекта:
A35: =IF('Данные объект'!B56="","",'Данные объект'!B56)
A55: =IF('Данные объект'!B4="","",'Данные объект'!B4)
A56: =IF('Данные объект'!B9="","",'Данные объект'!B9)

Sheet Акт опробования
N4: АКТ № | P4: =IF('Данные объект'!B2="","",'Данные объект'!B2)
A5: рабочей комиссии о приёмке оборудования после комплексного опробования
A7: г. | Y7: =IF('Данные объект'!B8="","",'Данные объект'!B8)
A9: Комиссия, назначенная
A13: {наименование организации-Заказчика (застройщика), назначившей комиссию}
A15: приказом СЭС | S15: от | T15: " | U15: 27 | W15: " | X15: января | AE15: 20 | AF15: 26
A17: № | B17: 197
A19: в составе:
A21: председателя-представителя Заказчика (застройщика)
A24: (фамилия, имя, отчество, должность)
A26: членов комиссии — представителей:
A27: генерального подрядчика
A29: (фамилия, имя, отчество, должность)
A31: (фамилия, имя, отчество, должность)
A33: пусконаладочной организации
A34: =IF('Данные организации'!A40="","",'Данные организации'!A40)
A35: (фамилия, имя, отчество, должность)
A37: субподрядных (монтажных) организаций
A38: нет
A40: (фамилия, имя, отчество, должность)
A42: эксплуатационной организации
A45: (фамилия, имя, отчество, должность)
A47: генерального проектировщика
A50: (фамилия, имя, отчество, должность)
A53: органов технического надзора
A54: -
A55: -
A56: (фамилия, имя, отчество, должность)
... A72: смонтированное в
A73: =IF('Данные объект'!B5="","",'Данные объект'!B5)
A74: (наименование предприятия, его очереди, пускового этапа)
A76: входящего в состав титула:
A77: =IF('Данные объект'!B3="","",'Данные объект'!B3)
A78: (наименование предприятия, его очереди, пускового этапа)
A80: прошло (не прошло) комплексное опробование, включая необходимые
A82: пусконаладочные работы, совместно с коммуникациями с | Y82: =IF('Данные объект'!B8="","",'Данные объект'!B8)
A84: по | C84: =IF(Y82="","",Y82+3) | P84: В течение | T84: 72 | Y84: часов, дней в соответствии с
A86: утверждённой Заказчиком Программой.
A88: 2. Комплексное опробование, включая необъодимые пусконаладочные работы, выполнены (не выполнено)
A90: (наименование организации - заказчика пусконаладочной организации)
...

Sheet Приложение_№_2
A4: АКТ № | Q4: =IF('Данные объект'!B2="","",'Данные объект'!B2)
A5: рабочей комиссии о приемке оборудования после индивидуального испытания для комплексного опробования
A7: г. | B7: ='Акт опробования'!B7:H7 | X7: =IF('Данные объект'!B8="","",'Данные объект'!B8)
A9: Комиссия, назначенная
A13: {наименование организации-Заказчика (застройщика), назначившей комиссию}
A15: приказом СЭС | S15: от | T15: " | U15: 27 | W15: " | X15: января | AE15: 20 | AF15: 26
A17: № | B17: 197
A19: в составе:
A21: председателя-представителя Заказчика (застройщика)
A24: (фамилия, имя, отчество, должность)
A26: членов комиссии — представителей:
A27: генерального подрядчика
A28: ='Акт опробования'!A28:AF28
A29: (фамилия, имя, отчество, должность)
A31: (фамилия, имя, отчество, должность)
A33: пусконаладочной организации
A34: ='Акт опробования'!A34:AF34
A35: (фамилия, имя, отчество, должность)
A37: субподрядных (монтажных) организаций
A38: нет
A40: (фамилия, имя, отчество, должность)
A42: эксплуатационной организации
A43: ='Акт опробования'!A43:AF43
A45: (фамилия, имя, отчество, должность)
A47: генерального проектировщика
A48: ='Акт опробования'!A48:AF48
A50: (фамилия, имя, отчество, должность)
A53: органов технического надзора
A54: -
A55: -
A56: (фамилия, имя, отчество, должность)
A58: других заинтересованных органов надзора и организаций (при необходимости)
A59: -
A60: (фамилия, имя, отчество, должность)
A62: УСТАНОВИЛА:
A64: 1. Генеральным подядчиком
A65: ='Акт опробования'!A28:AF28
A69: (фамилия, имя, отчество, должность)
A71: предъявлено к приемке следующее оборудование:
A72: СИП-2 3х70+1х95, протяженностью 0,028 км
...

Sheet Приложение_№_4
A4: =IF(Приложение_№_2!A4="","",Приложение_№_2!A4) | R4: =IF('Акт опробования'!P4="","",'Акт опробования'!P4)
A5: РАБОЧЕЙ КОМИССИИ О ГОТОВНОСТИ ОБОРУДОВАНИЯ ДЛЯ ПРЕДЪЯВЛЕНИЯ ПРИЕМОЧНОЙ КОМИССИИ
A7: г. | B7: ='Акт опробования'!B7:H7 | X7: =IF('Данные объект'!B8="","",'Данные объект'!B8)
A9: Комиссия, назначенная
A11: =IF(Приложение_№_2!A11="","",Приложение_№_2!A11)
A13: {наименование организации-Заказчика (застройщика), назначившей комиссию}
A15: приказом ЗЭС | S15: от | T15: " | U15: =IF(Приложение_№_2!U15="","",Приложение_№_2!U15) | W15: " | X15: =IF(Приложение_№_2!X15="","",Приложение_№_2!X15) | AE15: 20 | AF15: =IF(Приложение_№_2!AF15="","",Приложение_№_2!AF15)
A17: № | B17: =IF(Приложение_№_2!B17="","",Приложение_№_2!B17)
A19: в составе:
A21: председателя-представителя Заказчика (застройщика)
A22: =IF(Приложение_№_2!A22="","",Приложение_№_2!A22)
A24: (фамилия, имя, отчество, должность)
A26: членов комиссии — представителей:
A27: генерального подрядчика
A28: =IF(Приложение_№_2!A28="","",Приложение_№_2!A28)
A29: (фамилия, имя, отчество, должность)
A31: (фамилия, имя, отчество, должность)
A33: пусконаладочной организации
A34: =IF(Приложение_№_2!A34="","",Приложение_№_2!A34)
A35: (фамилия, имя, отчество, должность)
A37: субподрядных (монтажных) организаций
A38: нет
A40: (фамилия, имя, отчество, должность)
A42: эксплуатационной организации
A43: =IF(Приложение_№_2!A43="","",Приложение_№_2!A43)
A45: (фамилия, имя, отчество, должность)
A47: генерального проектировщика
A48: =IF(Приложение_№_2!A48="","",Приложение_№_2!A48)
A50: (фамилия, имя, отчество, должность)
A53: органов технического надзора
A54: -
A55: -
A56: (фамилия, имя, отчество, должность)
A58: других заинтересованных органов надзора и организаций (при необходимости)
A59: -
A60: (фамилия, имя, отчество, должность)
A62: УСТАНОВИЛА:
A64: 1. Генеральным подядчиком
A65: =IF(Приложение_№_2!A65="","",Приложение_№_2!A65)
A69: (наименование организации и ее ведомственная подчиненность)
...

Sheet Пр.6А
J1: Приложение 6А
A2: ЗАКЛЮЧЕНИЕ
A3: о контролепригодности рабочей документации
A4: =IF('Данные объект'!B2="","",'Данные объект'!B2)
A5: =IF('Данные объект'!B4="","",'Данные объект'!B4) | I5: ='Данные объект'!B6-3
A7: =IF('Данные объект'!B3="","",'Данные объект'!B3)
A8: =IF('Данные объект'!B56="","",'Данные объект'!B56)
A9: (полное наименование документации, шифр, реквизиты приказа об утверждении (при наличии)
A10: Мною, специалистом строительного контроля
A11: =IF('Данные объект'!B33="","",'Данные объект'!B33)
A12: (организация)
A13: =IF(AND('Данные объект'!B39="",'Данные объект'!B42=""),"",CONCATENATE(IF('Данные объект'!B39="","",'Данные объект'!B39)," ",IF('Данные объект'!B42="","",'Данные объект'!B42)))
A14: (Фамилия И.О.)
A15: назначенным приказом | C15: =IF('Данные объект'!B43="","",'Данные объект'!B43)
A16: за осуществление строительного контроля на объекте строительства:
A17: =IF('Данные объект'!B3="","",'Данные объект'!B3)
A18: (наименование объекта строительства)
A19: в период с | B19: =I5-3 | D19: по | E19: =IF(I5="","",I5) | G19: проведен анализ и оценка возможности
A21: № | B21: Оценка | J21: Результат
A22: 1 | B22: Комплектность рабочей документации в объеме необходимом и достаточном для контроля качества работ | J22: ⅴДа □Нет
A23: 2 | B23: Взаимная увязка размеров, координат и отметок (высот), соответствующих проектным осевым размерам и геодезической основе | J23: ⅴДа □Нет
A24: 3 | B24: Наличие ссылок на нормативные документы на материалы и изделия (технические условия и ГОСТ) | J24: ⅴДа □Нет
A25: 4 | B25: Наличие требований к фактической точности контролируемых параметров, оценка возможности ее контроля | J25: ⅴДа □Нет
A26: 5 | B26: Условия определения с необходимой точностью предлагаемых допусков на размеры изделий и конструкций, а также обеспечение выполнения контроля указанных в проектной документации параметров при установке изделий и конструкций в проектное положение, наличие указаний о методах и оборудовании для выполнения необходимых испытаний и измерений со ссылкой на нормативные документы | J26: ⅴДа □Нет
A27: 6 | B27: Техническая оснащенность и технологические возможности выполнения контроля качества в соответствии с нормативной документацией | J27: ⅴДа □Нет
A28: 7 | B28: Достаточность перечня скрытых работ, перечня ответственных конструкций, участков сетей, по которым требуется производить освидетельствование | J28: ⅴДа □Нет
A29: 8 | B29: Достаточность перечня работ и конструкций, показатели качества которых подлежат оценке соответствия в процессе строительства | J29: ⅴДа □Нет
A30: 9 | B30: Наличие предельных значений контролируемых параметров, допускаемых уровней несоответствия по каждому из них | J30: ⅴДа □Нет
A31: 10 | B31: Наличие и соответствие разделов рабочей документации требованиям законодательных и нормативных актов РФ в части организации и обеспечения качества строительства со стороны строительного подрядчика и Заказчика | J31: ⅴДа □Нет
A32: 11 | B32: Наличие указаний о применяемых инструментах, приборах, методах контроля и объемах, в том числе в виде ссылок на соответствующие нормативные документы | J32: ⅴДа □Нет
A33: В результате анализа и оценки на контролепригодность:
A34: рабочей документации по титулу
A35: =IF('Данные объект'!B3="","",'Данные объект'!B3)
A36: 1. | B36: -
A37: 2. | B37: -
A38: Выводы:
A39: На основании выполненного анализа и оценки организационно-технологической документации, Исполнитель СК удостоверяет о возможности/невозможности (нужное подчеркнуть) осуществления по ней контроля качества строительных процессов и материалов, изделий, оборудования установленным нормативным требованиям.
A40: Исполнитель СК: | F40: / | J40: =IF('Данные объект'!B42="","",'Данные объект'!B42)
F41: (подпись)/(дата) | J41: (Ф.И.О.)

Sheet Пр.6Б
J1: Приложение 6Б
A2: ЗАКЛЮЧЕНИЕ
A3: о контролепригодности организационно-технологической документации
A4: =IF('Данные объект'!B2="","",'Данные объект'!B2)
A5: =IF('Данные объект'!B4="","",'Данные объект'!B4) | I5: ='Данные объект'!B6-3
A7: =IF('Данные объект'!B3="","",'Данные объект'!B3)
A8: =IF('Данные объект'!B56="","",'Данные объект'!B56)
A9: (полное наименование документации, шифр, реквизиты приказа об утверждении (при наличии)
A10: Мною, специалистом строительного контроля
A11: =IF('Данные объект'!B33="","",'Данные объект'!B33)
A12: (организация)
A13: =IF(AND('Данные объект'!B39="",'Данные объект'!B42=""),"",CONCATENATE(IF('Данные объект'!B39="","",'Данные объект'!B39)," ",IF('Данные объект'!B42="","",'Данные объект'!B42)))
A14: (Фамилия И.О.)
A15: назначенным приказом | C15: =IF('Данные объект'!B43="","",'Данные объект'!B43)
A16: за осуществление строительного контроля на объекте строительства:
A17: =IF('Данные объект'!B3="","",'Данные объект'!B3)
A18: (наименование объекта строительства)
A19: в период с | B19: =I5-3 | D19: по | E19: =IF(I5="","",I5) | G19: проведен анализ и оценка возможности
A21: № | B21: Оценка | J21: Результат
A22: 1 | B22: Комплектность, полнота и качество разработки операционно-технологических карт, схем операционного контроля по видам работ и контроля в соответствии с требованиями утвержденной проектной документации и выданной в производство работ рабочей документации, в том числе входного контроля материалов, изделий и оборудования; операционного и приемочного контроля | J22: ⅴДа □Нет
A23: 2 | B23: Наличие и соответствие разделов требованиям законодательных и нормативных документов в части организации и обеспечения качества строительства со стороны строительного подрядчика и Заказчика | J23: ⅴДа □Нет
A24: 3 | B24: Наличие перечня работ и конструкций, показатели качества которых подлежат оценке соответствия в процессе строительства | J24: ⅴДа □Нет
A25: 4 | B25: Наличие перечня актов, оформляемых на скрытые работы и ответственные конструкции, оказывающие влияние на безопасность объекта или сооружения, подлежащие освидетельствованию | J25: ⅴДа □Нет
A26: 5 | B26: Наличие предельных значений контролируемых параметров, допускаемых уровней несоответствия по каждому из них | J26: ⅴДа □Нет
A27: 6 | B27: Наличие указаний о применяемых инструментах, приборах, объемах и методах контроля, в том числе в виде ссылок на соответствующие нормативные документы | J27: ⅴДа □Нет
A28: В результате анализа и оценки на контролепригодность:
A29: организационно-технологической документации по титулу
A30: =IF('Данные объект'!B3="","",'Данные объект'!B3)
A31: 1. | B31: -
A32: 2. | B32: -
A33: Выводы:
A34: На основании выполненного анализа и оценки организационно-технологической документации, Исполнитель СК удостоверяет о возможности/невозможности (нужное подчеркнуть) осуществления по ней контроля качества строительных процессов и материалов, изделий, оборудования установленным нормативным требованиям.
A35: Исполнитель СК: | F35: / | J35: =IF('Данные объект'!B42="","",'Данные объект'!B42)
F36: (подпись)/(дата) | J36: (Ф.И.О.)

Sheet Пр.7
A1: Приложение 7
A2: Форма заключения по проверке готовности строительной подрядной организации к выполнению работ по строительству, реконструкции, техперевооружению на объектах электросетевого комплекса
A3: ЗАКЛЮЧЕНИЕ
A4: =IF('Данные объект'!B2="","",'Данные объект'!B2)
A5: по проверке готовности строительной подрядной организации к выполнению работ
A6: по строительству, реконструкции, техперевооружению на объектах электросетевого комплекса
A8: ='Данные объект'!B6-3 | L8: =IF('Данные объект'!B4="","",'Данные объект'!B4)
L9: (место составления)
A10: Мною, специалистом строительного контроля
A11: =IF('Данные объект'!B33="","",'Данные объект'!B33)
A12: (организация)
A13: =IF('Данные объект'!C42="","",'Данные объект'!C42)
A14: (Фамилия И.О.)
A15: назначенным приказом : | D15: =IF('Данные объект'!B43="","",'Данные объект'!B43) | I15: за осуществление строительного контроля на объекте строительства:
A16: =IF('Данные объект'!B3="","",'Данные объект'!B3)
A17: (наименование объекта строительства)
A19: проведена проверка готовности | E19: =IF('Данные объект'!B19="","",'Данные объект'!B19)
A20: (наименование подрядной организации)
A22: В присутствии:
A24: полномочного представителя подрядной организации:
A25: =IF('Данные объект'!C28="","",'Данные объект'!C28)
A26: (должность, Ф.И.О.)
A28: к проведению работ:
A29: =IF('1 '!G41="","",'1 '!G41)
A30: =IF('1 '!G42="","",'1 '!G42)
A31: =IF('1 '!G43="","",'1 '!G43)
A32: =IF('1 '!G44="","",'1 '!G44)
A33: =IF('1 '!G45="","",'1 '!G45)
A34: =IF('1 '!G46="","",'1 '!G46)
A35: =IF('1 '!G47="","",'1 '!G47)
A36: =IF('1 '!G48="","",'1 '!G48)
A37: (наименование работ)
A39: № п/п | B39: Наименование проверяемого документа и его наличие | J39: Отметка о соответствии требованиям и нормативу * | L39: Параметры несоответствия нормативу, подлежащие к устранению до начала работ (наименование НТД)
A40: 1 | B40: ГОТОВНОСТЬ РАЗРЕШИТЕЛЬНОЙ ДОКУМЕНТАЦИИ НЕОБХОДИМОЙ ДЛЯ НАЧАЛА СТРОИТЕЛЬСТВА
A41: 1.1 | B41: Договор на выполнение СМР, договор на осуществление авторского надзора в случае разработки проекта подрядчиком (проверка на наличие). | J41: +
A42: 1.2 | B42: Согласование Заказчика, выдаваемое Строительному подрядчику на привлечение субподрядной организации (для проверки готовности субподрядной организации). | J42: +
A43: 1.3 | B43: Подтверждение членства в саморегулируемых организациях - актуальная выписка из реестра членов саморегулируемой организации (СРО). | J43: +
A44: 1.4 | B44: Лицензия, выдаваемая МЧС на монтаж средств обеспечения пожарной безопасности зданий и сооружений (при необходимости). | J44: не требуется
A45: 1.5 | B45: Разрешение на вырубку леса (при необходимости). | J45: не требуется
A46: 1.6 | B46: Разрешение на право производства работ в охранной зоне инженерных коммуникаций (при необходимости). | J46: +
...

Sheet Пр.10
A1: Приложение 10
A2: ЗАКЛЮЧЕНИЕ
A3: =IF('Данные объект'!B2="","",'Данные объект'!B2)
A4: о проверке готовности электротехнической (испытательной) лаборатории
A5: строительной подрядной организации к проведению работ по строительству, реконструкции, техническому перевооружению на объектах электросетевого комплекса
K7: =IF('Данные объект'!B4="","",'Данные объект'!B4)
K8: (место составления)
A9: Мною, специалистом строительного контроля
A10: =IF('Данные объект'!B33="","",'Данные объект'!B33)
A11: (организация)
A12: =IF('Данные объект'!C42="","",'Данные объект'!C42)
A13: (Фамилия И.О.)
A14: назначенным приказом : | C14: =IF('Данные объект'!B43="","",'Данные объект'!B43) | H14: за осуществление строительного контроля на объекте строительства:
A15: =IF('Данные объект'!B3="","",'Данные объект'!B3)
A16: (Наименование объекта строительства)
A18: проведена проверка готовности | D18: =IF('Данные объект'!B19="","",'Данные объект'!B19)
A19: (наименование подрядной организации)
A20: В присутствии:
A21: полномочного представителя подрядной организации:
A22: =IF('Данные объект'!C28="","",'Данные объект'!C28)
A23: (должность, Ф.И.О.)
A24: к проведению работ:
A25: Проверки (испытаний) электроустановки
A26: (наименование работ)
A28: № п/п | B28: Наименование документа | J28: Отметка о соотв. нормативу * | L28: Параметры несоответствия нормативу, подлежащие к устранению до начала работ (наименование нормативного документа).
A29: 1 | B29: 2 | J29: 3 | L29: 4
A30: 1 | B30: Свидетельство о регистрации ЭЛ. | J30: +
A31: 2 | B31: Аттестованный персонал на IV-V группы электробезопасности с правом испытания оборудования повышенным напряжением. | J31: +
A32: 3 | B32: Прохождение персоналом ЭЛ подготовки и проверки знаний по требованиям ПБ. | J32: +
A33: 4 | B33: Паспорт ЭЛ. | J33: +
A34: 5 | B34: Руководство по качеству ЭЛ. | J34: +
A35: 6 | B35: Положение ЭЛ. | J35: +
A36: 7 | B36: Должностные инструкции. | J36: +
A37: 8 | B37: Приказ о создании ЭЛ. | J37: +
A38: 9 | B38: Приказ о назначении ответственных лиц. | J38: +
A39: 10 | B39: Методики по электроиспытаниям в соответствии с разрешенными видами испытаний. | J39: +
A40: 11 | B40: Инструкции по охране труда. | J40: +
A41: 12 | B41: Наличие нормативно-технической документации. | J41: +
... A43: 14 | B43: Паспорта, руководство по эксплуатации на применяемое оборудование и средства измерения. | J43: +
A45: * Если документ не требуется, указать «не треб.»
...

Sheet Пр.11
A1: Приложение 11
A3: ЗАКЛЮЧЕНИЕ
A4: об оценке соответствия законченного строительством объекта и его готовности к предъявлению рабочей комиссии
A5: =IF('Данные объект'!B3="","",'Данные объект'!B3)
A7: =IF('Данные объект'!B2="","",'Данные объект'!B2)
A8: (наименование объекта (титула)
A9: =IF('Данные объект'!B4="","",'Данные объект'!B4) | K9: =IF('Данные объект'!B8="","",'Данные объект'!B8)
A10: (место составления)
A12: Нами:
A13: =IF('Данные объект'!B33="","",'Данные объект'!B33)
A14: (наименование структурного подразделения Заказчика, проводившего оценку соответствия)
A15: =IF('Данные объект'!B19="","",'Данные объект'!B19)
A16: (наименование организации генерального подрядчика, осуществившего строительство объекта)
A17: в лице:
A18: представителя Исполнителя СК:
A19: =IF('Данные объект'!C42="","",'Данные объект'!C42)
A20: (фамилия, имя, отчество, должность, идентификационный номер в НРС)
A21: _____________________________________________________________________________________________
A22: назначенным приказом : | C22: =IF('Данные объект'!B43="","",'Данные объект'!B43) | H22: за осуществление строительного контроля на объекте строительства:
A24: представителя организации Генерального подрядчика:
A25: =IF('Данные объект'!C28="","",'Данные объект'!C28)
A26: (фамилия, имя, отчество, должность, идентификационный номер в НРС)
A27: _____________________________________________________________________________________________
A28: назначенного ответственным лицом в соответствии с приказом:
A29: =IF('Данные объект'!B29="","",'Данные объект'!B29)
A31: в присутствии:
A32: представителя Проектировщика (авторского надзора):
A33: -
A34: (наименование организации Проектировщика, осуществившего авторский надзор за строительством объекта, фамилия, имя, отчество, должность, идентификационный номер в НРС)
A35: назначенного ответственным лицом в соответствии с приказом
A36: от «___» _________20___ г. № _____
A37: представителей субподрядных (монтажных) организации:
A38: -
A39: (фамилия, имя, отчество, должность)
A40: представителя эксплуатационной организации:
A41: =IF('Данные объект'!C37="","",'Данные объект'!C37)
A42: (фамилия, имя, отчество, должность)
A43: и представителей других заинтересованных организаций:
A44: -
A45: (фамилия, имя, отчество, должность)
...

Sheet Пр.13 Справка ИД
A1: Приложение 13
A3: Наименование Заказчика: | D3: =IF('Данные объект'!B33="","",'Данные объект'!B33)
A4: Наименование Подрядчика: | D4: =IF('Данные объект'!B19="","",'Данные объект'!B19)
A5: Объект: | D5: =IF('Данные объект'!B3="","",'Данные объект'!B3)
A6: Для представления: | D6: Заказчику
A7: Представляется по факту: | D7: Приемочной комиссии
A9: СПРАВКА
A10: об отсутствии замечаний по проверке приемо-сдаточной документации
L12: =IF('Данные объект'!B8="","",'Данные объект'!B8)
A14: Замечания по Перечню замечаний по результатам проверки приемо-сдаточной документации отсутствуют.
A15: Представленная документация соответствует Перечню приемо-сдаточной документации по объекту, утвержденного
L16: =IF('Данные объект'!C3="","",'Данные объект'!C3)
A17: =IF('Данные объект'!C2="","",'Данные объект'!C2)
A20: Приложение:
A21: 1. Реестр приемо-сдаточной документации от | F21: =IF(L12="","",L12) | H21: на | J21: листах.
A23: Представитель технического заказчика
A24: =IF('Данные объект'!C37="","",'Данные объект'!C37)
A25: =IF('Данные объект'!B38="","",'Данные объект'!B38)
A26: =IF(A30="","",A30)
A27: Исполнитель по строительному контролю (Исполнитель СК):
A28: =IF('Данные объект'!C42="","",'Данные объект'!C42)
A29: =IF('Данные объект'!B43="","",'Данные объект'!B43)
A30: (должность, наименование организации, фамилия, инициалы, реквизиты распорядительного документа о представительстве)
A31: Представитель лица строительного подрядчика, осуществляющего строительство:
A32: =IF('Данные объект'!C28="","",'Данные объект'!C28)
A33: =IF('Данные объект'!B29="","",'Данные объект'!B29)
A34: (должность, наименование организации, фамилия, инициалы, реквизиты распорядительного документа о представительстве)

Sheet Пр.15 Реестр
A1: Приложение 15
A2: Форма
A3: реестра приемо-сдаточной документации
C4: =IF('Данные объект'!B2="","",'Данные объект'!B2)
C5: =IF('Данные объект'!B33="","",'Данные объект'!B33)
C6: =IF('Данные объект'!B19="","",'Данные объект'!B19)
A8: =IF('Данные объект'!B3="","",'Данные объект'!B3)
A11: =IF(C4="","",C4)
A14: 1
A15: 1
A16: =A15+1
A17: =A16+1
A18: =A17+1
A21: =A18+1 | B21: =IF(AND(Пр.6А!A2="",Пр.6А!A3=""),"",CONCATENATE(IF(Пр.6А!A2="","",Пр.6А!A2),IF(Пр.6А!A3="","",Пр.6А!A3)," (Прил.6А)")) | D21: =IF(C6="","",C6)
A22: =A21+1 | B22: =IF(AND(Пр.6Б!A2="",Пр.6Б!A3=""),"",CONCATENATE(IF(Пр.6Б!A2="","",Пр.6Б!A2),IF(Пр.6Б!A3="","",Пр.6Б!A3)," (Прил.6Б)")) | D22: =IF(C6="","",C6)
A23: =A22+1 | B23: =IF(AND(Пр.7!A3="",Пр.7!A5="",Пр.7!A6=""),"",CONCATENATE(IF(Пр.7!A3="","",Пр.7!A3),IF(Пр.7!A5="","",Пр.7!A5),IF(Пр.7!A6="","",Пр.7!A6)," (Прил.7)")) | D23: =IF(C6="","",C6)
A24: =A23+1 | B24: =IF(AND(Пр.10!A2="",Пр.10!A4="",Пр.10!A5=""),"",CONCATENATE(IF(Пр.10!A2="","",Пр.10!A2),IF(Пр.10!A4="","",Пр.10!A4),IF(Пр.10!A5="","",Пр.10!A5)," (Прил.10)")) | D24: =IF(C6="","",C6)
A25: =A24+1 | B25: =IF(AND(Пр.11!A3="",Пр.11!A4=""),"",CONCATENATE(IF(Пр.11!A3="","",Пр.11!A3),IF(Пр.11!A4="","",Пр.11!A4)," (Прил.11)")) | D25: =IF(C6="","",C6)
A26: =A25+1 | B26: =IF(AND('Пр.13 Справка ИД'!A9="",'Пр.13 Справка ИД'!A10=""),"",CONCATENATE(IF('Пр.13 Справка ИД'!A9="","",'Пр.13 Справка ИД'!A9),IF('Пр.13 Справка ИД'!A10="","",'Пр.13 Справка ИД'!A10)," (Прил.13)")) | D26: =IF(C6="","",C6)
A27: =A26+1
A28: =A27+1 | D28: =IF(C9="","",C9)
A29: =A28+1 | D29: =IF(C6="","",C6)
A30: =A29+1 | D30: =IF(C6="","",C6)
A31: =A30+1 | D31: =IF(C6="","",C6)
A32: =A31+1 | D32: =IF(C6="","",C6)
A34: =A32+1 | B34: =IF('1 '!A15="","",'1 '!A15) | D34: =IF(C6="","",C6)
A35: =A34+1 | B35: =IF('2'!A14="","",'2'!A14) | D35: =IF(C6="","",C6)
A36: =A35+1 | B36: =IF('3'!A14="","",'3'!A14) | D36: =IF(C6="","",C6)
A37: =A36+1 | B37: =IF('Ведомость общ'!A14="","",'Ведомость общ'!A14) | D37: =IF(C6="","",C6)
A38: =A37+1 | B38: =IF(AND('ТП-1'!$A$16="",'ТП-1'!$A$17=""),"",CONCATENATE(IF('ТП-1'!$A$16="","",'ТП-1'!$A$16),IF('ТП-1'!$A$17="","",'ТП-1'!$A$17))) | D38: =IF(C6="","",C6)
A39: =A38+1 | B39: =IF(AND('ТП-2'!$A$13="",'ТП-2'!$A$14=""),"",CONCATENATE(IF('ТП-2'!$A$13="","",'ТП-2'!$A$13),IF('ТП-2'!$A$14="","",'ТП-2'!$A$14))) | D39: =IF(C6="","",C6)
A40: =A39+1 | B40: =IF(AND('ТП-3'!$A$13="",'ТП-3'!$A$14=""),"",CONCATENATE(IF('ТП-3'!$A$13="","",'ТП-3'!$A$13),IF('ТП-3'!$A$14="","",'ТП-3'!$A$14))) | D40: =IF(C6="","",C6)
A41: =A40+1 | B41: =IF(AND('ТП-4'!A13="",'ТП-4'!A14=""),"",CONCATENATE(IF('ТП-4'!A13="","",'ТП-4'!A13),IF('ТП-4'!A14="","",'ТП-4'!A14))) | D41: =IF(C6="","",C6)
A42: =A41+1 | D42: =IF(C6="","",C6)
A43: =A42+1 | D43: =IF(C6="","",C6)
A44: =A43+1 | D44: =IF(C6="","",C6)
A45: =A44+1 | D45: =IF(C6="","",C6)
A46: =A45+1
A47: =A46+1 | D47: =IF(C6="","",C6)
A48: =A47+1 | D48: =IF(C6="","",C6)
...

Sheet Ведомость перед
A1: Приложение 15
A2: Форма
A3: реестра приемо-сдаточной документации
C4: =IF('Данные объект'!B2="","",'Данные объект'!B2)
C5: =IF('Данные объект'!B33="","",'Данные объект'!B33)
C6: =IF('Данные объект'!B19="","",'Данные объект'!B19)
A8: =IF('Данные объект'!B3="","",'Данные объект'!B3)
A11: =IF(C4="","",C4)
A14: 1
A15: 1
A16: =A15+1
A17: =A16+1
A18: =A17+1
A19: =A18+1 | B19: =IF(AND(Пр.6А!A2="",Пр.6А!A3=""),"",CONCATENATE(IF(Пр.6А!A2="","",Пр.6А!A2),IF(Пр.6А!A3="","",Пр.6А!A3)," (Прил.6А)")) | D19: =IF(C6="","",C6)
A20: =A19+1 | B20: =IF(AND(Пр.6Б!A2="",Пр.6Б!A3=""),"",CONCATENATE(IF(Пр.6Б!A2="","",Пр.6Б!A2),IF(Пр.6Б!A3="","",Пр.6Б!A3)," (Прил.6Б)")) | D20: =IF(C6="","",C6)
A21: =A20+1 | B21: =IF(AND(Пр.7!A3="",Пр.7!A5="",Пр.7!A6=""),"",CONCATENATE(IF(Пр.7!A3="","",Пр.7!A3),IF(Пр.7!A5="","",Пр.7!A5),IF(Пр.7!A6="","",Пр.7!A6)," (Прил.7)")) | D21: =IF(C6="","",C6)
A22: =A21+1 | B22: =IF(AND(Пр.10!A2="",Пр.10!A4="",Пр.10!A5=""),"",CONCATENATE(IF(Пр.10!A2="","",Пр.10!A2),IF(Пр.10!A4="","",Пр.10!A4),IF(Пр.10!A5="","",Пр.10!A5)," (Прил.10)")) | D22: =IF(C6="","",C6)
A23: =A22+1 | B23: =IF(AND(Пр.11!A3="",Пр.11!A4=""),"",CONCATENATE(IF(Пр.11!A3="","",Пр.11!A3),IF(Пр.11!A4="","",Пр.11!A4)," (Прил.11)")) | D23: =IF(C6="","",C6)
A24: =A23+1 | B24: =IF(AND('Пр.13 Справка ИД'!A9="",'Пр.13 Справка ИД'!A10=""),"",CONCATENATE(IF('Пр.13 Справка ИД'!A9="","",'Пр.13 Справка ИД'!A9),IF('Пр.13 Справка ИД'!A10="","",'Пр.13 Справка ИД'!A10)," (Прил.13)")) | D24: =IF(C6="","",C6)
A25: =A24+1
A26: =A25+1 | D26: =IF(C9="","",C9)
A27: =A26+1 | D27: =IF(C6="","",C6)
A28: =A27+1 | D28: =IF(C6="","",C6)
A29: =A28+1 | D29: =IF(C6="","",C6)
A30: =A29+1 | D30: =IF(C6="","",C6)
A31: =A30+1 | B31: =IF('1 '!A15="","",'1 '!A15) | D31: =IF(C6="","",C6)
A32: =A31+1 | B32: =IF('2'!A14="","",'2'!A14) | D32: =IF(C6="","",C6)
A33: =A32+1 | B33: =IF('3'!A14="","",'3'!A14) | D33: =IF(C6="","",C6)
A34: =A33+1 | B34: =IF('Ведомость общ'!A14="","",'Ведомость общ'!A14) | D34: =IF(C6="","",C6)
A35: =A34+1 | B35: =IF(AND('ТП-1'!$A$16="",'ТП-1'!$A$17=""),"",CONCATENATE(IF('ТП-1'!$A$16="","",'ТП-1'!$A$16),IF('ТП-1'!$A$17="","",'ТП-1'!$A$17))) | D35: =IF(C6="","",C6)
A36: =A35+1 | B36: =IF(AND('ТП-2'!$A$13="",'ТП-2'!$A$14=""),"",CONCATENATE(IF('ТП-2'!$A$13="","",'ТП-2'!$A$13),IF('ТП-2'!$A$14="","",'ТП-2'!$A$14))) | D36: =IF(C6="","",C6)
A37: =A36+1 | B37: =IF(AND('ТП-3'!$A$13="",'ТП-3'!$A$14=""),"",CONCATENATE(IF('ТП-3'!$A$13="","",'ТП-3'!$A$13),IF('ТП-3'!$A$14="","",'ТП-3'!$A$14))) | D37: =IF(C6="","",C6)
A38: =A37+1 | B38: =IF(AND('ТП-4'!A13="",'ТП-4'!A14=""),"",CONCATENATE(IF('ТП-4'!A13="","",'ТП-4'!A13),IF('ТП-4'!A14="","",'ТП-4'!A14))) | D38: =IF(C6="","",C6)
A39: =A38+1 | D39: =IF(C6="","",C6)
A40: =A39+1 | D40: =IF(C6="","",C6)
A41: =A40+1 | D41: =IF(C6="","",C6)
A42: =A41+1 | D42: =IF(C6="","",C6)
A43: =A42+1
A44: =A43+1 | D44: =IF(C6="","",C6)
A45: =A44+1 | D45: =IF(C6="","",C6)
...

Sheet Пр.16
A1: Приложение 16
A2: Форма
A3: акта передачи приемо-сдаточной документации
A4: «____» ______________20___г.
A5: АКТ передачи приемо-сдаточной документации по объекту
A6: =IF('Данные объект'!B2="","",'Данные объект'!B2)
A7: =IF('Данные объект'!B3="","",'Данные объект'!B3)
A8: (наименование объекта строительства по титулу)
A9: Строительный подрядчик | C9: =IF('Данные объект'!B19="","",'Данные объект'!B19)
A10: в лице: | B10: =IF('Данные объект'!C25="","",'Данные объект'!C25)
A11: (наименование организации, должность, фамилия, инициалы, реквизиты распорядительного документа о представительстве)
A12: передал, а Заказчик / Исполнитель/СК
A13: в лице: | B13: =IF('Данные объект'!C45="","",'Данные объект'!C45)
A14: (наименование организации, должность, фамилия, инициалы, реквизиты распорядительного документа о представительстве)
A15: принял приемо-сдаточную документацию по завершенному строительством вышеуказанному объекту, в количестве:
A16: 1 | B16: книги, на | C16: =IF('Пр.15 Реестр'!B249="","",'Пр.15 Реестр'!B249) | D16: листах, | E16: в 1 экз. согласно Реестру приемо-сдаточной документации (Приложение15), на | K16: листах
A18: Приложения:
A19: 1. Реестр приемо-сдаточной документации на | E19: =IF(J16="","",J16) | F19: листах
A20: К Реестру и комплекту приемо - сдаточной документации также прилагаются:
A21: СПРАВКА об отсутствии замечаний по проверке приемо-сдаточной документации
A22: (Справка от лица, осуществляющего строительный контроль, эксплуатационных служб об отсутствии замечаний или устранении замечаний по результатам проверки приемо-сдаточной документации и другие документы по требованиям Заказчика и усмотрению Строительного подрядчика).
A23: Сдал:
A24: Представитель Строительного подрядчика | C24: =IF('Данные объект'!C25="","",'Данные объект'!C25)
C25: (должность, фамилия, инициалы) | G25: (подпись) | J25: (дата)
A26: Принял:
A27: Исполнитель СК / Заказчик | C27: =IF('Данные объект'!C45="","",'Данные объект'!C45)
C28: (должность, фамилия, инициалы) | G28: (подпись) | J28: (дата)

Sheet Пр.15 Реестр Химки
A1: Приложение 15
A2: Форма
A3: реестра приемо-сдаточной документации
C4: =IF('Данные объект'!B2="","",'Данные объект'!B2)
C5: =IF('Данные объект'!B33="","",'Данные объект'!B33)
C6: =IF('Данные объект'!B19="","",'Данные объект'!B19)
A8: =IF('Данные объект'!B3="","",'Данные объект'!B3)
A11: =IF(C4="","",C4)
A14: 1
A15: 1
A16: =A15+1
A17: =A16+1
A18: =A17+1
A19: =A18+1 | B19: =IF(AND(Пр.6А!A2="",Пр.6А!A3=""),"",CONCATENATE(IF(Пр.6А!A2="","",Пр.6А!A2),IF(Пр.6А!A3="","",Пр.6А!A3)," (Прил.6А)")) | D19: =IF(C6="","",C6)
A20: =A19+1 | B20: =IF(AND(Пр.6Б!A2="",Пр.6Б!A3=""),"",CONCATENATE(IF(Пр.6Б!A2="","",Пр.6Б!A2),IF(Пр.6Б!A3="","",Пр.6Б!A3)," (Прил.6Б)")) | D20: =IF(C6="","",C6)
A21: =A20+1 | B21: =IF(AND(Пр.7!A3="",Пр.7!A5="",Пр.7!A6=""),"",CONCATENATE(IF(Пр.7!A3="","",Пр.7!A3),IF(Пр.7!A5="","",Пр.7!A5),IF(Пр.7!A6="","",Пр.7!A6)," (Прил.7)")) | D21: =IF(C6="","",C6)
A22: =A21+1 | B22: =IF(AND(Пр.10!A2="",Пр.10!A4="",Пр.10!A5=""),"",CONCATENATE(IF(Пр.10!A2="","",Пр.10!A2),IF(Пр.10!A4="","",Пр.10!A4),IF(Пр.10!A5="","",Пр.10!A5)," (Прил.10)")) | D22: =IF(C6="","",C6)
A23: =A22+1 | B23: =IF(AND(Пр.11!A3="",Пр.11!A4=""),"",CONCATENATE(IF(Пр.11!A3="","",Пр.11!A3),IF(Пр.11!A4="","",Пр.11!A4)," (Прил.11)")) | D23: =IF(C6="","",C6)
A24: =A23+1 | B24: =IF(AND('Пр.13 Справка ИД'!A9="",'Пр.13 Справка ИД'!A10=""),"",CONCATENATE(IF('Пр.13 Справка ИД'!A9="","",'Пр.13 Справка ИД'!A9),IF('Пр.13 Справка ИД'!A10="","",'Пр.13 Справка ИД'!A10)," (Прил.13)")) | D24: =IF(C6="","",C6)
A25: =A24+1
A26: =A25+1 | D26: =IF(C9="","",C9)
A27: =A26+1 | D27: =IF(C6="","",C6)
A28: =A27+1 | D28: =IF(C6="","",C6)
A29: =A28+1 | D29: =IF(C6="","",C6)
A30: =A29+1 | D30: =IF(C6="","",C6)
A31: =A30+1 | B31: =IF('1 '!A15="","",'1 '!A15) | D31: =IF(C6="","",C6)
A32: =A31+1 | B32: =IF('2'!A14="","",'2'!A14) | D32: =IF(C6="","",C6)
A33: =A32+1 | B33: =IF('3'!A14="","",'3'!A14) | D33: =IF(C6="","",C6)
A34: =A33+1 | B34: =IF('Ведомость общ'!A14="","",'Ведомость общ'!A14) | D34: =IF(C6="","",C6)
A35: =A34+1 | B35: =IF(AND('ТП-1'!$A$16="",'ТП-1'!$A$17=""),"",CONCATENATE(IF('ТП-1'!$A$16="","",'ТП-1'!$A$16),IF('ТП-1'!$A$17="","",'ТП-1'!$A$17))) | D35: =IF(C6="","",C6)
A36: =A35+1 | B36: =IF(AND('ТП-2'!$A$13="",'ТП-2'!$A$14=""),"",CONCATENATE(IF('ТП-2'!$A$13="","",'ТП-2'!$A$13),IF('ТП-2'!$A$14="","",'ТП-2'!$A$14))) | D36: =IF(C6="","",C6)
A37: =A36+1 | B37: =IF(AND('ТП-3'!$A$13="",'ТП-3'!$A$14=""),"",CONCATENATE(IF('ТП-3'!$A$13="","",'ТП-3'!$A$13),IF('ТП-3'!$A$14="","",'ТП-3'!$A$14))) | D37: =IF(C6="","",C6)
A38: =A37+1 | B38: =IF(AND('ТП-4'!A13="",'ТП-4'!A14=""),"",CONCATENATE(IF('ТП-4'!A13="","",'ТП-4'!A13),IF('ТП-4'!A14="","",'ТП-4'!A14))) | D38: =IF(C6="","",C6)
A39: =A38+1 | D39: =IF(C6="","",C6)
A40: =A39+1 | D40: =IF(C6="","",C6)
A41: =A40+1 | D41: =IF(C6="","",C6)
A42: =A41+1 | D42: =IF(C6="","",C6)
A43: =A42+1
A44: =A43+1 | D44: =IF(C6="","",C6)
A45: =A44+1 | D45: =IF(C6="","",C6)
...

Sheet Пр.16 Химки
A1: Приложение 16
A2: Форма
A3: акта передачи приемо-сдаточной документации
A4: «____» ______________20___г.
A5: АКТ передачи приемо-сдаточной документации по объекту
A6: =IF('Данные объект'!B2="","",'Данные объект'!B2)
A7: =IF('Данные объект'!B3="","",'Данные объект'!B3)
A8: (наименование объекта строительства по титулу)
A9: Строительный подрядчик | C9: =IF('Данные объект'!B19="","",'Данные объект'!B19)
A10: в лице: | B10: =IF('Данные объект'!C25="","",'Данные объект'!C25)
A11: (наименование организации, должность, фамилия, инициалы, реквизиты распорядительного документа о представительстве)
A12: передал, а Заказчик / Исполнитель/СК
A13: в лице: | B13: =IF('Данные объект'!C42="","",'Данные объект'!C42)
A14: (наименование организации, должность, фамилия, инициалы, реквизиты распорядительного документа о представительстве)
A15: принял приемо-сдаточную документацию по завершенному строительством вышеуказанному объекту, в количестве:
A16: 1 | B16: книги, на | C16: =IF('Пр.15 Реестр'!B249="","",'Пр.15 Реестр'!B249) | D16: листах, | E16: в 1 экз. согласно Реестру приемо-сдаточной документации (Приложение15), на | K16: листах
A18: Приложения:
A19: 1. Реестр приемо-сдаточной документации на | E19: =IF(J16="","",J16) | F19: листах
A20: К Реестру и комплекту приемо - сдаточной документации также прилагаются:
A21: СПРАВКА об отсутствии замечаний по проверке приемо-сдаточной документации
A22: (Справка от лица, осуществляющего строительный контроль, эксплуатационных служб об отсутствии замечаний или устранении замечаний по результатам проверки приемо-сдаточной документации и другие документы по требованиям Заказчика и усмотрению Строительного подрядчика).
A23: Сдал:
A24: Представитель Строительного подрядчика | C24: =IF('Данные объект'!C25="","",'Данные объект'!C25)
C25: (должность, фамилия, инициалы) | G25: (подпись) | J25: (дата)
A26: Принял:
A27: Исполнитель СК / Заказчик | C27: =IF('Данные объект'!C42="","",'Данные объект'!C42)
C28: (должность, фамилия, инициалы) | G28: (подпись) | J28: (дата)
C30: =IF('Данные объект'!C37="","",'Данные объект'!C37)
C31: (должность, фамилия, инициалы) | G31: (подпись) | J31: (дата)

Sheet акт ГЕО
A1: Объект капитального строительства
A2: =IF('Данные объект'!B3="","",'Данные объект'!B3)
A3: (наименование, почтовый или строительный адрес объекта капитального строительства)
A4: Застройщик или технический заказчик | E4: =IF('Данные объект'!B33="","",'Данные объект'!B33)
E5: (наименование, ОГРН, ИНН, номер и дата выдачи свидетельства о допуске к видам работ
A6: =IF('Данные объект'!B34="","",'Данные объект'!B34)
A7: по строительству, реконструкции, капитальному ремонту объектов капитального строительства, которые оказывают влияние на безопасность объектов капитального строительства, с указанием саморегулируемой организации, его выдавшей1, почтовые реквизиты, телефон/факс - для юридических лиц и
A8: =IF('Данные объект'!B35="","",'Данные объект'!B35)
A9: индивидуальных предпринимателей; фамилия, имя, отчество, паспортные данные, место проживания, телефон/факс - для физических лиц)
A10: Лицо, осуществляющее строительство | E10: =IF('Данные объект'!B19="","",'Данные объект'!B19)
E11: (наименование, ОГРН, ИНН, номер и дата выдачи свидетельства о допуске к видам работ
A12: =IF('Данные объект'!B20="","",'Данные объект'!B20)
A13: (наименование, ОГРН, ИНН, номер и дата выдачи свидетельства о допуске к видам работ по строительству, реконструкции, капитальному ремонту объектов капитального строительства, которые оказывают влияние на безопасность объектов капитального строительства, с указанием саморегулируемой организации, его выдавшей1, почтовые реквизиты, телефон/факс - для юридических лиц и
A14: =IF('Данные объект'!B21="","",'Данные объект'!B21)
A15: индивидуальных предпринимателей; фамилия, имя, отчество, паспортные данные, место проживания, телефон/факс - для физических лиц)
A16: Лицо, осуществляющее подготовку проектной документации | G16: =IF('Данные объект'!B52="","",'Данные объект'!B52)
G17: (наименование, ОГРН, ИНН, номер и дата выдачи свидетельства
A18: =IF('Данные объект'!B53="","",'Данные объект'!B53)
A19: о допуске к видам работ по строительству, реконструкции, капитальному ремонту объектов капитального строительства, которые оказывают влияние на безопасность объектов капитального строительства, с указанием саморегулируемой организации, его выдавшей1, почтовые реквизиты, телефон/факс - для
A20: =IF('Данные объект'!B54="","",'Данные объект'!B54)
A21: юридических лиц и индивидуальных предпринимателей; фамилия, имя, отчество, паспортные данные, место проживания, телефон/факс - для физических лиц)
A22: Лицо, выполнившее работы по созданию геодезической разбивочной основы
A23: =IF('Данные объект'!C19="","",'Данные объект'!C19)
A24: (наименование, ОГРН, ИНН, номер и дата выдачи свидетельства о допуске к видам работ по строительству, реконструкции,
A25: которые оказывают влияние на безопасность объектов капитального строительства, с указанием саморегулируемой организации, его выдавшей1, почтовые реквизиты, телефон/факс - для юридических лиц и индивидуальных предпринимателей; фамилия, имя, отчество, паспортные данные, место проживания, телефон/факс - для физических лиц)
A27: АКТ освидетельствования геодезической разбивочной основы объекта капитального строительства
A29: № | B29: 1 | C29: /ГЕО | I29: =IF('Данные объект'!B6="","",'Данные объект'!B6)
I30: (дата составления акта)
A31: Представитель застройщика или технического заказчика по вопросам строительного контроля
A32: =IF('Данные объект'!C44="","",'Данные объект'!C44)
A33: (должность, фамилия, инициалы, реквизиты документа о представительстве)
A34: Представитель лица, осуществляющего строительство
A35: =IF('Данные объект'!C29="","",'Данные объект'!C29)
A36: (должность, фамилия, инициалы, реквизиты документа о представительстве)
A37: Представитель лица, осуществляющего строительство по вопросам строительного контроля
A38: =IF('Данные объект'!C26="","",'Данные объект'!C26)
A39: (должность, фамилия, инициалы, реквизиты документа о представительстве)
A40: Представитель застройщика
A41: =IF('Данные объект'!C46="","",'Данные объект'!C46)
A42: (должность, фамилия, инициалы, реквизиты документа о представительстве)
...

Sheet акт ГЕО оси
AJ2: приложение №1
A3: Объект капитального строительства
A4: =IF('Данные объект'!B3="","",'Данные объект'!B3)
A5: (наименование объекта капитального строительства в соответствии с проектной документацией, почтовый или строительный адрес объекта капитального строительства)
A6: Застройщик, технический заказчик, лицо, ответственное за эксплуатацию здания, сооружения, или региональный оператор
A7: =IF('Данные объект'!C31="","",'Данные объект'!C31)
A8: =IF('Данные объект'!B32="","",'Данные объект'!B32)
A9: (фамилия, имя, отчество (последнее - при наличии), адрес места жительства, ОРГНИП, ИНН индивидуального предпринимателя, полное и (или) сокращенное наименование, ОГРН, ИНН, адрес юридического лица в пределах его нахождения, телефон или факс,
A11: полное и (или) сокращенное наименование, ОГРН, ИНН саморегулируемой организации, членом которой является указанное юридическое лицо или индивидуальный предприниматель (за исключением случаев, когда членство в саморегулируемых организациях в области, строительства, реконструкции, капитального ремонта объектов капитального строительства не требуется);
A12: -
A13: фамилия, имя, отчество (последнее - при наличии), паспортные данные, адрес места жительства, телефон или факс - для физических лиц, не являющихся индивидуальными предпринимателями)
A14: Лицо, осуществляющее строительство, реконструкцию, капитальный ремонт
A15: =IF(AND('Данные объект'!B19="",'Данные объект'!B20=""),"",CONCATENATE(IF('Данные объект'!B19="","",'Данные объект'!B19)," ",IF('Данные объект'!B20="","",'Данные объект'!B20)))
A16: (фамилия, имя, отчество (последнее - при наличии), адрес места жительства, ОРГНИП, ИНН индивидуального предпринимателя,
A17: =IF('Данные объект'!B21="","",'Данные объект'!B21)
A18: полное и (или) сокращенное наименование, ОГРН, ИНН, адрес юридического лица в пределах его местонахождения, телефон или факс,
A19: =IF('Данные объект'!C65="","",'Данные объект'!C65)
A20: полное и (или) сокращенное наименование, ОГРН, ИНН саморегулируемой организации, членом которой является указанное юридическое лицо или индивидуальный предприниматель (за исключением случаев, когда членство в саморегулируемых организациях в области строительства, реконструкции, капитального ремонта объектов капитального строительства не требуется)
A21: Лицо, осуществляющее подготовку проектной документации
A22: =IF(A15="","",A15)
A23: (фамилия, имя, отчество (последнее - при наличии), адрес места жительства, ОРГНИП, ИНН индивидуального предпринимателя,
A24: =IF(A17="","",A17)
A25: полное и (или) сокращенное наименование, ОГРН, ИНН, адрес юридического лица в пределах его места нахождения, телефон или факс,
A26: =IF('Данные объект'!C63="","",'Данные объект'!C63)
A27: полное и (или) сокращенное наименование, ОГРН, ИНН саморегулируемой организации, членом которой является указанное юридическое лицо или индивидуальный предприниматель (за исключением случаев, когда членство в саморегулируемых организациях в области архитектурно-строительного проектирования не требуется)
A29: АКТ
A30: разбивки осей объекта капитального строительства на местности
B32: № | C32: 1 | E32: / | F32: ГЕО | AB32: =IF('Данные объект'!B6="","",'Данные объект'!B6)
AB33: (дата составления акта)
A35: Представитель застройщика, технического заказчика, лица, ответственного за эксплуатацию здания, сооружения, или регионального оператора по вопросам строительного контроля
A36: =IF('Данные объект'!C43="","",'Данные объект'!C43)
A37: (должность (при наличии), фамилия, инициалы, идентификационный номер в национальном реестре специалистов в области строительства (за исключением случаев, когда членство в саморегулируемых организациях в области строительства, реконструкции, капитального ремонта обектов капитального строительства не требуется), реквизиты распоряительного документа, подтверждающего полномочия,
A38: -
A39: с указанием полного и (или) сокращенного наименования, ОГРН, ИНН, адреса юридического лица в пределах его места нахождения (в случае осуществления строительного контроля на основании договора с застройщиком или техническим заказчиком), фамилии, имени, отчества (последнее - при наличии), адреса места жительства, ОГРНИП, ИНН индивиуального предпринимателя (в случае осуществления строительного контроля на основании договора с застройщиком или техническим заказчиком)
A40: Представитель лица, осуществляющего строительство, реконструкцию, капитальный ремонт
A41: =IF('Данные объект'!C29="","",'Данные объект'!C29)
A42: (должность (при наличии), фамилия, инициалы, реквизиты распорядительного документа, подтверждающего полномочия)
