Workbook

Sheet Данные организации
A1: организация
A2: реквизиты
A3: адрес
A4: район
A6: директор
A7: директор ФИО
A8: Строй.контроль
A9: Приказ стр.контр.
A10: ФИО стр.контр.
A11: Представитель
A12: ФИО предст.
A18: Прораб
... A20: ФИО прораб
A23: сцепленные организация | B23: =IF(AND(B2="",B3=""),"",CONCATENATE(IF(B2="","",B2),",",IF(B3="","",B3))) | C23: =IF(AND(C2="",C3=""),"",CONCATENATE(IF(C2="","",C2),",",IF(C3="","",C3))) | F23: =IF(AND(F8="",F1="",F10="",F9=""),"",CONCATENATE(IF(F8="","",F8)," ",IF(F1="","",F1),"-",IF(F10="","",F10)," .",IF(F9="","",F9))) | G23: =IF(AND(G8="",F1="",G9="",G10=""),"",CONCATENATE(IF(G8="","",G8)," ",IF(F1="","",F1),"-",IF(G9="","",G9),".",IF(G10="","",G10))) | H23: =IF(AND(H8="",F1="",H10="",H9=""),"",CONCATENATE(IF(H8="","",H8)," ",IF(F1="","",F1),"-",IF(H10="","",H10)," .",IF(H9="","",H9)))
A24: сцепленные организация | B24: =IF(AND(B1="",B2="",B3=""),"",CONCATENATE(IF(B1="","",B1),",",IF(B2="","",B2),",",IF(B3="","",B3))) | C24: =IF(AND(C1="",C2="",C3=""),"",CONCATENATE(IF(C1="","",C1),",",IF(C2="","",C2),",",IF(C3="","",C3))) | F24: =IF(AND(F8="",F1="",F10=""),"",CONCATENATE(IF(F8="","",F8)," ",IF(F1="","",F1)," ",IF(F10="","",F10))) | G24: =IF(AND(G8="",F1="",G10=""),"",CONCATENATE(IF(G8="","",G8)," ",IF(F1="","",F1)," ",IF(G10="","",G10))) | H24: =IF(AND(H8="",F1="",H10=""),"",CONCATENATE(IF(H8="","",H8)," ",IF(F1="","",F1)," ",IF(H10="","",H10)))
B25: =IF(AND(B8="",B1="",B10="",B9=""),"",CONCATENATE(IF(B8="","",B8)," ",IF(B1="","",B1),"-",IF(B10="","",B10),".",IF(B9="","",B9))) | C25: =IF(AND(C8="",C1="",C10="",C9=""),"",CONCATENATE(IF(C8="","",C8)," ",IF(C1="","",C1),"-",IF(C10="","",C10),".",IF(C9="","",C9))) | F25: =IF(AND(F8="",F1=""),"",CONCATENATE(IF(F8="","",F8)," ",IF(F1="","",F1))) | H25: =IF(AND(H8="",F1=""),"",CONCATENATE(IF(H8="","",H8)," ",IF(F1="","",F1)))
B26: =IF(AND(B8="",B1=""),"",CONCATENATE(IF(B8="","",B8)," ",IF(B1="","",B1))) | C26: =IF(AND(C8="",C1=""),"",CONCATENATE(IF(C8="","",C8)," ",IF(C1="","",C1))) | F26: =IF(AND(F6="",F1="",F7=""),"",CONCATENATE(IF(F6="","",F6)," ",IF(F1="","",F1)," ",IF(F7="","",F7))) | H26: =IF(AND(H6="",F1="",H7=""),"",CONCATENATE(IF(H6="","",H6)," ",IF(F1="","",F1)," ",IF(H7="","",H7)))
B27: =IF(AND(B18="",B1="",B20="",B19=""),"",CONCATENATE(IF(B18="","",B18)," ",IF(B1="","",B1),"-",IF(B20="","",B20),".",IF(B19="","",B19))) | C27: =IF(AND(C18="",C1="",C20="",C19=""),"",CONCATENATE(IF(C18="","",C18)," ",IF(C1="","",C1),"-",IF(C20="","",C20),".",IF(C19="","",C19))) | F27: =IF(AND(F14="",F1="",F15=""),"",CONCATENATE(IF(F14="","",F14)," ",IF(F1="","",F1)," ",IF(F15="","",F15))) | H27: =IF(AND(H14="",F1="",H15=""),"",CONCATENATE(IF(H14="","",H14)," ",IF(F1="","",F1)," ",IF(H15="","",H15)))
B28: =IF(AND(B18="",B1="",B20=""),"",CONCATENATE(IF(B18="","",B18)," ",IF(B1="","",B1)," ",IF(B20="","",B20))) | C28: =IF(AND(C18="",C1="",C20=""),"",CONCATENATE(IF(C18="","",C18)," ",IF(C1="","",C1),"-",IF(C20="","",C20))) | F28: =IF(AND(F16="",F1="",F17=""),"",CONCATENATE(IF(F16="","",F16)," ",IF(F1="","",F1)," ",IF(F17="","",F17)))
B29: =IF(AND(B18="",B1=""),"",CONCATENATE(IF(B18="","",B18)," ",IF(B1="","",B1))) | C29: =IF(AND(C18="",C1=""),"",CONCATENATE(IF(C18="","",C18)," ",IF(C1="","",C1)))
A32: Приказы НТД

Sheet Данные объект
A1: Данные объекта
A2: № САП
A3: Объект
A4: р-н
A5: Адрес
A6: Дата старт
A7: Дата финиш
A8: Наименование электроустановки
A9: ТП
A10: Монтажная организация
A11: Организация | C11: =IF(AND(B11="",B12="",B13=""),"",CONCATENATE(IF(B11="","",B11)," ",IF(B12="","",B12)," ",IF(B13="","",B13)))
A12: Реквизиты
A13: адрес
A14: Должность
A15: ФИО | C15: =IF(AND(B14="",B11="",B15=""),"",CONCATENATE(IF(B14="","",B14)," ",IF(B11="","",B11)," ",IF(B15="","",B15)))
A16: Должность | C16: =IF(AND(B16="",B11=""),"",CONCATENATE(IF(B16="","",B16)," ",IF(B11="","",B11)))
A17: Ф.И.О. | C17: =IF(AND(B16="",B11="",B17=""),"",CONCATENATE(IF(B16="","",B16)," ",IF(B11="","",B11)," ",IF(B17="","",B17)))
A18: Приказ | C18: =IF(AND(B16="",B11="",B17="",B18=""),"",CONCATENATE(IF(B16="","",B16)," ",IF(B11="","",B11)," ",IF(B17="","",B17),".",IF(B18="","",B18)))
A19: Должность | C19: =IF(AND(B19="",B11=""),"",CONCATENATE(IF(B19="","",B19)," ",IF(B11="","",B11)))
A20: Ф.И.О. | C20: =IF(AND(B19="",B11="",B20=""),"",CONCATENATE(IF(B19="","",B19)," ",IF(B11="","",B11)," ",IF(B20="","",B20)))
A21: Приказ | C21: =IF(AND(B19="",B11="",B20="",B21=""),"",CONCATENATE(IF(B19="","",B19)," ",IF(B11="","",B11)," ",IF(B20="","",B20),".",IF(B21="","",B21)))
A22: Заказчик
A23: Организация | C23: =IF(AND(B23="",B24="",B25=""),"",CONCATENATE(IF(B23="","",B23)," ",IF(B24="","",B24),",",IF(B25="","",B25)))
A24: Реквизиты | B24: =IF('Данные организации'!F2="","",'Данные организации'!F2)
A25: адрес | B25: =IF('Данные организации'!F3="","",'Данные организации'!F3)
A26: Должность | C26: =IF(AND(B26="",B23=""),"",CONCATENATE(IF(B26="","",B26)," ",IF(B23="","",B23)))
A27: Ф.И.О. | C27: =IF(AND(B26="",B23="",B27=""),"",CONCATENATE(IF(B26="","",B26)," ",IF(B23="","",B23)," ",IF(B27="","",B27)))
A28: Должность | C28: =IF(AND(B28="",B23=""),"",CONCATENATE(IF(B28="","",B28)," ",IF(B23="","",B23)))
A29: Ф.И.О. | C29: =IF(AND(B28="",B23="",B29=""),"",CONCATENATE(IF(B28="","",B28)," ",IF(B23="","",B23)," ",IF(B29="","",B29)))
A30: Должность | C30: =IF(AND(B30="",B23=""),"",CONCATENATE(IF(B30="","",B30)," ",IF(B23="","",B23)))
A31: Ф.И.О. | C31: =IF(AND(B30="",B23="",B31=""),"",CONCATENATE(IF(B30="","",B30)," ",IF(B23="","",B23)," ",IF(B31="","",B31)))
A32: Должность
A33: Ф.И.О.
A34: Приказ
A35: Проект
A36: Организация
A37: Реквизиты
A38: адрес
A39: Город
A40: №
...

Sheet  Журнал АВК
J1: Приложение 2
B10: ЖУРНАЛ №
C20: =IF('Данные объект'!B3="","",'Данные объект'!B3)
C21: =IF('Данные объект'!B5="","",'Данные объект'!B5)
C22: =IF('Данные объект'!B11="","",'Данные объект'!B11)
I27: =IF('Данные объект'!B6="","",'Данные объект'!B6)
I28: =IF('Данные объект'!B7="","",'Данные объект'!B7)
A34: № п.п. | B34: Дата поставки | C34: Наименование деталей, материалов, изделий, конструкций, оборудования | D34: Количество | E34: Поставщик | F34: Наименование и номер документа изготовителя | G34: Результат проверки сопроводительных документов изготовителя и визуального осмотра на соответствие требованиям утвержденной проектной документации и соответствующим документам по стандартизации | H34: Решение о необходимости проведения инструментального контроля | I34: Результат инструментального контроля | J34: Подпись лица, осуществляющего контроль со стороны лица, осуществляющего строительство, и застройщика (технического заказчика)
A35: 1 | B35: 2 | C35: 3 | D35: 4 | E35: 5 | F35: 6 | G35: 7 | H35: 8 | I35: 9 | J35: 10
A36: 1
A37: 2
A38: 3
A39: 4
A40: 5
A41: 6
A42: 7
A43: 8
A44: 9
A45: 10
A46: 11
A47: 12
... A86: 51

Sheet КТП
K1: Приложение 1
F5: ФОРМА
I6: ГОДЕН
I7: (результат контроля продукции)
A8: Объект строительства:
A9: ='Провод СИП 3'!A9:L9
A13: АКТ № 1/ | G13: =IF('Провод СИП 3'!G13="","",'Провод СИП 3'!G13)
A14: входного контроля
A16: =IF('Данные объект'!B5="","",'Данные объект'!B5) | K16: ='Провод СИП 3'!K16:L16
A17: (место проведения) | K17: (дата)
A19: Нами, комиссией | C19: =IF('Данные объект'!B11="","",'Данные объект'!B11) | H19: =IF('Данные объект'!B43="","",'Данные объект'!B43)
C20: (организация, от которой сформирована комиссия)
A22: Председателя: . | C22: =IF('Данные объект'!C45="","",'Данные объект'!C45)
A23: (должность, организация, фамилия, имя, отчество)
A25: и членов комиссии:
C26: =IF('Данные объект'!C47="","",'Данные объект'!C47)
A27: (должность, организация, фамилия, имя, отчество)
C28: =IF('Данные объект'!C49="","",'Данные объект'!C49)
A29: (должность, организация, фамилия, имя, отчество)
C30: =IF('Данные объект'!B32="","",'Данные объект'!B32)
A31: (должность, организация, фамилия, имя, отчество)
A32: руководствуясь, | C32: =IF('Данные объект'!B51="","",'Данные объект'!B51)
A33: (документ, устанавливающий требевания по организации и проведению входного контроля продукции)
A34: составила настоящий акт о выполненном входном контроле продукции для строительства.
A36: 1. К входному контролю представлена следующая продукция:
A37: Комплектная трансформаторная подстанция КТП-ТК/ВК-250/10/0,4
A38: (наименование продукции)
A39: 1.1. Наименование, номер документа, удостоверяющего качество и НТД на продукцию:
K40: (изготовитель,
H41: НТД
A42: № документа и дата, № партии, дата изготовления) (ГОСТ, ТУ, чертеж КМД)
A43: 1.2. Кол-во: | C43: 1 комп. | E43: Кол-во партии: | G43: 1 комп.
A44: (штуки, объем, вес в ед. изм.) (штуки, объем, вес в ед. изм.)
A45: 1.3. Поставщик: | C45: =IF(K39="","",K39) | F45: Договор
A46: (наименование организации) (реквизиты договора на поставку)
A47: 2. Подготовка продукции к контролю по НТД: | F47: выполнена
A48: (выполнена/не выполнена)
A49: 3. При входном контроле проведены следующие контрольные мероприятия:
A51: Количество, масса, объем проверенной продукции (в ед. изм.) | E51: Вид контроля (НТД) и дата сдачи образцов (проб) на контроль | G51: Приборы контроля | I51: № прибора и дата поверки прибора | K51: № и дата протокола контроля | L51: Заключение по контролю (годен/не годен)
A53: Визуальным осмотром | C53: Инструментальными и приборными методами
...

Sheet ТМГ
K1: Приложение 1
F5: ФОРМА
I6: ГОДЕН
I7: (результат контроля продукции)
A8: Объект строительства:
A9: ='Провод СИП 3'!A9:L9
A13: АКТ № 2/ | G13: =IF('Провод СИП 3'!G13="","",'Провод СИП 3'!G13)
A14: входного контроля
A16: =IF('Данные объект'!B5="","",'Данные объект'!B5) | K16: ='Провод СИП 3'!K16:L16
A17: (место проведения) | K17: (дата)
A19: Нами, комиссией | C19: =IF('Данные объект'!B11="","",'Данные объект'!B11) | H19: =IF('Данные объект'!B43="","",'Данные объект'!B43)
C20: (организация, от которой сформирована комиссия)
A22: Председателя: . | C22: =IF('Данные объект'!C45="","",'Данные объект'!C45)
A23: (должность, организация, фамилия, имя, отчество)
A25: и членов комиссии:
C26: =IF('Данные объект'!C47="","",'Данные объект'!C47)
A27: (должность, организация, фамилия, имя, отчество)
C28: =IF('Данные объект'!C49="","",'Данные объект'!C49)
A29: (должность, организация, фамилия, имя, отчество)
C30: =IF('Данные объект'!B32="","",'Данные объект'!B32)
A31: (должность, организация, фамилия, имя, отчество)
A32: руководствуясь, | C32: =IF('Данные объект'!B51="","",'Данные объект'!B51)
A33: (документ, устанавливающий требевания по организации и проведению входного контроля продукции)
A34: составила настоящий акт о выполненном входном контроле продукции для строительства.
A36: 1. К входному контролю представлена следующая продукция:
A37: Трансформатор ТМГ-250/10-0,4УХЛ1
A38: (наименование продукции)
A39: 1.1. Наименование, номер документа, удостоверяющего качество и НТД на продукцию: | K39: ТОО "Уральский трансформаторный завод"
K40: (изготовитель,
H41: НТД | I41: ГОСТ 11677-85
A42: № документа и дата, № партии, дата изготовления) (ГОСТ, ТУ, чертеж КМД)
A43: 1.2. Кол-во: | E43: Кол-во партии:
A44: (штуки, объем, вес в ед. изм.) (штуки, объем, вес в ед. изм.)
A45: 1.3. Поставщик: | F45: Договор
A46: (наименование организации) (реквизиты договора на поставку)
A47: 2. Подготовка продукции к контролю по НТД: | F47: выполнена
A48: (выполнена/не выполнена)
A49: 3. При входном контроле проведены следующие контрольные мероприятия:
A51: Количество, масса, объем проверенной продукции (в ед. изм.) | E51: Вид контроля (НТД) и дата сдачи образцов (проб) на контроль | G51: Приборы контроля | I51: № прибора и дата поверки прибора | K51: № и дата протокола контроля | L51: Заключение по контролю (годен/не годен)
A53: Визуальным осмотром | C53: Инструментальными и приборными методами
...

Sheet РЛК
K1: Приложение 1
F5: ФОРМА
I6: ГОДЕН
I7: (результат контроля продукции)
A8: Объект строительства:
A9: ='Провод СИП 3'!A9:L9
A13: АКТ №0/ | G13: =IF('Провод СИП 3'!G13="","",'Провод СИП 3'!G13)
A14: входного контроля
A16: =IF('Провод СИП 3'!A16="","",'Провод СИП 3'!A16) | K16: ='Провод СИП 3'!K16:L16
A17: (место проведения) | K17: (дата)
A19: Нами, комиссией | C19: =IF('Данные объект'!B11="","",'Данные объект'!B11) | H19: =IF('Данные объект'!B43="","",'Данные объект'!B43)
C20: (организация, от которой сформирована комиссия)
A22: Председателя: . | C22: =IF('Данные объект'!C45="","",'Данные объект'!C45)
A23: (должность, организация, фамилия, имя, отчество)
A25: и членов комиссии:
C26: =IF('Данные объект'!C47="","",'Данные объект'!C47)
A27: (должность, организация, фамилия, имя, отчество)
C28: =IF('Данные объект'!C49="","",'Данные объект'!C49)
A29: (должность, организация, фамилия, имя, отчество)
C30: =IF('Данные объект'!B32="","",'Данные объект'!B32)
A31: (должность, организация, фамилия, имя, отчество)
A32: руководствуясь, | C32: =IF('Данные объект'!B51="","",'Данные объект'!B51)
A33: (документ, устанавливающий требевания по организации и проведению входного контроля продукции)
A34: составила настоящий акт о выполненном входном контроле продукции для строительства.
A36: 1. К входному контролю представлена следующая продукция:
A37: Разъединитель трехполюсный с приводом РЛК 10/400
A38: (наименование продукции)
A39: 1.1. Наименование, номер документа, удостоверяющего качество и НТД на продукцию:
K40: (изготовитель,
H41: НТД | I41: ГОСТ Р 52726-2007
A42: № документа и дата, № партии, дата изготовления) (ГОСТ, ТУ, чертеж КМД)
A43: 1.2. Кол-во: | E43: Кол-во партии:
A44: (штуки, объем, вес в ед. изм.) (штуки, объем, вес в ед. изм.)
A45: 1.3. Поставщик: | C45: ООО ТК "Норма-кабель" | F45: Договор
A46: (наименование организации) (реквизиты договора на поставку)
A47: 2. Подготовка продукции к контролю по НТД: | F47: выполнена
A48: (выполнена/не выполнена)
A49: 3. При входном контроле проведены следующие контрольные мероприятия:
A51: Количество, масса, объем проверенной продукции (в ед. изм.) | E51: Вид контроля (НТД) и дата сдачи образцов (проб) на контроль | G51: Приборы контроля | I51: № прибора и дата поверки прибора | K51: № и дата протокола контроля | L51: Заключение по контролю (годен/не годен)
A53: Визуальным осмотром | C53: Инструментальными и приборными методами
...

Sheet ПРВТ
K1: Приложение 1
F5: ФОРМА
I6: ГОДЕН
I7: (результат контроля продукции)
A8: Объект строительства:
A9: ='Провод СИП 3'!A9:L9
A13: АКТ № 3/ | G13: =IF('Провод СИП 3'!G13="","",'Провод СИП 3'!G13)
A14: входного контроля
A16: =IF('Провод СИП 3'!A16="","",'Провод СИП 3'!A16) | K16: ='Провод СИП 3'!K16:L16
A17: (место проведения) | K17: (дата)
A19: Нами, комиссией | C19: =IF('Данные объект'!B11="","",'Данные объект'!B11) | H19: =IF('Данные объект'!B43="","",'Данные объект'!B43)
C20: (организация, от которой сформирована комиссия)
A22: Председателя: . | C22: =IF('Данные объект'!C45="","",'Данные объект'!C45)
A23: (должность, организация, фамилия, имя, отчество)
A25: и членов комиссии:
C26: =IF('Данные объект'!C47="","",'Данные объект'!C47)
A27: (должность, организация, фамилия, имя, отчество)
C28: =IF('Данные объект'!C49="","",'Данные объект'!C49)
A29: (должность, организация, фамилия, имя, отчество)
C30: =IF('Данные объект'!B32="","",'Данные объект'!B32)
A31: (должность, организация, фамилия, имя, отчество)
A32: руководствуясь, | C32: =IF('Данные объект'!B51="","",'Данные объект'!B51)
A33: (документ, устанавливающий требевания по организации и проведению входного контроля продукции)
A34: составила настоящий акт о выполненном входном контроле продукции для строительства.
A36: 1. К входному контролю представлена следующая продукция:
A37: Предохранитель-разъеденитель выхлопной ПРВТ-1-10.II-50Л-У1
A38: (наименование продукции)
A39: 1.1. Наименование, номер документа, удостоверяющего качество и НТД на продукцию: | K39: ОАО "ЗЭТО"
K40: (изготовитель,
H41: НТД
A42: № документа и дата, № партии, дата изготовления) (ГОСТ, ТУ, чертеж КМД)
A43: 1.2. Кол-во: | E43: Кол-во партии:
A44: (штуки, объем, вес в ед. изм.) (штуки, объем, вес в ед. изм.)
A45: 1.3. Поставщик: | C45: ООО ТК "Норма-кабель" | F45: Договор
A46: (наименование организации) (реквизиты договора на поставку)
A47: 2. Подготовка продукции к контролю по НТД: | F47: выполнена
A48: (выполнена/не выполнена)
A49: 3. При входном контроле проведены следующие контрольные мероприятия:
A51: Количество, масса, объем проверенной продукции (в ед. изм.) | E51: Вид контроля (НТД) и дата сдачи образцов (проб) на контроль | G51: Приборы контроля | I51: № прибора и дата поверки прибора | K51: № и дата протокола контроля | L51: Заключение по контролю (годен/не годен)
A53: Визуальным осмотром | C53: Инструментальными и приборными методами
...

Sheet счетчик СТЭМ
K1: Приложение 1
F5: ФОРМА
I6: ГОДЕН
I7: (результат контроля продукции)
A8: Объект строительства:
A9: =IF('Данные объект'!B3="","",'Данные объект'!B3)
A13: АКТ № 4/ | G13: =IF('Данные объект'!B2="","",'Данные объект'!B2)
A14: входного контроля
A16: =IF('Данные объект'!B5="","",'Данные объект'!B5) | K16: =IF('Данные объект'!B6="","",'Данные объект'!B6)
A17: (место проведения) | K17: (дата)
A19: Нами, комиссией | C19: =IF('Данные объект'!B11="","",'Данные объект'!B11) | H19: =IF('Данные объект'!B43="","",'Данные объект'!B43)
C20: (организация, от которой сформирована комиссия)
A22: Председателя: . | C22: =IF('Данные объект'!C45="","",'Данные объект'!C45)
A23: (должность, организация, фамилия, имя, отчество)
A25: и членов комиссии:
C26: =IF('Данные объект'!C47="","",'Данные объект'!C47)
A27: (должность, организация, фамилия, имя, отчество)
C28: =IF('Данные объект'!C49="","",'Данные объект'!C49)
A29: (должность, организация, фамилия, имя, отчество)
C30: =IF('Данные объект'!B32="","",'Данные объект'!B32)
A31: (должность, организация, фамилия, имя, отчество)
A32: руководствуясь, | C32: =IF('Данные объект'!B51="","",'Данные объект'!B51)
A33: (документ, устанавливающий требевания по организации и проведению входного контроля продукции)
A34: составила настоящий акт о выполненном входном контроле продукции для строительства.
A36: 1. К входному контролю представлена следующая продукция:
A37: Счетчик электрической энергии СТЭМ 300
A38: (наименование продукции)
A39: 1.1. Наименование, номер документа, удостоверяющего качество и НТД на продукцию:
K40: (изготовитель,
H41: НТД | I41: ТР ТС 004/2011, ТР ТС 020/2011
A42: № документа и дата, № партии, дата изготовления) (ГОСТ, ТУ, чертеж КМД)
A43: 1.2. Кол-во: | E43: Кол-во партии: | G43: =IF(C43="","",C43)
A44: (штуки, объем, вес в ед. изм.) (штуки, объем, вес в ед. изм.)
A45: 1.3. Поставщик: | C45: ООО ТК "Норма-кабель" | F45: Договор
A46: (наименование организации) (реквизиты договора на поставку)
A47: 2. Подготовка продукции к контролю по НТД: | F47: выполнена
A48: (выполнена/не выполнена)
A49: 3. При входном контроле проведены следующие контрольные мероприятия:
A51: Количество, масса, объем проверенной продукции (в ед. изм.) | E51: Вид контроля (НТД) и дата сдачи образцов (проб) на контроль | G51: Приборы контроля | I51: № прибора и дата поверки прибора | K51: № и дата протокола контроля | L51: Заключение по контролю (годен/не годен)
A53: Визуальным осмотром | C53: Инструментальными и приборными методами
...

Sheet выключатели ВА
K1: Приложение 1
F5: ФОРМА
I6: ГОДЕН
I7: (результат контроля продукции)
A8: Объект строительства:
A9: ='Провод СИП 3'!A9:L9
A13: АКТ № 5/ | G13: =IF('Провод СИП 3'!G13="","",'Провод СИП 3'!G13)
A14: входного контроля
A16: =IF('Провод СИП 3'!A16="","",'Провод СИП 3'!A16) | K16: ='Провод СИП 3'!K16:L16
A17: (место проведения) | K17: (дата)
A19: Нами, комиссией | C19: =IF('Данные объект'!B11="","",'Данные объект'!B11) | H19: =IF('Данные объект'!B43="","",'Данные объект'!B43)
C20: (организация, от которой сформирована комиссия)
A22: Председателя: . | C22: =IF('Данные объект'!C45="","",'Данные объект'!C45)
A23: (должность, организация, фамилия, имя, отчество)
A25: и членов комиссии:
C26: =IF('Данные объект'!C47="","",'Данные объект'!C47)
A27: (должность, организация, фамилия, имя, отчество)
C28: =IF('Данные объект'!C49="","",'Данные объект'!C49)
A29: (должность, организация, фамилия, имя, отчество)
C30: =IF('Данные объект'!B32="","",'Данные объект'!B32)
A31: (должность, организация, фамилия, имя, отчество)
A32: руководствуясь, | C32: =IF('Данные объект'!B51="","",'Данные объект'!B51)
A33: (документ, устанавливающий требевания по организации и проведению входного контроля продукции)
A34: составила настоящий акт о выполненном входном контроле продукции для строительства.
A36: 1. К входному контролю представлена следующая продукция:
A38: (наименование продукции)
A39: 1.1. Наименование, номер документа, удостоверяющего качество и НТД на продукцию:
K40: (изготовитель,
H41: НТД
A42: № документа и дата, № партии, дата изготовления) (ГОСТ, ТУ, чертеж КМД)
A43: 1.2. Кол-во: | C43: 2 | E43: Кол-во партии: | G43: =IF(C43="","",C43)
A44: (штуки, объем, вес в ед. изм.) (штуки, объем, вес в ед. изм.)
A45: 1.3. Поставщик: | C45: ООО ТК "Норма-кабель" | F45: Договор
A46: (наименование организации) (реквизиты договора на поставку)
A47: 2. Подготовка продукции к контролю по НТД: | F47: выполнена
A48: (выполнена/не выполнена)
A49: 3. При входном контроле проведены следующие контрольные мероприятия:
A51: Количество, масса, объем проверенной продукции (в ед. изм.) | E51: Вид контроля (НТД) и дата сдачи образцов (проб) на контроль | G51: Приборы контроля | I51: № прибора и дата поверки прибора | K51: № и дата протокола контроля | L51: Заключение по контролю (годен/не годен)
A53: Визуальным осмотром | C53: Инструментальными и приборными методами
A56: 1 | C56: 2 | E56: 3 | G56: 4 | I56: 5 | K56: 6 | L56: 7
...

Sheet стойки
K1: Приложение 1
F5: ФОРМА
I6: ГОДЕН
I7: (результат контроля продукции)
A8: Объект строительства:
A9: ='Провод СИП 3'!A9:L9
A13: АКТ №6/ | G13: =IF('Провод СИП 3'!G13="","",'Провод СИП 3'!G13)
A14: входного контроля
A16: =IF('Провод СИП 3'!A16="","",'Провод СИП 3'!A16) | K16: ='Провод СИП 3'!K16:L16
A17: (место проведения) | K17: (дата)
A19: Нами, комиссией | C19: =IF('Данные объект'!B11="","",'Данные объект'!B11) | H19: =IF('Данные объект'!B43="","",'Данные объект'!B43)
C20: (организация, от которой сформирована комиссия)
A22: Председателя: . | C22: =IF('Данные объект'!C45="","",'Данные объект'!C45)
A23: (должность, организация, фамилия, имя, отчество)
A25: и членов комиссии:
C26: =IF('Данные объект'!C47="","",'Данные объект'!C47)
A27: (должность, организация, фамилия, имя, отчество)
C28: =IF('Данные объект'!C49="","",'Данные объект'!C49)
A29: (должность, организация, фамилия, имя, отчество)
C30: =IF('Данные объект'!B32="","",'Данные объект'!B32)
A31: (должность, организация, фамилия, имя, отчество)
A32: руководствуясь, | C32: =IF('Данные объект'!B51="","",'Данные объект'!B51)
A33: (документ, устанавливающий требевания по организации и проведению входного контроля продукции)
A34: составила настоящий акт о выполненном входном контроле продукции для строительства.
A36: 1. К входному контролю представлена следующая продукция:
A37: Ж/б опоры СВ110-5
A38: (наименование продукции)
A39: 1.1. Наименование, номер документа, удостоверяющего качество и НТД на продукцию:
K40: (изготовитель,
H41: НТД
A42: № документа и дата, № партии, дата изготовления) (ГОСТ, ТУ, чертеж КМД)
A43: 1.2. Кол-во: | E43: Кол-во партии:
A44: (штуки, объем, вес в ед. изм.) (штуки, объем, вес в ед. изм.)
A45: 1.3. Поставщик: | C45: ООО ТК "Норма-кабель" | F45: Договор
A46: (наименование организации) (реквизиты договора на поставку)
A47: 2. Подготовка продукции к контролю по НТД: | F47: выполнена
A48: (выполнена/не выполнена)
A49: 3. При входном контроле проведены следующие контрольные мероприятия:
A51: Количество, масса, объем проверенной продукции (в ед. изм.) | E51: Вид контроля (НТД) и дата сдачи образцов (проб) на контроль | G51: Приборы контроля | I51: № прибора и дата поверки прибора | K51: № и дата протокола контроля | L51: Заключение по контролю (годен/не годен)
A53: Визуальным осмотром | C53: Инструментальными и приборными методами
...

Sheet лин.армат 6-10к
K1: Приложение 1
F5: ФОРМА
I6: ГОДЕН
I7: (результат контроля продукции)
A8: Объект строительства:
A9: ='Провод СИП 3'!A9:L9
A13: АКТ № 7/ | G13: =IF('Провод СИП 3'!G13="","",'Провод СИП 3'!G13)
A14: входного контроля
A16: =IF('Данные объект'!B5="","",'Данные объект'!B5) | K16: ='Провод СИП 3'!K16:L16
A17: (место проведения) | K17: (дата)
A19: Нами, комиссией | C19: =IF('Данные объект'!B11="","",'Данные объект'!B11) | H19: =IF('Данные объект'!B43="","",'Данные объект'!B43)
C20: (организация, от которой сформирована комиссия)
A22: Председателя: . | C22: =IF('Данные объект'!C45="","",'Данные объект'!C45)
A23: (должность, организация, фамилия, имя, отчество)
A25: и членов комиссии:
C26: =IF('Данные объект'!C47="","",'Данные объект'!C47)
A27: (должность, организация, фамилия, имя, отчество)
C28: =IF('Данные объект'!C49="","",'Данные объект'!C49)
A29: (должность, организация, фамилия, имя, отчество)
C30: =IF('Данные объект'!B32="","",'Данные объект'!B32)
A31: (должность, организация, фамилия, имя, отчество)
A32: руководствуясь, | C32: =IF('Данные объект'!B51="","",'Данные объект'!B51)
A33: (документ, устанавливающий требевания по организации и проведению входного контроля продукции)
A34: составила настоящий акт о выполненном входном контроле продукции для строительства.
A36: 1. К входному контролю представлена следующая продукция:
A37: Линейная арматура 10кВ (Траверса ТМ74, ТМ73, Зажим SLW.36, Изолятор штырьевой IF27, Колпачок К-9, Заземляющий проводник ЗП1-1, Плашечный зажим CD35, Зажим ответвительный RP150, Хомут Х51, Вязка спиральная СВ70, Траверса ТМ63, Плашечный зажим CD70, Металлическая лента F207, Скрепа NC20)
A38: (наименование продукции)
A39: 1.1. Наименование, номер документа, удостоверяющего качество и НТД на продукцию:
K40: (изготовитель,
H41: НТД
A42: № документа и дата, № партии, дата изготовления) (ГОСТ, ТУ, чертеж КМД)
A43: 1.2. Кол-во: | E43: Кол-во партии: | G43: =IF(C43="","",C43)
A44: (штуки, объем, вес в ед. изм.) (штуки, объем, вес в ед. изм.)
A45: 1.3. Поставщик: | C45: ООО ТК "Норма-кабель" | F45: Договор
A46: (наименование организации) (реквизиты договора на поставку)
A47: 2. Подготовка продукции к контролю по НТД: | F47: выполнена
A48: (выполнена/не выполнена)
A49: 3. При входном контроле проведены следующие контрольные мероприятия:
A51: Количество, масса, объем проверенной продукции (в ед. изм.) | E51: Вид контроля (НТД) и дата сдачи образцов (проб) на контроль | G51: Приборы контроля | I51: № прибора и дата поверки прибора | K51: № и дата протокола контроля | L51: Заключение по контролю (годен/не годен)
A53: Визуальным осмотром | C53: Инструментальными и приборными методами
...

Sheet лин.армат 0,4
K1: Приложение 1
F5: ФОРМА
I6: ГОДЕН
I7: (результат контроля продукции)
A8: Объект строительства:
A9: ='Провод СИП 3'!A9:L9
A13: АКТ №14/ | G13: =IF('Провод СИП 3'!G13="","",'Провод СИП 3'!G13)
A14: входного контроля
A16: =IF('Данные объект'!B5="","",'Данные объект'!B5) | K16: ='Провод СИП 3'!K16:L16
A17: (место проведения) | K17: (дата)
A19: Нами, комиссией | C19: =IF('Данные объект'!B11="","",'Данные объект'!B11) | H19: =IF('Данные объект'!B43="","",'Данные объект'!B43)
C20: (организация, от которой сформирована комиссия)
A22: Председателя: . | C22: =IF('Данные объект'!C45="","",'Данные объект'!C45)
A23: (должность, организация, фамилия, имя, отчество)
A25: и членов комиссии:
C26: =IF('Данные объект'!C47="","",'Данные объект'!C47)
A27: (должность, организация, фамилия, имя, отчество)
C28: =IF('Данные объект'!C49="","",'Данные объект'!C49)
A29: (должность, организация, фамилия, имя, отчество)
C30: =IF('Данные объект'!B32="","",'Данные объект'!B32)
A31: (должность, организация, фамилия, имя, отчество)
A32: руководствуясь, | C32: =IF('Данные объект'!B51="","",'Данные объект'!B51)
A33: (документ, устанавливающий требевания по организации и проведению входного контроля продукции)
A34: составила настоящий акт о выполненном входном контроле продукции для строительства.
A36: 1. К входному контролю представлена следующая продукция:
A37: Линейная арматура 0,4кВ (Заземляющий проводник ЗП6, Зажим Р72, Ответвительный зажим Р70, Натяжной зажим РА1500, Плашечный зажим ПС-2-1, Анкерный кронштейн CS10.3, Комплект промежуточной подвески ES1500, Стяжной хомут Е778, Мателлическая летна F207, Скрепа NC20, Бугель NB20, Герметичный зажим РС481, Ограничитель перенапряжения ОР600/28, Колпачек изолирующий СЕ16-150)
A38: (наименование продукции)
A39: 1.1. Наименование, номер документа, удостоверяющего качество и НТД на продукцию:
K40: (изготовитель,
H41: НТД
A43: 1.2. Кол-во: | E43: Кол-во партии: | G43: =IF(C43="","",C43)
A44: (штуки, объем, вес в ед. изм.) (штуки, объем, вес в ед. изм.)
A45: 1.3. Поставщик: | C45: ООО ТК "Норма-кабель" | F45: Договор
A46: (наименование организации) (реквизиты договора на поставку)
A47: 2. Подготовка продукции к контролю по НТД: | F47: выполнена
A48: (выполнена/не выполнена)
A49: 3. При входном контроле проведены следующие контрольные мероприятия:
A51: Количество, масса, объем проверенной продукции (в ед. изм.) | E51: Вид контроля (НТД) и дата сдачи образцов (проб) на контроль | G51: Приборы контроля | I51: № прибора и дата поверки прибора | K51: № и дата протокола контроля | L51: Заключение по контролю (годен/не годен)
A53: Визуальным осмотром | C53: Инструментальными и приборными методами
A56: 1 | C56: 2 | E56: 3 | G56: 4 | I56: 5 | K56: 6 | L56: 7
...

Sheet ВРЩ
K1: Приложение 1
F5: ФОРМА
I6: ГОДЕН
I7: (результат контроля продукции)
A8: Объект строительства:
A9: ='Провод СИП 3'!A9:L9
A13: АКТ № 3/ | G13: =IF('Провод СИП 3'!G13="","",'Провод СИП 3'!G13)
A14: входного контроля
A16: =IF('Провод СИП 3'!A16="","",'Провод СИП 3'!A16) | K16: ='Провод СИП 3'!K16:L16
A17: (место проведения) | K17: (дата)
A19: Нами, комиссией | C19: ='Провод СИП 3'!C19:G19 | H19: =IF('Данные объект'!B43="","",'Данные объект'!B43)
C20: (организация, от которой сформирована комиссия)
A22: Председателя: . | C22: =IF('Данные объект'!C45="","",'Данные объект'!C45)
A23: (должность, организация, фамилия, имя, отчество)
A25: и членов комиссии:
C26: =IF('Данные объект'!C47="","",'Данные объект'!C47)
A27: (должность, организация, фамилия, имя, отчество)
C28: =IF('Данные объект'!C49="","",'Данные объект'!C49)
A29: (должность, организация, фамилия, имя, отчество)
C30: =IF('Данные объект'!B32="","",'Данные объект'!B32)
A31: (должность, организация, фамилия, имя, отчество)
A32: руководствуясь, | C32: =IF('Данные объект'!B51="","",'Данные объект'!B51)
A33: (документ, устанавливающий требевания по организации и проведению входного контроля продукции)
A34: составила настоящий акт о выполненном входном контроле продукции для строительства.
A36: 1. К входному контролю представлена следующая продукция:
A37: ВРЩ-0,4кВ
A38: (наименование продукции)
A39: 1.1. Наименование, номер документа, удостоверяющего качество и НТД на продукцию:
K40: (изготовитель,
H41: НТД
A42: № документа и дата, № партии, дата изготовления) (ГОСТ, ТУ, чертеж КМД)
A43: 1.2. Кол-во: | E43: Кол-во партии: | G43: =IF(C43="","",C43)
A44: (штуки, объем, вес в ед. изм.) (штуки, объем, вес в ед. изм.)
A45: 1.3. Поставщик: | F45: Договор | G45: №Т1/22-238
A46: (наименование организации) (реквизиты договора на поставку)
A47: 2. Подготовка продукции к контролю по НТД: | F47: выполнена
A48: (выполнена/не выполнена)
A49: 3. При входном контроле проведены следующие контрольные мероприятия:
A51: Количество, масса, объем проверенной продукции (в ед. изм.) | E51: Вид контроля (НТД) и дата сдачи образцов (проб) на контроль | G51: Приборы контроля | I51: № прибора и дата поверки прибора | K51: № и дата протокола контроля | L51: Заключение по контролю (годен/не годен)
A53: Визуальным осмотром | C53: Инструментальными и приборными методами
...

Sheet изоляторы
K1: Приложение 1
F5: ФОРМА
I6: ГОДЕН
I7: (результат контроля продукции)
A8: Объект строительства:
A9: ='Провод СИП 3'!A9:L9
A13: АКТ № 0/ | G13: =IF('Провод СИП 3'!G13="","",'Провод СИП 3'!G13)
A14: входного контроля
A16: =IF('Провод СИП 3'!A16="","",'Провод СИП 3'!A16) | K16: ='Провод СИП 3'!K16:L16
A17: (место проведения) | K17: (дата)
A19: Нами, комиссией | C19: ='Провод СИП 3'!C19:G19 | H19: =IF('Данные объект'!B43="","",'Данные объект'!B43)
C20: (организация, от которой сформирована комиссия)
A22: Председателя: . | C22: =IF('Данные объект'!C45="","",'Данные объект'!C45)
A23: (должность, организация, фамилия, имя, отчество)
A25: и членов комиссии:
C26: =IF('Данные объект'!C47="","",'Данные объект'!C47)
A27: (должность, организация, фамилия, имя, отчество)
C28: =IF('Данные объект'!C49="","",'Данные объект'!C49)
A29: (должность, организация, фамилия, имя, отчество)
C30: =IF('Данные объект'!B32="","",'Данные объект'!B32)
A31: (должность, организация, фамилия, имя, отчество)
A33: (должность, организация, фамилия, имя, отчество)
A34: руководствуясь, | C34: =IF('Данные объект'!B51="","",'Данные объект'!B51)
A35: (документ, устанавливающий требевания по организации и проведению входного контроля продукции)
A36: составила настоящий акт о выполненном входном контроле продукции для строительства.
A38: 1. К входному контролю представлена следующая продукция:
A39: Изолятор штырьевой ШФ20-Г
A40: (наименование продукции)
A41: 1.1. Наименование, номер документа, удостоверяющего качество и НТД на продукцию:
K42: (изготовитель,
H43: НТД | I43: ГОСТ 1232-2017
A44: № документа и дата, № партии, дата изготовления) (ГОСТ, ТУ, чертеж КМД)
A45: 1.2. Кол-во: | E45: Кол-во партии:
A46: (штуки, объем, вес в ед. изм.) (штуки, объем, вес в ед. изм.)
A47: 1.3. Поставщик: | C47: ООО ТК "Норма-кабель" | F47: Договор
A48: (наименование организации) (реквизиты договора на поставку)
A49: 2. Подготовка продукции к контролю по НТД: | F49: выполнена
A50: (выполнена/не выполнена)
A51: 3. При входном контроле проведены следующие контрольные мероприятия:
A53: Количество, масса, объем проверенной продукции (в ед. изм.) | E53: Вид контроля (НТД) и дата сдачи образцов (проб) на контроль | G53: Приборы контроля | I53: № прибора и дата поверки прибора | K53: № и дата протокола контроля | L53: Заключение по контролю (годен/не годен)
...

Sheet  муфты 
K1: Приложение 1
F5: ФОРМА
I6: ГОДЕН
I7: (результат контроля продукции)
A8: Объект строительства:
A9: =IF('Данные объект'!B3="","",'Данные объект'!B3)
A13: АКТ № 8/ | G13: =IF('Данные объект'!B2="","",'Данные объект'!B2)
A14: входного контроля
A16: =IF('Данные объект'!B5="","",'Данные объект'!B5) | K16: =IF('Данные объект'!B6="","",'Данные объект'!B6)
A17: (место проведения) | K17: (дата)
A19: Нами, комиссией | C19: ='Провод СИП 3'!C19:G19 | H19: =IF('Данные объект'!B43="","",'Данные объект'!B43)
C20: (организация, от которой сформирована комиссия)
A22: Председателя: . | C22: =IF('Данные объект'!C45="","",'Данные объект'!C45)
A23: (должность, организация, фамилия, имя, отчество)
A25: и членов комиссии:
C26: =IF('Данные объект'!C47="","",'Данные объект'!C47)
A27: (должность, организация, фамилия, имя, отчество)
C28: =IF('Данные объект'!C49="","",'Данные объект'!C49)
A29: (должность, организация, фамилия, имя, отчество)
C30: =IF('Данные объект'!B32="","",'Данные объект'!B32)
A31: (должность, организация, фамилия, имя, отчество)
A32: руководствуясь, | C32: =IF('Данные объект'!B51="","",'Данные объект'!B51)
A33: (документ, устанавливающий требевания по организации и проведению входного контроля продукции)
A34: составила настоящий акт о выполненном входном контроле продукции для строительства.
A36: 1. К входному контролю представлена следующая продукция:
A37: Муфта концевая термоусаживаемая 3 КВНТп-1 70/120
A38: (наименование продукции)
A39: 1.1. Наименование, номер документа, удостоверяющего качество и НТД на продукцию:
K40: (изготовитель,
H41: НТД | I41: ГОСТ 34839-2022
A42: № документа и дата, № партии, дата изготовления) (ГОСТ, ТУ, чертеж КМД)
A43: 1.2. Кол-во: | E43: Кол-во партии: | G43: =IF(C43="","",C43)
A44: (штуки, объем, вес в ед. изм.) (штуки, объем, вес в ед. изм.)
A45: 1.3. Поставщик: | F45: Договор
A46: (наименование организации) (реквизиты договора на поставку)
A47: 2. Подготовка продукции к контролю по НТД: | F47: выполнена
A48: (выполнена/не выполнена)
A49: 3. При входном контроле проведены следующие контрольные мероприятия:
A51: Количество, масса, объем проверенной продукции (в ед. изм.) | E51: Вид контроля (НТД) и дата сдачи образцов (проб) на контроль | G51: Приборы контроля | I51: № прибора и дата поверки прибора | K51: № и дата протокола контроля | L51: Заключение по контролю (годен/не годен)
A53: Визуальным осмотром | C53: Инструментальными и приборными методами
...

Sheet ПКТ
K1: Приложение 1
F5: ФОРМА
I6: ГОДЕН
I7: (результат контроля продукции)
A8: Объект строительства:
A9: ='Провод СИП 3'!A9:L9
A13: АКТ № 0/ | G13: =IF('Провод СИП 3'!G13="","",'Провод СИП 3'!G13)
A14: входного контроля
A16: =IF('Провод СИП 3'!A16="","",'Провод СИП 3'!A16) | K16: ='Провод СИП 3'!K16:L16
A17: (место проведения) | K17: (дата)
A19: Нами, комиссией | C19: ='Провод СИП 3'!C19:G19 | H19: =IF('Данные объект'!B43="","",'Данные объект'!B43)
C20: (организация, от которой сформирована комиссия)
A22: Председателя: . | C22: =IF('Данные объект'!C45="","",'Данные объект'!C45)
A23: (должность, организация, фамилия, имя, отчество)
A25: и членов комиссии:
C26: =IF('Данные объект'!C47="","",'Данные объект'!C47)
A27: (должность, организация, фамилия, имя, отчество)
C28: =IF('Данные объект'!C49="","",'Данные объект'!C49)
A29: (должность, организация, фамилия, имя, отчество)
C30: =IF('Данные объект'!B32="","",'Данные объект'!B32)
A31: (должность, организация, фамилия, имя, отчество)
A32: руководствуясь, | C32: =IF('Данные объект'!B51="","",'Данные объект'!B51)
A33: (документ, устанавливающий требевания по организации и проведению входного контроля продукции)
A34: составила настоящий акт о выполненном входном контроле продукции для строительства.
A36: 1. К входному контролю представлена следующая продукция:
A37: Предохранитель высоковольтный с кварцевым наполнителем 3ПКТ-103-6-100А-31,5УЗ
A38: (наименование продукции)
A39: 1.1. Наименование, номер документа, удостоверяющего качество и НТД на продукцию:
K40: (изготовитель,
H41: НТД
A42: № документа и дата, № партии, дата изготовления) (ГОСТ, ТУ, чертеж КМД)
A43: 1.2. Кол-во: | E43: Кол-во партии: | G43: =IF(C43="","",C43)
A44: (штуки, объем, вес в ед. изм.) (штуки, объем, вес в ед. изм.)
A45: 1.3. Поставщик: | C45: ООО ТК "Норма-кабель" | F45: Договор
A46: (наименование организации) (реквизиты договора на поставку)
A47: 2. Подготовка продукции к контролю по НТД: | F47: выполнена
A48: (выполнена/не выполнена)
A49: 3. При входном контроле проведены следующие контрольные мероприятия:
A51: Количество, масса, объем проверенной продукции (в ед. изм.) | E51: Вид контроля (НТД) и дата сдачи образцов (проб) на контроль | G51: Приборы контроля | I51: № прибора и дата поверки прибора | K51: № и дата протокола контроля | L51: Заключение по контролю (годен/не годен)
A53: Визуальным осмотром | C53: Инструментальными и приборными методами
...

Sheet ТТ Т-0,66
K1: Приложение 1
F5: ФОРМА
I6: ГОДЕН
I7: (результат контроля продукции)
A8: Объект строительства:
A9: ='Провод СИП 3'!A9:L9
A13: АКТ № 0/ | G13: =IF('Провод СИП 3'!G13="","",'Провод СИП 3'!G13)
A14: входного контроля
A16: =IF('Провод СИП 3'!A16="","",'Провод СИП 3'!A16) | K16: ='Провод СИП 3'!K16:L16
A17: (место проведения) | K17: (дата)
A19: Нами, комиссией | C19: ='Провод СИП 3'!C19:G19 | H19: =IF('Данные объект'!B43="","",'Данные объект'!B43)
C20: (организация, от которой сформирована комиссия)
A22: Председателя: . | C22: =IF('Данные объект'!C45="","",'Данные объект'!C45)
A23: (должность, организация, фамилия, имя, отчество)
A25: и членов комиссии:
C26: =IF('Данные объект'!C47="","",'Данные объект'!C47)
A27: (должность, организация, фамилия, имя, отчество)
C28: =IF('Данные объект'!C49="","",'Данные объект'!C49)
A29: (должность, организация, фамилия, имя, отчество)
C30: =IF('Данные объект'!B32="","",'Данные объект'!B32)
A31: (должность, организация, фамилия, имя, отчество)
A32: руководствуясь, | C32: =IF('Данные объект'!B51="","",'Данные объект'!B51)
A33: (документ, устанавливающий требевания по организации и проведению входного контроля продукции)
A34: составила настоящий акт о выполненном входном контроле продукции для строительства.
A36: 1. К входному контролю представлена следующая продукция:
A37: Трансформатор тока Т-0,66 400/5
A38: (наименование продукции)
A39: 1.1. Наименование, номер документа, удостоверяющего качество и НТД на продукцию: | K39: ФК ИК-1
K40: (изготовитель,
H41: НТД
A42: № документа и дата, № партии, дата изготовления) (ГОСТ, ТУ, чертеж КМД)
A43: 1.2. Кол-во: | E43: Кол-во партии: | G43: =IF(C43="","",C43)
A44: (штуки, объем, вес в ед. изм.) (штуки, объем, вес в ед. изм.)
A45: 1.3. Поставщик: | C45: ООО ТК "Норма-кабель" | F45: Договор
A46: (наименование организации) (реквизиты договора на поставку)
A47: 2. Подготовка продукции к контролю по НТД: | F47: выполнена
A48: (выполнена/не выполнена)
A49: 3. При входном контроле проведены следующие контрольные мероприятия:
A51: Количество, масса, объем проверенной продукции (в ед. изм.) | E51: Вид контроля (НТД) и дата сдачи образцов (проб) на контроль | G51: Приборы контроля | I51: № прибора и дата поверки прибора | K51: № и дата протокола контроля | L51: Заключение по контролю (годен/не годен)
A53: Визуальным осмотром | C53: Инструментальными и приборными методами
...

Sheet РМК
K1: Приложение 1
F5: ФОРМА
I6: ГОДЕН
I7: (результат контроля продукции)
A8: Объект строительства:
A9: ='Провод СИП 3'!A9:L9
A13: АКТ № 0/ | G13: =IF('Провод СИП 3'!G13="","",'Провод СИП 3'!G13)
A14: входного контроля
A16: =IF('Провод СИП 3'!A16="","",'Провод СИП 3'!A16) | K16: ='Провод СИП 3'!K16:L16
A17: (место проведения) | K17: (дата)
A19: Нами, комиссией | C19: ='Провод СИП 3'!C19:G19 | H19: =IF('Данные объект'!B43="","",'Данные объект'!B43)
C20: (организация, от которой сформирована комиссия)
A22: Председателя: . | C22: =IF('Данные объект'!C45="","",'Данные объект'!C45)
A23: (должность, организация, фамилия, имя, отчество)
A25: и членов комиссии:
C26: =IF('Данные объект'!C47="","",'Данные объект'!C47)
A27: (должность, организация, фамилия, имя, отчество)
C28: =IF('Данные объект'!C49="","",'Данные объект'!C49)
A29: (должность, организация, фамилия, имя, отчество)
C30: =IF('Данные объект'!B32="","",'Данные объект'!B32)
A31: (должность, организация, фамилия, имя, отчество)
A32: руководствуясь, | C32: =IF('Данные объект'!B51="","",'Данные объект'!B51)
A33: (документ, устанавливающий требевания по организации и проведению входного контроля продукции)
A34: составила настоящий акт о выполненном входном контроле продукции для строительства.
A36: 1. К входному контролю представлена следующая продукция:
A37: Длинно-искровой разрядник РМК
A38: (наименование продукции)
A39: 1.1. Наименование, номер документа, удостоверяющего качество и НТД на продукцию:
K40: (изготовитель,
H41: НТД
A42: № документа и дата, № партии, дата изготовления) (ГОСТ, ТУ, чертеж КМД)
A43: 1.2. Кол-во: | E43: Кол-во партии: | G43: =IF(C43="","",C43)
A44: (штуки, объем, вес в ед. изм.) (штуки, объем, вес в ед. изм.)
A45: 1.3. Поставщик: | C45: ООО ТК "Норма-кабель" | F45: Договор
A46: (наименование организации) (реквизиты договора на поставку)
A47: 2. Подготовка продукции к контролю по НТД: | F47: выполнена
A48: (выполнена/не выполнена)
A49: 3. При входном контроле проведены следующие контрольные мероприятия:
A51: Количество, масса, объем проверенной продукции (в ед. изм.) | E51: Вид контроля (НТД) и дата сдачи образцов (проб) на контроль | G51: Приборы контроля | I51: № прибора и дата поверки прибора | K51: № и дата протокола контроля | L51: Заключение по контролю (годен/не годен)
A53: Визуальным осмотром | C53: Инструментальными и приборными методами
...

Sheet КРН
K1: Приложение 1
F5: ФОРМА
I6: ГОДЕН
I7: (результат контроля продукции)
A8: Объект строительства:
A9: ='Провод СИП 3'!A9:L9
A13: АКТ № 0/ | G13: =IF('Провод СИП 3'!G13="","",'Провод СИП 3'!G13)
A14: входного контроля
A16: =IF('Провод СИП 3'!A16="","",'Провод СИП 3'!A16) | K16: ='Провод СИП 3'!K16:L16
A17: (место проведения) | K17: (дата)
A19: Нами, комиссией | C19: =IF(каб.АСБ!C19="","",каб.АСБ!C19) | H19: =IF('Данные объект'!B43="","",'Данные объект'!B43)
C20: (организация, от которой сформирована комиссия)
A22: Председателя: . | C22: =IF('Данные объект'!C45="","",'Данные объект'!C45)
A23: (должность, организация, фамилия, имя, отчество)
A25: и членов комиссии:
C26: =IF('Данные объект'!C47="","",'Данные объект'!C47)
A27: (должность, организация, фамилия, имя, отчество)
C28: =IF('Данные объект'!C49="","",'Данные объект'!C49)
A29: (должность, организация, фамилия, имя, отчество)
C30: =IF('Данные объект'!B32="","",'Данные объект'!B32)
A31: (должность, организация, фамилия, имя, отчество)
A32: руководствуясь, | C32: =IF('Данные объект'!B51="","",'Данные объект'!B51)
A33: (документ, устанавливающий требевания по организации и проведению входного контроля продукции)
A34: составила настоящий акт о выполненном входном контроле продукции для строительства.
A36: 1. К входному контролю представлена следующая продукция:
A37: Комплектное распределительное устройство наружной установки, 10кВ, 1000А, ввод КРУН-017-1000-УХЛ1; Комплектное распределительное устройство наружной установки, 10кВ, 1000А, линия КРУН-002-1000-УХЛ1
A38: (наименование продукции)
A39: 1.1. Наименование, номер документа, удостоверяющего качество и НТД на продукцию: | K39: АО"ЧЭАЗ"
K40: (изготовитель,
H41: НТД | I41: ГОСТ 14693-90
A42: № документа и дата, № партии, дата изготовления) (ГОСТ, ТУ, чертеж КМД)
A43: 1.2. Кол-во: | E43: Кол-во партии: | G43: =IF(C43="","",C43)
A44: (штуки, объем, вес в ед. изм.) (штуки, объем, вес в ед. изм.)
A45: 1.3. Поставщик: | F45: Договор
A46: (наименование организации) (реквизиты договора на поставку)
A47: 2. Подготовка продукции к контролю по НТД: | F47: выполнена
A48: (выполнена/не выполнена)
A49: 3. При входном контроле проведены следующие контрольные мероприятия:
A51: Количество, масса, объем проверенной продукции (в ед. изм.) | E51: Вид контроля (НТД) и дата сдачи образцов (проб) на контроль | G51: Приборы контроля | I51: № прибора и дата поверки прибора | K51: № и дата протокола контроля | L51: Заключение по контролю (годен/не годен)
A53: Визуальным осмотром | C53: Инструментальными и приборными методами
...

Sheet КСО
K1: Приложение 1
F5: ФОРМА
I6: ГОДЕН
I7: (результат контроля продукции)
A8: Объект строительства:
A9: =IF('Данные объект'!B3="","",'Данные объект'!B3)
A13: АКТ №4/ | G13: =IF('Данные объект'!B2="","",'Данные объект'!B2)
A14: входного контроля
A16: =IF('Провод СИП 3'!A16="","",'Провод СИП 3'!A16) | K16: =IF('Данные объект'!B6="","",'Данные объект'!B6)
A17: (место проведения) | K17: (дата)
A19: Нами, комиссией | C19: ='Провод СИП 3'!C19:G19 | H19: =IF('Данные объект'!B43="","",'Данные объект'!B43)
C20: (организация, от которой сформирована комиссия)
A22: Председателя: . | C22: =IF('Данные объект'!C45="","",'Данные объект'!C45)
A23: (должность, организация, фамилия, имя, отчество)
A25: и членов комиссии:
C26: =IF('Данные объект'!C47="","",'Данные объект'!C47)
A27: (должность, организация, фамилия, имя, отчество)
C28: =IF('Данные объект'!C49="","",'Данные объект'!C49)
A29: (должность, организация, фамилия, имя, отчество)
C30: =IF('Данные объект'!B32="","",'Данные объект'!B32)
A31: (должность, организация, фамилия, имя, отчество)
A32: руководствуясь, | C32: =IF('Данные объект'!B51="","",'Данные объект'!B51)
A33: (документ, устанавливающий требевания по организации и проведению входного контроля продукции)
A34: составила настоящий акт о выполненном входном контроле продукции для строительства.
A36: 1. К входному контролю представлена следующая продукция:
A37: Ячейка КСО-298 MSI
A38: (наименование продукции)
A39: 1.1. Наименование, номер документа, удостоверяющего качество и НТД на продукцию: | K39: АО"ГК"Электрощит" - ТМ Самара"
K40: (изготовитель,
H41: НТД
A42: № документа и дата, № партии, дата изготовления) (ГОСТ, ТУ, чертеж КМД)
A43: 1.2. Кол-во: | E43: Кол-во партии: | G43: =IF(C43="","",C43)
A44: (штуки, объем, вес в ед. изм.) (штуки, объем, вес в ед. изм.)
A45: 1.3. Поставщик: | F45: Договор
A46: (наименование организации) (реквизиты договора на поставку)
A47: 2. Подготовка продукции к контролю по НТД: | F47: выполнена
A48: (выполнена/не выполнена)
A49: 3. При входном контроле проведены следующие контрольные мероприятия:
A51: Количество, масса, объем проверенной продукции (в ед. изм.) | E51: Вид контроля (НТД) и дата сдачи образцов (проб) на контроль | G51: Приборы контроля | I51: № прибора и дата поверки прибора | K51: № и дата протокола контроля | L51: Заключение по контролю (годен/не годен)
A53: Визуальным осмотром | C53: Инструментальными и приборными методами
...

Sheet ТОЛ
K1: Приложение 1
F5: ФОРМА
I6: ГОДЕН
I7: (результат контроля продукции)
A8: Объект строительства:
A9: =IF('Данные объект'!B3="","",'Данные объект'!B3)
A13: АКТ № 5/ | G13: =IF('Данные объект'!B2="","",'Данные объект'!B2)
A14: входного контроля
A16: =IF('Провод СИП 3'!A16="","",'Провод СИП 3'!A16) | K16: =IF('Данные объект'!B6="","",'Данные объект'!B6)
A17: (место проведения) | K17: (дата)
A19: Нами, комиссией | C19: ='Провод СИП 3'!C19:G19 | H19: =IF('Данные объект'!B43="","",'Данные объект'!B43)
C20: (организация, от которой сформирована комиссия)
A22: Председателя: . | C22: =IF('Данные объект'!C45="","",'Данные объект'!C45)
A23: (должность, организация, фамилия, имя, отчество)
A25: и членов комиссии:
C26: =IF('Данные объект'!C47="","",'Данные объект'!C47)
A27: (должность, организация, фамилия, имя, отчество)
C28: =IF('Данные объект'!C49="","",'Данные объект'!C49)
A29: (должность, организация, фамилия, имя, отчество)
C30: =IF('Данные объект'!B32="","",'Данные объект'!B32)
A31: (должность, организация, фамилия, имя, отчество)
A32: руководствуясь, | C32: =IF('Данные объект'!B51="","",'Данные объект'!B51)
A33: (документ, устанавливающий требевания по организации и проведению входного контроля продукции)
A34: составила настоящий акт о выполненном входном контроле продукции для строительства.
A36: 1. К входному контролю представлена следующая продукция:
A37: Трансформатор тока ТОЛ-10 300А.
A38: (наименование продукции)
A39: 1.1. Наименование, номер документа, удостоверяющего качество и НТД на продукцию:
K40: (изготовитель,
H41: НТД | I41: ГОСТ 7746-2015
A42: № документа и дата, № партии, дата изготовления) (ГОСТ, ТУ, чертеж КМД)
A43: 1.2. Кол-во: | C43: 6шт | E43: Кол-во партии: | G43: =IF(C43="","",C43)
A44: (штуки, объем, вес в ед. изм.) (штуки, объем, вес в ед. изм.)
A45: 1.3. Поставщик: | F45: Договор
A46: (наименование организации) (реквизиты договора на поставку)
A47: 2. Подготовка продукции к контролю по НТД: | F47: выполнена
A48: (выполнена/не выполнена)
A49: 3. При входном контроле проведены следующие контрольные мероприятия:
A51: Количество, масса, объем проверенной продукции (в ед. изм.) | E51: Вид контроля (НТД) и дата сдачи образцов (проб) на контроль | G51: Приборы контроля | I51: № прибора и дата поверки прибора | K51: № и дата протокола контроля | L51: Заключение по контролю (годен/не годен)
A53: Визуальным осмотром | C53: Инструментальными и приборными методами
...

Sheet Провод СИП 3
K1: Приложение 1
F5: ФОРМА
I6: ГОДЕН
I7: (результат контроля продукции)
A8: Объект строительства:
A9: =IF('Данные объект'!B3="","",'Данные объект'!B3)
A13: АКТ №9/ | G13: =IF('Данные объект'!B2="","",'Данные объект'!B2)
A14: входного контроля
A16: =IF('Данные объект'!B5="","",'Данные объект'!B5) | K16: =IF('Данные объект'!B6="","",'Данные объект'!B6)
A17: (место проведения) | K17: (дата)
A19: Нами, комиссией | C19: =IF('Данные объект'!B11="","",'Данные объект'!B11) | H19: =IF('Данные объект'!B43="","",'Данные объект'!B43)
C20: (организация, от которой сформирована комиссия)
A22: Председателя: . | C22: =IF('Данные объект'!C45="","",'Данные объект'!C45)
A23: (должность, организация, фамилия, имя, отчество)
A25: и членов комиссии:
C26: =IF('Данные объект'!C47="","",'Данные объект'!C47)
A27: (должность, организация, фамилия, имя, отчество)
C28: =IF('Данные объект'!C49="","",'Данные объект'!C49)
A29: (должность, организация, фамилия, имя, отчество)
C30: =IF('Данные объект'!B32="","",'Данные объект'!B32)
A31: (должность, организация, фамилия, имя, отчество)
A32: руководствуясь, | C32: =IF('Данные объект'!B51="","",'Данные объект'!B51)
A33: (документ, устанавливающий требевания по организации и проведению входного контроля продукции)
A34: составила настоящий акт о выполненном входном контроле продукции для строительства.
A36: 1. К входному контролю представлена следующая продукция:
A37: Провод 3СИП3 1х70
A38: (наименование продукции)
A39: 1.1. Наименование, номер документа, удостоверяющего качество и НТД на продукцию:
K40: (изготовитель,
H41: НТД | I41: ГОСТ 31946-2012
A42: № документа и дата, № партии, дата изготовления) (ГОСТ, ТУ, чертеж КМД)
A43: 1.2. Кол-во: | E43: Кол-во партии:
A44: (штуки, объем, вес в ед. изм.) (штуки, объем, вес в ед. изм.)
A45: 1.3. Поставщик: | C45: ООО ТК "Норма-кабель" | F45: Договор
A46: (наименование организации) (реквизиты договора на поставку)
A47: 2. Подготовка продукции к контролю по НТД: | F47: выполнена
A48: (выполнена/не выполнена)
A49: 3. При входном контроле проведены следующие контрольные мероприятия:
A51: Количество, масса, объем проверенной продукции (в ед. изм.) | E51: Вид контроля (НТД) и дата сдачи образцов (проб) на контроль | G51: Приборы контроля | I51: № прибора и дата поверки прибора | K51: № и дата протокола контроля | L51: Заключение по контролю (годен/не годен)
A53: Визуальным осмотром | C53: Инструментальными и приборными методами
...

Sheet Провод СИП 2
K1: Приложение 1
F5: ФОРМА
I6: ГОДЕН
I7: (результат контроля продукции)
A8: Объект строительства:
A9: =IF('Данные объект'!B3="","",'Данные объект'!B3)
A13: АКТ №1/ | G13: =IF('Данные объект'!B2="","",'Данные объект'!B2)
A14: входного контроля
A16: =IF('Данные объект'!B5="","",'Данные объект'!B5) | K16: =IF('Данные объект'!B6="","",'Данные объект'!B6)
A17: (место проведения) | K17: (дата)
A19: Нами, комиссией | C19: =IF('Данные объект'!B11="","",'Данные объект'!B11) | H19: =IF('Данные объект'!B43="","",'Данные объект'!B43)
C20: (организация, от которой сформирована комиссия)
A22: Председателя: . | C22: =IF('Данные объект'!C45="","",'Данные объект'!C45)
A23: (должность, организация, фамилия, имя, отчество)
A25: и членов комиссии:
C26: =IF('Данные объект'!C47="","",'Данные объект'!C47)
A27: (должность, организация, фамилия, имя, отчество)
C28: =IF('Данные объект'!C49="","",'Данные объект'!C49)
A29: (должность, организация, фамилия, имя, отчество)
C30: =IF('Данные объект'!B32="","",'Данные объект'!B32)
A31: (должность, организация, фамилия, имя, отчество)
A33: (должность, организация, фамилия, имя, отчество)
A34: руководствуясь, | C34: =IF('Данные объект'!B51="","",'Данные объект'!B51)
A35: (документ, устанавливающий требевания по организации и проведению входного контроля продукции)
A36: составила настоящий акт о выполненном входном контроле продукции для строительства.
A38: 1. К входному контролю представлена следующая продукция:
A39: Провод СИП2 3х70+1х70
A40: (наименование продукции)
A41: 1.1. Наименование, номер документа, удостоверяющего качество и НТД на продукцию:
K42: (изготовитель,
H43: НТД | I43: ГОСТ 31946-2012
A44: № документа и дата, № партии, дата изготовления) (ГОСТ, ТУ, чертеж КМД)
A45: 1.2. Кол-во: | E45: Кол-во партии:
A46: (штуки, объем, вес в ед. изм.) (штуки, объем, вес в ед. изм.)
A47: 1.3. Поставщик: | C47: ООО ТК "Норма-кабель" | F47: Договор
A48: (наименование организации) (реквизиты договора на поставку)
A49: 2. Подготовка продукции к контролю по НТД: | F49: выполнена
A50: (выполнена/не выполнена)
A51: 3. При входном контроле проведены следующие контрольные мероприятия:
A53: Количество, масса, объем проверенной продукции (в ед. изм.) | E53: Вид контроля (НТД) и дата сдачи образцов (проб) на контроль | G53: Приборы контроля | I53: № прибора и дата поверки прибора | K53: № и дата протокола контроля | L53: Заключение по контролю (годен/не годен)
...

Sheet провод Пувг
K1: Приложение 1
F5: ФОРМА
I6: ГОДЕН
I7: (результат контроля продукции)
A8: Объект строительства:
A9: =IF('Данные объект'!B3="","",'Данные объект'!B3)
A13: АКТ № 6/ | G13: =IF('Провод СИП 3'!G13="","",'Провод СИП 3'!G13)
A14: входного контроля
A16: =IF('Провод СИП 3'!A16="","",'Провод СИП 3'!A16) | K16: ='Провод СИП 3'!K16:L16
A17: (место проведения) | K17: (дата)
A19: Нами, комиссией | C19: ='Провод СИП 3'!C19:G19 | H19: =IF('Данные объект'!B43="","",'Данные объект'!B43)
C20: (организация, от которой сформирована комиссия)
A22: Председателя: . | C22: =IF('Данные объект'!C45="","",'Данные объект'!C45)
A23: (должность, организация, фамилия, имя, отчество)
A25: и членов комиссии:
C26: =IF('Данные объект'!C47="","",'Данные объект'!C47)
A27: (должность, организация, фамилия, имя, отчество)
C28: =IF('Данные объект'!C49="","",'Данные объект'!C49)
A29: (должность, организация, фамилия, имя, отчество)
C30: =IF('Данные объект'!B32="","",'Данные объект'!B32)
A31: (должность, организация, фамилия, имя, отчество)
A32: руководствуясь, | C32: =IF('Данные объект'!B51="","",'Данные объект'!B51)
A33: (документ, устанавливающий требевания по организации и проведению входного контроля продукции)
A34: составила настоящий акт о выполненном входном контроле продукции для строительства.
A36: 1. К входному контролю представлена следующая продукция:
A37: Провод установочный с медной жилой на напряжение 380 В гибкий сечением 10 мм² ПуГВ 1х10
A38: (наименование продукции)
A39: 1.1. Наименование, номер документа, удостоверяющего качество и НТД на продукцию:
K40: (изготовитель,
H41: НТД | I41: ГОСТ 31947-2012
A42: № документа и дата, № партии, дата изготовления) (ГОСТ, ТУ, чертеж КМД)
A43: 1.2. Кол-во: | E43: Кол-во партии: | G43: =IF(C43="","",C43)
A44: (штуки, объем, вес в ед. изм.) (штуки, объем, вес в ед. изм.)
A45: 1.3. Поставщик: | F45: Договор
A46: (наименование организации) (реквизиты договора на поставку)
A47: 2. Подготовка продукции к контролю по НТД: | F47: выполнена
A48: (выполнена/не выполнена)
A49: 3. При входном контроле проведены следующие контрольные мероприятия:
A51: Количество, масса, объем проверенной продукции (в ед. изм.) | E51: Вид контроля (НТД) и дата сдачи образцов (проб) на контроль | G51: Приборы контроля | I51: № прибора и дата поверки прибора | K51: № и дата протокола контроля | L51: Заключение по контролю (годен/не годен)
A53: Визуальным осмотром | C53: Инструментальными и приборными методами
...

Sheet провод ПВС
K1: Приложение 1
F5: ФОРМА
I6: ГОДЕН
I7: (результат контроля продукции)
A8: Объект строительства:
A9: ='Провод СИП 3'!A9:L9
A13: АКТ № 0/ | G13: =IF('Провод СИП 3'!G13="","",'Провод СИП 3'!G13)
A14: входного контроля
A16: =IF('Данные объект'!B5="","",'Данные объект'!B5) | K16: ='Провод СИП 3'!K16:L16
A17: (место проведения) | K17: (дата)
A19: Нами, комиссией | C19: ='Провод СИП 3'!C19:G19 | H19: =IF('Данные объект'!B43="","",'Данные объект'!B43)
C20: (организация, от которой сформирована комиссия)
A22: Председателя: . | C22: =IF('Данные объект'!C45="","",'Данные объект'!C45)
A23: (должность, организация, фамилия, имя, отчество)
A25: и членов комиссии:
C26: =IF('Данные объект'!C47="","",'Данные объект'!C47)
A27: (должность, организация, фамилия, имя, отчество)
C28: =IF('Данные объект'!C49="","",'Данные объект'!C49)
A29: (должность, организация, фамилия, имя, отчество)
C30: =IF('Данные объект'!B32="","",'Данные объект'!B32)
A31: (должность, организация, фамилия, имя, отчество)
A32: руководствуясь, | C32: =IF('Данные объект'!B51="","",'Данные объект'!B51)
A33: (документ, устанавливающий требевания по организации и проведению входного контроля продукции)
A34: составила настоящий акт о выполненном входном контроле продукции для строительства.
A36: 1. К входному контролю представлена следующая продукция:
A37: Провод с резиновой изоляцией ПВС 2х2,5
A38: (наименование продукции)
A39: 1.1. Наименование, номер документа, удостоверяющего качество и НТД на продукцию:
K40: (изготовитель,
H41: НТД | I41: ГОСТ 7399-97
A42: № документа и дата, № партии, дата изготовления) (ГОСТ, ТУ, чертеж КМД)
A43: 1.2. Кол-во: | E43: Кол-во партии: | G43: =IF(C43="","",C43)
