Workbook

Sheet Данные организации
A1: организация | B1: ООО"Энергосистемы" | C1: ООО «Гефест» | D1: ООО "Энком" | F1: ПАО "Россети Московский регион"
A2: реквизиты | B2: ОГРН 1135044003709 ИНН 5044089069 КПП 504401001 | C2: ОГРН 1215000057238 ИНН 5044122213 КПП 504401001 | F2: ОГРН 1057746555811 ИНН 5036065113 КПП 772501001
A3: адрес | B3: 141508, Московская область, г.о. Солнечногорск, г. Солнечногорск, ул. Промышленная, стр. 5, помещение 179 | C3: 141508, Московская область, г.о. Солнечногорск, г Солнечногорск, ул Промышленная, строение 29А, корпус 1, офис 11 | F3: 115114, город Москва, проезд Павелецкий 2-й, дом 3, строение 2
A4: район | F4: Солнечногорский р-н | G4: Химкинский р-н
F5: СРЭС филиала | G5: ХРЭС филиала
A6: директор | B6: И.о.генерального директора | C6: Генеральный директор | F6: Начальник СРЭС СЭС филиала | G6: Начальник ХРЭС СЭС филиала
A7: директор ФИО | B7: Чернявская Н.Ю. | C7: Звездов Р.Е. | F7: Чуев А.Н.
A8: Строй.контроль | B8: Инженер по строительному контролю | C8: Специалист по строительному контролю | F8: Гл. специалист ССК УКС | G8: Гл. специалист ССК УКС
A9: Приказ стр.контр. | B9: Приказ № 18-ОТ/24 от 03 июня 2024 (НОСТРОЙ С-50-188017) | C9: Приказ №01/24-ОТ от 15.01.2024 (НРС № С-61-104369) | F9: Приказ №2363 от 29 июля 2025г (НРС С-50-069023) | G9: Приказ №263 от 31 января 2024г (НОСТРОЙ С-50-15922)
A10: ФИО стр.контр. | B10: Капитонов Д.А. | C10: Саженова Л.В. | F10: Алексанян Г.Р. | G10: Хлебнов Д.Ф.
A11: Представитель | F11: Технический надзор | G11: Технический надзор
A12: ФИО предст.
F14: Гл. спец. сектора по льготным договорам тп | G14: Гл.инженер
F15: Ефремкин Е.И. | G15: Игнатьев К.А.
F16: Гл. специалист ПТГ
F17: Царькова Н.К.
A18: Прораб | B18: Прораб | C18: Мастер электромонтажного участка
A19: Приказ прораб | B19: Приказ №05-ОТ/24 от 09 января 2024г | C19: Приказ №01/24-ОТ от 15.01.2024
A20: ФИО прораб | B20: Волков М.Ю. | C20: Красилов К.А.
A23: сцепленные организация | B23: =CONCATENATE(B2,",",B3) -> ОГРН 1135044003709 ИНН 5044089069 КПП 504401001,141508, Московская область, г.о. Солнечногорск, г. Солнечногорск, ул. Промышленная, стр. 5, помещение 179 | C23: =CONCATENATE(C2,",",C3) -> ОГРН 1215000057238 ИНН 5044122213 КПП 504401001,141508, Московская область, г.о. Солнечногорск, г Солнечногорск, ул Промышленная, строение 29А, корпус 1, офис 11 | F23: =CONCATENATE(F8," ",F1,"-",F10," .",F9) -> Гл. специалист ССК УКС ПАО "Россети Московский регион"-Алексанян Г.Р. .Приказ №2363 от 29 июля 2025г (НРС С-50-069023) | G23: =CONCATENATE(G8," ",F1,"-",G10," .",G9) -> Гл. специалист ССК УКС ПАО "Россети Московский регион"-Хлебнов Д.Ф. .Приказ №263 от 31 января 2024г (НОСТРОЙ С-50-15922)
A24: сцепленные организация | B24: =CONCATENATE(B1,",",B2,",",B3) -> ООО"Энергосистемы",ОГРН 1135044003709 ИНН 5044089069 КПП 504401001,141508, Московская область, г.о. Солнечногорск, г. Солнечногорск, ул. Промышленная, стр. 5, помещение 179 | C24: =CONCATENATE(C1,",",C2,",",C3) -> ООО «Гефест»,ОГРН 1215000057238 ИНН 5044122213 КПП 504401001,141508, Московская область, г.о. Солнечногорск, г Солнечногорск, ул Промышленная, строение 29А, корпус 1, офис 11 | F24: =CONCATENATE(F8," ",F1,"-",F10) -> Гл. специалист ССК УКС ПАО "Россети Московский регион"-Алексанян Г.Р. | G24: =CONCATENATE(G8," ",F1,"-",G10) -> Гл. специалист ССК УКС ПАО "Россети Московский регион"-Хлебнов Д.Ф.
B25: =CONCATENATE(B8," ",B1,"-",B10,".",B9) -> Инженер по строительному контролю ООО"Энергосистемы"-Капитонов Д.А..Приказ № 18-ОТ/24 от 03 июня 2024 (НОСТРОЙ С-50-188017) | C25: =CONCATENATE(C8," ",C1,"-",C10,".",C9) -> Специалист по строительному контролю ООО «Гефест»-Саженова Л.В..Приказ №01/24-ОТ от 15.01.2024 (НРС № С-61-104369) | F25: =CONCATENATE(F8," ",F1) -> Гл. специалист ССК УКС ПАО "Россети Московский регион" | G25: =CONCATENATE(G8," ",F1) -> Гл. специалист ССК УКС ПАО "Россети Московский регион"
B26: =CONCATENATE(B8," ",B1) -> Инженер по строительному контролю ООО"Энергосистемы" | C26: =CONCATENATE(C8," ",C1) -> Специалист по строительному контролю ООО «Гефест» | F26: =CONCATENATE(F6," ",F1," ",F7) -> Начальник СРЭС СЭС филиала ПАО "Россети Московский регион" Чуев А.Н. | G26: =CONCATENATE(G6," ",F1," ",G7) -> Начальник ХРЭС СЭС филиала ПАО "Россети Московский регион"
B27: =CONCATENATE(B18," ",B1,"-",B20,".",B19) -> Прораб ООО"Энергосистемы"-Волков М.Ю..Приказ №05-ОТ/24 от 09 января 2024г | C27: =CONCATENATE(C18," ",C1,"-",C20,".",C19) -> Мастер электромонтажного участка ООО «Гефест»-Красилов К.А..Приказ №01/24-ОТ от 15.01.2024 | F27: =CONCATENATE(F14," ",F1," ",F15) -> Гл. спец. сектора по льготным договорам тп ПАО "Россети Московский регион" Ефремкин Е.И. | G27: =CONCATENATE(G14," ",F1," ",G15) -> Гл.инженер ПАО "Россети Московский регион" Игнатьев К.А.
B28: =CONCATENATE(B18," ",B1," ",B20) -> Прораб ООО"Энергосистемы" Волков М.Ю. | C28: =CONCATENATE(C18," ",C1,"-",C20) -> Мастер электромонтажного участка ООО «Гефест»-Красилов К.А. | F28: =CONCATENATE(F16," ",F1," ",F17) -> Гл. специалист ПТГ ПАО "Россети Московский регион" Царькова Н.К.
B29: =CONCATENATE(B18," ",B1) -> Прораб ООО"Энергосистемы" | C29: =CONCATENATE(C18," ",C1) -> Мастер электромонтажного участка ООО «Гефест»

Sheet Данные объект
A1: Данные объекта
A2: № САП | B2: SAP - 325834
A3: Объект | B3: Строительство РП-10 кВ, 4КЛ-10 кВ от яч. № 316 3-й с.ш. и № 503 5-й с.ш. ЗРУ-10 кВ до 1-ой и 2-ой с.ш. РУ- 10 кВ сооруж. РП-10кВ, ПС 110/35/10 кВ № 71 "Поварово", в т.ч. ПИР, МО, Солнечногорский р-н, д. Ложки
A4: р-н | B4: Солнечногорский р-н
A5: Адрес | B5: МО, Солнечногорский р-н, д. Ложки
A6: Дата старт | B6: 45949
A7: Дата финиш | B7: 46219
A8: Наименование электроустановки
A9: ТП | B9: 2БРП №171
A10: Монтажная организация
A11: Организация | B11: ООО"Энергосистемы" | C11: =CONCATENATE(B11," ",B12," ",B13) -> ООО"Энергосистемы" ОГРН 1135044003709 ИНН 5044089069 КПП 504401001 141508, Московская область, г.о. Солнечногорск, г. Солнечногорск, ул. Промышленная, стр. 5, помещение 179
A12: Реквизиты | B12: ='Данные организации'!B2:C2 -> ОГРН 1135044003709 ИНН 5044089069 КПП 504401001
A13: адрес | B13: 141508, Московская область, г.о. Солнечногорск, г. Солнечногорск, ул. Промышленная, стр. 5, помещение 179
A14: Должность | B14: Генеральный директор
A15: ФИО | B15: Звездов Р.Е. | C15: =CONCATENATE(B14," ",B11," ",B15) -> Генеральный директор ООО"Энергосистемы" Звездов Р.Е.
A16: Должность | B16: Инженер по строительному контролю | C16: =CONCATENATE(B16," ",B11) -> Инженер по строительному контролю ООО"Энергосистемы"
A17: Ф.И.О. | B17: Русин В.А. | C17: =CONCATENATE(B16," ",B11," ",B17) -> Инженер по строительному контролю ООО"Энергосистемы" Русин В.А.
A18: Приказ | B18: Приказ № 13-ОТ/25 от 05 мая 2025 (НОСТРОЙ С-50-085497) | C18: =CONCATENATE(B16," ",B11," ",B17,".",B18) -> Инженер по строительному контролю ООО"Энергосистемы" Русин В.А..Приказ № 13-ОТ/25 от 05 мая 2025 (НОСТРОЙ С-50-085497)
A19: Должность | B19: Прораб | C19: =CONCATENATE(B19," ",B11) -> Прораб ООО"Энергосистемы"
A20: Ф.И.О. | B20: Волков М.Ю. | C20: =CONCATENATE(B19," ",B11," ",B20) -> Прораб ООО"Энергосистемы" Волков М.Ю.
A21: Приказ | B21: Приказ №05-ОТ/24 от 09 января 2024г | C21: =CONCATENATE(B19," ",B11," ",B20,".",B21) -> Прораб ООО"Энергосистемы" Волков М.Ю..Приказ №05-ОТ/24 от 09 января 2024г
A22: Заказчик
A23: Организация | B23: ПАО "Россети Московский регион" | C23: =CONCATENATE(B23," ",B24,",",B25) -> ПАО "Россети Московский регион" ОГРН 1057746555811 ИНН 5036065113 КПП 772501001,115114, город Москва, проезд Павелецкий 2-й, дом 3, строение 2
A24: Реквизиты | B24: ='[1]Данные организации'!F2 -> ОГРН 1057746555811 ИНН 5036065113 КПП 772501001
A25: адрес | B25: ='[1]Данные организации'!F3 -> 115114, город Москва, проезд Павелецкий 2-й, дом 3, строение 2
A26: Должность | B26: Начальник СРЭС СЭС филиала | C26: =CONCATENATE(B26," ",B23) -> Начальник СРЭС СЭС филиала ПАО "Россети Московский регион"
A27: Ф.И.О. | B27: Чуев А.Н. | C27: =CONCATENATE(B26," ",B23," ",B27) -> Начальник СРЭС СЭС филиала ПАО "Россети Московский регион" Чуев А.Н.
A28: Должность | B28: Гл. спец. сектора по льготным договорам тп | C28: =CONCATENATE(B28," ",B23) -> Гл. спец. сектора по льготным договорам тп ПАО "Россети Московский регион"
A29: Ф.И.О. | B29: Ефремкин Е.И. | C29: =CONCATENATE(B28," ",B23," ",B29) -> Гл. спец. сектора по льготным договорам тп ПАО "Россети Московский регион" Ефремкин Е.И.
A30: Должность | B30: Гл. специалист ПТГ | C30: =CONCATENATE(B30," ",B23) -> Гл. специалист ПТГ ПАО "Россети Московский регион"
A31: Ф.И.О. | B31: Царькова Н.К. | C31: =CONCATENATE(B30," ",B23," ",B31) -> Гл. специалист ПТГ ПАО "Россети Московский регион" Царькова Н.К.
A32: Должность | B32: Гл. специалист ССК УКС | C32: =CONCATENATE(B32," ",B23) -> Гл. специалист ССК УКС ПАО "Россети Московский регион"
A33: Ф.И.О. | B33: Алексанян Г.Р. | C33: =CONCATENATE(B32," ",B23," ",B33) -> Гл. специалист ССК УКС ПАО "Россети Московский регион" Алексанян Г.Р.
A34: Приказ | B34: Приказ №2363 от 29 июля 2025г (НРС С-50-069023) | C34: =CONCATENATE(B32," ",B23," ",B33,".",B34) -> Гл. специалист ССК УКС ПАО "Россети Московский регион" Алексанян Г.Р..Приказ №2363 от 29 июля 2025г (НРС С-50-069023)
A35: Проект
A36: Организация | B36: ООО"Энергосистемы"
A37: Реквизиты | B37: ОГРН 1135044003709 ИНН 5044089069 КПП 504401001
A38: адрес | B38: 141508, Московская область, г.о. Солнечногорск, г. Солнечногорск, ул. Промышленная, стр. 5, помещение 179
A39: Город | B39: г. Солнечногорск
A40: № | B40: 4980-325834-216-09/24
...

Sheet АОСР-1.1
AJ1: Приказ Минстроя №344/пр от 16.05.2023
AJ2: приложение №3
A3: Объект капитального строительства
A4: ='Данные объект'!B3 -> Строительство РП-10 кВ, 4КЛ-10 кВ от яч. № 316 3-й с.ш. и № 503 5-й с.ш. ЗРУ-10 кВ до 1-ой и 2-ой с.ш. РУ- 10 кВ сооруж. РП-10кВ, ПС 110/35/10 кВ № 71 "Поварово", в т.ч. ПИР, МО, Солнечногорский р-н, д. Ложки
A5: ='Данные объект'!B9 -> 2БРП №171
A6: (наименование объекта капитального строительства в соответствии с проектной документацией, почтовый или строительный адрес объекта капитального строительства)
A7: Застройщик, технический заказчик, лицо, ответственное за эксплуатацию здания, сооружения, или региональный оператор
A9: ='Данные объект'!B23 -> ПАО "Россети Московский регион"
A10: (фамилия, имя, отчество (последнее - при наличии), адрес места жительства, ОРГНИП, ИНН индивидуального предпринимателя, полное и (или) сокращенное наименование, ОГРН, ИНН, адрес юридического лица в пределах его нахождения, телефон или факс,
A11: ='Данные объект'!B24 -> ОГРН 1057746555811 ИНН 5036065113 КПП 772501001
A12: полное и (или) сокращенное наименование, ОГРН, ИНН саморегулируемой организации, членом которой является указанное юридическое лицо или индивидуальный предприниматель (за исключением случаев, когда членство в саморегулируемых организациях в области, строительства, реконструкции, капитального ремонта объектов капитального строительства не требуется); фамилия, имя, отчество
A13: ='Данные объект'!B25 -> 115114, город Москва, проезд Павелецкий 2-й, дом 3, строение 2
A14: (последнее - при наличии), паспортные данные, адрес места жительства, телефон или факс - для физических лиц, не являющихся индивидуальными предпринимателями)
A15: Лицо, осуществляющее строительство, реконструкцию, капитальный ремонт
A16: ='Данные объект'!B11 -> ООО"Энергосистемы"
A17: (фамилия, имя, отчество (последнее - при наличии), адрес места жительства, ОРГНИП, ИНН индивидуального предпринимателя,
A18: ='Данные объект'!B12 -> ОГРН 1135044003709 ИНН 5044089069 КПП 504401001
A19: полное и (или) сокращенное наименование, ОГРН, ИНН, адрес юридического лица в пределах его местонахождения, телефон или факс,
A20: ='Данные объект'!B13 -> 141508, Московская область, г.о. Солнечногорск, г. Солнечногорск, ул. Промышленная, стр. 5, помещение 179
A21: полное и (или) сокращенное наименование, ОГРН, ИНН саморегулируемой организации, членом которой является указанное юридическое лицо или индивидуальный предприниматель (за исключением случаев, когда членство в саморегулируемых организациях в области строительства, реконструкции, капитального ремонта объектов капитального строительства не требуется)
A22: Лицо, осуществляющее подготовку проектной документации
A23: ='Данные объект'!B36 -> ООО"Энергосистемы"
A24: (фамилия, имя, отчество (последнее - при наличии), адрес места жительства, ОРГНИП, ИНН индивидуального предпринимателя,
A25: ='Данные объект'!B37 -> ОГРН 1135044003709 ИНН 5044089069 КПП 504401001
A26: полное и (или) сокращенное наименование, ОГРН, ИНН, адрес юридического лица в пределах его места нахождения, телефон или факс,
A27: ='Данные объект'!B38 -> 141508, Московская область, г.о. Солнечногорск, г. Солнечногорск, ул. Промышленная, стр. 5, помещение 179
A28: полное и (или) сокращенное наименование, ОГРН, ИНН саморегулируемой организации, членом которой является указанное юридическое лицо или индивидуальный предприниматель (за исключением случаев, когда членство в саморегулируемых организациях в области архитектурно-строительного проектирования не требуется)
A30: АКТ
A31: освидетельствования скрытых работ
B33: № | C33: 1 | E33: /2БРП №171 | AB33: =P79 -> 46219
AB34: (дата составления акта)
A36: Представитель застройщика, технического заказчика, лица, ответственного за эксплуатацию здания, сооружения, или регионального оператора по вопросам строительного контроля
A37: ='Данные объект'!C34 -> Гл. специалист ССК УКС ПАО "Россети Московский регион" Алексанян Г.Р..Приказ №2363 от 29 июля 2025г (НРС С-50-069023)
A38: (должность (при наличии), фамилия, инициалы, идентификационный номер в национальном реестре специалистов в области строительства (за исключением случаев, когда членство в саморегулируемых организациях в области строительства, реконструкции, капитального ремонта обектов капитального строительства не требуется), реквизиты распоряительного документа, подтверждающего полномочия,
A39: ='Данные объект'!C23 -> ПАО "Россети Московский регион" ОГРН 1057746555811 ИНН 5036065113 КПП 772501001,115114, город Москва, проезд Павелецкий 2-й, дом 3, строение 2
A40: с указанием полного и (или) сокращенного наименования, ОГРН, ИНН, адреса юридического лица в пределах его места нахождения (в случае осуществления строительного контроля на основании договора с застройщиком или техническим заказчиком), фамилии, имени, отчества (последнее - при наличии), адреса места жительства, ОГРНИП, ИНН индивиуального предпринимателя (в случае осуществления строительного контроля на основании договора с застройщиком или техническим заказчиком)
A41: Представитель лица, осуществляющего строительство, реконструкцию, капитальный ремонт
A42: ='Данные объект'!C21 -> Прораб ООО"Энергосистемы" Волков М.Ю..Приказ №05-ОТ/24 от 09 января 2024г
A43: (должность (при наличии), фамилия, инициалы, реквизиты распорядительного документа, подтверждающего полномочия)
A44: Представитель лица, осуществляющего строительство, реконструкцию, капитальный ремонт, по вопросам строительного контроля
...

Sheet АОСР-2
AJ1: Приказ Минстроя №344/пр от 16.05.2023
AJ2: приложение №3
A3: Объект капитального строительства
A4: ='Данные объект'!B3 -> Строительство РП-10 кВ, 4КЛ-10 кВ от яч. № 316 3-й с.ш. и № 503 5-й с.ш. ЗРУ-10 кВ до 1-ой и 2-ой с.ш. РУ- 10 кВ сооруж. РП-10кВ, ПС 110/35/10 кВ № 71 "Поварово", в т.ч. ПИР, МО, Солнечногорский р-н, д. Ложки
A5: ='Данные объект'!B9 -> 2БРП №171
A6: (наименование объекта капитального строительства в соответствии с проектной документацией, почтовый или строительный адрес объекта капитального строительства)
A7: Застройщик, технический заказчик, лицо, ответственное за эксплуатацию здания, сооружения, или региональный оператор
A9: ='Данные объект'!B23 -> ПАО "Россети Московский регион"
A10: (фамилия, имя, отчество (последнее - при наличии), адрес места жительства, ОРГНИП, ИНН индивидуального предпринимателя, полное и (или) сокращенное наименование, ОГРН, ИНН, адрес юридического лица в пределах его нахождения, телефон или факс,
A11: ='Данные объект'!B24 -> ОГРН 1057746555811 ИНН 5036065113 КПП 772501001
A12: полное и (или) сокращенное наименование, ОГРН, ИНН саморегулируемой организации, членом которой является указанное юридическое лицо или индивидуальный предприниматель (за исключением случаев, когда членство в саморегулируемых организациях в области, строительства, реконструкции, капитального ремонта объектов капитального строительства не требуется); фамилия, имя, отчество
A13: ='Данные объект'!B25 -> 115114, город Москва, проезд Павелецкий 2-й, дом 3, строение 2
A14: (последнее - при наличии), паспортные данные, адрес места жительства, телефон или факс - для физических лиц, не являющихся индивидуальными предпринимателями)
A15: Лицо, осуществляющее строительство, реконструкцию, капитальный ремонт
A16: ='Данные объект'!B11 -> ООО"Энергосистемы"
A17: (фамилия, имя, отчество (последнее - при наличии), адрес места жительства, ОРГНИП, ИНН индивидуального предпринимателя,
A18: ='Данные объект'!B12 -> ОГРН 1135044003709 ИНН 5044089069 КПП 504401001
A19: полное и (или) сокращенное наименование, ОГРН, ИНН, адрес юридического лица в пределах его местонахождения, телефон или факс,
A20: ='Данные объект'!B13 -> 141508, Московская область, г.о. Солнечногорск, г. Солнечногорск, ул. Промышленная, стр. 5, помещение 179
A21: полное и (или) сокращенное наименование, ОГРН, ИНН саморегулируемой организации, членом которой является указанное юридическое лицо или индивидуальный предприниматель (за исключением случаев, когда членство в саморегулируемых организациях в области строительства, реконструкции, капитального ремонта объектов капитального строительства не требуется)
A22: Лицо, осуществляющее подготовку проектной документации
A23: ='Данные объект'!B36 -> ООО"Энергосистемы"
A24: (фамилия, имя, отчество (последнее - при наличии), адрес места жительства, ОРГНИП, ИНН индивидуального предпринимателя,
A25: ='Данные объект'!B37 -> ОГРН 1135044003709 ИНН 5044089069 КПП 504401001
A26: полное и (или) сокращенное наименование, ОГРН, ИНН, адрес юридического лица в пределах его места нахождения, телефон или факс,
A27: ='Данные объект'!B38 -> 141508, Московская область, г.о. Солнечногорск, г. Солнечногорск, ул. Промышленная, стр. 5, помещение 179
A28: полное и (или) сокращенное наименование, ОГРН, ИНН саморегулируемой организации, членом которой является указанное юридическое лицо или индивидуальный предприниматель (за исключением случаев, когда членство в саморегулируемых организациях в области архитектурно-строительного проектирования не требуется)
A30: АКТ
A31: освидетельствования скрытых работ
B33: № | C33: ='АОСР-1'!C33+1 -> 2 | E33: /2БРП №171 | AB33: =P79 -> 46219
AB34: (дата составления акта)
A36: Представитель застройщика, технического заказчика, лица, ответственного за эксплуатацию здания, сооружения, или регионального оператора по вопросам строительного контроля
A37: ='Данные объект'!C34 -> Гл. специалист ССК УКС ПАО "Россети Московский регион" Алексанян Г.Р..Приказ №2363 от 29 июля 2025г (НРС С-50-069023)
A38: (должность (при наличии), фамилия, инициалы, идентификационный номер в национальном реестре специалистов в области строительства (за исключением случаев, когда членство в саморегулируемых организациях в области строительства, реконструкции, капитального ремонта обектов капитального строительства не требуется), реквизиты распоряительного документа, подтверждающего полномочия,
A39: ='Данные объект'!C23 -> ПАО "Россети Московский регион" ОГРН 1057746555811 ИНН 5036065113 КПП 772501001,115114, город Москва, проезд Павелецкий 2-й, дом 3, строение 2
A40: с указанием полного и (или) сокращенного наименования, ОГРН, ИНН, адреса юридического лица в пределах его места нахождения (в случае осуществления строительного контроля на основании договора с застройщиком или техническим заказчиком), фамилии, имени, отчества (последнее - при наличии), адреса места жительства, ОГРНИП, ИНН индивиуального предпринимателя (в случае осуществления строительного контроля на основании договора с застройщиком или техническим заказчиком)
A41: Представитель лица, осуществляющего строительство, реконструкцию, капитальный ремонт
A42: ='Данные объект'!C21 -> Прораб ООО"Энергосистемы" Волков М.Ю..Приказ №05-ОТ/24 от 09 января 2024г
A43: (должность (при наличии), фамилия, инициалы, реквизиты распорядительного документа, подтверждающего полномочия)
A44: Представитель лица, осуществляющего строительство, реконструкцию, капитальный ремонт, по вопросам строительного контроля
...

Sheet АОСР-5.1 (5)
AJ1: Приказ Минстроя №344/пр от 16.05.2023
AJ2: приложение №3
A3: Объект капитального строительства
A4: ='Данные объект'!B3 -> Строительство РП-10 кВ, 4КЛ-10 кВ от яч. № 316 3-й с.ш. и № 503 5-й с.ш. ЗРУ-10 кВ до 1-ой и 2-ой с.ш. РУ- 10 кВ сооруж. РП-10кВ, ПС 110/35/10 кВ № 71 "Поварово", в т.ч. ПИР, МО, Солнечногорский р-н, д. Ложки
A5: ='Данные объект'!B9 -> 2БРП №171
A6: (наименование объекта капитального строительства в соответствии с проектной документацией, почтовый или строительный адрес объекта капитального строительства)
A7: Застройщик, технический заказчик, лицо, ответственное за эксплуатацию здания, сооружения, или региональный оператор
A9: ='Данные объект'!B23 -> ПАО "Россети Московский регион"
A10: (фамилия, имя, отчество (последнее - при наличии), адрес места жительства, ОРГНИП, ИНН индивидуального предпринимателя, полное и (или) сокращенное наименование, ОГРН, ИНН, адрес юридического лица в пределах его нахождения, телефон или факс,
A11: ='Данные объект'!B24 -> ОГРН 1057746555811 ИНН 5036065113 КПП 772501001
A12: полное и (или) сокращенное наименование, ОГРН, ИНН саморегулируемой организации, членом которой является указанное юридическое лицо или индивидуальный предприниматель (за исключением случаев, когда членство в саморегулируемых организациях в области, строительства, реконструкции, капитального ремонта объектов капитального строительства не требуется); фамилия, имя, отчество
A13: ='Данные объект'!B25 -> 115114, город Москва, проезд Павелецкий 2-й, дом 3, строение 2
A14: (последнее - при наличии), паспортные данные, адрес места жительства, телефон или факс - для физических лиц, не являющихся индивидуальными предпринимателями)
A15: Лицо, осуществляющее строительство, реконструкцию, капитальный ремонт
A16: ='Данные объект'!B11 -> ООО"Энергосистемы"
A17: (фамилия, имя, отчество (последнее - при наличии), адрес места жительства, ОРГНИП, ИНН индивидуального предпринимателя,
A18: ='Данные объект'!B12 -> ОГРН 1135044003709 ИНН 5044089069 КПП 504401001
A19: полное и (или) сокращенное наименование, ОГРН, ИНН, адрес юридического лица в пределах его местонахождения, телефон или факс,
A20: ='Данные объект'!B13 -> 141508, Московская область, г.о. Солнечногорск, г. Солнечногорск, ул. Промышленная, стр. 5, помещение 179
A21: полное и (или) сокращенное наименование, ОГРН, ИНН саморегулируемой организации, членом которой является указанное юридическое лицо или индивидуальный предприниматель (за исключением случаев, когда членство в саморегулируемых организациях в области строительства, реконструкции, капитального ремонта объектов капитального строительства не требуется)
A22: Лицо, осуществляющее подготовку проектной документации
A23: ='Данные объект'!B36 -> ООО"Энергосистемы"
A24: (фамилия, имя, отчество (последнее - при наличии), адрес места жительства, ОРГНИП, ИНН индивидуального предпринимателя,
A25: ='Данные объект'!B37 -> ОГРН 1135044003709 ИНН 5044089069 КПП 504401001
A26: полное и (или) сокращенное наименование, ОГРН, ИНН, адрес юридического лица в пределах его места нахождения, телефон или факс,
A27: ='Данные объект'!B38 -> 141508, Московская область, г.о. Солнечногорск, г. Солнечногорск, ул. Промышленная, стр. 5, помещение 179
A28: полное и (или) сокращенное наименование, ОГРН, ИНН саморегулируемой организации, членом которой является указанное юридическое лицо или индивидуальный предприниматель (за исключением случаев, когда членство в саморегулируемых организациях в области архитектурно-строительного проектирования не требуется)
A30: АКТ
A31: освидетельствования скрытых работ
B33: № | C33: 3 | E33: /2БРП №171 | AB33: =P78 -> 46219
AB34: (дата составления акта)
A36: Представитель застройщика, технического заказчика, лица, ответственного за эксплуатацию здания, сооружения, или регионального оператора по вопросам строительного контроля
A37: ='Данные объект'!C34 -> Гл. специалист ССК УКС ПАО "Россети Московский регион" Алексанян Г.Р..Приказ №2363 от 29 июля 2025г (НРС С-50-069023)
A38: (должность (при наличии), фамилия, инициалы, идентификационный номер в национальном реестре специалистов в области строительства (за исключением случаев, когда членство в саморегулируемых организациях в области строительства, реконструкции, капитального ремонта обектов капитального строительства не требуется), реквизиты распоряительного документа, подтверждающего полномочия,
A39: ='Данные объект'!C23 -> ПАО "Россети Московский регион" ОГРН 1057746555811 ИНН 5036065113 КПП 772501001,115114, город Москва, проезд Павелецкий 2-й, дом 3, строение 2
A40: с указанием полного и (или) сокращенного наименования, ОГРН, ИНН, адреса юридического лица в пределах его места нахождения (в случае осуществления строительного контроля на основании договора с застройщиком или техническим заказчиком), фамилии, имени, отчества (последнее - при наличии), адреса места жительства, ОГРНИП, ИНН индивиуального предпринимателя (в случае осуществления строительного контроля на основании договора с застройщиком или техническим заказчиком)
A41: Представитель лица, осуществляющего строительство, реконструкцию, капитальный ремонт
A42: ='Данные объект'!C21 -> Прораб ООО"Энергосистемы" Волков М.Ю..Приказ №05-ОТ/24 от 09 января 2024г
A43: (должность (при наличии), фамилия, инициалы, реквизиты распорядительного документа, подтверждающего полномочия)
A44: Представитель лица, осуществляющего строительство, реконструкцию, капитальный ремонт, по вопросам строительного контроля
...

Sheet АОСР-4
AJ1: Приказ Минстроя №344/пр от 16.05.2023
AJ2: приложение №3
A3: Объект капитального строительства
A4: ='Данные объект'!B3 -> Строительство РП-10 кВ, 4КЛ-10 кВ от яч. № 316 3-й с.ш. и № 503 5-й с.ш. ЗРУ-10 кВ до 1-ой и 2-ой с.ш. РУ- 10 кВ сооруж. РП-10кВ, ПС 110/35/10 кВ № 71 "Поварово", в т.ч. ПИР, МО, Солнечногорский р-н, д. Ложки
A5: ='Данные объект'!B9 -> 2БРП №171
A6: (наименование объекта капитального строительства в соответствии с проектной документацией, почтовый или строительный адрес объекта капитального строительства)
A7: Застройщик, технический заказчик, лицо, ответственное за эксплуатацию здания, сооружения, или региональный оператор
A9: ='Данные объект'!B23 -> ПАО "Россети Московский регион"
A10: (фамилия, имя, отчество (последнее - при наличии), адрес места жительства, ОРГНИП, ИНН индивидуального предпринимателя, полное и (или) сокращенное наименование, ОГРН, ИНН, адрес юридического лица в пределах его нахождения, телефон или факс,
A11: ='Данные объект'!B24 -> ОГРН 1057746555811 ИНН 5036065113 КПП 772501001
A12: полное и (или) сокращенное наименование, ОГРН, ИНН саморегулируемой организации, членом которой является указанное юридическое лицо или индивидуальный предприниматель (за исключением случаев, когда членство в саморегулируемых организациях в области, строительства, реконструкции, капитального ремонта объектов капитального строительства не требуется); фамилия, имя, отчество
A13: ='Данные объект'!B25 -> 115114, город Москва, проезд Павелецкий 2-й, дом 3, строение 2
A14: (последнее - при наличии), паспортные данные, адрес места жительства, телефон или факс - для физических лиц, не являющихся индивидуальными предпринимателями)
A15: Лицо, осуществляющее строительство, реконструкцию, капитальный ремонт
A16: ='Данные объект'!B11 -> ООО"Энергосистемы"
A17: (фамилия, имя, отчество (последнее - при наличии), адрес места жительства, ОРГНИП, ИНН индивидуального предпринимателя,
A18: ='Данные объект'!B12 -> ОГРН 1135044003709 ИНН 5044089069 КПП 504401001
A19: полное и (или) сокращенное наименование, ОГРН, ИНН, адрес юридического лица в пределах его местонахождения, телефон или факс,
A20: ='Данные объект'!B13 -> 141508, Московская область, г.о. Солнечногорск, г. Солнечногорск, ул. Промышленная, стр. 5, помещение 179
A21: полное и (или) сокращенное наименование, ОГРН, ИНН саморегулируемой организации, членом которой является указанное юридическое лицо или индивидуальный предприниматель (за исключением случаев, когда членство в саморегулируемых организациях в области строительства, реконструкции, капитального ремонта объектов капитального строительства не требуется)
A22: Лицо, осуществляющее подготовку проектной документации
A23: ='Данные объект'!B36 -> ООО"Энергосистемы"
A24: (фамилия, имя, отчество (последнее - при наличии), адрес места жительства, ОРГНИП, ИНН индивидуального предпринимателя,
A25: ='Данные объект'!B37 -> ОГРН 1135044003709 ИНН 5044089069 КПП 504401001
A26: полное и (или) сокращенное наименование, ОГРН, ИНН, адрес юридического лица в пределах его места нахождения, телефон или факс,
A27: ='Данные объект'!B38 -> 141508, Московская область, г.о. Солнечногорск, г. Солнечногорск, ул. Промышленная, стр. 5, помещение 179
A28: полное и (или) сокращенное наименование, ОГРН, ИНН саморегулируемой организации, членом которой является указанное юридическое лицо или индивидуальный предприниматель (за исключением случаев, когда членство в саморегулируемых организациях в области архитектурно-строительного проектирования не требуется)
A30: АКТ
A31: освидетельствования скрытых работ
B33: № | C33: 4 | E33: /2БРП №171 | AB33: =P79 -> 46219
AB34: (дата составления акта)
A36: Представитель застройщика, технического заказчика, лица, ответственного за эксплуатацию здания, сооружения, или регионального оператора по вопросам строительного контроля
A37: ='Данные объект'!C34 -> Гл. специалист ССК УКС ПАО "Россети Московский регион" Алексанян Г.Р..Приказ №2363 от 29 июля 2025г (НРС С-50-069023)
A38: (должность (при наличии), фамилия, инициалы, идентификационный номер в национальном реестре специалистов в области строительства (за исключением случаев, когда членство в саморегулируемых организациях в области строительства, реконструкции, капитального ремонта обектов капитального строительства не требуется), реквизиты распоряительного документа, подтверждающего полномочия,
A39: ='Данные объект'!C23 -> ПАО "Россети Московский регион" ОГРН 1057746555811 ИНН 5036065113 КПП 772501001,115114, город Москва, проезд Павелецкий 2-й, дом 3, строение 2
A40: с указанием полного и (или) сокращенного наименования, ОГРН, ИНН, адреса юридического лица в пределах его места нахождения (в случае осуществления строительного контроля на основании договора с застройщиком или техническим заказчиком), фамилии, имени, отчества (последнее - при наличии), адреса места жительства, ОГРНИП, ИНН индивиуального предпринимателя (в случае осуществления строительного контроля на основании договора с застройщиком или техническим заказчиком)
A41: Представитель лица, осуществляющего строительство, реконструкцию, капитальный ремонт
A42: ='Данные объект'!C21 -> Прораб ООО"Энергосистемы" Волков М.Ю..Приказ №05-ОТ/24 от 09 января 2024г
A43: (должность (при наличии), фамилия, инициалы, реквизиты распорядительного документа, подтверждающего полномочия)
A44: Представитель лица, осуществляющего строительство, реконструкцию, капитальный ремонт, по вопросам строительного контроля
...

Sheet АОСР-4 (2)
AJ1: Приказ Минстроя №344/пр от 16.05.2023
AJ2: приложение №3
A3: Объект капитального строительства
A4: ='Данные объект'!B3 -> Строительство РП-10 кВ, 4КЛ-10 кВ от яч. № 316 3-й с.ш. и № 503 5-й с.ш. ЗРУ-10 кВ до 1-ой и 2-ой с.ш. РУ- 10 кВ сооруж. РП-10кВ, ПС 110/35/10 кВ № 71 "Поварово", в т.ч. ПИР, МО, Солнечногорский р-н, д. Ложки
A5: ='Данные объект'!B9 -> 2БРП №171
A6: (наименование объекта капитального строительства в соответствии с проектной документацией, почтовый или строительный адрес объекта капитального строительства)
A7: Застройщик, технический заказчик, лицо, ответственное за эксплуатацию здания, сооружения, или региональный оператор
A9: ='Данные объект'!B23 -> ПАО "Россети Московский регион"
A10: (фамилия, имя, отчество (последнее - при наличии), адрес места жительства, ОРГНИП, ИНН индивидуального предпринимателя, полное и (или) сокращенное наименование, ОГРН, ИНН, адрес юридического лица в пределах его нахождения, телефон или факс,
A11: ='Данные объект'!B24 -> ОГРН 1057746555811 ИНН 5036065113 КПП 772501001
A12: полное и (или) сокращенное наименование, ОГРН, ИНН саморегулируемой организации, членом которой является указанное юридическое лицо или индивидуальный предприниматель (за исключением случаев, когда членство в саморегулируемых организациях в области, строительства, реконструкции, капитального ремонта объектов капитального строительства не требуется); фамилия, имя, отчество
A13: ='Данные объект'!B25 -> 115114, город Москва, проезд Павелецкий 2-й, дом 3, строение 2
A14: (последнее - при наличии), паспортные данные, адрес места жительства, телефон или факс - для физических лиц, не являющихся индивидуальными предпринимателями)
A15: Лицо, осуществляющее строительство, реконструкцию, капитальный ремонт
A16: ='Данные объект'!B11 -> ООО"Энергосистемы"
A17: (фамилия, имя, отчество (последнее - при наличии), адрес места жительства, ОРГНИП, ИНН индивидуального предпринимателя,
A18: ='Данные объект'!B12 -> ОГРН 1135044003709 ИНН 5044089069 КПП 504401001
A19: полное и (или) сокращенное наименование, ОГРН, ИНН, адрес юридического лица в пределах его местонахождения, телефон или факс,
A20: ='Данные объект'!B13 -> 141508, Московская область, г.о. Солнечногорск, г. Солнечногорск, ул. Промышленная, стр. 5, помещение 179
A21: полное и (или) сокращенное наименование, ОГРН, ИНН саморегулируемой организации, членом которой является указанное юридическое лицо или индивидуальный предприниматель (за исключением случаев, когда членство в саморегулируемых организациях в области строительства, реконструкции, капитального ремонта объектов капитального строительства не требуется)
A22: Лицо, осуществляющее подготовку проектной документации
A23: ='Данные объект'!B36 -> ООО"Энергосистемы"
A24: (фамилия, имя, отчество (последнее - при наличии), адрес места жительства, ОРГНИП, ИНН индивидуального предпринимателя,
A25: ='Данные объект'!B37 -> ОГРН 1135044003709 ИНН 5044089069 КПП 504401001
A26: полное и (или) сокращенное наименование, ОГРН, ИНН, адрес юридического лица в пределах его места нахождения, телефон или факс,
A27: ='Данные объект'!B38 -> 141508, Московская область, г.о. Солнечногорск, г. Солнечногорск, ул. Промышленная, стр. 5, помещение 179
A28: полное и (или) сокращенное наименование, ОГРН, ИНН саморегулируемой организации, членом которой является указанное юридическое лицо или индивидуальный предприниматель (за исключением случаев, когда членство в саморегулируемых организациях в области архитектурно-строительного проектирования не требуется)
A30: АКТ
A31: освидетельствования скрытых работ
B33: № | C33: 4 | E33: /2БКТП №4301 | AB33: =P79 -> 45454
AB34: (дата составления акта)
A36: Представитель застройщика, технического заказчика, лица, ответственного за эксплуатацию здания, сооружения, или регионального оператора по вопросам строительного контроля
A37: ='Данные объект'!C34 -> Гл. специалист ССК УКС ПАО "Россети Московский регион" Алексанян Г.Р..Приказ №2363 от 29 июля 2025г (НРС С-50-069023)
A38: (должность (при наличии), фамилия, инициалы, идентификационный номер в национальном реестре специалистов в области строительства (за исключением случаев, когда членство в саморегулируемых организациях в области строительства, реконструкции, капитального ремонта обектов капитального строительства не требуется), реквизиты распоряительного документа, подтверждающего полномочия,
A39: ='Данные объект'!C23 -> ПАО "Россети Московский регион" ОГРН 1057746555811 ИНН 5036065113 КПП 772501001,115114, город Москва, проезд Павелецкий 2-й, дом 3, строение 2
A40: с указанием полного и (или) сокращенного наименования, ОГРН, ИНН, адреса юридического лица в пределах его места нахождения (в случае осуществления строительного контроля на основании договора с застройщиком или техническим заказчиком), фамилии, имени, отчества (последнее - при наличии), адреса места жительства, ОГРНИП, ИНН индивиуального предпринимателя (в случае осуществления строительного контроля на основании договора с застройщиком или техническим заказчиком)
A41: Представитель лица, осуществляющего строительство, реконструкцию, капитальный ремонт
A42: ='Данные объект'!C21 -> Прораб ООО"Энергосистемы" Волков М.Ю..Приказ №05-ОТ/24 от 09 января 2024г
A43: (должность (при наличии), фамилия, инициалы, реквизиты распорядительного документа, подтверждающего полномочия)
A44: Представитель лица, осуществляющего строительство, реконструкцию, капитальный ремонт, по вопросам строительного контроля
...

Sheet АОСР-3
AJ1: Приказ Минстроя №344/пр от 16.05.2023
AJ2: приложение №3
A3: Объект капитального строительства
A4: ='Данные объект'!B3 -> Строительство РП-10 кВ, 4КЛ-10 кВ от яч. № 316 3-й с.ш. и № 503 5-й с.ш. ЗРУ-10 кВ до 1-ой и 2-ой с.ш. РУ- 10 кВ сооруж. РП-10кВ, ПС 110/35/10 кВ № 71 "Поварово", в т.ч. ПИР, МО, Солнечногорский р-н, д. Ложки
A5: ='Данные объект'!B9 -> 2БРП №171
A6: (наименование объекта капитального строительства в соответствии с проектной документацией, почтовый или строительный адрес объекта капитального строительства)
A7: Застройщик, технический заказчик, лицо, ответственное за эксплуатацию здания, сооружения, или региональный оператор
A9: ='Данные объект'!B23 -> ПАО "Россети Московский регион"
A10: (фамилия, имя, отчество (последнее - при наличии), адрес места жительства, ОРГНИП, ИНН индивидуального предпринимателя, полное и (или) сокращенное наименование, ОГРН, ИНН, адрес юридического лица в пределах его нахождения, телефон или факс,
A11: ='Данные объект'!B24 -> ОГРН 1057746555811 ИНН 5036065113 КПП 772501001
A12: полное и (или) сокращенное наименование, ОГРН, ИНН саморегулируемой организации, членом которой является указанное юридическое лицо или индивидуальный предприниматель (за исключением случаев, когда членство в саморегулируемых организациях в области, строительства, реконструкции, капитального ремонта объектов капитального строительства не требуется); фамилия, имя, отчество
A13: ='Данные объект'!B25 -> 115114, город Москва, проезд Павелецкий 2-й, дом 3, строение 2
A14: (последнее - при наличии), паспортные данные, адрес места жительства, телефон или факс - для физических лиц, не являющихся индивидуальными предпринимателями)
A15: Лицо, осуществляющее строительство, реконструкцию, капитальный ремонт
A16: ='Данные объект'!B11 -> ООО"Энергосистемы"
A17: (фамилия, имя, отчество (последнее - при наличии), адрес места жительства, ОРГНИП, ИНН индивидуального предпринимателя,
A18: ='Данные объект'!B12 -> ОГРН 1135044003709 ИНН 5044089069 КПП 504401001
A19: полное и (или) сокращенное наименование, ОГРН, ИНН, адрес юридического лица в пределах его местонахождения, телефон или факс,
A20: ='Данные объект'!B13 -> 141508, Московская область, г.о. Солнечногорск, г. Солнечногорск, ул. Промышленная, стр. 5, помещение 179
A21: полное и (или) сокращенное наименование, ОГРН, ИНН саморегулируемой организации, членом которой является указанное юридическое лицо или индивидуальный предприниматель (за исключением случаев, когда членство в саморегулируемых организациях в области строительства, реконструкции, капитального ремонта объектов капитального строительства не требуется)
A22: Лицо, осуществляющее подготовку проектной документации
A23: ='Данные объект'!B36 -> ООО"Энергосистемы"
A24: (фамилия, имя, отчество (последнее - при наличии), адрес места жительства, ОРГНИП, ИНН индивидуального предпринимателя,
A25: ='Данные объект'!B37 -> ОГРН 1135044003709 ИНН 5044089069 КПП 504401001
A26: полное и (или) сокращенное наименование, ОГРН, ИНН, адрес юридического лица в пределах его места нахождения, телефон или факс,
A27: ='Данные объект'!B38 -> 141508, Московская область, г.о. Солнечногорск, г. Солнечногорск, ул. Промышленная, стр. 5, помещение 179
A28: полное и (или) сокращенное наименование, ОГРН, ИНН саморегулируемой организации, членом которой является указанное юридическое лицо или индивидуальный предприниматель (за исключением случаев, когда членство в саморегулируемых организациях в области архитектурно-строительного проектирования не требуется)
A30: АКТ
A31: освидетельствования скрытых работ
B33: № | C33: 5 | E33: /2БРП №171 | AB33: =P79 -> 46219
AB34: (дата составления акта)
A36: Представитель застройщика, технического заказчика, лица, ответственного за эксплуатацию здания, сооружения, или регионального оператора по вопросам строительного контроля
A37: ='Данные объект'!C34 -> Гл. специалист ССК УКС ПАО "Россети Московский регион" Алексанян Г.Р..Приказ №2363 от 29 июля 2025г (НРС С-50-069023)
A38: (должность (при наличии), фамилия, инициалы, идентификационный номер в национальном реестре специалистов в области строительства (за исключением случаев, когда членство в саморегулируемых организациях в области строительства, реконструкции, капитального ремонта обектов капитального строительства не требуется), реквизиты распоряительного документа, подтверждающего полномочия,
A39: ='Данные объект'!C23 -> ПАО "Россети Московский регион" ОГРН 1057746555811 ИНН 5036065113 КПП 772501001,115114, город Москва, проезд Павелецкий 2-й, дом 3, строение 2
A40: с указанием полного и (или) сокращенного наименования, ОГРН, ИНН, адреса юридического лица в пределах его места нахождения (в случае осуществления строительного контроля на основании договора с застройщиком или техническим заказчиком), фамилии, имени, отчества (последнее - при наличии), адреса места жительства, ОГРНИП, ИНН индивиуального предпринимателя (в случае осуществления строительного контроля на основании договора с застройщиком или техническим заказчиком)
A41: Представитель лица, осуществляющего строительство, реконструкцию, капитальный ремонт
A42: ='Данные объект'!C21 -> Прораб ООО"Энергосистемы" Волков М.Ю..Приказ №05-ОТ/24 от 09 января 2024г
A43: (должность (при наличии), фамилия, инициалы, реквизиты распорядительного документа, подтверждающего полномочия)
A44: Представитель лица, осуществляющего строительство, реконструкцию, капитальный ремонт, по вопросам строительного контроля
...

Sheet АОСР-5.1 (8)
AJ1: Приказ Минстроя №344/пр от 16.05.2023
AJ2: приложение №3
A3: Объект капитального строительства
A4: ='Данные объект'!B3 -> Строительство РП-10 кВ, 4КЛ-10 кВ от яч. № 316 3-й с.ш. и № 503 5-й с.ш. ЗРУ-10 кВ до 1-ой и 2-ой с.ш. РУ- 10 кВ сооруж. РП-10кВ, ПС 110/35/10 кВ № 71 "Поварово", в т.ч. ПИР, МО, Солнечногорский р-н, д. Ложки
A5: ='Данные объект'!B9 -> 2БРП №171
A6: (наименование объекта капитального строительства в соответствии с проектной документацией, почтовый или строительный адрес объекта капитального строительства)
A7: Застройщик, технический заказчик, лицо, ответственное за эксплуатацию здания, сооружения, или региональный оператор
A9: ='Данные объект'!B23 -> ПАО "Россети Московский регион"
A10: (фамилия, имя, отчество (последнее - при наличии), адрес места жительства, ОРГНИП, ИНН индивидуального предпринимателя, полное и (или) сокращенное наименование, ОГРН, ИНН, адрес юридического лица в пределах его нахождения, телефон или факс,
A11: ='Данные объект'!B24 -> ОГРН 1057746555811 ИНН 5036065113 КПП 772501001
A12: полное и (или) сокращенное наименование, ОГРН, ИНН саморегулируемой организации, членом которой является указанное юридическое лицо или индивидуальный предприниматель (за исключением случаев, когда членство в саморегулируемых организациях в области, строительства, реконструкции, капитального ремонта объектов капитального строительства не требуется); фамилия, имя, отчество
A13: ='Данные объект'!B25 -> 115114, город Москва, проезд Павелецкий 2-й, дом 3, строение 2
A14: (последнее - при наличии), паспортные данные, адрес места жительства, телефон или факс - для физических лиц, не являющихся индивидуальными предпринимателями)
A15: Лицо, осуществляющее строительство, реконструкцию, капитальный ремонт
A16: ='Данные объект'!B11 -> ООО"Энергосистемы"
A17: (фамилия, имя, отчество (последнее - при наличии), адрес места жительства, ОРГНИП, ИНН индивидуального предпринимателя,
A18: ='Данные объект'!B12 -> ОГРН 1135044003709 ИНН 5044089069 КПП 504401001
A19: полное и (или) сокращенное наименование, ОГРН, ИНН, адрес юридического лица в пределах его местонахождения, телефон или факс,
A20: ='Данные объект'!B13 -> 141508, Московская область, г.о. Солнечногорск, г. Солнечногорск, ул. Промышленная, стр. 5, помещение 179
A21: полное и (или) сокращенное наименование, ОГРН, ИНН саморегулируемой организации, членом которой является указанное юридическое лицо или индивидуальный предприниматель (за исключением случаев, когда членство в саморегулируемых организациях в области строительства, реконструкции, капитального ремонта объектов капитального строительства не требуется)
A22: Лицо, осуществляющее подготовку проектной документации
A23: ='Данные объект'!B36 -> ООО"Энергосистемы"
A24: (фамилия, имя, отчество (последнее - при наличии), адрес места жительства, ОРГНИП, ИНН индивидуального предпринимателя,
A25: ='Данные объект'!B37 -> ОГРН 1135044003709 ИНН 5044089069 КПП 504401001
A26: полное и (или) сокращенное наименование, ОГРН, ИНН, адрес юридического лица в пределах его места нахождения, телефон или факс,
A27: ='Данные объект'!B38 -> 141508, Московская область, г.о. Солнечногорск, г. Солнечногорск, ул. Промышленная, стр. 5, помещение 179
A28: полное и (или) сокращенное наименование, ОГРН, ИНН саморегулируемой организации, членом которой является указанное юридическое лицо или индивидуальный предприниматель (за исключением случаев, когда членство в саморегулируемых организациях в области архитектурно-строительного проектирования не требуется)
A30: АКТ
A31: освидетельствования скрытых работ
B33: № | C33: 6 | E33: /2БРП №171 | AB33: =P81 -> 46219
AB34: (дата составления акта)
A36: Представитель застройщика, технического заказчика, лица, ответственного за эксплуатацию здания, сооружения, или регионального оператора по вопросам строительного контроля
A37: ='Данные объект'!C34 -> Гл. специалист ССК УКС ПАО "Россети Московский регион" Алексанян Г.Р..Приказ №2363 от 29 июля 2025г (НРС С-50-069023)
A38: (должность (при наличии), фамилия, инициалы, идентификационный номер в национальном реестре специалистов в области строительства (за исключением случаев, когда членство в саморегулируемых организациях в области строительства, реконструкции, капитального ремонта обектов капитального строительства не требуется), реквизиты распоряительного документа, подтверждающего полномочия,
A39: ='Данные объект'!C23 -> ПАО "Россети Московский регион" ОГРН 1057746555811 ИНН 5036065113 КПП 772501001,115114, город Москва, проезд Павелецкий 2-й, дом 3, строение 2
A40: с указанием полного и (или) сокращенного наименования, ОГРН, ИНН, адреса юридического лица в пределах его места нахождения (в случае осуществления строительного контроля на основании договора с застройщиком или техническим заказчиком), фамилии, имени, отчества (последнее - при наличии), адреса места жительства, ОГРНИП, ИНН индивиуального предпринимателя (в случае осуществления строительного контроля на основании договора с застройщиком или техническим заказчиком)
A41: Представитель лица, осуществляющего строительство, реконструкцию, капитальный ремонт
A42: ='Данные объект'!C21 -> Прораб ООО"Энергосистемы" Волков М.Ю..Приказ №05-ОТ/24 от 09 января 2024г
A43: (должность (при наличии), фамилия, инициалы, реквизиты распорядительного документа, подтверждающего полномочия)
A44: Представитель лица, осуществляющего строительство, реконструкцию, капитальный ремонт, по вопросам строительного контроля
...

Sheet АОСР-6.1
AJ1: Приказ Минстроя №344/пр от 16.05.2023
AJ2: приложение №3
A3: Объект капитального строительства
A4: ='Данные объект'!B3 -> Строительство РП-10 кВ, 4КЛ-10 кВ от яч. № 316 3-й с.ш. и № 503 5-й с.ш. ЗРУ-10 кВ до 1-ой и 2-ой с.ш. РУ- 10 кВ сооруж. РП-10кВ, ПС 110/35/10 кВ № 71 "Поварово", в т.ч. ПИР, МО, Солнечногорский р-н, д. Ложки
A5: ='Данные объект'!B9 -> 2БРП №171
A6: (наименование объекта капитального строительства в соответствии с проектной документацией, почтовый или строительный адрес объекта капитального строительства)
A7: Застройщик, технический заказчик, лицо, ответственное за эксплуатацию здания, сооружения, или региональный оператор
A9: ='Данные объект'!B23 -> ПАО "Россети Московский регион"
A10: (фамилия, имя, отчество (последнее - при наличии), адрес места жительства, ОРГНИП, ИНН индивидуального предпринимателя, полное и (или) сокращенное наименование, ОГРН, ИНН, адрес юридического лица в пределах его нахождения, телефон или факс,
A11: ='Данные объект'!B24 -> ОГРН 1057746555811 ИНН 5036065113 КПП 772501001
A12: полное и (или) сокращенное наименование, ОГРН, ИНН саморегулируемой организации, членом которой является указанное юридическое лицо или индивидуальный предприниматель (за исключением случаев, когда членство в саморегулируемых организациях в области, строительства, реконструкции, капитального ремонта объектов капитального строительства не требуется); фамилия, имя, отчество
A13: ='Данные объект'!B25 -> 115114, город Москва, проезд Павелецкий 2-й, дом 3, строение 2
A14: (последнее - при наличии), паспортные данные, адрес места жительства, телефон или факс - для физических лиц, не являющихся индивидуальными предпринимателями)
A15: Лицо, осуществляющее строительство, реконструкцию, капитальный ремонт
A16: ='Данные объект'!B11 -> ООО"Энергосистемы"
A17: (фамилия, имя, отчество (последнее - при наличии), адрес места жительства, ОРГНИП, ИНН индивидуального предпринимателя,
A18: ='Данные объект'!B12 -> ОГРН 1135044003709 ИНН 5044089069 КПП 504401001
A19: полное и (или) сокращенное наименование, ОГРН, ИНН, адрес юридического лица в пределах его местонахождения, телефон или факс,
A20: ='Данные объект'!B13 -> 141508, Московская область, г.о. Солнечногорск, г. Солнечногорск, ул. Промышленная, стр. 5, помещение 179
A21: полное и (или) сокращенное наименование, ОГРН, ИНН саморегулируемой организации, членом которой является указанное юридическое лицо или индивидуальный предприниматель (за исключением случаев, когда членство в саморегулируемых организациях в области строительства, реконструкции, капитального ремонта объектов капитального строительства не требуется)
A22: Лицо, осуществляющее подготовку проектной документации
A23: ='Данные объект'!B36 -> ООО"Энергосистемы"
A24: (фамилия, имя, отчество (последнее - при наличии), адрес места жительства, ОРГНИП, ИНН индивидуального предпринимателя,
A25: ='Данные объект'!B37 -> ОГРН 1135044003709 ИНН 5044089069 КПП 504401001
A26: полное и (или) сокращенное наименование, ОГРН, ИНН, адрес юридического лица в пределах его места нахождения, телефон или факс,
A27: ='Данные объект'!B38 -> 141508, Московская область, г.о. Солнечногорск, г. Солнечногорск, ул. Промышленная, стр. 5, помещение 179
A28: полное и (или) сокращенное наименование, ОГРН, ИНН саморегулируемой организации, членом которой является указанное юридическое лицо или индивидуальный предприниматель (за исключением случаев, когда членство в саморегулируемых организациях в области архитектурно-строительного проектирования не требуется)
A30: АКТ
A31: освидетельствования скрытых работ
B33: № | C33: 7 | E33: /2БРП №171 | AB33: =P81 -> 46219
AB34: (дата составления акта)
A36: Представитель застройщика, технического заказчика, лица, ответственного за эксплуатацию здания, сооружения, или регионального оператора по вопросам строительного контроля
A37: ='Данные объект'!C34 -> Гл. специалист ССК УКС ПАО "Россети Московский регион" Алексанян Г.Р..Приказ №2363 от 29 июля 2025г (НРС С-50-069023)
A38: (должность (при наличии), фамилия, инициалы, идентификационный номер в национальном реестре специалистов в области строительства (за исключением случаев, когда членство в саморегулируемых организациях в области строительства, реконструкции, капитального ремонта обектов капитального строительства не требуется), реквизиты распоряительного документа, подтверждающего полномочия,
A39: ='Данные объект'!C23 -> ПАО "Россети Московский регион" ОГРН 1057746555811 ИНН 5036065113 КПП 772501001,115114, город Москва, проезд Павелецкий 2-й, дом 3, строение 2
A40: с указанием полного и (или) сокращенного наименования, ОГРН, ИНН, адреса юридического лица в пределах его места нахождения (в случае осуществления строительного контроля на основании договора с застройщиком или техническим заказчиком), фамилии, имени, отчества (последнее - при наличии), адреса места жительства, ОГРНИП, ИНН индивиуального предпринимателя (в случае осуществления строительного контроля на основании договора с застройщиком или техническим заказчиком)
A41: Представитель лица, осуществляющего строительство, реконструкцию, капитальный ремонт
A42: ='Данные объект'!C21 -> Прораб ООО"Энергосистемы" Волков М.Ю..Приказ №05-ОТ/24 от 09 января 2024г
A43: (должность (при наличии), фамилия, инициалы, реквизиты распорядительного документа, подтверждающего полномочия)
A44: Представитель лица, осуществляющего строительство, реконструкцию, капитальный ремонт, по вопросам строительного контроля
...

Sheet АОСР-5.1 (3)
AJ1: Приказ Минстроя №344/пр от 16.05.2023
AJ2: приложение №3
A3: Объект капитального строительства
A4: ='Данные объект'!B3 -> Строительство РП-10 кВ, 4КЛ-10 кВ от яч. № 316 3-й с.ш. и № 503 5-й с.ш. ЗРУ-10 кВ до 1-ой и 2-ой с.ш. РУ- 10 кВ сооруж. РП-10кВ, ПС 110/35/10 кВ № 71 "Поварово", в т.ч. ПИР, МО, Солнечногорский р-н, д. Ложки
A5: ='Данные объект'!B9 -> 2БРП №171
A6: (наименование объекта капитального строительства в соответствии с проектной документацией, почтовый или строительный адрес объекта капитального строительства)
A7: Застройщик, технический заказчик, лицо, ответственное за эксплуатацию здания, сооружения, или региональный оператор
A9: ='Данные объект'!B23 -> ПАО "Россети Московский регион"
A10: (фамилия, имя, отчество (последнее - при наличии), адрес места жительства, ОРГНИП, ИНН индивидуального предпринимателя, полное и (или) сокращенное наименование, ОГРН, ИНН, адрес юридического лица в пределах его нахождения, телефон или факс,
A11: ='Данные объект'!B24 -> ОГРН 1057746555811 ИНН 5036065113 КПП 772501001
A12: полное и (или) сокращенное наименование, ОГРН, ИНН саморегулируемой организации, членом которой является указанное юридическое лицо или индивидуальный предприниматель (за исключением случаев, когда членство в саморегулируемых организациях в области, строительства, реконструкции, капитального ремонта объектов капитального строительства не требуется); фамилия, имя, отчество
A13: ='Данные объект'!B25 -> 115114, город Москва, проезд Павелецкий 2-й, дом 3, строение 2
A14: (последнее - при наличии), паспортные данные, адрес места жительства, телефон или факс - для физических лиц, не являющихся индивидуальными предпринимателями)
A15: Лицо, осуществляющее строительство, реконструкцию, капитальный ремонт
A16: ='Данные объект'!B11 -> ООО"Энергосистемы"
A17: (фамилия, имя, отчество (последнее - при наличии), адрес места жительства, ОРГНИП, ИНН индивидуального предпринимателя,
A18: ='Данные объект'!B12 -> ОГРН 1135044003709 ИНН 5044089069 КПП 504401001
A19: полное и (или) сокращенное наименование, ОГРН, ИНН, адрес юридического лица в пределах его местонахождения, телефон или факс,
A20: ='Данные объект'!B13 -> 141508, Московская область, г.о. Солнечногорск, г. Солнечногорск, ул. Промышленная, стр. 5, помещение 179
A21: полное и (или) сокращенное наименование, ОГРН, ИНН саморегулируемой организации, членом которой является указанное юридическое лицо или индивидуальный предприниматель (за исключением случаев, когда членство в саморегулируемых организациях в области строительства, реконструкции, капитального ремонта объектов капитального строительства не требуется)
A22: Лицо, осуществляющее подготовку проектной документации
A23: ='Данные объект'!B36 -> ООО"Энергосистемы"
A24: (фамилия, имя, отчество (последнее - при наличии), адрес места жительства, ОРГНИП, ИНН индивидуального предпринимателя,
A25: ='Данные объект'!B37 -> ОГРН 1135044003709 ИНН 5044089069 КПП 504401001
A26: полное и (или) сокращенное наименование, ОГРН, ИНН, адрес юридического лица в пределах его места нахождения, телефон или факс,
A27: ='Данные объект'!B38 -> 141508, Московская область, г.о. Солнечногорск, г. Солнечногорск, ул. Промышленная, стр. 5, помещение 179
A28: полное и (или) сокращенное наименование, ОГРН, ИНН саморегулируемой организации, членом которой является указанное юридическое лицо или индивидуальный предприниматель (за исключением случаев, когда членство в саморегулируемых организациях в области архитектурно-строительного проектирования не требуется)
A30: АКТ
A31: освидетельствования скрытых работ
B33: № | C33: 8 | E33: /2БРП №171 | AB33: =P79 -> 46219
AB34: (дата составления акта)
A36: Представитель застройщика, технического заказчика, лица, ответственного за эксплуатацию здания, сооружения, или регионального оператора по вопросам строительного контроля
A37: ='Данные объект'!C34 -> Гл. специалист ССК УКС ПАО "Россети Московский регион" Алексанян Г.Р..Приказ №2363 от 29 июля 2025г (НРС С-50-069023)
A38: (должность (при наличии), фамилия, инициалы, идентификационный номер в национальном реестре специалистов в области строительства (за исключением случаев, когда членство в саморегулируемых организациях в области строительства, реконструкции, капитального ремонта обектов капитального строительства не требуется), реквизиты распоряительного документа, подтверждающего полномочия,
A39: ='Данные объект'!C23 -> ПАО "Россети Московский регион" ОГРН 1057746555811 ИНН 5036065113 КПП 772501001,115114, город Москва, проезд Павелецкий 2-й, дом 3, строение 2
A40: с указанием полного и (или) сокращенного наименования, ОГРН, ИНН, адреса юридического лица в пределах его места нахождения (в случае осуществления строительного контроля на основании договора с застройщиком или техническим заказчиком), фамилии, имени, отчества (последнее - при наличии), адреса места жительства, ОГРНИП, ИНН индивиуального предпринимателя (в случае осуществления строительного контроля на основании договора с застройщиком или техническим заказчиком)
A41: Представитель лица, осуществляющего строительство, реконструкцию, капитальный ремонт
A42: ='Данные объект'!C21 -> Прораб ООО"Энергосистемы" Волков М.Ю..Приказ №05-ОТ/24 от 09 января 2024г
A43: (должность (при наличии), фамилия, инициалы, реквизиты распорядительного документа, подтверждающего полномочия)
A44: Представитель лица, осуществляющего строительство, реконструкцию, капитальный ремонт, по вопросам строительного контроля
...

Sheet АОСР-5.1 (9)
AJ1: Приказ Минстроя №344/пр от 16.05.2023
AJ2: приложение №3
A3: Объект капитального строительства
A4: ='Данные объект'!B3 -> Строительство РП-10 кВ, 4КЛ-10 кВ от яч. № 316 3-й с.ш. и № 503 5-й с.ш. ЗРУ-10 кВ до 1-ой и 2-ой с.ш. РУ- 10 кВ сооруж. РП-10кВ, ПС 110/35/10 кВ № 71 "Поварово", в т.ч. ПИР, МО, Солнечногорский р-н, д. Ложки
A5: ='Данные объект'!B9 -> 2БРП №171
A6: (наименование объекта капитального строительства в соответствии с проектной документацией, почтовый или строительный адрес объекта капитального строительства)
A7: Застройщик, технический заказчик, лицо, ответственное за эксплуатацию здания, сооружения, или региональный оператор
A9: ='Данные объект'!B23 -> ПАО "Россети Московский регион"
A10: (фамилия, имя, отчество (последнее - при наличии), адрес места жительства, ОРГНИП, ИНН индивидуального предпринимателя, полное и (или) сокращенное наименование, ОГРН, ИНН, адрес юридического лица в пределах его нахождения, телефон или факс,
A11: ='Данные объект'!B24 -> ОГРН 1057746555811 ИНН 5036065113 КПП 772501001
A12: полное и (или) сокращенное наименование, ОГРН, ИНН саморегулируемой организации, членом которой является указанное юридическое лицо или индивидуальный предприниматель (за исключением случаев, когда членство в саморегулируемых организациях в области, строительства, реконструкции, капитального ремонта объектов капитального строительства не требуется); фамилия, имя, отчество
